Workbook

Sheet BPTRA
A1: PERUSAHAAN DAERAH AIR MINUM
A2: KABUPATEN SERUYAN
A4: BUKTI PENERIMAAN TAGIHAN REKENING NON AIR
A5: BULAN : JANUARI 2021
E7: BPTRNA/01/I/2021
A8: NO | B8: NAMA PELANGGAN | C8: NO. PELANGGAN | D8: NO. BUKTI | E8: JUMLAH
A9: 1
A10: 2 | B10: Tidak Ada Transaksi Penerimaan Rek. Air
A11: 3
A12: 4
B14: JUMLAH | E14: =SUM(E9:E13) -> 0
D16: Kuala Pembuang, ... Januari 2021
D17: Kasi. Pembukuan

Sheet BPTRNA
A1: PERUSAHAAN DAERAH AIR MINUM
A2: KABUPATEN SERUYAN
A4: BUKTI PENERIMAAN TAGIHAN REKENING NON AIR
A5: BULAN : JANUARI 2021
E7: BPTRNA/01/I/2021
A8: NO | B8: NAMA PELANGGAN | C8: NO. PELANGGAN | D8: NO. BUKTI | E8: JUMLAH
A9: 1 | B9: Penerimaan SR Baru 3 SR | E9: =875000*3 -> 2625000
A10: =A9+1 -> 2
A11: =A10+1 -> 3
A12: =A11+1 -> 4
A13: =A12+1 -> 5
A14: =A13+1 -> 6
A15: =A14+1 -> 7
B17: JUMLAH | E17: =SUM(E9:E15) -> 2625000
D19: Kuala Pembuang, 06 Januari 2021
A54: PERUSAHAAN DAERAH AIR MINUM
A55: KABUPATEN SERUYAN
A57: BUKTI PENERIMAAN TAGIHAN REKENING NON AIR
A58: BULAN : JANUARI 2021
E60: BPTRNA/02/I/2021
A61: NO | B61: NAMA PELANGGAN | C61: NO. PELANGGAN | D61: NO. BUKTI | E61: JUMLAH
A62: 1 | B62: Penerimaan SR Baru 19 SR | E62: =19*875000 -> 16625000
A63: =A62+1 -> 2
A64: =A63+1 -> 3
A65: =A64+1 -> 4
A66: =A65+1 -> 5
A67: =A66+1 -> 6
A68: =A67+1 -> 7
B70: JUMLAH | E70: =SUM(E62:E68) -> 16625000
D72: Kuala Pembuang, 12 Januari 2021
A107: PERUSAHAAN DAERAH AIR MINUM
A108: KABUPATEN SERUYAN
A110: BUKTI PENERIMAAN TAGIHAN REKENING NON AIR
A111: BULAN : JANUARI 2021
E113: BPTRNA/03/I/2021
A114: NO | B114: NAMA PELANGGAN | C114: NO. PELANGGAN | D114: NO. BUKTI | E114: JUMLAH
A115: 1 | B115: Penerimaan Balik Nama | E115: 100000
A116: =A115+1 -> 2
A117: =A116+1 -> 3
A118: =A117+1 -> 4
...

Sheet BPTDN
A1: PERUSAHAAN DAERAH AIR MINUM
A2: KABUPATEN SERUYAN
A4: BUKTI PENERIMAAN DENDA
A5: BULAN : JANUARI 2018
E7: BPTDN/01/I/2018
A8: NO | B8: NAMA PELANGGAN | C8: NO. PELANGGAN | D8: NO. BUKTI | E8: JUMLAH
A9: 1 | B9: Rafiah | C9: 000408 | E9: 50000
A10: =A9+1 -> 2 | B10: Hj. Nurlaila A | C10: 000802 | E10: 12500
A11: =A10+1 -> 3 | B11: Eko Budi S | C11: 000942 | E11: 5000
A12: =A11+1 -> 4 | B12: Titin Yuli Susanti | C12: 000966 | E12: 42500
A13: =A12+1 -> 5 | B13: Irsyad Munawar, ST | C13: 000969 | E13: 42500
A14: =A13+1 -> 6 | B14: Sudirman | C14: 001430 | E14: 12500
A15: =A14+1 -> 7 | B15: Norhanisah | C15: 001491 | E15: 32500
A16: =A15+1 -> 8 | B16: Heri | C16: 001658 | E16: 17500
A17: =A16+1 -> 9 | B17: Raden Kartono, S. Pd | C17: 001809 | E17: 5000
A18: =A17+1 -> 10 | B18: Suriansyah | C18: 001820 | E18: 5000
A19: =A18+1 -> 11 | B19: H. Muhammad Hanafie | C19: 002055 | E19: 12500
A20: =A19+1 -> 12 | B20: Agus Wakidjo | C20: 002381 | E20: 5000
A21: =A20+1 -> 13 | B21: Wahana | C21: 002452 | E21: 5000
A22: =A21+1 -> 14 | B22: Norhayati | C22: 002542 | E22: 5000
B24: JUMLAH | E24: =SUM(E9:E23) -> 252500
D26: Kuala Pembuang, 02 Januari 2018
D27: Kasi. Pembukuan
A54: PERUSAHAAN DAERAH AIR MINUM
A55: KABUPATEN SERUYAN
A57: BUKTI PENERIMAAN DENDA
A58: BULAN : JANUARI 2018
E60: BPTDN/02/I/2018
A61: NO | B61: NAMA PELANGGAN | C61: NO. PELANGGAN | D61: NO. BUKTI | E61: JUMLAH
A62: 1 | B62: Nur Aiti | C62: 000134 | E62: 12500
A63: =A62+1 -> 2 | B63: Suriyadi | C63: 000203 | E63: 5000
A64: =A63+1 -> 3 | B64: Koesnan AS | C64: 000318 | E64: 5000
A65: =A64+1 -> 4 | B65: Bandu | C65: 000345 | E65: 5000
A66: =A65+1 -> 5 | B66: Roby Kurniawan | C66: 000425 | E66: 22500
A67: =A66+1 -> 6 | B67: Susilawati | C67: 000712 | E67: 42500
A68: =A67+1 -> 7 | B68: H. Ahmad Dehen | C68: 000735 | E68: 22500
A69: =A68+1 -> 8 | B69: Mujibur Rahman | C69: 000745 | E69: 47500
A70: =A69+1 -> 9 | B70: Indra Gunawi | C70: 000872 | E70: 52500
A71: =A70+1 -> 10 | B71: H. Sutriasmono | C71: 000925 | E71: 62500
A72: =A71+1 -> 11 | B72: Muliannor | C72: 000935 | E72: 5000
...

Sheet BKM
A1: PERUSAHAAN DAERAH AIR MINUM
A2: KABUPATEN SERUYAN
A5: BUKTI KAS MASUK
A6: BULAN : JANUARI 2021
I7: No. KM/01/I/2021
A8: NO | B8: URAIAN | C8: NO. BUKTI | D8: PENERIMAAN | I8: JUMLAH
D9: TAGIHAN | E9: TAGIHAN | F9: DENDA | G9: ANGSURAN | H9: DANA
D10: REKENING | E10: REKENING | F10: REKENING | G10: PIUTANG | H10: METER
D11: AIR | E11: NON AIR | F11: AIR | G11: KARYAWAN
A12: 1 | B12: Penerimaan Rek Air & Adm | C12: BPTRA/01/I/2021 | D12: Tidak Ada Transaksi | I12: =SUM(D12:H12) -> 0
I13: =SUM(D13:H13) -> 0
I14: =SUM(D14:H14) -> 0
I15: =SUM(D15:H15) -> 0
B18: JUMLAH | D18: =SUM(D12:D17) -> 0 | E18: =SUM(E12:E17) -> 0 | F18: =SUM(F12:F17) -> 0 | G18: =SUM(G12:G17) -> 0 | H18: =SUM(H12:H17) -> 0 | I18: =SUM(I12:I17) -> 0
G20: Kuala Pembuang, 01 Januari 2021
A34: PERUSAHAAN DAERAH AIR MINUM
A35: KABUPATEN SERUYAN
A38: BUKTI KAS MASUK
A39: BULAN : JANUARI 2021
I40: No. KM/02/I/2021
A41: NO | B41: URAIAN | C41: NO. BUKTI | D41: PENERIMAAN | I41: JUMLAH
D42: TAGIHAN | E42: TAGIHAN | F42: DENDA | G42: ANGSURAN | H42: DANA
D43: REKENING | E43: REKENING | F43: REKENING | G43: PIUTANG | H43: METER
D44: AIR | E44: NON AIR | F44: AIR | G44: KARYAWAN
A45: 1 | B45: Penerimaan Rek Air & Adm | C45: BPTRA/02/I/2021 | D45: 412045 | F45: 10000 | H45: 120000 | I45: =SUM(D45:H45) -> 542045
I46: =SUM(D46:H46) -> 0
I47: =SUM(D47:H47) -> 0
I48: =SUM(D48:H48) -> 0
B51: JUMLAH | D51: =SUM(D45:D50) -> 412045 | E51: =SUM(E45:E50) -> 0 | F51: =SUM(F45:F50) -> 10000 | G51: =SUM(G45:G50) -> 0 | H51: =SUM(H45:H50) -> 120000 | I51: =SUM(I45:I50) -> 542045
G53: Kuala Pembuang, 02 Januari 2021
A67: PERUSAHAAN DAERAH AIR MINUM
A68: KABUPATEN SERUYAN
A71: BUKTI KAS MASUK
A72: BULAN : JANUARI 2021
I73: No. KM/03/I/2021
A74: NO | B74: URAIAN | C74: NO. BUKTI | D74: PENERIMAAN | I74: JUMLAH
D75: TAGIHAN | E75: TAGIHAN | F75: DENDA | G75: ANGSURAN | H75: DANA
D76: REKENING | E76: REKENING | F76: REKENING | G76: PIUTANG | H76: METER
D77: AIR | E77: NON AIR | F77: AIR | G77: KARYAWAN
A78: 1 | B78: Penerimaan Rek Air & Adm | C78: BPTRA/03/I/2021 | D78: 96478 | F78: 10000 | H78: 40000 | I78: =SUM(D78:H78) -> 146478
...

Sheet JRNA2 
A1: PERUSAHAAN DAERAH AIR MINUM
A2: KABUPATEN SERUYAN
A3: Jalan : Soekarno-Hatta No. Telp (0538) 2706777 Fax (0538) 21815
A4: JOURNAL REKENING NON AIR (JRNA)
A5: BULAN : JANUARI 2020
A7: No | B7: Tgl | C7: Uraian | E7: Ref. | F7: Debet | G7: Kredit
B9: 30 Sept | C9: Piutang Non Air
D10: Pendapatan Non Air (Samb. Baru)
D11: Pendapatan Non Air ( Assessories SR)
A21: JUMLAH | F21: =SUM(F8:F19) -> 0 | G21: =SUM(G8:G19) -> 0

Sheet DVUD(1)
A1: PERUSAHAAN DAERAH AIR MINUM
A2: KABUPATEN SERUYAN
A3: DAFTAR VOUCHER UTANG YANG HARUS DIBAYAR
A4: BULAN JANUARI
A6: VOUCHER | C6: URAIAN | D6: DIBAYAR | F6: KREDIT | M6: DEBET
A7: TGL | B7: NO | D7: TGL | E7: CHEK/B. GIRO | F7: UTANG | H7: ASET TETAP | K7: PERSEDIAAN BAHAN KIMIA | N7: BAHAN INSTALASI | Q7: BIAYA OPRS SUMBER | T7: BIAYA OPRS PENGOLAHAN | W7: BIAYA OPRS DISTRIBUSI | Z7: BIAYA UMUM & ADM
F8: USAHA | G8: NON USAHA | H8: SUB. PERK | I8: Nama Perkiraan | J8: JUMLAH | K8: SUB. PERK | L8: Nama Perkiraan | M8: JUMLAH | N8: SUB. PERK | O8: Nama Perkiraan | P8: JUMLAH | Q8: SUB. PERK | R8: Nama Perkiraan | S8: JUMLAH | T8: SUB. PERK | U8: Nama Perkiraan | V8: JUMLAH | W8: SUB. PERK | X8: Nama Perkiraan | Y8: JUMLAH | Z8: B. PEGAWAI UMUM&ADM (96.01.00) | AC8: B. KANTOR (96.02.00) | AF8: B. HUBLANG ( 96.03.00) | AI8: B. PENELITIAN & PENGEMBANGAN (96.04.00) | AL8: B. PEMELIHARAAN (96.06.00) | AO8: BIAYA UMUM LAINNYA (96.07.00 DAN 96.08.00)
F9: 50.01.00 | G9: 50.02.00 | H9: 31.01.00 | K9: 15.01.00 | N9: 41.02.00 | Q9: 91.01.00 | T9: 92.01.00 | W9: 93.01.00 | Z9: SUB. PERK | AA9: Nama Perkiraan | AB9: JUMLAH | AC9: SUB. PERK | AD9: Nama Perkiraan | AE9: JUMLAH | AF9: SUB. PERK | AG9: Nama Perkiraan | AH9: JUMLAH | AI9: SUB. PERK | AJ9: Nama Perkiraan | AK9: JUMLAH | AL9: SUB. PERK | AM9: Nama Perkiraan | AN9: JUMLAH | AO9: SUB. PERK | AP9: Nama Perkiraan | AQ9: JUMLAH
A10: 02 Jan | B10: 001 | C10: Pembelian Pengukur Kadar Garam | D10: 02 Jan | E10: Tunai | F10: =M10+P10+S10+V10+Y10+AB10+AE10+AH10+AK10+AN10+AQ10+J10 -> 150000 | T10: 92.02.90 | U10: B. Pemeliharaan Pengolahan | V10: 150000
B11: 002 | C11: Pembelian Sylinder 3 Zel | D11: 02 Jan | E11: Tunai | F11: =M11+P11+S11+V11+Y11+AB11+AE11+AH11+AK11+AN11+AQ11+J11 -> 130000 | AC11: 96.02.90 | AD11: Rupa2 B. Kantor | AE11: 130000
B12: 003 | C12: Pembelian Tas Lap top | D12: =A12 -> 0 | E12: Tunai | F12: =M12+P12+S12+V12+Y12+AB12+AE12+AH12+AK12+AN12+AQ12+J12 -> 150000 | AC12: 96.02.90 | AD12: Rupa2 B. Kantor | AE12: 150000
A13: 04 Jan | B13: 004 | C13: Pembelian Pasir Cor | D13: =A13 -> 04 Jan | E13: Tunai | F13: =M13+P13+S13+V13+Y13+AB13+AE13+AH13+AK13+AN13+AQ13+J13 -> 110000 | W13: 93.02.90 | X13: B. Pemeliharaan Trandist lainnya | Y13: 110000
A14: 06 jan | B14: 005 | C14: Pembelian Terminal, Stiker Braco, Paku | D14: =A14 -> 06 jan | E14: Tunai | F14: =M14+P14+S14+V14+Y14+AB14+AE14+AH14+AK14+AN14+AQ14+J14 -> 188000 | AC14: 96.02.90 | AD14: Rupa2 B. Kantor | AE14: 188000
B15: 006 | C15: Pemb. Gorden, Tutup Gorden, Tongkat dan Rol Gorden | D15: =A15 -> 0 | E15: Tunai | F15: =M15+P15+S15+V15+Y15+AB15+AE15+AH15+AK15+AN15+AQ15+J15 -> 334000 | AC15: 96.02.90 | AD15: Rupa2 B. Kantor | AE15: 334000
A16: 20 Jan | B16: 007 | C16: Pemb. Raoundap & Primaxone | D16: =A16 -> 20 Jan | E16: Tunai | F16: =M16+P16+S16+V16+Y16+AB16+AE16+AH16+AK16+AN16+AQ16+J16 -> 185000 | AL16: 96.06.50 | AM16: B. Pemeliharaan taman & lapangan | AN16: 185000
A17: 22 Jan | B17: 008 | C17: Pemeliharaan avanza KH 1407PE | D17: =A17 -> 22 Jan | E17: Tunai | F17: =M17+P17+S17+V17+Y17+AB17+AE17+AH17+AK17+AN17+AQ17+J17 -> 636000 | AL17: 96.06.20 | AM17: Pemeliharaan Kendaraan | AN17: 636000
B18: 009 | C18: SPPD ke Sampit An. Ilias dll | D18: 22 Jan | E18: Tunai | F18: =M18+P18+S18+V18+Y18+AB18+AE18+AH18+AK18+AN18+AQ18+J18 -> 12550000 | AO18: 96.08.30 | AP18: B. Perjalanan Dinas | AQ18: 12550000
B19: 010 | C19: Pemy. Listrik Bag. Produksi | D19: 22 Jan | E19: Tunai | F19: =M19+P19+S19+V19+Y19+AB19+AE19+AH19+AK19+AN19+AQ19+J19 -> 28173777 | Q19: 91.01.30 | R19: B. Listrik PLN Sumber Air | S19: 28173777
B20: 011 | C20: Pemb. Lap Top Acer | D20: =A20 -> 0 | E20: Tunai | F20: =M20+P20+S20+V20+Y20+AB20+AE20+AH20+AK20+AN20+AQ20+J20 -> 6800000 | H20: 31.09..20 | I20: Mesin-mesin kantor | J20: 6800000
B21: 012 | C21: Pemb. 2 unit sepeda motor | D21: =A21 -> 0 | E21: Tunai | F21: =M21+P21+S21+V21+Y21+AB21+AE21+AH21+AK21+AN21+AQ21+J21 -> 41820000 | H21: 31.08.00 | I21: Kendaraan/Alat Pengangkutan | J21: 41820000
B22: 013 | C22: Pemb. Aki Mobil Avanza KH 1179PU | D22: =A22 -> 0 | E22: Tunai | F22: =M22+P22+S22+V22+Y22+AB22+AE22+AH22+AK22+AN22+AQ22+J22 -> 810000 | AL22: 96.06.20 | AM22: Pemeliharaan Kendaraan | AN22: 810000
B23: 014 | C23: Pemb. Cat & Kuas Utk Pipa Intake | D23: =A23 -> 0 | E23: Tunai | F23: =M23+P23+S23+V23+Y23+AB23+AE23+AH23+AK23+AN23+AQ23+J23 -> 202000 | Q23: 91.02.90 | R23: Pemelih Inst. Sumber lainnya | S23: 202000
A24: 23 Jan | B24: 015 | C24: Pemb. Paket Internet | D24: =A24 -> 23 Jan | E24: Tunai | F24: =M24+P24+S24+V24+Y24+AB24+AE24+AH24+AK24+AN24+AQ24+J24 -> 1023500 | AC24: 96.02.90 | AD24: Rupa2 B. Kantor | AE24: 1023500
B25: 016 | C25: Pulsa Listrik kantor, Loket dan Gudang | D25: =A25 -> 0 | E25: Tunai | F25: =M25+P25+S25+V25+Y25+AB25+AE25+AH25+AK25+AN25+AQ25+J25 -> 1207500 | AC25: 96.02.70 | AD25: B. Listrik/Penerangan | AE25: 1207500
B26: 017 | C26: Pemby. Rek Telp/HP/Fax | D26: =A26 -> 0 | E26: Tunai | F26: =M26+P26+S26+V26+Y26+AB26+AE26+AH26+AK26+AN26+AQ26+J26 -> 71660 | AC26: 96.02.40 | AD26: B. Telepon | AE26: 71660
B27: 018 | C27: Pemb. Sapu Lidi, soklin lantai,tisu,dll | D27: =A27 -> 0 | E27: Tunai | F27: =M27+P27+S27+V27+Y27+AB27+AE27+AH27+AK27+AN27+AQ27+J27 -> 377000 | AC27: 96.02.90 | AD27: Rupa2 B. Kantor | AE27: 377000
B28: 019 | C28: Pemb. ATK & B. Fotocopy | D28: =A28 -> 0 | E28: Tunai | F28: =M28+P28+S28+V28+Y28+AB28+AE28+AH28+AK28+AN28+AQ28+J28 -> 4230575 | AC28: 96.02.10 | AD28: B. ATK dan Fotocopy | AE28: 4230575
B29: 020 | C29: Pemb. Kertas De Paper (rek) | D29: =A29 -> 0 | E29: Tunai | F29: =M29+P29+S29+V29+Y29+AB29+AE29+AH29+AK29+AN29+AQ29+J29 -> 500000 | AC29: 96.02.20 | AD29: Barang2 Cetakkan | AE29: 500000
A30: 24 Jan | B30: 021 | C30: SPPD A. Rijali,Kardi,Bagus ke Sampit | D30: =A30 -> 24 Jan | E30: Tunai | F30: =M30+P30+S30+V30+Y30+AB30+AE30+AH30+AK30+AN30+AQ30+J30 -> 5850000 | AC30: 96.02.90 | AO30: 96.08.30 | AP30: B. Perjalanan Dinas | AQ30: 5850000
B31: 022 | C31: Pemb. Kabel &terminal | D31: =A31 -> 0 | E31: Tunai | F31: =M31+P31+S31+V31+Y31+AB31+AE31+AH31+AK31+AN31+AQ31+J31 -> 229000 | AD31: Rupa2 B. Kantor | AE31: 229000
A32: 27 Jan | B32: 023 | C32: Pemy. SPPD Ilias dan Jawi ke SBY | D32: =A32 -> 27 Jan | E32: Tunai | F32: =M32+P32+S32+V32+Y32+AB32+AE32+AH32+AK32+AN32+AQ32+J32 -> 12282800 | AO32: 96.08.30 | AP32: B. Perjalanan Dinas | AQ32: 12282800
B33: 024 | C33: Pemby. Iuran DPD PERPAMSI Kal-Teng | D33: =A33 -> 0 | E33: Tunai | F33: =M33+P33+S33+V33+Y33+AB33+AE33+AH33+AK33+AN33+AQ33+J33 -> 1500000 | AO33: 96.08.10 | AP33: B. Iuran Berlangganan | AQ33: 1500000
B34: 025 | C34: Pemby. Iuran DAPENMA PAMSI | D34: =A34 -> 0 | E34: Tunai | F34: =M34+P34+S34+V34+Y34+AB34+AE34+AH34+AK34+AN34+AQ34+J34 -> 9987916 | Z34: 96.01.30 | AA34: Iuran Pensiun | AB34: 9987916
B35: 026 | C35: Iuran BPJS Ketenagakerjaan | D35: =A35 -> 0 | E35: Tunai | F35: =M35+P35+S35+V35+Y35+AB35+AE35+AH35+AK35+AN35+AQ35+J35 -> 4399533 | AO35: 96.08.60 | AP35: B. Asuransi | AQ35: 4399533
B36: 027 | C36: Pemby. Dana Representatif Direktur | D36: =A36 -> 0 | E36: Tunai | F36: =M36+P36+S36+V36+Y36+AB36+AE36+AH36+AK36+AN36+AQ36+J36 -> 8000000 | AO36: 96.08.80 | AP36: Rupa2 B. Umum Lainnya | AQ36: 8000000
B37: 028 | C37: Pemby. Biaya Konsumsi Pegawai | D37: =A37 -> 0 | E37: Tunai | F37: =M37+P37+S37+V37+Y37+AB37+AE37+AH37+AK37+AN37+AQ37+J37 -> 14855000 | AO37: 96.08.80 | AP37: Rupa2 B. Umum Lainnya | AQ37: 14855000
B38: 029 | C38: Pemb. Kasur,bantal, dll | D38: =A38 -> 0 | E38: Tunai | F38: =M38+P38+S38+V38+Y38+AB38+AE38+AH38+AK38+AN38+AQ38+J38 -> 195000 | AO38: 96.08.81 | AP38: Rupa2 B. Umum Lainnya | AQ38: 195000
B39: 030 | C39: Honorarium Dewas & Sekretariat Dewas | D39: =A39 -> 0 | E39: Tunai | F39: =M39+P39+S39+V39+Y39+AB39+AE39+AH39+AK39+AN39+AQ39+J39 -> 9970080 | AO39: 96.08.20 | AP39: B. Badan Pengawas | AQ39: 9970080
B40: 031 | C40: Gaji Pegawai Bag. Umum | D40: =A40 -> 0 | E40: Tunai | F40: =M40+P40+S40+V40+Y40+AB40+AE40+AH40+AK40+AN40+AQ40+J40 -> 82346378 | Z40: 96.01.10 | AA40: B. Pegawai Bagian Umum | AB40: 82346378
B41: 032 | C41: Gaji Bagian Transist | D41: =A41 -> 0 | E41: Tunai | F41: =M41+P41+S41+V41+Y41+AB41+AE41+AH41+AK41+AN41+AQ41+J41 -> 17840702 | W41: 93.01.10 | X41: B. Pegawai Operasi Trandist | Y41: 17840702
...

Sheet DVUD
A1: PERUSAHAAN DAERAH AIR MINUM
A2: KABUPATEN SERUYAN
A3: DAFTAR VOUCHER UTANG YANG HARUS DIBAYAR
A4: BULAN JANUARI
A6: VOUCHER | C6: URAIAN | D6: DIBAYAR | F6: DEBET | I6: KREDIT
A7: TGL | B7: NO | D7: TGL | E7: CHEK/B. GIRO | F7: NO. PERK | G7: NAMA PERKIRAAN | H7: JUMLAH (Rp) | I7: NO. PERK | J7: NAMA PERKIRAAN | K7: JUMLAH (Rp)
A9: 02 Jan | B9: 01 | C9: Pembayaran Biaya Perpanjangan STNK Mobil Pick Up KH 1234 PU | D9: =A9 -> 02 Jan | E9: Tunai | F9: 97.06.20 | G9: Pemeliharaan Kendaraan | H9: 200000 | I9: 50.01.00 | J9: Utang Usaha | K9: =H9 -> 200000 | L9: Example
A10: 21 Jan | B10: 02 | C10: Pembayaran Belanja Bahan Habis Pakai Tawas dll | D10: =A10 -> 21 Jan | E10: Tunai | F10: 15.01.00 | G10: Persediaan Bahan Operasi Kimia | H10: 125000 | I10: 50.01.01 | J10: Utang Usaha | K10: =H10 -> 125000
B11: 03 | D11: =A11 -> 0 | K11: =H11 -> 0
B12: 04 | D12: =A12 -> 0 | K12: =H12 -> 0
B13: 05 | D13: =A13 -> 0 | K13: =H13 -> 0
B14: 06 | D14: =A14 -> 0 | K14: =H14 -> 0
B15: 07 | D15: =A15 -> 0 | K15: =H15 -> 0
D16: =A16 -> 0 | K16: =H16 -> 0
D17: =A17 -> 0 | K17: =H17 -> 0
B18: 08 | D18: =A18 -> 0 | K18: =H18 -> 0
B19: 09 | D19: =A19 -> 0 | K19: =H19 -> 0
B20: 10 | D20: =A20 -> 0 | K20: =H20 -> 0
B21: 11 | D21: =A21 -> 0 | K21: =H21 -> 0
B22: 12 | D22: =A22 -> 0 | K22: =H22 -> 0
B23: 13 | D23: =A23 -> 0 | K23: =H23 -> 0
B24: 14 | D24: =A24 -> 0 | K24: =H24 -> 0
B25: 15 | D25: =A25 -> 0 | K25: =H25 -> 0
B26: 16 | D26: =A26 -> 0 | K26: =H26 -> 0
B27: 17 | D27: =A27 -> 0 | K27: =H27 -> 0
B28: 18 | D28: =A28 -> 0 | K28: =H28 -> 0
B29: 19 | D29: =A29 -> 0 | K29: =H29 -> 0
B30: 20 | D30: =A30 -> 0 | K30: =H30 -> 0
B31: 21 | K31: =H31 -> 0
B32: 22 | D32: =A32 -> 0 | K32: =H32 -> 0
B33: 23 | D33: =A33 -> 0 | K33: =H33 -> 0
B34: 24 | D34: =A34 -> 0 | K34: =H34 -> 0
B35: 25 | D35: =A35 -> 0 | K35: =H35 -> 0
B36: 26 | D36: =A36 -> 0 | K36: =H36 -> 0
B37: 27 | D37: =A37 -> 0 | K37: =H37 -> 0
B38: 28 | D38: =A38 -> 0 | K38: =H38 -> 0
B39: 29 | D39: =A39 -> 0 | K39: =H39 -> 0
B40: 30 | D40: =A40 -> 0 | K40: =H40 -> 0
B41: 31 | D41: =A41 -> 0 | K41: =H41 -> 0
B42: 32 | D42: =A42 -> 0 | K42: =H42 -> 0
...

Sheet J. Pemblk
A1: PERUSAHAAN DAERAH AIR MINUM
A2: KABUPATEN SERUYAN
A3: Jalan : Soekarno-Hatta No. Telp (0538) 2706777 Fax (0538) 21815
A5: JOURNAL PEMBALIK
A6: BULAN : JANUARI 2019
A8: No | B8: Tgl | C8: Uraian | E8: Ref. | F8: Debet | G8: Kredit
A10: 1 | B10: 1 Jan | C10: Beban Operasi Pengolahan Air (Tawas) | E10: JP '18 | F10: 107317500
C11: Beban Operasi Pengolahan Air (Kaporit) | E11: =E10 -> JP '18 | F11: 7112000
C12: Beban Operasi Pengolahan Air (Soda Ash) | E12: =E11 -> JP '18 | F12: 44280000
D13: Persediaan Bahan Kimia | E13: =E12 -> JP '18 | G13: =SUM(F10:F12) -> 158709500
B15: 1 Jan | C15: Beban ATK & Barang Cetakkan | E15: =E13 -> JP '18 | F15: 681000
D16: Persediaan ATK | E16: =E15 -> JP '18 | G16: =F15 -> 681000
A18: JUMLAH | F18: =SUM(F10:F17) -> 159390500 | G18: =SUM(G10:G17) -> 159390500
A50: PERUSAHAAN DAERAH AIR MINUM
A51: KABUPATEN SERUYAN
A52: Jalan : Soekarno-Hatta No. Telp (0538) 2706777 Fax (0538) 21815
A54: JOURNAL PEMBALIK
A55: BULAN : FEBRUARI 2019
A57: No | B57: Tgl | C57: Uraian | E57: Ref. | F57: Debet | G57: Kredit
A59: 1 | B59: 1 Feb | C59: Beban Operasi Pengolahan Air (Tawas) | E59: JP 'Jan | F59: =#REF! -> #REF!
C60: Beban Operasi Pengolahan Air (Kaporit) | E60: JP 'Jan | F60: =#REF! -> #REF!
C61: Beban Operasi Pengolahan Air (Soda Ash) | E61: JP 'Jan | F61: =#REF! -> #REF!
D62: Persediaan Bahan Kimia | E62: JP 'Jan | G62: =#REF! -> #REF!
A66: JUMLAH | F66: =SUM(F59:F65) -> #REF! | G66: =SUM(G59:G65) -> #REF!
A100: PERUSAHAAN DAERAH AIR MINUM
A101: KABUPATEN SERUYAN
A102: Jalan : Soekarno-Hatta No. Telp (0538) 2706777 Fax (0538) 21815
A104: JOURNAL PEMBALIK
A105: BULAN : MARET 2019
A107: No | B107: Tgl | C107: Uraian | E107: Ref. | F107: Debet | G107: Kredit
A109: 1 | B109: 1 Maret | C109: Beban Operasi Pengolahan Air (Tawas) | E109: JP 'FEB | F109: =#REF! -> #REF!
C110: Beban Operasi Pengolahan Air (Kaporit) | E110: JP 'FEB | F110: =#REF! -> #REF!
C111: Beban Operasi Pengolahan Air (Soda Ash) | E111: JP 'FEB | F111: =#REF! -> #REF!
D112: Persediaan Bahan Kimia | E112: JP 'FEB | G112: =#REF! -> #REF!
A117: JUMLAH | F117: =SUM(F109:F116) -> #REF! | G117: =SUM(G109:G116) -> #REF!
A150: PERUSAHAAN DAERAH AIR MINUM
A151: KABUPATEN SERUYAN
A152: Jalan : Soekarno-Hatta No. Telp (0538) 2706777 Fax (0538) 21815
A154: JOURNAL PEMBALIK
A155: BULAN : APRIL 2019
...

Sheet DUVHD
A1: PERUSAHAAN DAERAH AIR MINUM
A3: DAFTAR UTANG VOUCER YANG HARUS DIBAYAR (DUVHD)
A4: BULAN JANUARI 2012
A6: VOUCER | C6: URAIAN | D6: DIBAYAR | F6: PERKIRAAN DI KREDIT | H6: PERKIRAAN DI DEBET
A7: TGL | B7: NO | D7: TGL | E7: CEK/GIRO NO. | F7: UTANG | H7: PERSEDIAN | I7: BAHAN | J7: UANG MUKA | K7: BOP | L7: BOP | M7: BOP | N7: BIAYA UMUM & ADM | P7: RUPA-RUPA
F8: USAHA | G8: NON USAHA | H8: BHN. KIMIA | I8: INSTALASI | J8: KERJA | K8: SUMBER | L8: PENGOLAHAN | M8: DISTRIBUSI | N8: B. KANTOR | O8: B. HUB.PEL | P8: KD. PERKIRAAN | Q8: JUMLAH
F9: (50.01.00) | G9: (50.02.00) | H9: (15.00.01) | I9: (41.02.00) | J9: (16.02.00) | K9: (91.01.00) | L9: (92.01.00) | M9: (93.01.00) | N9: (96.02.00) | O9: (96.03.00)

Sheet J.Koreksi
A1: PERUSAHAAN DAERAH AIR MINUM
A2: KABUPATEN SERUYAN
A3: Jalan : Soekarno-Hatta No. Telp (0538) 2706777 Fax (0538) 21815
A4: JOURNAL KOREKSI
A5: BULAN : JANUARI 2020
A7: No | B7: Tgl | C7: Uraian | E7: Ref. | F7: Debet | G7: Kredit
B9: 81.01.10 | C9: Pendapatan Air-Harga Air
B10: 13.01.11 | D10: Piutang Rek Air - Tempat Ibadah (TI)
A21: JUMLAH | F21: =SUM(F8:F19) -> 0 | G21: =SUM(G8:G19) -> 0

Sheet BKU

Sheet BKU PM
