Workbook

Sheet Tawas
A1: LAPORAN PERSEDIAAN BAHAN KIMIA
A2: PDAM KAB SERUYAN TAHUN 2022
A3: TAWAS
A4: BULAN | B4: SALDO AWAL | E4: PENAMBAHAN | H4: PEMAKAIAN | J4: SALDO AKHIR
B5: Volume | C5: Hrg/Kg (Rp) | D5: Jumlah (Rp) | E5: Volume | F5: Hrg/Kg (Rp) | G5: Jumlah | H5: Volume | I5: Jumlah (Rp) | J5: Volume | K5: Jumlahm (Rp)
A7: Januari | B7: 2 | C7: 6100 | D7: =B7*C7 -> 12200 | I7: =H7*C7 -> 0 | J7: =B7+E7-H7 -> 2 | K7: =D7+G7-I7 -> 12200
G8: =E8*F8 -> 0 | J8: =B8+E8-H8 -> 0 | K8: =D8+G8-I8 -> 0 | L8: example
J9: =SUM(J7:J8) -> 2 | K9: =SUM(K7:K8) -> 12200
A11: Februari | I11: =H11*C11 -> 0 | J11: =B11+E11-H11 -> 0 | K11: =D11+G11-I11 -> 0
J12: =B12+E12-H12 -> 0 | K12: =D12+G12-I12 -> 0
B13: =SUM(B11:B12) -> 0 | J13: =SUM(J11:J12) -> 0 | K13: =SUM(K11:K12) -> 0
A15: Maret | I15: =H15*C15 -> 0 | J15: =B15+E15-H15 -> 0 | K15: =D15+G15-I15 -> 0
B16: =J12 -> 0 | J16: =B16+E16-H16 -> 0 | K16: =D16+G16-I16 -> 0
B17: =SUM(B15:B16) -> 0 | J17: =SUM(J15:J16) -> 0 | K17: =SUM(K15:K16) -> 0
A19: April | I19: =H19*C19 -> 0 | J19: =B19+E19-H19 -> 0 | K19: =D19+G19-I19 -> 0
B20: =J16 -> 0 | J20: =B20+E20-H20 -> 0 | K20: =D20+G20-I20 -> 0
B21: =SUM(B19:B20) -> 0 | J21: =SUM(J19:J20) -> 0 | K21: =SUM(K19:K20) -> 0
A23: Mei | I23: =H23*C23 -> 0 | J23: =B23+E23-H23 -> 0 | K23: =D23+G23-I23 -> 0
B24: =J20 -> 0 | I24: =C24*H24 -> 0 | J24: =B24+E24-H24 -> 0 | K24: =D24+G24-I24 -> 0 | L24: =J24*C24 -> 0
B25: =SUM(B23:B24) -> 0 | H25: =SUM(H23:H24) -> 0 | I25: =SUM(I23:I24) -> 0 | J25: =SUM(J23:J24) -> 0 | K25: =SUM(K23:K24) -> 0
A27: JUNI | D27: =K24 -> 0 | I27: =C27*H27 -> 0 | J27: =B27+E27-H27 -> 0 | K27: =D27+G27-I27 -> 0 | L27: =J27*C27 -> 0
L28: ='TAWAS BENAR'!Q25+'TAWAS BENAR'!J16+'TAWAS BENAR'!J21+'TAWAS BENAR'!#REF!+'TAWAS BENAR'!M8 -> #REF!
A29: JULI | D29: =K27 -> 0 | I29: =C29*H29 -> 0 | J29: =B29+E29-H29 -> 0 | K29: =D29+G29-I29 -> 0
A31: AGUSTUS | D31: =K29 -> 0 | G31: =E31*F31 -> 0 | I31: =C31*H31 -> 0 | J31: =B31+E31-H31 -> 0 | K31: =D31+G31-I31 -> 0
A33: SEPTEMBER | D33: =K31 -> 0 | I33: =C33*H33 -> 0 | J33: =B33+E33-H33 -> 0 | K33: =D33+G33-I33 -> 0
A35: OKTOBER | D35: =K33 -> 0 | I35: =C35*H35 -> 0 | J35: =B35+E35-H35 -> 0 | K35: =D35+G35-I35 -> 0
A37: NOVEMBER | D37: =K35 -> 0 | I37: =C37*H37 -> 0 | J37: =B37+E37-H37 -> 0 | K37: =D37+G37-I37 -> 0 | L37: =J37*C37 -> 0
A39: DESEMBER | D39: =K37 -> 0 | I39: =C39*H39 -> 0 | J39: =B39+E39-H39 -> 0 | K39: =D39+G39-I39 -> 0
A41: JUMLAH PEMBELIAN & PEMAKAIAN TAWAS | E41: =SUM(E13:E40) -> 0 | G41: =SUM(G13:G40) -> 0 | H41: =H7+H11+H12+H15+H16+H17+H18+H19+H20+H21+H27+H28 -> 0 | I41: =I7+I11+I12+I15+I16+I17+I18+I19+I20+I21+I27+I28 -> 0 | J41: =J28 -> 0 | K41: =K28 -> 0

Sheet Kaporit
A1: LAPORAN PERSEDIAAN BAHAN KIMIA
A2: PDAM KAB SERUYAN TAHUN 2022
A3: KAPORIT
A5: BULAN | B5: SALDO AWAL | E5: PENAMBAHAN | H5: PEMAKAIAN | J5: SALDO AKHIR
B6: Volume | C6: Hrg/Kg | D6: Jumlah (Rp) | E6: Volume | F6: Hrg/Kg | G6: Jumlah | H6: Volume | I6: Jumlah (Rp) | J6: Volume | K6: Jumlah (Rp)
A8: Januari | D8: =B8*C8 -> 0 | I8: =H8*C8 -> 0 | J8: =B8+E8-H8 -> 0 | K8: =D8+G8-I8 -> 0
G9: =E9*F9 -> 0 | J9: =B9+E9-H9 -> 0 | K9: =D9+G9-I9 -> 0
J10: =SUM(J8:J9) -> 0 | K10: =SUM(K8:K9) -> 0
A12: Februari | D12: =K8 -> 0 | I12: =H12*C12 -> 0 | J12: =B12+E12-H12 -> 0 | K12: =D12+G12-I12 -> 0
D13: =K9 -> 0 | J13: =B13+E13-H13 -> 0 | K13: =D13+G13-I13 -> 0
B14: =SUM(B12:B13) -> 0 | D14: =SUM(D12:D13) -> 0 | J14: =SUM(J12:J13) -> 0 | K14: =SUM(K12:K13) -> 0
A16: Maret | D16: =K12 -> 0 | I16: =H16*C16 -> 0 | J16: =B16+E16-H16 -> 0 | K16: =D16+G16-I16 -> 0
B17: =J13 -> 0 | D17: =K13 -> 0 | J17: =B17+E17-H17 -> 0 | K17: =D17+G17-I17 -> 0
B18: =SUM(B16:B17) -> 0 | D18: =SUM(D16:D17) -> 0 | J18: =SUM(J16:J17) -> 0 | K18: =SUM(K16:K17) -> 0
A20: April | D20: =K16 -> 0 | I20: =H20*C20 -> 0 | J20: =B20+E20-H20 -> 0 | K20: =D20+G20-I20 -> 0
B21: =J17 -> 0 | D21: =K17 -> 0 | J21: =B21+E21-H21 -> 0 | K21: =D21+G21-I21 -> 0
B22: =SUM(B20:B21) -> 0 | D22: =SUM(D20:D21) -> 0 | J22: =SUM(J20:J21) -> 0 | K22: =SUM(K20:K21) -> 0
A24: MEI | D24: =K20 -> 0 | I24: =H24*C24 -> 0 | J24: =B24+E24-H24 -> 0 | K24: =D24+G24-I24 -> 0
B25: =J21 -> 0 | D25: =K21 -> 0 | I25: =H25*C25 -> 0 | J25: =B25+E25-H25 -> 0 | K25: =D25+G25-I25 -> 0
B26: =SUM(B24:B25) -> 0 | D26: =SUM(D24:D25) -> 0 | H26: =SUM(H24:H25) -> 0 | I26: =SUM(I24:I25) -> 0 | J26: =SUM(J24:J25) -> 0 | K26: =SUM(K24:K25) -> 0 | M26: =J25*C25 -> 0
A28: JUNI | D28: =K25 -> 0 | I28: =H28*C28 -> 0 | J28: =B28+E28-H28 -> 0 | K28: =D28+G28-I28 -> 0 | M28: =C28*J28 -> 0
A30: JULI | D30: =K28 -> 0 | I30: =H30*C30 -> 0 | J30: =B30+E30-H30 -> 0 | K30: =D30+G30-I30 -> 0
A32: AGUSTUS | D32: =K30 -> 0 | I32: =H32*C32 -> 0 | J32: =B32+E32-H32 -> 0 | K32: =D32+G32-I32 -> 0
A34: SEPTEMBER | D34: =K32 -> 0 | I34: =H34*C34 -> 0 | J34: =B34+E34-H34 -> 0 | K34: =D34+G34-I34 -> 0
A36: OKTOBER | D36: =K34 -> 0 | I36: =H36*C36 -> 0 | J36: =B36+E36-H36 -> 0 | K36: =D36+G36-I36 -> 0
A38: NOVEMBER | D38: =K36 -> 0 | I38: =H38*C38 -> 0 | J38: =B38+E38-H38 -> 0 | K38: =D38+G38-I38 -> 0 | M38: =J38*C38 -> 0
A39: DESEMBER | D39: =K38 -> 0 | I39: =H39*C39 -> 0 | J39: =B39+E39-H39 -> 0 | K39: =D39+G39-I39 -> 0
A42: JUMLAH PEMAKAIAN & PEMBELIAN KAPORIT | E42: =SUM(E8:E41) -> 0 | G42: =SUM(G8:G41) -> 0 | H42: =SUM(H8:H41) -> 0 | I42: =I8+I16+I17+I18+I19+I20+I21+I22+I23+I24+I32+I40 -> 0 | J42: =J40 -> 0 | K42: =K40 -> 0

Sheet Soda Ash
A1: LAPORAN PERSEDIAAN BAHAN KIMIA
A2: PDAM KAB SERUYAN TAHUN 2022
A4: Soda Ash
A6: BULAN | B6: SALDO AWAL | E6: PENAMBAHAN | H6: PEMAKAIAN | J6: SALDO AKHIR
B7: Volume | C7: Hrg/Kg | D7: Jumlah (Rp) | E7: Volume | F7: Hrg/Kg | G7: Jumlah (Rp) | H7: Volume | I7: Jumlah (Rp) | J7: Volume | K7: Jumlah (Rp)
A9: Januari | D9: =B9*C9 -> 0 | I9: =H9*C9 -> 0 | J9: =B9+E9-H9 -> 0 | K9: =D9+G9-I9 -> 0
D10: =B10*C10 -> 0 | G10: =E10*F10 -> 0 | J10: =B10+E10-H10 -> 0 | K10: =D10+G10-I10 -> 0
B11: =SUM(B9:B10) -> 0 | D11: =SUM(D9:D10) -> 0 | J11: =SUM(J9:J10) -> 0 | K11: =SUM(K9:K10) -> 0
A13: Februari | D13: =K9 -> 0 | I13: =H13*C13 -> 0 | J13: =B13+E13-H13 -> 0 | K13: =D13+G13-I13 -> 0
D14: =K10 -> 0 | J14: =B14+E14-H14 -> 0 | K14: =D14+G14-I14 -> 0
B15: =SUM(B13:B14) -> 0 | D15: =SUM(D13:D14) -> 0 | J15: =SUM(J13:J14) -> 0 | K15: =SUM(K13:K14) -> 0
A17: Maret | D17: =K13 -> 0 | I17: =H17*C17 -> 0 | J17: =B17+E17-H17 -> 0 | K17: =D17+G17-I17 -> 0
B18: =J14 -> 0 | D18: =K14 -> 0 | J18: =B18+E18-H18 -> 0 | K18: =D18+G18-I18 -> 0
B19: =SUM(B17:B18) -> 0 | D19: =SUM(D17:D18) -> 0 | J19: =SUM(J17:J18) -> 0 | K19: =SUM(K17:K18) -> 0
A21: April | D21: =K17 -> 0 | I21: =H21*C21 -> 0 | J21: =B21+E21-H21 -> 0 | K21: =D21+G21-I21 -> 0
B22: =J18 -> 0 | D22: =K18 -> 0 | J22: =B22+E22-H22 -> 0 | K22: =D22+G22-I22 -> 0
B23: =SUM(B21:B22) -> 0 | D23: =SUM(D21:D22) -> 0 | J23: =SUM(J21:J22) -> 0 | K23: =SUM(K21:K22) -> 0
A25: MEI | D25: =K21 -> 0 | I25: =H25*C25 -> 0 | J25: =B25+E25-H25 -> 0 | K25: =D25+G25-I25 -> 0 | L25: =J25*C25 -> 0
B26: =J22 -> 0 | D26: =K22 -> 0 | J26: =B26+E26-H26 -> 0 | K26: =D26+G26-I26 -> 0 | L26: =J26*C26 -> 0
B27: =SUM(B25:B26) -> 0 | D27: =SUM(D25:D26) -> 0 | J27: =SUM(J25:J26) -> 0 | K27: =SUM(K25:K26) -> 0
A29: JUNI | D29: =K25 -> 0 | I29: =H29*C29 -> 0 | J29: =B29+E29-H29 -> 0 | K29: =D29+G29-I29 -> 0 | L29: =J29*C29 -> 0
B30: =J26 -> 0 | D30: =K26 -> 0 | J30: =B30+E30-H30 -> 0 | K30: =D30+G30-I30 -> 0 | L30: =J30*C30 -> 0
B31: =SUM(B29:B30) -> 0 | D31: =SUM(D29:D30) -> 0 | J31: =SUM(J29:J30) -> 0 | K31: =SUM(K29:K30) -> 0 | L31: ='SODA ASH BENAR'!#REF!+'SODA ASH BENAR'!J22 -> #REF!
A33: JULI | D33: =K29 -> 0 | I33: =H33*C33 -> 0 | J33: =B33+E33-H33 -> 0 | K33: =D33+G33-I33 -> 0
B34: =J30 -> 0 | D34: =K30 -> 0 | J34: =B34+E34-H34 -> 0 | K34: =D34+G34-I34 -> 0
B35: =SUM(B33:B34) -> 0 | D35: =SUM(D33:D34) -> 0 | J35: =SUM(J33:J34) -> 0 | K35: =SUM(K33:K34) -> 0
A37: AGUSTUS | D37: =K33 -> 0 | I37: =H37*C37 -> 0 | J37: =B37+E37-H37 -> 0 | K37: =D37+G37-I37 -> 0 | L37: =J37*C37 -> 0
B38: =J34 -> 0 | D38: =K34 -> 0 | J38: =B38+E38-H38 -> 0 | K38: =D38+G38-I38 -> 0 | L38: =J38*C38 -> 0
B39: =SUM(B37:B38) -> 0 | D39: =SUM(D37:D38) -> 0 | J39: =SUM(J37:J38) -> 0 | K39: =SUM(K37:K38) -> 0
A41: SEPTEMBER | D41: =K37 -> 0 | I41: =H41*C41 -> 0 | J41: =B41+E41-H41 -> 0 | K41: =D41+G41-I41 -> 0
B42: =J38 -> 0 | D42: =K38 -> 0 | J42: =B42+E42-H42 -> 0 | K42: =D42+G42-I42 -> 0
B43: =SUM(B41:B42) -> 0 | D43: =SUM(D41:D42) -> 0 | J43: =SUM(J41:J42) -> 0 | K43: =SUM(K41:K42) -> 0
A45: OKTOBER | D45: =K41 -> 0 | I45: =H45*C45 -> 0 | J45: =B45+E45-H45 -> 0 | K45: =D45+G45-I45 -> 0
B46: =J42 -> 0 | D46: =K42 -> 0 | J46: =B46+E46-H46 -> 0 | K46: =D46+G46-I46 -> 0
B47: =SUM(B45:B46) -> 0 | D47: =SUM(D45:D46) -> 0 | J47: =SUM(J45:J46) -> 0 | K47: =SUM(K45:K46) -> 0
A49: NOVEMBER | D49: =K45 -> 0 | I49: =H49*C49 -> 0 | J49: =B49+E49-H49 -> 0 | K49: =D49+G49-I49 -> 0 | L49: =J49*C49 -> 0
B50: =J46 -> 0 | D50: =K46 -> 0 | J50: =B50+E50-H50 -> 0 | K50: =D50+G50-I50 -> 0 | L50: =J50*C50 -> 0
B51: =SUM(B49:B50) -> 0 | D51: =SUM(D49:D50) -> 0 | J51: =SUM(J49:J50) -> 0 | K51: =SUM(K49:K50) -> 0
A53: DESEMBER | D53: =K49 -> 0 | I53: =H53*C53 -> 0 | J53: =B53+E53-H53 -> 0 | K53: =D53+G53-I53 -> 0
B54: =J50 -> 0 | D54: =K50 -> 0 | J54: =B54+E54-H54 -> 0 | K54: =D54+G54-I54 -> 0
...

Sheet BBM Solar
A1: LAPORAN PERSEDIAAN BAHAN KIMIA
A2: PERUMDAM TIRTA SERUYAN TAHUN 2024
A4: DEXLITE
A6: BULAN | B6: SALDO AWAL | E6: PENAMBAHAN | H6: PEMAKAIAN | J6: SALDO AKHIR
B7: Volume | C7: Hrg/Kg | D7: Jumlah | E7: Volume | F7: Hrg/Kg | G7: Jumlah | H7: Volume | I7: Jumlah | J7: Volume | K7: Hrg/Kg | L7: Jumlah
A9: Januari
A11: Feb
A13: Maret
A15: April
A17: MEI
A22: JUNI
A25: JULI
A27: AGUSTUS
A34: SEPTEMBER
A36: OKTOBER
A38: NOVEMBER
A40: DESEMBER
A42: JUMLAH | E42: =SUM(E9:E41) -> 0 | G42: =SUM(G9:G41) -> 0 | H42: =#REF!+H11 -> #REF! | I42: =#REF!+I11 -> #REF! | J42: =#REF! -> #REF! | K42: =K39 -> 0 | L42: =#REF! -> #REF!

Sheet Tawas Hanau
A1: LAPORAN PERSEDIAAN BAHAN KIMIA
A2: PERUMDAM TIRTA SERUYAN TAHUN 2026
A3: TAWAS
A4: BULAN | B4: SALDO AWAL | E4: PENAMBAHAN | H4: PEMAKAIAN | J4: SALDO AKHIR
B5: Volume | C5: Hrg/Kg (Rp) | D5: Jumlah (Rp) | E5: Volume | F5: Hrg/Kg (Rp) | G5: Jumlah | H5: Volume | I5: Jumlah (Rp) | J5: Volume | K5: Jumlahm (Rp)
A7: Januari | D7: =B7*C7 -> 0 | G7: =E7*F7 -> 0 | I7: =H7*C7 -> 0 | J7: =B7+E7-H7 -> 0 | K7: =D7+G7-I7 -> 0
G8: =E8*F8 -> 0
A9: Februari | D9: =B9*C9 -> 0 | G9: =E9*F9 -> 0 | H9: =B9 -> 0 | I9: =H9*C9 -> 0 | J9: =B9+E9-H9 -> 0 | K9: =J9*C9 -> 0
G10: =E10*F10 -> 0 | I10: =H10*F10 -> 0 | J10: =B10+E10-H10 -> 0 | K10: =J10*F10 -> 0
I11: =SUM(I9:I10) -> 0 | J11: =SUM(J9:J10) -> 0 | K11: =SUM(K9:K10) -> 0
A14: Maret | D14: =C14*B14 -> 0 | F14: =C14 -> 0 | G14: =E14*F14 -> 0 | I14: =H14*C14 -> 0 | J14: =B14+E14-H14 -> 0 | K14: =J14*C14 -> 0
J15: =E15-H15 -> 0 | K15: =J15*F15 -> 0
J16: =J15 -> 0 | K16: =J16*F15 -> 0
D18: =B18*C18 -> 0 | I18: =H18*C18 -> 0 | J18: =B18+E18-H18 -> 0 | K18: =J18*C18 -> 0
A19: April | D19: =B19*C19 -> 0 | I19: =H19*C19 -> 0 | J19: =B19+E19-H19 -> 0 | K19: =J19*C19 -> 0
A21: MEI | D21: =B21*C21 -> 0 | G21: =E21*F21 -> 0 | I21: =H21*C21 -> 0 | J21: =B21+E21-H21 -> 0 | K21: =J21*C21 -> 0
G22: =E22*F22 -> 0
A23: JUNI | D23: =B23*C23 -> 0 | G23: =E23*F23 -> 0 | I23: =H23*C23 -> 0 | J23: =B23+E23-H23 -> 0 | K23: =J23*C23 -> 0
G24: =E24*F24 -> 0 | J24: =B24+E24-H24 -> 0 | K24: =J24*F24 -> 0
A25: JULI | D25: =B25*C25 -> 0 | G25: =E25*F25 -> 0 | I25: =H25*C25 -> 0 | J25: =B25+E25-H25 -> 0 | K25: =J25*C25 -> 0
A27: AGUSTUS | D27: =B27*C27 -> 0 | G27: =E27*F27 -> 0 | I27: =H27*C27 -> 0 | J27: =B27+E27-H27 -> 0 | K27: =J27*C27 -> 0
J28: =B28+E28-H28 -> 0
A29: SEPTEMBER | D29: =B29*C29 -> 0 | I29: =H29*C29 -> 0 | J29: =B29+E29-H29 -> 0 | K29: =J29*C29 -> 0
A31: OKTOBER | D31: =B31*C31 -> 0 | G31: =E31*F31 -> 0 | I31: =H31*C31 -> 0 | J31: =B31+E31-H31 -> 0 | K31: =J31*C31 -> 0
G32: =E32*F32 -> 0 | I32: =H32*F32 -> 0 | J32: =B32+E32-H32 -> 0 | K32: =J32*F32 -> 0
A33: NOVEMBER | D33: =B33*C33 -> 0 | G33: =E33*F33 -> 0 | I33: =H33*C33 -> 0 | J33: =B33+E33-H33 -> 0 | K33: =J33*C33 -> 0 | L33: =J33*C33 -> 0
J34: =B34+E34-H34 -> 0 | K34: =J34*C34 -> 0
A35: DESEMBER | D35: =B35*C35 -> 0 | G35: =E35*F35 -> 0 | I35: =H35*C35 -> 0 | J35: =B35+E35-H35 -> 0 | K35: =J35*C35 -> 0
A37: JUMLAH PEMBELIAN & PEMAKAIAN TAWAS | E37: =SUM(E8:E36) -> 0 | G37: =SUM(G8:G36) -> 0 | J37: =J14 -> 0 | K37: =K14 -> 0

Sheet Kaporit Hanau
A1: LAPORAN PERSEDIAAN BAHAN KIMIA
A2: PERUMDAM TIRTA SERUYAN TAHUN 2026
A3: KAPORIT
A4: BULAN | B4: SALDO AWAL | E4: PENAMBAHAN | H4: PEMAKAIAN | J4: SALDO AKHIR
B5: Volume | C5: Hrg/Kg (Rp) | D5: Jumlah (Rp) | E5: Volume | F5: Hrg/Kg (Rp) | G5: Jumlah | H5: Volume | I5: Jumlah (Rp) | J5: Volume | K5: Jumlah (Rp)
A7: Januari | D7: =B7*C7 -> 0 | H7: 0 | I7: =H7*C7 -> 0 | J7: =B7+E7-H7 -> 0 | K7: =D7+G7-I7 -> 0
A9: Februari | D9: =B9*C9 -> 0 | G9: =E9*F9 -> 0 | I9: =H9*F9 -> 0 | J9: =B9+E9-H9 -> 0 | K9: =J9*C9 -> 0
A11: Maret | D11: =B11*C11 -> 0 | G11: =F11*E11 -> 0 | I11: =H11*C11 -> 0 | J11: =B11+E11-H11 -> 0 | K11: =J11*C11 -> 0
D12: =B12*C12 -> 0 | G12: =E12*F12 -> 0 | J12: =B12+E12-H12 -> 0 | K12: =J12*F12 -> 0
D13: =B13*C13 -> 0 | H13: 0 | I13: =H13*C13 -> 0 | J13: =SUM(J11:J12) -> 0 | K13: =SUM(K11:K12) -> 0
D14: =B14*C14 -> 0 | K14: =J14*C14 -> 0
A15: April | D15: =B15*C15 -> 0 | I15: =H15*C15 -> 0 | J15: =B15+E15-H15 -> 0 | K15: =J15*C15 -> 0
K16: =J16*C16 -> 0
A17: MEI | D17: =B17*C17 -> 0 | I17: =H17*C17 -> 0 | J17: =B17+E17-H17 -> 0 | K17: =J17*C17 -> 0
D18: =B18*C18 -> 0 | J18: =B18+E18-H18 -> 0 | K18: =J18*C18 -> 0
A19: JULI | D19: =B19*C19 -> 0 | I19: =H19*C19 -> 0 | J19: =B19+E19-H19 -> 0 | K19: =J19*C19 -> 0
J20: =B20+E20-H20 -> 0 | K20: =J20*C20 -> 0
A21: AGUSTUS | D21: =B21*C21 -> 0 | I21: =H21*C21 -> 0 | J21: =B21+E21-H21 -> 0 | K21: =J21*C21 -> 0
A23: SEPTEMBER | D23: =B23*C23 -> 0 | I23: =H23*C23 -> 0 | J23: =B23+E23-H23 -> 0 | K23: =J23*C23 -> 0
J24: =B24+E24-H24 -> 0
A25: OKTOBER | D25: =B25*C25 -> 0 | H25: 0 | J25: =B25+E25-H25 -> 0 | K25: =J25*C25 -> 0
J26: =B26+E26-H26 -> 0 | K26: =J26*C26 -> 0
A27: NOIVEMBER | D27: =B27*C27 -> 0 | H27: 0 | J27: =B27+E27-H27 -> 0 | K27: =J27*C27 -> 0 | L27: =J27*C27 -> 0
D28: =B28*C28 -> 0 | J28: =B28+E28-H28 -> 0 | K28: =J28*C28 -> 0
A29: DESEMBER | D29: =B29*C29 -> 0 | I29: =H29*C29 -> 0 | J29: =B29+E29-H29 -> 0 | K29: =J29*C29 -> 0
A31: JUMLAH PEMBELIAN & PEMAKAIAN HAPORIT | E31: =SUM(E8:E30) -> 0 | G31: =SUM(G8:G30) -> 0 | J31: =J15 -> 0 | K31: =K15 -> 0

Sheet Soda Ash Hanau
A1: LAPORAN PERSEDIAAN BAHAN KIMIA
A2: PERUMDAM TIRTA SERUYAN TAHUN 2025
A3: SODA ASH
A4: BULAN | B4: SALDO AWAL | E4: PENAMBAHAN | H4: PEMAKAIAN | J4: SALDO AKHIR
B5: Volume | C5: Hrg/Kg (Rp) | D5: Jumlah (Rp) | E5: Volume | F5: Hrg/Kg (Rp) | G5: Jumlah | H5: Volume | I5: Jumlah (Rp) | J5: Volume | K5: Jumlahm (Rp)
A7: Januari | D7: =B7*C7 -> 0 | G7: =E7*F7 -> 0 | I7: =H7*C7 -> 0 | J7: =B7+E7-H7 -> 0 | K7: =D7+G7-I7 -> 0
J8: =B8+E8-H8 -> 0 | K8: =D8+G8-I8 -> 0
A9: Februari | D9: =B9*C9 -> 0 | G9: =E9*F9 -> 0 | I9: =H9*C9 -> 0 | J9: =B9+E9-H9 -> 0 | K9: =J9*C9 -> 0
J10: =B10+E10-H10 -> 0
A11: Maret | D11: =B11*C11 -> 0 | G11: =F11*E11 -> 0 | I11: =H11*C11 -> 0 | J11: =B11+E11-H11 -> 0 | K11: =J11*C11 -> 0
G12: =E12*F12 -> 0 | I12: =H12*F12 -> 0 | J12: =B12+E12-H12 -> 0 | K12: =J12*F12 -> 0
D13: =B13*C13 -> 0 | I13: =SUM(I11:I12) -> 0 | J13: =SUM(J11:J12) -> 0 | K13: =SUM(K11:K12) -> 0
J14: =B14+E14-H14 -> 0 | K14: =J14*C14 -> 0
A15: April | D15: =B15*C15 -> 0 | G15: =E15*F15 -> 0 | I15: =H15*C15 -> 0 | J15: =B15+E15-H15 -> 0 | K15: =J15*C15 -> 0
A17: MEI | D17: =B17*C17 -> 0 | I17: =H17*C17 -> 0 | J17: =B17+E17-H17 -> 0 | K17: =J17*C17 -> 0
A19: JULI | D19: =B19*C19 -> 0 | G19: =E19*F19 -> 0 | I19: =H19*C19 -> 0 | J19: =B19+E19-H19 -> 0 | K19: =J19*C19 -> 0
A21: AGUSTUS | D21: =B21*C21 -> 0 | G21: =E21*F21 -> 0 | I21: =H21*C21 -> 0 | J21: =B21+E21-H21 -> 0 | K21: =J21*C21 -> 0
A23: SEPTEMBER | D23: =B23*C23 -> 0 | I23: =H23*C23 -> 0 | J23: =B23+E23-H23 -> 0 | K23: =J23*C23 -> 0
J24: =B24+E24-H24 -> 0
A25: OKTOBER | D25: =B25*C25 -> 0 | G25: =E25*F25 -> 0 | I25: =H25*C25 -> 0 | J25: =B25+E25-H25 -> 0 | K25: =J25*C25 -> 0
D26: =B26*C26 -> 0
A27: NOVEMBER | D27: =B27*C27 -> 0 | G27: =E27*F27 -> 0 | I27: =H27*C27 -> 0 | J27: =B27+E27-H27 -> 0 | K27: =J27*C27 -> 0 | L27: =J27*C27 -> 0
D28: =B28*C28 -> 0 | I28: =H28*C28 -> 0 | J28: =B28+E28-H28 -> 0 | K28: =J28*C28 -> 0
A29: DESEMBER | D29: =B29*C29 -> 0 | I29: =H29*C29 -> 0 | J29: =B29+E29-H29 -> 0 | K29: =J29*C29 -> 0
A30: JUMLAH PEMBELIAN & PEMAKAIAN SODA ASH | E30: =SUM(E8:E29) -> 0 | G30: =SUM(G8:G29) -> 0 | K30: =K15 -> 0

Sheet Polimer Hanau
A1: LAPORAN PERSEDIAAN BAHAN KIMIA
A2: PERUMDAM SERUYAN TAHUN 2024
A4: POLIMER
A6: BULAN | B6: SALDO AWAL | E6: PENAMBAHAN | H6: PEMAKAIAN | J6: SALDO AKHIR
B7: Volume | C7: Hrg/Kg | D7: Jumlah (Rp) | E7: Volume | F7: Hrg/Kg | G7: Jumlah (Rp) | H7: Volume | I7: Jumlah (Rp) | J7: Volume | K7: Jumlah (Rp)
A8: Januari | D8: =B8*C8 -> 0 | J8: =B8+E8-H8 -> 0 | K8: =J8*C8 -> 0
A9: Februari | C9: =C8 -> 0 | D9: =B9*C9 -> 0 | G9: =E9*F9 -> 0 | I9: =H9*F9 -> 0 | J9: =B9+E9-H9 -> 0 | K9: =J9*C9 -> 0
A10: Maret | D10: =B10*C10 -> 0 | I10: =H10*C10 -> 0 | J10: =B10+E10-H10 -> 0 | K10: =J10*C10 -> 0
A11: April | D11: =B11*C11 -> 0 | I11: =H11*C11 -> 0 | J11: =B11+E11-H11 -> 0 | K11: =J11*C11 -> 0
A12: Mei | D12: =B12*C12 -> 0 | I12: =H12*C12 -> 0 | J12: =B12+E12-H12 -> 0 | K12: =J12*C12 -> 0
A13: Juni | D13: =B13*C13 -> 0 | I13: =H13*C13 -> 0 | J13: =B13+E13-H13 -> 0 | K13: =J13*C13 -> 0
A14: Juli | D14: =B14*C14 -> 0 | G14: =E14*F14 -> 0 | I14: =H14*C14 -> 0 | J14: =B14+E14-H14 -> 0 | K14: =J14*C14 -> 0
A15: Agustus | D15: =B15*C15 -> 0 | I15: =H15*C15 -> 0 | J15: =B15+E15-H15 -> 0 | K15: =J15*C15 -> 0
A16: September | D16: =B16*C16 -> 0 | I16: =H16*C16 -> 0 | J16: =B16+E16-H16 -> 0 | K16: =J16*C16 -> 0
A17: Oktober | D17: =B17*C17 -> 0 | I17: =H17*C17 -> 0 | J17: =B17+E17-H17 -> 0 | K17: =J17*C17 -> 0
A18: November | D18: =B18*C18 -> 0 | I18: =H18*C18 -> 0 | J18: =B18+E18-H18 -> 0 | K18: =J18*C18 -> 0
A19: Desember | D19: =B19*C19 -> 0 | H19: 10 | I19: =H19*C19 -> 0 | J19: =B19+E19-H19 -> -10 | K19: =J19*C19 -> 0
A20: JUMLAH PEMBELIAN & PEMAKAIAN | E20: =SUM(E8:E19) -> 0 | F20: =SUM(F8:F19) -> 0 | G20: =SUM(G8:G19) -> 0 | H20: =SUM(H8:H19) -> 10 | I20: =SUM(I8:I19) -> 0 | J20: =SUM(J8:J19) -> -10 | K20: =SUM(K8:K19) -> 0

Sheet Tawas K. B
A1: LAPORAN PERSEDIAAN BAHAN KIMIA
A2: PERUMDAM TIRTA SERUYAN TAHUN 2024
A3: TAWAS
A4: BULAN | B4: SALDO AWAL | E4: PENAMBAHAN | H4: PEMAKAIAN | J4: SALDO AKHIR
B5: Volume | C5: Hrg/Kg (Rp) | D5: Jumlah (Rp) | E5: Volume | F5: Hrg/Kg (Rp) | G5: Jumlah | H5: Volume | I5: Jumlah (Rp) | J5: Volume | K5: Jumlahm (Rp)
A7: Januari | D7: =B7*C7 -> 0 | G7: =E7*F7 -> 0 | I7: =H7*C7 -> 0 | J7: =B7+E7-H7 -> 0 | K7: =D7+G7-I7 -> 0
J8: =B8+E8-H8 -> 0 | K8: =D8+G8-I8 -> 0
A9: Februari | D9: =B9*C9 -> 0 | F9: =C9 -> 0 | G9: =E9*F9 -> 0 | I9: =H9*C9 -> 0 | J9: =B9+E9-H9 -> 0 | K9: =D9+G9-I9 -> 0
G10: =E10*F10 -> 0 | I10: =H10*F10 -> 0 | K10: =D10+G10-I10 -> 0
E11: =SUM(E9:E10) -> 0 | G11: =SUM(G9:G10) -> 0 | H11: =SUM(H9:H10) -> 0 | I11: =SUM(I9:I10) -> 0 | J11: =SUM(J9:J10) -> 0 | K11: =SUM(K9:K10) -> 0
J13: =B13+E13-H13 -> 0
A14: Maret | D14: =B14*C14 -> 0 | F14: =C14 -> 0 | G14: =E14*F14 -> 0 | I14: =H14*C14 -> 0 | K14: =J14*C14 -> 0
G18: =E18*F18 -> 0 | I18: =H18*F18 -> 0 | J18: =B18+E18-H18 -> 0 | K18: =J18*F18 -> 0
A19: April | D19: =B19*C19 -> 0 | G19: =E19*F19 -> 0 | I19: =H19*C19 -> 0 | J19: =B19+E19-H19 -> 0 | K19: =J19*C19 -> 0
A21: MEI | D21: =B21*C21 -> 0 | G21: =E21*F21 -> 0 | I21: =H21*C21 -> 0 | J21: =B21+E21-H21 -> 0 | K21: =J21*C21 -> 0 | L21: =J21*C21 -> 0
D22: =B22*C22 -> 0 | I22: =H22*C22 -> 0 | J22: =B22+E22-H22 -> 0 | K22: =J22*C22 -> 0
A23: JUNI | D23: =B23*C23 -> 0 | G23: =E23*F23 -> 0 | I23: =H23*C23 -> 0 | J23: =B23+E23-H23 -> 0 | K23: =J23*C23 -> 0
G24: =E24*F24 -> 0 | I24: =H24*F24 -> 0 | J24: =B24+E24-H24 -> 0 | K24: =J24*F24 -> 0
A25: JULI | D25: =B25*C25 -> 0 | G25: =E25*F25 -> 0 | I25: =H25*C25 -> 0 | J25: =B25+E25-H25 -> 0 | K25: =J25*C25 -> 0 | L25: =J25*C25 -> 0
A27: AGUSTUS | D27: =B27*C27 -> 0 | G27: =E27*F27 -> 0 | I27: =H27*C27 -> 0 | J27: =B27+E27-H27 -> 0 | K27: =J27*C27 -> 0 | L27: =J27*C27 -> 0
J28: =B28+E28-H28 -> 0 | K28: =J28*F28 -> 0
A29: SEPTEMBER | D29: =B29*C29 -> 0 | G29: =E29*F29 -> 0 | I29: =H29*C29 -> 0 | J29: =B29+E29-H29 -> 0 | K29: =J29*C29 -> 0
G30: =E30*F30 -> 0 | I30: =H30*F30 -> 0 | J30: =B30+E30-H30 -> 0 | K30: =J30*F30 -> 0
A31: OKTOBER | D31: =B31*C31 -> 0 | G31: =E31*F31 -> 0 | I31: =H31*C31 -> 0 | J31: =B31+E31-H31 -> 0 | K31: =J31*C31 -> 0
A33: NOVEMBER | D33: =B33*C33 -> 0 | G33: =E33*F33 -> 0 | I33: =H33*C33 -> 0 | J33: =B33+E33-H33 -> 0 | K33: =J33*C33 -> 0 | L33: =C33*J33 -> 0
G34: =E34*F34 -> 0 | I34: =H34*F34 -> 0 | J34: =B34+E34-H34 -> 0 | K34: =J34*F34 -> 0
A35: DESEMBER | D35: =B35*C35 -> 0 | G35: =E35*F35 -> 0 | I35: =H35*C35 -> 0 | J35: =B35+E35-H35 -> 0 | K35: =J35*C35 -> 0
A38: JUMLAH PEMBELIAN & PEMAKAIAN TAWAS | E38: =SUM(E8:E37) -> 0 | G38: =SUM(G8:G37) -> 0 | J38: =#REF! -> #REF! | K38: =#REF! -> #REF!

Sheet Kaporit K. B
A1: LAPORAN PERSEDIAAN BAHAN KIMIA
A2: PERUMDAM TIRTA SERUYAN TAHUN 2024
A3: KAPORIT
A4: BULAN | B4: SALDO AWAL | E4: PENAMBAHAN | H4: PEMAKAIAN | J4: SALDO AKHIR
B5: Volume | C5: Hrg/Kg (Rp) | D5: Jumlah (Rp) | E5: Volume | F5: Hrg/Kg (Rp) | G5: Jumlah | H5: Volume | I5: Jumlah (Rp) | J5: Volume | K5: Jumlahm (Rp)
A7: Januari | D7: =B7*C7 -> 0 | G7: =E7*F7 -> 0 | J7: =B7+E7-H7 -> 0 | K7: =D7+G7-I7 -> 0
D8: =B8*C8 -> 0 | G8: =E8*F8 -> 0 | I8: =H8*F8 -> 0 | J8: =B8+E8-H8 -> 0 | K8: =D8+G8-I8 -> 0
B9: =SUM(B7:B8) -> 0 | D9: =SUM(D7:D8) -> 0 | J9: =SUM(J7:J8) -> 0 | K9: =SUM(K7:K8) -> 0
A11: Februari | C11: =C7 -> 0 | D11: =B11*C11 -> 0 | G11: =E11*F11 -> 0 | I11: =H11*C11 -> 0 | J11: =B11+E11-H11 -> 0 | K11: =J11*C11 -> 0
C12: =C8 -> 0 | D12: =B12*C12 -> 0 | I12: =C12 -> 0 | J12: =B12+E12-H12 -> 0 | K12: =J12*C12 -> 0
B13: =SUM(B11:B12) -> 0 | D13: =SUM(D11:D12) -> 0 | H13: =SUM(H11:H12) -> 0 | I13: =SUM(I11:I12) -> 0 | J13: =SUM(J11:J12) -> 0 | K13: =SUM(K11:K12) -> 0
A16: Maret | C16: =C12 -> 0 | D16: =B16*C16 -> 0 | I16: =H16*C16 -> 0 | J16: =B16+E16-H16 -> 0 | K16: =J16*C16 -> 0
D17: =B17*C17 -> 0 | G17: =E17*F17 -> 0 | I17: =H17*C17 -> 0 | J17: =B17+E17-H17 -> 0 | K17: =J17*F17 -> 0
A18: April | C18: =C16 -> 0 | D18: =B18*C18 -> 0 | G18: =E18*F18 -> 0 | I18: =H18*C18 -> 0 | J18: =B18+E18-H18 -> 0 | K18: =J18*C18 -> 0
J19: =B19+E19-H19 -> 0
A20: MEI | D20: =B20*C20 -> 0 | G20: 0 | I20: =H20*C20 -> 0 | J20: =B20+E20-H20 -> 0 | K20: =J20*C20 -> 0 | L20: =J20*C20 -> 0
A22: JUNI | D22: =B22*C22 -> 0 | G22: =E22*F22 -> 0 | I22: =H22*C22 -> 0 | J22: =B22+E22-H22 -> 0 | K22: =J22*C22 -> 0
A24: JULI | D24: =B24*C24 -> 0 | G24: =E24*F24 -> 0 | I24: =H24*C24 -> 0 | J24: =B24+E24-H24 -> 0 | K24: =J24*C24 -> 0 | L24: =J24*C24 -> 0
A26: AGUSTUS | D26: =B26*C26 -> 0 | G26: =E26*F26 -> 0 | I26: =H26*C26 -> 0 | J26: =B26+E26-H26 -> 0 | K26: =J26*C26 -> 0 | L26: =J26*C26 -> 0
J27: =B27+E27-H27 -> 0
A28: SEPTEMBER | D28: =B28*C28 -> 0 | I28: =H28*C28 -> 0 | J28: =B28+E28-H28 -> 0 | K28: =J28*C28 -> 0
J29: =B29+E29-H29 -> 0
A30: OKTOBER | D30: =B30*C30 -> 0 | I30: =H30*C30 -> 0 | J30: =B30+E30-H30 -> 0 | K30: =J30*C30 -> 0
L31: =C31*J31 -> 0
A32: NOVEMBER | D32: =B32*C32 -> 0 | G32: =E32*F32 -> 0 | I32: =H32*C32 -> 0 | J32: =B32+E32-H32 -> 0 | K32: =J32*C32 -> 0
J33: =B33+E33-H33 -> 0
A34: DESEMBER | D34: =B34*C34 -> 0 | I34: =H34*C34 -> 0 | J34: =B34+E34-H34 -> 0 | K34: =J34*C34 -> 0
D35: =B35*C35 -> 0 | G35: =E35*F35 -> 0 | J35: =B35+E35-H35 -> 0 | K35: =J35*C35 -> 0
A36: JUMLAH PEMBELIAN & PEMAKAIAN KAPORIT | E36: =SUM(E8:E35) -> 0 | G36: =SUM(G8:G35) -> 0 | J36: =J18 -> 0 | K36: =K18 -> 0

Sheet Soda Ash K. B
A1: LAPORAN PERSEDIAAN BAHAN KIMIA
A2: PERUMDAM TIRTA SERUYAN TAHUN 2026
A3: SODA ASH
A4: BULAN | B4: SALDO AWAL | E4: PENAMBAHAN | H4: PEMAKAIAN | J4: SALDO AKHIR
B5: Volume | C5: Hrg/Kg (Rp) | D5: Jumlah (Rp) | E5: Volume | F5: Hrg/Kg (Rp) | G5: Jumlah | H5: Volume | I5: Jumlah (Rp) | J5: Volume | K5: Jumlahm (Rp)
A7: Januari | D7: =B7*C7 -> 0 | G7: =E7*F7 -> 0 | I7: =H7*C7 -> 0 | J7: =B7+E7-H7 -> 0 | K7: =D7+G7-I7 -> 0
D8: =B8*C8 -> 0 | I8: =H8*C8 -> 0 | J8: =B8+E8-H8 -> 0 | K8: =D8+G8-I8 -> 0
A9: Februari | D9: =B9*C9 -> 0 | G9: =E9*F9 -> 0 | I9: =H9*C9 -> 0 | J9: =B9+E9-H9 -> 0 | K9: =J9*C9 -> 0
G10: =E10*F10 -> 0 | J10: =B10+E10-H10 -> 0 | K10: =J10*F10 -> 0
A11: Maret | D11: =B11*C11 -> 0 | I11: =H11*C11 -> 0 | J11: =B11+E11-H11 -> 0 | K11: =J11*C11 -> 0
G12: =E12*F12 -> 0 | J12: =B12+E12-H12 -> 0 | K12: =J12*F12 -> 0
J13: =SUM(J11:J12) -> 0 | K13: =SUM(K11:K12) -> 0
J17: =B17+E17-H17 -> 0
A18: April | D18: =B18*C18 -> 0 | G18: =E18*F18 -> 0 | I18: =H18*C18 -> 0 | J18: =B18+E18-H18 -> 0 | K18: =J18*C18 -> 0
D19: =B19*C19 -> 0 | G19: 0 | I19: 0 | J19: =B19+E19-H19 -> 0 | K19: =J19*C19 -> 0 | L19: =J19*C19 -> 0
D20: =B20*C20 -> 0 | G20: =E20*F20 -> 0 | I20: =H20*C20:C20 -> 0 | J20: =SUM(J18:J19) -> 0 | K20: =SUM(K18:K19) -> 0 | L20: =J20*C20 -> 0
A22: MEI | D22: =B22*C22 -> 0 | I22: =H22*C22 -> 0 | J22: =B22-H22 -> 0 | K22: =J22*C22 -> 0
D23: =B23*C23 -> 0 | I23: =H23*C23 -> 0 | J23: =B23-H23 -> 0 | K23: =J23*C23 -> 0
J24: =SUM(J22:J23) -> 0 | K24: =SUM(K22:K23) -> 0 | L24: =J24*C24 -> 0
D25: =B25*C25 -> 0 | G25: =E25*F25 -> 0 | I25: =H25*C25 -> 0 | J25: =B25-H25 -> 0 | K25: =J25*C25 -> 0
A26: AGUSTUS | D26: =B26*C26 -> 0 | G26: =E26*F26 -> 0 | I26: =H26*C26 -> 0 | J26: =B26-H26 -> 0 | K26: =J26*C26 -> 0 | L26: =J26*F26 -> 0
D27: =B27*C27 -> 0 | G27: =E27*F27 -> 0 | I27: =H27*C27 -> 0 | J27: =B27-H27 -> 0 | K27: =J27*C27 -> 0
A28: SEPTEMBER | D28: =B28*C28 -> 0 | G28: =E28*F28 -> 0 | I28: =H28*C28 -> 0 | J28: =B28-H28 -> 0 | K28: =J28*C28 -> 0
D29: =B29*C29 -> 0 | G29: =E29*F29 -> 0 | I29: =H29*C29 -> 0 | K29: =J29*C29 -> 0
A30: OKTOBER | D30: =B30*C30 -> 0 | G30: =E30*F30 -> 0 | I30: =H30*C30 -> 0 | J30: =B30+E30-H30 -> 0 | K30: =J30*C30 -> 0
D31: =B31*C31 -> 0 | G31: =E31*F31 -> 0 | I31: =H31*C31 -> 0
A32: NOVEMBER | D32: =B32*C32 -> 0 | G32: =E32*F32 -> 0 | I32: =H32*F32 -> 0 | J32: =B32+E32-H32 -> 0 | K32: =J32*F32 -> 0 | L32: =J32*C32 -> 0
D33: =B33*C33 -> 0 | G33: =E33*F33 -> 0 | J33: =B33+E33-H33 -> 0 | K33: =J33*F33 -> 0
A34: DESEMBER | D34: =B34*C34 -> 0 | G34: =E34*F34 -> 0 | I34: =H34*C34 -> 0 | J34: =B34+E34-H34 -> 0 | K34: =J34*C34 -> 0
D35: =B35*C35 -> 0 | G35: =E35*F35 -> 0 | J35: =B35+E35-H35 -> 0 | K35: =J35*C35 -> 0
A36: JUMLAH PEMBELIAN & PEMAKAIAN SODA ASH | E36: =SUM(E8:E35) -> 0 | G36: =SUM(G8:G35) -> 0 | J36: =J18 -> 0 | K36: =K18 -> 0

Sheet POLIMER K.B
A1: LAPORAN PERSEDIAAN BAHAN KIMIA
A2: PERUMDAM SERUYAN TAHUN 2024
A4: POLIMER
A6: BULAN | B6: SALDO AWAL | E6: PENAMBAHAN | H6: PEMAKAIAN | J6: SALDO AKHIR
B7: Volume | C7: Hrg/Kg | D7: Jumlah (Rp) | E7: Volume | F7: Hrg/Kg | G7: Jumlah (Rp) | H7: Volume | I7: Jumlah (Rp) | J7: Volume | K7: Jumlah (Rp)
A8: Januari | D8: =B8*C8 -> 0 | I8: =H8*C8 -> 0 | J8: =B8+E8-H8 -> 0 | K8: =J8*C8 -> 0
A9: Februari | D9: =B9*C9 -> 0 | G9: =E9*F9 -> 0 | I9: =H9*F9 -> 0 | J9: =B9+E9-H9 -> 0 | K9: =J9*C9 -> 0
A10: Maret | D10: =B10*C10 -> 0 | I10: =H10*C10 -> 0 | J10: =B10+E10-H10 -> 0 | K10: =J10*C10 -> 0
A11: April | D11: =B11*C11 -> 0 | G11: =E11*F11 -> 0 | I11: =H11*C11 -> 0 | J11: =B11+E11-H11 -> 0 | K11: =J11*C11 -> 0
A12: Mei | D12: =B12*C12 -> 0 | G12: =E12*F12 -> 0 | I12: =H12*C12 -> 0 | J12: =B12+E12-H12 -> 0 | K12: =J12*C12 -> 0
A13: Juni | D13: =B13*C13 -> 0 | I13: =H13*C13 -> 0 | J13: =B13+E13-H13 -> 0 | K13: =J13*C13 -> 0
A14: Juli | D14: =B14*C14 -> 0 | I14: =H14*C14 -> 0 | J14: =B14-H14 -> 0 | K14: =J14*C14 -> 0
A15: Agustus | D15: =B15*C15 -> 0 | G15: =E15*F15 -> 0 | I15: =H15*C15 -> 0 | J15: =B15+E15-H15 -> 0 | K15: =J15*C15 -> 0
A16: September | D16: =B16*C16 -> 0 | I16: =H16*C16 -> 0 | J16: =B16-H16 -> 0 | K16: =J16*C16 -> 0
A17: Oktober | D17: =B17*C17 -> 0 | G17: =E17*F17 -> 0 | I17: =H17*C17 -> 0 | J17: =B17+E17-H17 -> 0 | K17: =J17*C17 -> 0
A18: November | D18: =B18*C18 -> 0 | G18: =E18*F18 -> 0 | I18: =H18*F18 -> 0 | J18: =B18+E18-H18 -> 0 | K18: =J18*C18 -> 0
A19: Desember | D19: =B19*C19 -> 0 | G19: =E19*F19 -> 0 | I19: =H19*C19 -> 0 | J19: =B19+E19-H19 -> 0 | K19: =J19*C19 -> 0
A20: JUMLAH PEMBELIAN & PEMAKAIAN | E20: =SUM(E8:E19) -> 0 | F20: =SUM(F8:F19) -> 0 | G20: =SUM(G8:G19) -> 0 | H20: =SUM(H8:H19) -> 0 | I20: =SUM(I8:I19) -> 0 | J20: =SUM(J8:J19) -> 0 | K20: =SUM(K8:K19) -> 0

Sheet TAWAS BENAR
A1: LAPORAN PERSEDIAAN BAHAN KIMIA
A2: PERUMDAM TIRTA SERUYAN TAHUN 2026
A3: TAWAS
A4: BULAN | B4: SALDO AWAL | E4: PENAMBAHAN | H4: MUTASI KARTIKA BHAKTI | K4: MUTASI HANAU | N4: PEMAKAIAN | P4: SALDO AKHIR
B5: Volume | C5: Hrg/Kg (Rp) | D5: Jumlah (Rp) | E5: Volume | F5: Hrg/Kg (Rp) | G5: Jumlah | H5: Volume | I5: Hrg/Kg | J5: Jumlah (Rp) | K5: Volume | L5: Hrg/Kg | M5: Jumlah (Rp) | N5: Volume | O5: Jumlah (Rp) | P5: Volume | Q5: Jumlahm (Rp)
A7: Januari | D7: =B7*C7 -> 0 | J7: =H7*I7 -> 0 | M7: =K7*L7 -> 0 | O7: =N7*C7 -> 0 | P7: =B7+E7-N7-H7-K7 -> 0 | Q7: =D7+G7-O7-J7-M7 -> 0
D8: =B8*C8 -> 0 | P8: =B8+E8-N8-H8-K8 -> 0 | Q8: =D8+G8-O8-J8-M8 -> 0
D9: =SUM(D7:D8) -> 0 | P9: =SUM(P7:P8) -> 0 | Q9: =SUM(Q7:Q8) -> 0
A11: Februari | D11: =B11*C11 -> 0 | I11: =C11 -> 0 | J11: =H11*I11 -> 0 | M11: =K11*L11 -> 0 | O11: =N11*C11 -> 0 | P11: =B11+E11-N11-H11-K11 -> 0 | Q11: =P11*C11 -> 0
D12: =B12*C12 -> 0 | I12: =C12 -> 0 | J12: =H12*I12 -> 0 | L12: =C12 -> 0 | M12: =K12*L12 -> 0 | O12: =N12*C12 -> 0 | P12: =B12+E12-N12-H12-K12 -> 0 | Q12: =P12*C12 -> 0
D13: =SUM(D11:D12) -> 0 | J13: =SUM(J11:J12) -> 0 | P13: =SUM(P11:P12) -> 0 | Q13: =SUM(Q11:Q12) -> 0
A16: Maret | D16: =B16*C16 -> 0 | I16: =C16 -> 0 | J16: =H16*I16 -> 0 | L16: =C16 -> 0 | M16: =K16*L16 -> 0 | O16: =N16*C16 -> 0 | P16: =B16+E16-H16-K16-N16 -> 0 | Q16: =P16*C16 -> 0
G17: =E17*F17 -> 0 | O17: =N17*F17 -> 0 | P17: =B17+E17-H17-K17-N17 -> 0 | Q17: =P17*F17 -> 0
O18: =SUM(O16:O17) -> 0 | P18: =SUM(P16:P17) -> 0 | Q18: =SUM(Q16:Q17) -> 0
G20: =E20*F20 -> 0 | O20: =N20*F20 -> 0 | P20: =B20+E20-H20-K20-N20 -> 0 | Q20: =P20*C20 -> 0
A21: April | D21: =B21*C21 -> 0 | G21: =E21*F21 -> 0 | J21: =H21*I21 -> 0 | M21: =K21*L21 -> 0 | O21: =N21*C21 -> 0 | P21: =B21+E21-H21-K21-N21 -> 0 | Q21: =P21*C21 -> 0
R22: =Q22+'Tawas Hanau'!K19+'Tawas K. B'!#REF! -> #REF!
A23: Mei | D23: =B23*C23 -> 0 | J23: =H23*I23 -> 0 | M23: =K23*L23 -> 0 | O23: =N23*C23 -> 0 | P23: =B23+E23-H23-K23-N23 -> 0 | Q23: =P23*C23 -> 0
A25: JUNI | D25: =B25*C25 -> 0 | J25: =H25*I25 -> 0 | M25: =K25*L25 -> 0 | O25: =N25*C25 -> 0 | P25: =B25+E25-H25-K25-N25 -> 0 | Q25: =P25*C25 -> 0 | R25: =P25*C25 -> 0
G26: =E26*F26 -> 0 | J26: =H26*I26 -> 0 | M26: =K26*L26 -> 0 | O26: =N26*F26 -> 0 | P26: =B26+E26-H26-K26-N26 -> 0 | Q26: =P26*F26 -> 0
A27: JULI | D27: =B27*C27 -> 0 | G27: =E27*F27 -> 0 | J27: =H27*I27 -> 0 | M27: =K27*L27 -> 0 | O27: =N27*C27 -> 0 | P27: =B27+E27-H27-K27-N27 -> 0 | Q27: =P27*C27 -> 0 | R27: =P27*C27 -> 0
D28: =B28*C28 -> 0 | P28: =B28+E28-H28-N28 -> 0 | Q28: =P28*C28 -> 0
A29: AGUSTUS | D29: =B29*C29 -> 0 | J29: =H29*I29 -> 0 | M29: =K29*L29 -> 0 | O29: =N29*C29 -> 0 | P29: =B29+E29-H29-K29-N29 -> 0 | Q29: =P29*C29 -> 0 | R29: =P29*C29 -> 0
D30: =B30*C30 -> 0 | G30: =E30*F30 -> 0 | O30: =N30*F30 -> 0 | P30: =B30+E30-H30-K30-N30 -> 0 | Q30: =P30*C30 -> 0
A31: SEPTEMBER | D31: =B31*C31 -> 0 | J31: =H31*I31 -> 0 | O31: =N31*C31 -> 0 | P31: =B31+E31-H31-K31-N31 -> 0 | Q31: =P31*C31 -> 0 | R31: =P31*C31 -> 0
D32: =B32*C32 -> 0 | O32: =N32*C32 -> 0 | P32: =B32+E32-H32-K32-N32 -> 0 | Q32: =P32*C32 -> 0
A33: OKTOBER | D33: =B33*C33 -> 0 | G33: =E33*F33 -> 0 | J33: =H33*I33 -> 0 | M33: =K33*L33 -> 0 | O33: =N33*C33 -> 0 | P33: =B33+E33-H33-K33-N33 -> 0 | Q33: =P33*C33 -> 0 | R33: =P33*C33 -> 0
A35: NOVEMBER | D35: =B35*C35 -> 0 | J35: =H35*I35 -> 0 | M35: =K35*L35 -> 0 | O35: =N35*C35 -> 0 | P35: =B35+E35-H35-K35-N35 -> 0 | Q35: =P35*C35 -> 0
P36: =B36+E36-H36-K36-N36 -> 0
A37: DESEMBER | D37: =B37*C37 -> 0 | G37: =E37*F37 -> 0 | J37: =H37*I37 -> 0 | M37: =K37*L37 -> 0 | O37: =N37*C37 -> 0 | P37: =B37+E37-H37-K37-N37 -> 0 | Q37: =P37*C37 -> 0
A38: JUMLAH PEMBELIAN & PEMAKAIAN TAWAS | E38: =SUM(E7:E37) -> 0 | G38: =SUM(G15:G37) -> 0 | H38: =SUM(H8:H37) -> 0 | K38: =SUM(K8:K37) -> 0 | N38: =N7+N11+#REF!+N16+N20+#REF!+#REF!+N21+#REF!+N22+N24+N25 -> #REF! | O38: =O7+O11+#REF!+O16+O20+#REF!+#REF!+O21+#REF!+O22+O24+O25 -> #REF! | P38: =P25 -> 0 | Q38: =Q25 -> 0

Sheet Kaporit BENAR
A1: LAPORAN PERSEDIAAN BAHAN KIMIA
A2: PERUMDAM TIRTA SERUYAN TAHUN 2026
A3: KAPORIT
A5: BULAN | B5: SALDO AWAL | E5: PENAMBAHAN | H5: MUTASI KARTIKA BHAKTI | K5: MUTASI HANAU | N5: PEMAKAIAN | P5: SALDO AKHIR
B6: Volume | C6: Hrg/Kg | D6: Jumlah (Rp) | E6: Volume | F6: Hrg/Kg | G6: Jumlah | H6: Volume | I6: Hrg/Kg | J6: Jumlah (Rp) | K6: Volume | L6: Hrg/Kg | M6: Jumlah (Rp) | N6: Volume | O6: Jumlah (Rp) | P6: Volume | Q6: Jumlah (Rp)
A8: Januari | D8: =B8*C8 -> 0 | J8: =H8*I8 -> 0 | O8: =N8*C8 -> 0 | P8: =B8+E8-N8-H8-K8 -> 0 | Q8: =D8+G8-O8-J8-M8 -> 0
P9: =B9+E9-N9-H9-K9 -> 0 | Q9: =D9+G9-O9-J9-M9 -> 0
A10: Februari | D10: =B10*C10 -> 0 | G10: =E10*F10 -> 0 | M10: =K10*L10 -> 0 | O10: =N10*C10 -> 0 | P10: =B10+E10-N10-H10-K10 -> 0 | Q10: =D10+G10-O10-J10-M10 -> 0
A12: Maret | D12: =B12*C12 -> 0 | J12: =H12*I12 -> 0 | L12: =C12 -> 0 | M12: =K12*L12 -> 0 | O12: =N12*C12 -> 0 | P12: =B12+E12-H12-K12-N12 -> 0 | Q12: =P12*C12 -> 0
G13: =E13*F13 -> 0 | O13: =N13*F13 -> 0 | P13: =B13+E13-H13-K13-N13 -> 0 | Q13: =P13*F13 -> 0
D14: =B14*C14 -> 0 | G14: =E14*F14 -> 0 | O14: =SUM(O12:O13) -> 0 | P14: =SUM(P12:P13) -> 0 | Q14: =SUM(Q12:Q13) -> 0
D15: =B15*C15 -> 0 | G15: =E15*F15 -> 0 | P15: =B15+E15-H15-K15-N15 -> 0
A16: April | D16: =B16*C16 -> 0 | O16: =N16*C16 -> 0 | P16: =B16+E16-H16-K16-N16 -> 0 | Q16: =P16*C16 -> 0
D17: =B17*C17 -> 0 | P17: =B17+E17-H17-K17-M17 -> 0 | Q17: =P17*C17 -> 0
A18: MEI | D18: =B18*C18 -> 0 | G18: =E18*F18 -> 0 | O18: =N18*C18 -> 0 | P18: =B18+E18-H18-N18 -> 0 | Q18: =P18*C18 -> 0
A20: JULI | D20: =B20*C20 -> 0 | O20: =N20*C20 -> 0 | P20: =B20+E20-H20-N20 -> 0 | Q20: =P20*C20 -> 0 | S20: =P20*C20 -> 0
A22: AGUSTUS | D22: =B22*C22 -> 0 | G22: =E22*F22 -> 0 | O22: =N22*C22 -> 0 | P22: =B22+E22-H22-K22-N22 -> 0 | Q22: =P22*C22 -> 0
A24: SEPTEMBER | D24: =B24*C24 -> 0 | O24: =N24*C24 -> 0 | P24: =B24+E24-H24-K24-N24 -> 0 | S24: =P24*C24 -> 0
P25: =B25+E25-H25-K25-N25 -> 0 | Q25: =P25*C25 -> 0
A26: OKTOBER | D26: =B26*C26 -> 0 | G26: =E26*F26 -> 0 | O26: =N26*F26 -> 0 | P26: =B26+E26-H26-K26-N26 -> 0 | Q26: =P26*F26 -> 0
A28: NOVEMBER | D28: =B28*C28 -> 0 | O28: =N28*C28 -> 0 | P28: =B28+E28-H28-K28-N28 -> 0 | Q28: =P28*C28 -> 0
D29: =B29*C29 -> 0 | O29: =N29*C29 -> 0 | P29: =B29+E29-H29-K29-N29 -> 0 | Q29: =P29*C29 -> 0
A30: DESEMBER | D30: =B30*C30 -> 0 | G30: =E30*F30 -> 0 | O30: =N30*C30 -> 0 | P30: =B30+E30-H30-K30-N30 -> 0 | Q30: =P30*C30 -> 0
A32: JUMLAH PEMAKAIAN & PEMBELIAN KAPORIT | E32: =SUM(E8:E31) -> 0 | G32: =SUM(G8:G31) -> 0

Sheet SODA ASH BENAR
A1: LAPORAN PERSEDIAAN BAHAN KIMIA
A2: PERUMDAM SERUYAN TAHUN 2026
A4: Soda Ash
A6: BULAN | B6: SALDO AWAL | E6: PENAMBAHAN | H6: MUTASI KARTIKA BHAKTI | K6: MUTASI HANAU | N6: PEMAKAIAN | P6: SALDO AKHIR
B7: Volume | C7: Hrg/Kg | D7: Jumlah (Rp) | E7: Volume | F7: Hrg/Kg | G7: Jumlah (Rp) | H7: Volume | I7: Hrg/Kg | J7: Jumlah (Rp) | K7: Volume | L7: Hrg/Kg | M7: Jumlah (Rp) | N7: Volume | O7: Jumlah (Rp) | P7: Volume | Q7: Jumlah (Rp)
A9: Januari | D9: =B9*C9 -> 0 | G9: =E9*F9 -> 0 | J9: =H9*I9 -> 0 | L9: =C9 -> 0 | M9: =K9*L9 -> 0 | O9: =N9*C9 -> 0 | P9: =B9+E9-N9-H9-K9 -> 0 | Q9: =D9+G9-O9-J9-M9 -> 0
D10: =B10*C10 -> 0 | O10: =N10*C10 -> 0 | P10: =B10+E10-N10-H10-K10 -> 0 | Q10: =D10+G10-O10-J10-M10 -> 0
D11: =SUM(D9:D10) -> 0 | P11: =SUM(P9:P10) -> 0 | Q11: =SUM(Q9:Q10) -> 0
A14: Februari | D14: =B14*C14 -> 0 | J14: =H14*I14 -> 0 | M14: =K14*L14 -> 0 | O14: =N14*C14 -> 0 | P14: =B14+E14-H14-K14-N14 -> 0 | Q14: =P14*C14 -> 0
D15: =B15*C15 -> 0 | G15: =E15*F15 -> 0 | O15: =N15*C15 -> 0 | P15: =B15+E15-H15-K15-N15 -> 0 | Q15: =P15*C15 -> 0
D16: =SUM(D14:D15) -> 0 | O16: =SUM(O14:O15) -> 0 | P16: =SUM(P14:P15) -> 0 | Q16: =SUM(Q14:Q15) -> 0
A19: Maret | D19: =B19*C19 -> 0 | I19: =C19 -> 0 | J19: =H19*I19 -> 0 | L19: =C19 -> 0 | M19: =K19*L19 -> 0 | O19: =N19*C19 -> 0 | P19: =B19+E19-H19-K19-N19 -> 0 | Q19: =P19*C19 -> 0
G20: =E20*F20 -> 0 | O20: =N20*F20 -> 0 | P20: =B20+E20-H20-K20-N20 -> 0 | Q20: =P20*F20 -> 0
O21: =SUM(O19:O20) -> 0 | P21: =SUM(P19:P20) -> 0 | Q21: =SUM(Q19:Q20) -> 0
R22: ='Soda Ash'!L26 -> 0
A23: April | D23: =B23*C23 -> 0 | G23: =E23*F23 -> 0 | J23: =H23*I23 -> 0 | O23: =N23*C23 -> 0 | P23: =B23+E23-H23-K23-N23 -> 0 | Q23: =P23*C23 -> 0
G24: =E24*F24 -> 0 | J24: =H24*I24 -> 0 | O24: =N24*F24 -> 0 | P24: =B24+E24-H24-K24-N24 -> 0 | Q24: =P24*F24 -> 0
J25: =SUM(J23:J24) -> 0 | P25: =SUM(P23:P24) -> 0 | Q25: =SUM(Q23:Q24) -> 0
A27: MEI | D27: =B27*C27 -> 0 | G27: =E27*F27 -> 0 | J27: =H27*I27 -> 0 | M27: =K27*L27 -> 0 | O27: =N27*C27 -> 0 | P27: =B27+E27-H27-K27-N27 -> 0 | Q27: =P27*C27 -> 0 | R27: =P27*C27 -> 0
R28: =P28*C28 -> 0
A30: JUNI | D30: =B30*C30 -> 0 | J30: =H30*I30 -> 0 | M30: =K30*L30 -> 0 | O30: =N30*C30 -> 0 | P30: =B30+E30-H30-K30-N30 -> 0 | Q30: =P30*C30 -> 0
G31: =E31*F31 -> 0 | J31: =H31*I31 -> 0 | O31: =N31*F31 -> 0 | P31: =B31+E31-H31-K31-N31 -> 0 | Q31: =P31*F31 -> 0
A32: JULI | D32: =B32*C32 -> 0 | M32: =K32*L32 -> 0 | O32: =N32*C32 -> 0 | P32: =B32+E32-H32-K32-N32 -> 0 | Q32: =P32*C32 -> 0 | R32: =P32*C32 -> 0
D33: =B33*C33 -> 0 | G33: =E33*F33 -> 0 | O33: =N33*C33 -> 0 | P33: =B33+E33-H33-K33-N33 -> 0 | Q33: =P33*F33 -> 0 | R33: =P33*C33 -> 0
D34: =B34*C34 -> 0 | J34: =H34*I34 -> 0 | O34: =N34*C34 -> 0 | P34: =SUM(P32:P33) -> 0 | Q34: =SUM(Q32:Q33) -> 0
A36: AGUSTUS | D36: =B36*C36 -> 0 | J36: =H36*I36 -> 0 | M36: =K36*L36 -> 0 | O36: =N36*C36 -> 0 | P36: =B36-H36-K36-N36 -> 0 | Q36: =P36*C36 -> 0
D37: =B37*C37 -> 0 | O37: =N37*C37 -> 0 | P37: =B37-H37-K37-N37 -> 0 | Q37: =P37*C37 -> 0
D38: =SUM(D36:D37) -> 0 | O38: =SUM(O36:O37) -> 0 | P38: =SUM(P36:P37) -> 0 | Q38: =SUM(Q36:Q37) -> 0
G39: =E39*F39 -> 0
A40: SEPTEMBER | D40: =B40*C40 -> 0 | J40: =H40*I40 -> 0 | O40: =N40*C40 -> 0 | P40: =B40+E40-H40-K40-N40 -> 0 | Q40: =P40*C40 -> 0 | R40: =P40*C40 -> 0
D41: =B41*C41 -> 0 | O41: =N41*C41 -> 0 | P41: =B41+E41-H41-K41-N41 -> 0 | Q41: =P41*C41 -> 0
A42: OKTOBER | D42: =B42*C42 -> 0 | G42: =E42*F42 -> 0 | J42: =H42*I42 -> 0 | M42: =K42*L42 -> 0 | O42: =N42*C42 -> 0 | P42: =B42+E42-H42-K42-N42 -> 0 | Q42: =P42*C42 -> 0
G43: =E43*F43 -> 0 | P43: =B43+E43-H43-K43-N43 -> 0 | Q43: =P43*F43 -> 0
D44: =B44*C44 -> 0 | J44: =H44*I44 -> 0 | M44: =K44*L44 -> 0 | O44: =N44*C44 -> 0 | P44: =SUM(P42:P43) -> 0 | Q44: =SUM(Q42:Q43) -> 0
A46: NOVEMBER | D46: =B46*C46 -> 0 | J46: =H46*I46 -> 0 | P46: =B46+E46-H46-K46-N46 -> 0 | Q46: =P46*C46 -> 0
D47: =B47*C47 -> 0 | J47: =H47*I47 -> 0 | M47: =K47*L47 -> 0 | O47: =N47*C47 -> 0 | P47: =B47+E47-H47-K47-N47 -> 0 | Q47: =P47*C47 -> 0
D48: =SUM(D46:D47) -> 0 | J48: =SUM(J46:J47) -> 0 | O48: =N48*C48 -> 0 | P48: =SUM(P46:P47) -> 0 | Q48: =SUM(Q46:Q47) -> 0
A50: DESEMBER | D50: =B50*C50 -> 0 | G50: =E50*F50 -> 0 | J50: =H50*I50 -> 0 | M50: =K50*L50 -> 0 | O50: =N50*C50 -> 0 | P50: =B50+E50-H50-K50-N50 -> 0 | Q50: =P50*C50 -> 0
G51: =E51*F51 -> 0 | P51: =B51+E51-H51-K51-N51 -> 0 | Q51: =P51*F51 -> 0
P52: =SUM(P50:P51) -> 0 | Q52: =SUM(Q50:Q51) -> 0
...

Sheet POLIMER
A1: LAPORAN PERSEDIAAN BAHAN KIMIA
A2: PERUMDAM SERUYAN TAHUN 2026
A4: POLIMER
A6: BULAN | B6: SALDO AWAL | E6: PENAMBAHAN | H6: MUTASI KARTIKA BHAKTI | K6: MUTASI HANAU | N6: PEMAKAIAN | P6: SALDO AKHIR
B7: Volume | C7: Hrg/Kg | D7: Jumlah (Rp) | E7: Volume | F7: Hrg/Kg | G7: Jumlah (Rp) | H7: Volume | I7: Hrg/Kg | J7: Jumlah (Rp) | K7: Volume | L7: Hrg/Kg | M7: Jumlah (Rp) | N7: Volume | O7: Jumlah (Rp) | P7: Volume | Q7: Jumlah (Rp)
A8: Januari | D8: =B8*C8 -> 0 | O8: =N8*C8 -> 0 | P8: =B8+E8-H8-K8-N8 -> 0 | Q8: =P8*C8 -> 0
A9: Februari | C9: =C8 -> 0 | D9: =B9*C9 -> 0 | G9: =E9*F9 -> 0 | J9: =H9*I9 -> 0 | M9: =K9*L9 -> 0 | O9: =N9*C9 -> 0 | P9: =B9+E9-H9-K9-N9 -> 0 | Q9: =P9*C9 -> 0
A10: Maret | C10: =C9 -> 0 | D10: =B10*C10 -> 0 | O10: =N10*C10 -> 0 | P10: =B10+E10-H10-K10-N10 -> 0 | Q10: =P10*C10 -> 0
A11: April | C11: =C10 -> 0 | D11: =B11*C11 -> 0 | G11: =E11*F11 -> 0 | J11: =H11*I11 -> 0 | O11: =N11*C11 -> 0 | P11: =B11+E11-H11-K11-N11 -> 0 | Q11: =P11*C11 -> 0
A12: Mei | C12: =C11 -> 0 | D12: =B12*C12 -> 0 | J12: =H12*I12 -> 0 | O12: =N12*C12 -> 0 | P12: =B12+E12-H12-K12-N12 -> 0 | Q12: =P12*C12 -> 0
A13: Juni | D13: =B13*C13 -> 0 | J13: =H13*I13 -> 0 | O13: =N13*C13 -> 0 | P13: =B13+E13-H13-K13-N13 -> 0 | Q13: =P13*C13 -> 0
A14: Juli | D14: =B14*C14 -> 0 | G14: =E14*F14 -> 0 | M14: =K14*L14 -> 0 | O14: =N14*C14 -> 0 | P14: =B14+E14-H14-K14-N14 -> 0 | Q14: =P14*C14 -> 0
A15: Agustus | D15: =B15*C15 -> 0 | J15: =H15*I15 -> 0 | O15: =N15*C15 -> 0 | P15: =B15+E15-H15-K15-N15 -> 0 | Q15: =P15*C15 -> 0
A16: September | D16: =B16*C16 -> 0 | O16: =N16*C16 -> 0 | P16: =B16+E16-H16-N16 -> 0 | Q16: =P16*C16 -> 0
A17: Oktober | D17: =B17*C17 -> 0 | J17: =H17*I17 -> 0 | O17: =N17*C17 -> 0 | P17: =B17+E17-H17-N17 -> 0 | Q17: =P17*C17 -> 0
A18: November | D18: =B18*C18 -> 0 | G18: =E18*F18 -> 0 | J18: =H18*I18 -> 0 | O18: =N18*C18 -> 0 | P18: =B18+E18-H18-K18-N18 -> 0 | Q18: =P18*C18 -> 0
A19: Desenber | D19: =B19*C19 -> 0 | O19: =N19*C19 -> 0 | P19: =B19+H19-N19 -> 0 | Q19: =P19*C19 -> 0
A20: JUMLAH PEMBELIAN & PEMAKAIAN | E20: =SUM(E8:E18) -> 0 | F20: =SUM(F8:F18) -> 0 | G20: =SUM(G8:G18) -> 0 | H20: =SUM(H8:H18) -> 0 | I20: =SUM(I8:I18) -> 0 | J20: =SUM(J8:J18) -> 0 | K20: =SUM(K8:K18) -> 0 | L20: =SUM(L8:L18) -> 0 | M20: =SUM(M8:M18) -> 0 | N20: =SUM(N8:N19) -> 0 | O20: =SUM(O8:O19) -> 0 | P20: =SUM(P8:P18) -> 0 | Q20: =SUM(Q8:Q18) -> 0

Sheet REKAP TAWAS
A1: JANUARI 2026
A3: TAWAS PUSAT
A4: BULAN | B4: SALDO AWAL | E4: PENAMBAHAN | H4: MUTASI KARTIKA BHAKTI | K4: MUTASI HANAU | N4: PEMAKAIAN | P4: SALDO AKHIR
B5: Volume | C5: Hrg/Kg (Rp) | D5: Jumlah (Rp) | E5: Volume | F5: Hrg/Kg (Rp) | G5: Jumlah | H5: Volume | I5: Hrg/Kg | J5: Jumlah (Rp) | K5: Volume | L5: Hrg/Kg | M5: Jumlah (Rp) | N5: Volume | O5: Jumlah (Rp) | P5: Volume | Q5: Jumlah (Rp)
A7: Januari | B7: ='TAWAS BENAR'!B7 -> 0 | C7: ='TAWAS BENAR'!C7 -> 0 | D7: ='TAWAS BENAR'!D7 -> 0 | E7: ='TAWAS BENAR'!E7 -> 0 | F7: ='TAWAS BENAR'!F7 -> 0 | G7: ='TAWAS BENAR'!G7 -> 0 | H7: ='TAWAS BENAR'!H7 -> 0 | I7: ='TAWAS BENAR'!I7 -> 0 | ... Q7: ='TAWAS BENAR'!Q7 -> 0
B8: ='TAWAS BENAR'!B8 -> 0 | C8: ='TAWAS BENAR'!C8 -> 0 | D8: ='TAWAS BENAR'!D8 -> 0 | E8: ='TAWAS BENAR'!E8 -> 0 | F8: ='TAWAS BENAR'!F8 -> 0 | G8: ='TAWAS BENAR'!G8 -> 0 | H8: ='TAWAS BENAR'!H8 -> 0 | I8: ='TAWAS BENAR'!I8 -> 0 | ... Q8: ='TAWAS BENAR'!Q8 -> 0
B9: ='TAWAS BENAR'!B9 -> 0 | C9: ='TAWAS BENAR'!C9 -> 0 | D9: ='TAWAS BENAR'!D9 -> 0 | E9: ='TAWAS BENAR'!E9 -> 0 | F9: ='TAWAS BENAR'!F9 -> 0 | G9: ='TAWAS BENAR'!G9 -> 0 | H9: ='TAWAS BENAR'!H9 -> 0 | I9: ='TAWAS BENAR'!I9 -> 0 | ... Q9: ='TAWAS BENAR'!Q9 -> 0
O10: =N10*C10 -> 0
A13: TAWAS KARTIKA BHAKTI
A14: BULAN | B14: SALDO AWAL | E14: PENAMBAHAN | H14: PEMAKAIAN | J14: SALDO AKHIR
B15: Volume | C15: Hrg/Kg (Rp) | D15: Jumlah (Rp) | E15: Volume | F15: Hrg/Kg (Rp) | G15: Jumlah | H15: Volume | I15: Jumlah (Rp) | J15: Volume | K15: Jumlah (Rp)
A17: Januari | B17: ='Tawas K. B'!B7 -> 0 | C17: ='Tawas K. B'!C7 -> 0 | D17: ='Tawas K. B'!D7 -> 0 | E17: ='Tawas K. B'!E7 -> 0 | F17: ='Tawas K. B'!F7 -> 0 | G17: ='Tawas K. B'!G7 -> 0 | H17: ='Tawas K. B'!H7 -> 0 | I17: ='Tawas K. B'!I7 -> 0 | ... K17: ='Tawas K. B'!K7 -> 0
A22: TAWAS HANAU
A23: BULAN | B23: SALDO AWAL | E23: PENAMBAHAN | H23: PEMAKAIAN | J23: SALDO AKHIR
B24: Volume | C24: Hrg/Kg (Rp) | D24: Jumlah (Rp) | E24: Volume | F24: Hrg/Kg (Rp) | G24: Jumlah | H24: Volume | I24: Jumlah (Rp) | J24: Volume | K24: Jumlah (Rp)
A26: Januari | B26: ='Tawas Hanau'!B7 -> 0 | C26: ='Tawas Hanau'!C7 -> 0 | D26: ='Tawas Hanau'!D7 -> 0 | E26: ='Tawas Hanau'!E7 -> 0 | F26: ='Tawas Hanau'!F7 -> 0 | G26: ='Tawas Hanau'!G7 -> 0 | H26: ='Tawas Hanau'!H7 -> 0 | I26: ='Tawas Hanau'!I7 -> 0 | ... K26: ='Tawas Hanau'!K7 -> 0
A31: FEBRUARI 2026
A32: TAWAS PUSAT
A33: BULAN | B33: SALDO AWAL | E33: PENAMBAHAN | H33: MUTASI KARTIKA BHAKTI | K33: MUTASI HANAU | N33: PEMAKAIAN | P33: SALDO AKHIR
B34: Volume | C34: Hrg/Kg (Rp) | D34: Jumlah (Rp) | E34: Volume | F34: Hrg/Kg (Rp) | G34: Jumlah | H34: Volume | I34: Hrg/Kg | J34: Jumlah (Rp) | K34: Volume | L34: Hrg/Kg | M34: Jumlah (Rp) | N34: Volume | O34: Jumlah (Rp) | P34: Volume | Q34: Jumlah (Rp)
A36: Februari | B36: ='TAWAS BENAR'!B11 -> 0 | C36: ='TAWAS BENAR'!C11 -> 0 | D36: ='TAWAS BENAR'!D11 -> 0 | E36: ='TAWAS BENAR'!E11 -> 0 | F36: ='TAWAS BENAR'!F11 -> 0 | G36: ='TAWAS BENAR'!G11 -> 0 | H36: ='TAWAS BENAR'!H11 -> 0 | I36: ='TAWAS BENAR'!I11 -> 0 | ... Q36: ='TAWAS BENAR'!Q11 -> 0
B37: ='TAWAS BENAR'!B12 -> 0 | C37: ='TAWAS BENAR'!C12 -> 0 | D37: ='TAWAS BENAR'!D12 -> 0 | E37: ='TAWAS BENAR'!E12 -> 0 | F37: ='TAWAS BENAR'!F12 -> 0 | G37: ='TAWAS BENAR'!G12 -> 0 | H37: ='TAWAS BENAR'!H12 -> 0 | I37: ='TAWAS BENAR'!I12 -> 0 | ... Q37: ='TAWAS BENAR'!Q12 -> 0
B38: ='TAWAS BENAR'!B13 -> 0 | C38: ='TAWAS BENAR'!C13 -> 0 | D38: ='TAWAS BENAR'!D13 -> 0 | E38: ='TAWAS BENAR'!E13 -> 0 | F38: ='TAWAS BENAR'!F13 -> 0 | G38: ='TAWAS BENAR'!G13 -> 0 | H38: ='TAWAS BENAR'!H13 -> 0 | I38: ='TAWAS BENAR'!I13 -> 0 | ... Q38: ='TAWAS BENAR'!Q13 -> 0
A42: TAWAS KARTIKA BHAKTI
A43: BULAN | B43: SALDO AWAL | E43: PENAMBAHAN | H43: PEMAKAIAN | J43: SALDO AKHIR
B44: Volume | C44: Hrg/Kg (Rp) | D44: Jumlah (Rp) | E44: Volume | F44: Hrg/Kg (Rp) | G44: Jumlah | H44: Volume | I44: Jumlah (Rp) | J44: Volume | K44: Jumlah (Rp)
A46: Februari | B46: ='Tawas K. B'!B9 -> 0 | C46: ='Tawas K. B'!C9 -> 0 | D46: ='Tawas K. B'!D9 -> 0 | E46: ='Tawas K. B'!E9 -> 0 | F46: ='Tawas K. B'!F9 -> 0 | G46: ='Tawas K. B'!G9 -> 0 | H46: ='Tawas K. B'!H9 -> 0 | I46: ='Tawas K. B'!I9 -> 0 | ... K46: ='Tawas K. B'!K9 -> 0
B47: ='Tawas K. B'!B10 -> 0 | C47: ='Tawas K. B'!C10 -> 0 | D47: ='Tawas K. B'!D10 -> 0 | E47: ='Tawas K. B'!E10 -> 0 | F47: ='Tawas K. B'!F10 -> 0 | G47: ='Tawas K. B'!G10 -> 0 | H47: ='Tawas K. B'!H10 -> 0 | I47: ='Tawas K. B'!I10 -> 0 | ... K47: ='Tawas K. B'!K10 -> 0
B48: ='Tawas K. B'!B11 -> 0 | C48: ='Tawas K. B'!C11 -> 0 | D48: ='Tawas K. B'!D11 -> 0 | E48: ='Tawas K. B'!E11 -> 0 | F48: ='Tawas K. B'!F11 -> 0 | G48: ='Tawas K. B'!G11 -> 0 | H48: ='Tawas K. B'!H11 -> 0 | I48: ='Tawas K. B'!I11 -> 0 | ... K48: ='Tawas K. B'!K11 -> 0
A53: TAWAS HANAU
A54: BULAN | B54: SALDO AWAL | E54: PENAMBAHAN | H54: PEMAKAIAN | J54: SALDO AKHIR
B55: Volume | C55: Hrg/Kg (Rp) | D55: Jumlah (Rp) | E55: Volume | F55: Hrg/Kg (Rp) | G55: Jumlah | H55: Volume | I55: Jumlah (Rp) | J55: Volume | K55: Jumlah (Rp)
A57: Februari | B57: ='Tawas Hanau'!B9 -> 0 | C57: ='Tawas Hanau'!C9 -> 0 | D57: ='Tawas Hanau'!D9 -> 0 | E57: ='Tawas Hanau'!E9 -> 0 | F57: ='Tawas Hanau'!F9 -> 0 | G57: ='Tawas Hanau'!G9 -> 0 | H57: ='Tawas Hanau'!H9 -> 0 | I57: ='Tawas Hanau'!I9 -> 0 | ... K57: ='Tawas Hanau'!K9 -> 0
B58: ='Tawas Hanau'!B10 -> 0 | C58: ='Tawas Hanau'!C10 -> 0 | D58: ='Tawas Hanau'!D10 -> 0 | E58: ='Tawas Hanau'!E10 -> 0 | F58: ='Tawas Hanau'!F10 -> 0 | G58: ='Tawas Hanau'!G10 -> 0 | H58: ='Tawas Hanau'!H10 -> 0 | I58: ='Tawas Hanau'!I10 -> 0 | ... K58: ='Tawas Hanau'!K10 -> 0
B59: ='Tawas Hanau'!B11 -> 0 | C59: ='Tawas Hanau'!C11 -> 0 | D59: ='Tawas Hanau'!D11 -> 0 | E59: ='Tawas Hanau'!E11 -> 0 | F59: ='Tawas Hanau'!F11 -> 0 | G59: ='Tawas Hanau'!G11 -> 0 | H59: ='Tawas Hanau'!H11 -> 0 | I59: ='Tawas Hanau'!I11 -> 0 | ... K59: ='Tawas Hanau'!K11 -> 0
A64: MARET 2026
A65: TAWAS PUSAT
A66: BULAN | B66: SALDO AWAL | E66: PENAMBAHAN | H66: MUTASI KARTIKA BHAKTI | K66: MUTASI HANAU | N66: PEMAKAIAN | P66: SALDO AKHIR
B67: Volume | C67: Hrg/Kg (Rp) | D67: Jumlah (Rp) | E67: Volume | F67: Hrg/Kg (Rp) | G67: Jumlah | H67: Volume | I67: Hrg/Kg | J67: Jumlah (Rp) | K67: Volume | L67: Hrg/Kg | M67: Jumlah (Rp) | N67: Volume | O67: Jumlah (Rp) | P67: Volume | Q67: Jumlah (Rp)
A69: Maret | B69: ='TAWAS BENAR'!B16 -> 0 | C69: ='TAWAS BENAR'!C16 -> 0 | D69: ='TAWAS BENAR'!D16 -> 0 | E69: ='TAWAS BENAR'!E16 -> 0 | F69: ='TAWAS BENAR'!F16 -> 0 | G69: ='TAWAS BENAR'!G16 -> 0 | H69: ='TAWAS BENAR'!H16 -> 0 | I69: ='TAWAS BENAR'!I16 -> 0 | ... Q69: ='TAWAS BENAR'!Q16 -> 0
...

Sheet REKAP KAPORIT
A1: JANUARI 2026
A3: KAPORIT PUSAT
A5: BULAN | B5: SALDO AWAL | E5: PENAMBAHAN | H5: MUTASI KARTIKA BHAKTI | K5: MUTASI HANAU | N5: PEMAKAIAN | P5: SALDO AKHIR
B6: Volume | C6: Hrg/Kg | D6: Jumlah (Rp) | E6: Volume | F6: Hrg/Kg | G6: Jumlah | H6: Volume | I6: Hrg/Kg | J6: Jumlah (Rp) | K6: Volume | L6: Hrg/Kg | M6: Jumlah (Rp) | N6: Volume | O6: Jumlah (Rp) | P6: Volume | Q6: Jumlah (Rp)
A8: Januari | E8: ='Kaporit BENAR'!E8 -> 0 | F8: ='Kaporit BENAR'!F8 -> 0 | G8: ='Kaporit BENAR'!G8 -> 0 | H8: ='Kaporit BENAR'!H8 -> 0 | I8: ='Kaporit BENAR'!I8 -> 0 | J8: ='Kaporit BENAR'!J8 -> 0 | K8: ='Kaporit BENAR'!K8 -> 0 | L8: ='Kaporit BENAR'!L8 -> 0 | M8: ='Kaporit BENAR'!M8 -> 0
G9: =E9*F9 -> 0 | P9: =B9+E9-N9-H9-K9 -> 0 | Q9: =D9+G9-O9-J9-M9 -> 0
A14: KAPORIT KARTIKA BHAKTI
A15: BULAN | B15: SALDO AWAL | E15: PENAMBAHAN | H15: PEMAKAIAN | J15: SALDO AKHIR
B16: Volume | C16: Hrg/Kg (Rp) | D16: Jumlah (Rp) | E16: Volume | F16: Hrg/Kg (Rp) | G16: Jumlah | H16: Volume | I16: Jumlah (Rp) | J16: Volume | K16: Jumlah (Rp)
A18: Januari | B18: ='Kaporit K. B'!B7 -> 0 | C18: ='Kaporit K. B'!C7 -> 0 | D18: ='Kaporit K. B'!D7 -> 0 | E18: ='Kaporit K. B'!E7 -> 0 | F18: ='Kaporit K. B'!F7 -> 0 | G18: ='Kaporit K. B'!G7 -> 0 | H18: ='Kaporit K. B'!H7 -> 0 | I18: ='Kaporit K. B'!I7 -> 0 | ... K18: ='Kaporit K. B'!K7 -> 0
B19: ='Kaporit K. B'!B8 -> 0 | C19: ='Kaporit K. B'!C8 -> 0 | D19: ='Kaporit K. B'!D8 -> 0 | E19: ='Kaporit K. B'!E8 -> 0 | F19: ='Kaporit K. B'!F8 -> 0 | G19: ='Kaporit K. B'!G8 -> 0 | H19: ='Kaporit K. B'!H8 -> 0 | I19: ='Kaporit K. B'!I8 -> 0 | ... K19: ='Kaporit K. B'!K8 -> 0 | L19: ='Soda Ash K. B'!L8 -> 0
B20: ='Kaporit K. B'!B9 -> 0 | C20: ='Kaporit K. B'!C9 -> 0 | D20: ='Kaporit K. B'!D9 -> 0 | E20: ='Kaporit K. B'!E9 -> 0 | F20: ='Kaporit K. B'!F9 -> 0 | G20: ='Kaporit K. B'!G9 -> 0 | H20: ='Kaporit K. B'!H9 -> 0 | I20: ='Kaporit K. B'!I9 -> 0 | ... K20: ='Kaporit K. B'!K9 -> 0
A24: KAPOIT HANAU
A25: BULAN | B25: SALDO AWAL | E25: PENAMBAHAN | H25: PEMAKAIAN | J25: SALDO AKHIR
B26: Volume | C26: Hrg/Kg (Rp) | D26: Jumlah (Rp) | E26: Volume | F26: Hrg/Kg (Rp) | G26: Jumlah | H26: Volume | I26: Jumlah (Rp) | J26: Volume | K26: Jumlah (Rp)
A28: Januari | B28: ='Kaporit Hanau'!B7 -> 0 | C28: ='Kaporit Hanau'!C7 -> 0 | D28: ='Kaporit Hanau'!D7 -> 0 | E28: ='Kaporit Hanau'!E7 -> 0 | F28: ='Kaporit Hanau'!F7 -> 0 | G28: ='Kaporit Hanau'!G7 -> 0 | H28: ='Kaporit Hanau'!H7 -> 0 | I28: ='Kaporit Hanau'!I7 -> 0 | ... K28: ='Kaporit Hanau'!K7 -> 0
A33: FEBRUARI 2026
A34: KAPORIT PUSAT
A36: BULAN | B36: SALDO AWAL | E36: PENAMBAHAN | H36: MUTASI KARTIKA BHAKTI | K36: MUTASI HANAU | N36: PEMAKAIAN | P36: SALDO AKHIR
B37: Volume | C37: Hrg/Kg | D37: Jumlah (Rp) | E37: Volume | F37: Hrg/Kg | G37: Jumlah | H37: Volume | I37: Hrg/Kg | J37: Jumlah (Rp) | K37: Volume | L37: Hrg/Kg | M37: Jumlah (Rp) | N37: Volume | O37: Jumlah (Rp) | P37: Volume | Q37: Jumlah (Rp)
A39: Februari | B39: ='Kaporit BENAR'!B10 -> 0 | C39: ='Kaporit BENAR'!C10 -> 0 | D39: ='Kaporit BENAR'!D10 -> 0 | E39: ='Kaporit BENAR'!E10 -> 0 | F39: ='Kaporit BENAR'!F10 -> 0 | G39: ='Kaporit BENAR'!G10 -> 0 | H39: ='Kaporit BENAR'!H10 -> 0 | I39: ='Kaporit BENAR'!I10 -> 0 | ... Q39: ='Kaporit BENAR'!Q10 -> 0
B40: ='Kaporit BENAR'!B11 -> 0 | C40: ='Kaporit BENAR'!C11 -> 0 | D40: ='Kaporit BENAR'!D11 -> 0 | E40: ='Kaporit BENAR'!E11 -> 0 | F40: ='Kaporit BENAR'!F11 -> 0 | G40: ='Kaporit BENAR'!G11 -> 0 | H40: ='Kaporit BENAR'!H11 -> 0 | I40: ='Kaporit BENAR'!I11 -> 0 | ... Q40: ='Kaporit BENAR'!Q11 -> 0
A45: KAPORIT KARTIKA BHAKTI
A46: BULAN | B46: SALDO AWAL | E46: PENAMBAHAN | H46: PEMAKAIAN | J46: SALDO AKHIR
B47: Volume | C47: Hrg/Kg (Rp) | D47: Jumlah (Rp) | E47: Volume | F47: Hrg/Kg (Rp) | G47: Jumlah | H47: Volume | I47: Jumlah (Rp) | J47: Volume | K47: Jumlah (Rp)
A49: Februari | B49: ='Kaporit K. B'!B11 -> 0 | C49: ='Kaporit K. B'!C11 -> 0 | D49: ='Kaporit K. B'!D11 -> 0 | E49: ='Kaporit K. B'!E11 -> 0 | F49: ='Kaporit K. B'!F11 -> 0 | G49: ='Kaporit K. B'!G11 -> 0 | H49: ='Kaporit K. B'!H11 -> 0 | I49: ='Kaporit K. B'!I11 -> 0 | ... K49: ='Kaporit K. B'!K11 -> 0
B50: ='Kaporit K. B'!B12 -> 0 | C50: ='Kaporit K. B'!C12 -> 0 | D50: ='Kaporit K. B'!D12 -> 0 | E50: ='Kaporit K. B'!E12 -> 0 | F50: ='Kaporit K. B'!F12 -> 0 | G50: ='Kaporit K. B'!G12 -> 0 | H50: ='Kaporit K. B'!H12 -> 0 | I50: ='Kaporit K. B'!I12 -> 0 | ... K50: ='Kaporit K. B'!K12 -> 0
B51: ='Kaporit K. B'!B13 -> 0 | C51: ='Kaporit K. B'!C13 -> 0 | D51: ='Kaporit K. B'!D13 -> 0 | E51: ='Kaporit K. B'!E13 -> 0 | F51: ='Kaporit K. B'!F13 -> 0 | G51: ='Kaporit K. B'!G13 -> 0 | H51: ='Kaporit K. B'!H13 -> 0 | I51: ='Kaporit K. B'!I13 -> 0 | ... K51: ='Kaporit K. B'!K13 -> 0
A57: KAPORIT HANAU
A58: BULAN | B58: SALDO AWAL | E58: PENAMBAHAN | H58: PEMAKAIAN | J58: SALDO AKHIR
B59: Volume | C59: Hrg/Kg (Rp) | D59: Jumlah (Rp) | E59: Volume | F59: Hrg/Kg (Rp) | G59: Jumlah | H59: Volume | I59: Jumlah (Rp) | J59: Volume | K59: Jumlah (Rp)
A61: Februari | B61: ='Kaporit Hanau'!B9 -> 0 | C61: ='Kaporit Hanau'!C9 -> 0 | D61: ='Kaporit Hanau'!D9 -> 0 | E61: ='Kaporit Hanau'!E9 -> 0 | F61: ='Kaporit Hanau'!F9 -> 0 | G61: ='Kaporit Hanau'!G9 -> 0 | H61: ='Kaporit Hanau'!H9 -> 0 | I61: ='Kaporit Hanau'!I9 -> 0 | ... K61: ='Kaporit Hanau'!K9 -> 0
B62: ='Kaporit Hanau'!B10 -> 0 | C62: ='Kaporit Hanau'!C10 -> 0 | D62: ='Kaporit Hanau'!D10 -> 0 | E62: ='Kaporit Hanau'!E10 -> 0 | F62: ='Kaporit Hanau'!F10 -> 0 | G62: ='Kaporit Hanau'!G10 -> 0 | H62: ='Kaporit Hanau'!H10 -> 0 | I62: ='Kaporit Hanau'!I10 -> 0 | ... K62: ='Kaporit Hanau'!K10 -> 0
A67: MARET 2026
A68: KAPORIT PUSAT
A70: BULAN | B70: SALDO AWAL | E70: PENAMBAHAN | H70: MUTASI KARTIKA BHAKTI | K70: MUTASI HANAU | N70: PEMAKAIAN | P70: SALDO AKHIR
B71: Volume | C71: Hrg/Kg | D71: Jumlah (Rp) | E71: Volume | F71: Hrg/Kg | G71: Jumlah | H71: Volume | I71: Hrg/Kg | J71: Jumlah (Rp) | K71: Volume | L71: Hrg/Kg | M71: Jumlah (Rp) | N71: Volume | O71: Jumlah (Rp) | P71: Volume | Q71: Jumlah (Rp)
A73: Maret | B73: ='Kaporit BENAR'!B12 -> 0 | C73: ='Kaporit BENAR'!C12 -> 0 | D73: ='Kaporit BENAR'!D12 -> 0 | E73: ='Kaporit BENAR'!E12 -> 0 | F73: ='Kaporit BENAR'!F12 -> 0 | G73: ='Kaporit BENAR'!G12 -> 0 | H73: ='Kaporit BENAR'!H12 -> 0 | I73: ='Kaporit BENAR'!I12 -> 0 | ... Q73: ='Kaporit BENAR'!Q12 -> 0
B74: ='Kaporit BENAR'!B13 -> 0 | C74: ='Kaporit BENAR'!C13 -> 0 | D74: ='Kaporit BENAR'!D13 -> 0 | E74: ='Kaporit BENAR'!E13 -> 0 | F74: ='Kaporit BENAR'!F13 -> 0 | G74: ='Kaporit BENAR'!G13 -> 0 | H74: ='Kaporit BENAR'!H13 -> 0 | I74: ='Kaporit BENAR'!I13 -> 0 | ... Q74: ='Kaporit BENAR'!Q13 -> 0
B75: ='Kaporit BENAR'!B14 -> 0 | C75: ='Kaporit BENAR'!C14 -> 0 | D75: ='Kaporit BENAR'!D14 -> 0 | E75: ='Kaporit BENAR'!E14 -> 0 | F75: ='Kaporit BENAR'!F14 -> 0 | G75: ='Kaporit BENAR'!G14 -> 0 | H75: ='Kaporit BENAR'!H14 -> 0 | I75: ='Kaporit BENAR'!I14 -> 0 | ... Q75: ='Kaporit BENAR'!Q14 -> 0
...

Sheet REKAP SODA ASH
A1: JANUARI 2026
A3: Soda Ash PUSAT
A5: BULAN | B5: SALDO AWAL | E5: PENAMBAHAN | H5: MUTASI KARTIKA BHAKTI | K5: MUTASI HANAU | N5: PEMAKAIAN | P5: SALDO AKHIR
B6: Volume | C6: Hrg/Kg | D6: Jumlah (Rp) | E6: Volume | F6: Hrg/Kg | G6: Jumlah (Rp) | H6: Volume | I6: Hrg/Kg | J6: Jumlah (Rp) | K6: Volume | L6: Hrg/Kg | M6: Jumlah (Rp) | N6: Volume | O6: Jumlah (Rp) | P6: Volume | Q6: Jumlah (Rp)
A8: Januari | B8: ='SODA ASH BENAR'!B9 -> 0 | C8: ='SODA ASH BENAR'!C9 -> 0 | D8: ='SODA ASH BENAR'!D9 -> 0 | E8: ='SODA ASH BENAR'!E9 -> 0 | F8: ='SODA ASH BENAR'!F9 -> 0 | G8: ='SODA ASH BENAR'!G9 -> 0 | H8: ='SODA ASH BENAR'!H9 -> 0 | I8: ='SODA ASH BENAR'!I9 -> 0 | ... R8: ='SODA ASH BENAR'!R9 -> 0
B9: ='SODA ASH BENAR'!B10 -> 0 | C9: ='SODA ASH BENAR'!C10 -> 0 | D9: ='SODA ASH BENAR'!D10 -> 0 | N9: ='SODA ASH BENAR'!N10 -> 0 | O9: ='SODA ASH BENAR'!O10 -> 0 | P9: ='SODA ASH BENAR'!P10 -> 0 | Q9: ='SODA ASH BENAR'!Q10 -> 0
B10: ='SODA ASH BENAR'!B11 -> 0 | C10: ='SODA ASH BENAR'!C11 -> 0 | D10: ='SODA ASH BENAR'!D11 -> 0 | N10: ='SODA ASH BENAR'!N11 -> 0 | O10: ='SODA ASH BENAR'!O11 -> 0 | P10: ='SODA ASH BENAR'!P11 -> 0 | Q10: ='SODA ASH BENAR'!Q11 -> 0
A16: SODA ASH KARTIKA BHAKTI
A17: BULAN | B17: SALDO AWAL | E17: PENAMBAHAN | H17: PEMAKAIAN | J17: SALDO AKHIR
B18: Volume | C18: Hrg/Kg (Rp) | D18: Jumlah (Rp) | E18: Volume | F18: Hrg/Kg (Rp) | G18: Jumlah | H18: Volume | I18: Jumlah (Rp) | J18: Volume | K18: Jumlah (Rp)
A20: Januari | B20: ='Soda Ash K. B'!B7 -> 0 | C20: ='Soda Ash K. B'!C7 -> 0 | D20: ='Soda Ash K. B'!D7 -> 0 | E20: ='Soda Ash K. B'!E7 -> 0 | F20: ='Soda Ash K. B'!F7 -> 0 | G20: ='Soda Ash K. B'!G7 -> 0 | H20: ='Soda Ash K. B'!H7 -> 0 | I20: ='Soda Ash K. B'!I7 -> 0 | ... K20: ='Soda Ash K. B'!K7 -> 0
A27: SODA ASH HANAU
A28: BULAN | B28: SALDO AWAL | E28: PENAMBAHAN | H28: PEMAKAIAN | J28: SALDO AKHIR
B29: Volume | C29: Hrg/Kg (Rp) | D29: Jumlah (Rp) | E29: Volume | F29: Hrg/Kg (Rp) | G29: Jumlah | H29: Volume | I29: Jumlah (Rp) | J29: Volume | K29: Jumlah (Rp)
A31: Januari | B31: ='Soda Ash Hanau'!B7 -> 0 | C31: ='Soda Ash Hanau'!C7 -> 0 | D31: ='Soda Ash Hanau'!D7 -> 0 | E31: ='Soda Ash Hanau'!E7 -> 0 | F31: ='Soda Ash Hanau'!F7 -> 0 | G31: ='Soda Ash Hanau'!G7 -> 0 | H31: ='Soda Ash Hanau'!H7 -> 0 | I31: ='Soda Ash Hanau'!I7 -> 0 | ... K31: ='Soda Ash Hanau'!K7 -> 0
E32: ='Soda Ash Hanau'!E8 -> 0 | F32: ='Soda Ash Hanau'!F8 -> 0 | G32: ='Soda Ash Hanau'!G8 -> 0 | H32: ='Soda Ash Hanau'!H8 -> 0 | I32: ='Soda Ash Hanau'!I8 -> 0 | J32: ='Soda Ash Hanau'!J8 -> 0 | K32: ='Soda Ash Hanau'!K8 -> 0
K34: =D34+G34-I34 -> 0
A38: FEBRUARI 2026
A41: Soda Ash PUSAT
A43: BULAN | B43: SALDO AWAL | E43: PENAMBAHAN | H43: MUTASI KARTIKA BHAKTI | K43: MUTASI HANAU | N43: PEMAKAIAN | P43: SALDO AKHIR
B44: Volume | C44: Hrg/Kg | D44: Jumlah (Rp) | E44: Volume | F44: Hrg/Kg | G44: Jumlah (Rp) | H44: Volume | I44: Hrg/Kg | J44: Jumlah (Rp) | K44: Volume | L44: Hrg/Kg | M44: Jumlah (Rp) | N44: Volume | O44: Jumlah (Rp) | P44: Volume | Q44: Jumlah (Rp)
A46: Februari | B46: ='SODA ASH BENAR'!B14 -> 0 | C46: ='SODA ASH BENAR'!C14 -> 0 | D46: ='SODA ASH BENAR'!D14 -> 0 | E46: ='SODA ASH BENAR'!E14 -> 0 | F46: ='SODA ASH BENAR'!F14 -> 0 | G46: ='SODA ASH BENAR'!G14 -> 0 | H46: ='SODA ASH BENAR'!H14 -> 0 | I46: ='SODA ASH BENAR'!I14 -> 0 | ... Q46: ='SODA ASH BENAR'!Q14 -> 0
B47: ='SODA ASH BENAR'!B15 -> 0 | C47: ='SODA ASH BENAR'!C15 -> 0 | D47: ='SODA ASH BENAR'!D15 -> 0 | E47: ='SODA ASH BENAR'!E15 -> 0 | F47: ='SODA ASH BENAR'!F15 -> 0 | G47: ='SODA ASH BENAR'!G15 -> 0 | H47: ='SODA ASH BENAR'!H15 -> 0 | I47: ='SODA ASH BENAR'!I15 -> 0 | ... Q47: ='SODA ASH BENAR'!Q15 -> 0
B48: ='SODA ASH BENAR'!B16 -> 0 | C48: ='SODA ASH BENAR'!C16 -> 0 | D48: ='SODA ASH BENAR'!D16 -> 0 | E48: ='SODA ASH BENAR'!E16 -> 0 | F48: ='SODA ASH BENAR'!F16 -> 0 | G48: ='SODA ASH BENAR'!G16 -> 0 | H48: ='SODA ASH BENAR'!H16 -> 0 | I48: ='SODA ASH BENAR'!I16 -> 0 | ... Q48: ='SODA ASH BENAR'!Q16 -> 0
G49: =E49*F49 -> 0 | P49: =B49+E49-N49-H49-K49 -> 0 | Q49: =D49+G49-O49-J49-M49 -> 0
A54: SODA ASH KARTIKA BHAKTI
A55: BULAN | B55: SALDO AWAL | E55: PENAMBAHAN | H55: PEMAKAIAN | J55: SALDO AKHIR
B56: Volume | C56: Hrg/Kg (Rp) | D56: Jumlah (Rp) | E56: Volume | F56: Hrg/Kg (Rp) | G56: Jumlah | H56: Volume | I56: Jumlah (Rp) | J56: Volume | K56: Jumlah (Rp)
A58: Februari | B58: ='Soda Ash K. B'!B9 -> 0 | C58: ='Soda Ash K. B'!C9 -> 0 | D58: ='Soda Ash K. B'!D9 -> 0 | E58: ='Soda Ash K. B'!E9 -> 0 | F58: ='Soda Ash K. B'!F9 -> 0 | G58: ='Soda Ash K. B'!G9 -> 0 | H58: ='Soda Ash K. B'!H9 -> 0 | I58: ='Soda Ash K. B'!I9 -> 0 | ... K58: ='Soda Ash K. B'!K9 -> 0
A65: SODA ASH HANAU
A66: BULAN | B66: SALDO AWAL | E66: PENAMBAHAN | H66: PEMAKAIAN | J66: SALDO AKHIR
B67: Volume | C67: Hrg/Kg (Rp) | D67: Jumlah (Rp) | E67: Volume | F67: Hrg/Kg (Rp) | G67: Jumlah | H67: Volume | I67: Jumlah (Rp) | J67: Volume | K67: Jumlah (Rp)
