Workbook

Sheet LAP ARUS KAS
A1: 3. | C1: LAPORAN ARUS KAS
B4: PERUMDAM TIRTA SERUYAN
B5: LAPORAN ARUS KAS
B6: UNTUK TAHUN YANG BERAKHIR 31 JANUARI 2025 DAN TAHUN 2024
B8: URAIAN | G8: TAHUN | I8: TAHUN
G9: 2025 | I9: 2024
B10: A. ARUS KAS OPERASI | C10: ARUS KAS OPERASI
C11: I. PENERIMAAN
D12: 1 | E12: Penerimaan dari Pendapatan Air | G12: =I875 -> #REF! | I12: 6000650100
D13: 2 | E13: Penerimaan dari Pendapatan Non Air | G13: =I876 -> #REF! | I13: 386252632
D14: 3 | E14: Penerimaan dari Pendapatan Lain-lain | G14: =I877 -> #REF! | I14: 2041490791
D15: 4 | E15: Penerimaan dari Aset Lancar Lain-lain | G15: =I878 -> 0
D16: 5 | E16: Penambahan Liabilitas Lancar | G16: =I879 -> 0
D18: JUMLAH PENERIMAAN | G18: =SUM(G12:G16) -> #REF! | I18: =SUM(I12:I16) -> 8428393523
C20: II. PENGELUARAN | L20: =[1]JU!$E$1021 -> 1204164
D21: 1 | E21: Beban Sumber Air | G21: =I884 -> 0 | I21: =1111320581-1204164 -> 1110116417 | L21: (-) hutang pap desember
D22: 2 | E22: Beban Pengolahan Air | G22: =I885 -> 0 | I22: =1595983560 -> 1595983560
D23: 3 | E23: Beban Transmisi & Distribusi | G23: =I886 -> 1200000 | I23: =791611737 -> 791611737
D24: 4 | E24: Beban Umum & Administrasi | G24: =I887 -> 0 | I24: =8414279225-(I21+I22+I23+I34+I25+I27) -> 4086728863 | L24: Total pengeluaran kas dlm 1 tahun dikurang (1+2+3+5+6+pengeluaran aset)
D25: 5 | E25: Beban Lain-lain | G25: =I888 -> 0 | I25: 110400 | L25: 8414279225 | M25: (pengeluaran kas 1 th)
D26: 6 | E26: Pembayaran Aset Lancar Lain - lain | G26: =I889 -> 0
D27: 7 | E27: Pembayaran Liabilitas Lancar Lain - lain | G27: =I890 -> 0 | I27: 13680368 | L27: pembayaran utang sesuai neraca 2023
D29: JUMLAH PENGELUARAN | G29: =SUM(G21:G28) -> 1200000 | I29: =SUM(I21:I28) -> 7598231345
C31: ARUS KAS BERSIH DARI AKTIVITAS OPERASI | G31: =G18-G29 -> #REF! | I31: =I18-I29 -> 830162178
B33: B. | C33: ARUS KAS DARI AKTIVITAS INVESTASI | L33: Reklas pembelian bahan karena sdh dipakai assesories & bahan kimia
D34: Penambahan Aset Tetap | G34: =I897 -> #REF! | I34: =782747880+33300000 -> 816047880 | L34: Pemeliharaan trandist | M34: 203476069
C35: ARUS KAS BERSIH DIGUNAKAN AKTIVITAS INVESTASI | G35: =SUM(G34) -> #REF! | I35: =SUM(I34) -> 816047880 | L35: DM | M35: 111540600
L36: Bahan kimia | M36: 805603800
B37: C. | C37: ARUS KAS DARI AKTIVITAS PENDANAAN | L37: Pemasangan SR &Jaringan | M37: 112943995
D38: Penambahan PMP | G38: =I901 -> 0
D39: Pembayaran Deviden kepada KPM | G39: =I902 -> 0 | M39: =SUM(M34:M38) -> 1233564464
D40: Pembayaran Jasa Produksi dan Tantiem | G40: =I903 -> 0
D41: Penambahan Cadangan Dana/Koreksi Tahu Lalu | G41: =I904 -> 0
C42: ARUS KAS BERSIH UNTUK AKTIVITAS PENDANAAN | G42: =SUM(G38:G41) -> 0 | I42: =SUM(I38:I41) -> 0
B44: D. | C44: KENAIKAN/BERKURANG BERSIH KAS DAN SETARA KAS | G44: =G31-G35+G42 -> #REF! | I44: =I31-I35+I42 -> 14114298
B46: E. | C46: SALDO KAS SETARA KAS AWAL TAHUN | G46: 1.3122519e+09 | I46: 1.2981376e+09
B48: F. | C48: SALDO KAS SETARA KAS AWAL TAHUN | G48: =G44+G46 -> #REF! | I48: =I44+I46 -> 1.3122519e+09
G50: =#REF! -> #REF!
A51: Diketahui / Disetujui Oleh, | F51: Dibuat Oleh,
A52: Pjs. Direktur | F52: Kabag. Adm. & Keuangan
...

Sheet LAP ARUS KAS (2)
A1: 3. | C1: LAPORAN ARUS KAS
B4: PERUMDAM TIRTA SERUYAN
B5: LAPORAN ARUS KAS
B6: UNTUK TAHUN YANG BERAKHIR 31 JANUARI 2025 DAN TAHUN 2024
B8: URAIAN | G8: TAHUN | I8: TAHUN
G9: 2025 | I9: 2024
B10: A. ARUS KAS OPERASI | C10: ARUS KAS OPERASI
C11: I. PENERIMAAN
D12: 1 | E12: Penerimaan dari Pendapatan Air | G12: =I875 -> #REF! | I12: 6000650100 | L12: =I12-6000670100 -> -20000
D13: 2 | E13: Penerimaan dari Pendapatan Non Air | G13: =I876 -> #REF! | I13: 386252632 | L13: =I13-386232632 -> 20000
D14: 3 | E14: Penerimaan dari Pendapatan Lain-lain | G14: =I877 -> #REF! | I14: 2041490791
D15: 4 | E15: Penerimaan dari Aset Lancar Lain-lain | G15: =I878 -> 0
D16: 5 | E16: Penambahan Liabilitas Lancar | G16: =I879 -> 0
D18: JUMLAH PENERIMAAN | G18: =SUM(G12:G16) -> #REF! | I18: =SUM(I12:I16) -> 8428393523
C20: II. PENGELUARAN | L20: =[1]JU!$E$1021 -> 1204164
D21: 1 | E21: Beban Sumber Air | G21: =I884 -> 0 | I21: =1111320581-1204164 -> 1110116417 | L21: (-) hutang pap desember
D22: 2 | E22: Beban Pengolahan Air | G22: =I885 -> 0 | I22: =1595983560-M36 -> 790379760
D23: 3 | E23: Beban Transmisi & Distribusi | G23: =I886 -> 1200000 | I23: =791611737-M34+M35+M37 -> 812620263
D24: 4 | E24: Beban Umum & Administrasi | G24: =I887 -> 0 | I24: =4152198749-26434435-26503037 -> 4099261277 | L24: Beban ADM -B.Imbalan kerja-B.penysihan
D25: 5 | E25: Beban Lain-lain | G25: =I888 -> 0 | I25: 110400 | L25: 8414279225 | M25: (pengeluaran kas 1 th)
D26: 6 | E26: Pembayaran Aset Lancar Lain - lain | G26: =I889 -> 0 | I26: =8414279225-(I21+I22+I23+I24+I25+I34+I27) -> 772062860 | L26: Total pengeluaran kas dlm 1 tahun dikurang (1+2+3+5+6+pengeluaran aset)
D27: 7 | E27: Pembayaran Liabilitas Lancar Lain - lain | G27: =I890 -> 0 | I27: 13680368 | L27: pembayaran utang sesuai neraca 2023
D29: JUMLAH PENGELUARAN | G29: =SUM(G21:G28) -> 1200000 | I29: =SUM(I21:I28) -> 7598231345
C31: ARUS KAS BERSIH DARI AKTIVITAS OPERASI | G31: =G18-G29 -> #REF! | I31: =I18-I29 -> 830162178
B33: B. | C33: ARUS KAS DARI AKTIVITAS INVESTASI | L33: Reklas pembelian bahan karena sdh dipakai assesories & bahan kimia
D34: Penambahan Aset Tetap | G34: =I897 -> #REF! | I34: =782747880+33300000 -> 816047880 | L34: Pemeliharaan trandist | M34: 203476069
C35: ARUS KAS BERSIH DIGUNAKAN AKTIVITAS INVESTASI | G35: =SUM(G34) -> #REF! | I35: =SUM(I34) -> 816047880 | L35: DM | M35: 111540600
L36: Bahan kimia | M36: 805603800
B37: C. | C37: ARUS KAS DARI AKTIVITAS PENDANAAN | L37: Pemasangan SR &Jaringan | M37: 112943995
D38: Penambahan PMP | G38: =I901 -> 0
D39: Pembayaran Deviden kepada KPM | G39: =I902 -> 0 | M39: =SUM(M34:M38) -> 1233564464
D40: Pembayaran Jasa Produksi dan Tantiem | G40: =I903 -> 0
D41: Penambahan Cadangan Dana/Koreksi Tahu Lalu | G41: =I904 -> 0
C42: ARUS KAS BERSIH UNTUK AKTIVITAS PENDANAAN | G42: =SUM(G38:G41) -> 0 | I42: =SUM(I38:I41) -> 0
B44: D. | C44: KENAIKAN/BERKURANG BERSIH KAS DAN SETARA KAS | G44: =G31-G35+G42 -> #REF! | I44: =I31-I35+I42 -> 14114298
B46: E. | C46: SALDO KAS SETARA KAS AWAL TAHUN | G46: 1.3122519e+09 | I46: 1.2981376e+09
B48: F. | C48: SALDO KAS SETARA KAS AWAL TAHUN | G48: =G44+G46 -> #REF! | I48: =I44+I46 -> 1.3122519e+09
G50: =#REF! -> #REF!
A51: Diketahui / Disetujui Oleh, | F51: Dibuat Oleh,
A52: Pjs. Direktur | F52: Kabag. Adm. & Keuangan
...

Sheet NERACA KOMPARATIF
A1: PERUSAHAAN DAERAH AIR MINUM (PDAM)
A2: KABUPATEN SERUYAN
A3: NERACA KOMPORATIF TAHUN 2012
A5: AKTIVA
A6: URAIAN | E6: TAHUN 2012
A8: AKTIVA LANCAR | G8: =F9+F15+F18+F19+F22 -> 1.1431059e+09
B9: KAS DAN BANK | F9: =E10+E11 -> 7.960439e+08
C10: Kas | E10: 589885
C11: Bank | E11: =[3]Kas!$G$33-E10 -> 7.9545401e+08
B12: INVESTASI JANGKA PENDEK | F12: =0 -> 0
C13: Deposito | E13: =0 -> 0
C14: Surat Berharga | E14: =0 -> 0
B15: PIUTANG USAHA | F15: =E16 -> 108725960
C16: Piutang Rek Air | E16: =[3]Piutang!$F$32 -> 108725960
C17: Piutang Rekening Non Air | E17: =0 -> 0
B18: PENYISIHAN PIUTANG USAHA | F18: =-[3]Piutang!$F$50 -> -29241802
B19: PIUTANG NON USAHA | F19: =E20+E21 -> 17713535
C20: Piutang Non Air | E20: =[3]Piutang!$D$60 -> 87535
C21: Pinjaman Pegawai | E21: =[3]Piutang!$F$97 -> 17626000
B22: PERSEDIAAN | F22: =E23+E24+E25 -> 2.4986429e+08
C23: Persediaan Bahan Kimia | E23: =[3]Persediaan!$F$21+[3]Persediaan!$F$39+[3]Persediaan!$F$57 -> 125608580
C24: Persediaan BBM | E24: =[3]Persediaan!$F$98 -> 2097500
C25: Persediaan Instalasi SR | E25: =[3]Persediaan!$F$80 -> 1.2215821e+08
B26: PEMBAYARAN DIMUKA | F26: =0 -> 0
C27: Biaya di bayar dimuka | E27: =0 -> 0
B28: INVESTASI JANGKA PANJANG
C29: Deposito Berjangka Lebih dari 1 tahun | E29: =0 -> 0
C30: Penyertaan | E30: =0 -> 0
C31: Penanaman dalam aktiva tak berwujud | E31: =0 -> 0
C32: Investasi Jangka Panjang Lainnya | E32: =0 -> 0
A33: AKTIVA TETAP | G33: =F34+F44 -> 4.120016e+09
B34: AKTIVA TETAP PRODUKTIF | F34: =SUM(E35:E43) -> 6.5291748e+09
C35: Tanah dan Penyempurnaan Tanah | E35: ='[3]Aktiva Tetap'!$D$9 -> 232450000
C36: Instalasi Sumber Iar | E36: ='[3]Aktiva Tetap'!$F$20 -> 510559191
C37: Instalasi Pompa | E37: ='[3]Aktiva Tetap'!$F$30 -> 117602561
C38: Instalasi Pengolahan Air | E38: ='[3]Aktiva Tetap'!$F$39 -> 2528466809
C39: Instalasi Tranmisi & distribusi | E39: ='[3]Aktiva Tetap'!$F$59 -> 2.333422e+09
C40: Bangunan/Gedung | E40: ='[3]Aktiva Tetap'!$F$76 -> 409862308
C41: Peralatan & Perlengkapan | E41: ='[3]Aktiva Tetap'!$D$90 -> 10182000
C42: Kendaraan/Alat Pengangkutan | E42: ='[3]Aktiva Tetap'!$F$100 -> 284050000
...

Sheet RL KOMPARATIF
A2: PERUSAHAAN DAERAH AIR MINUM (PDAM) KABUPATEN SERUYAN
A3: LAPORAN LABA RUGI KOMPARATIF
A4: TAHUN 2012
A6: URAIAN | D6: 41274
A7: PENDAPATAN
B8: Pendapatan Penjualan Air | E8: =D9 -> #REF!
C9: Penjualan Rekening Air | D9: =#REF! -> #REF!
B10: Pendapatan Non Air | E10: =SUM(D11:D17) -> #REF!
C11: Pendapatan Sambungan Baru | D11: =#REF! -> #REF!
C12: Pendapatan Denda | D12: =#REF! -> #REF!
C13: Pendapatan Administrasi | D13: =#REF! -> #REF!
C14: Pendapatan Penyambungan Kembali | D14: =#REF! -> #REF!
C15: Pendapatan Balik Nama | D15: =#REF! -> #REF!
C16: Pendapatan Mobil Tangki | D16: =#REF! -> #REF!
C17: Pendapatan Subsidi | D17: =#REF! -> #REF!
B19: Pendapatan Lain-lain | E19: =SUM(D20:D21) -> #REF!
C20: Pendapatan Jasa Giro | D20: =#REF! -> #REF!
C21: Pendapatan Lainnya | D21: =#REF! -> #REF!
C23: Jumlah Pendapatan Usaha | F23: =E8+E10+E19 -> #REF!
A25: BIAYA USAHA
B26: Beban Pegawai | E26: =SUM(D27:D28) -> #REF!
C27: Gaji dan Tunjangan | D27: =#REF! -> #REF!
C28: Beban Pegawai Linnya | D28: =#REF!+#REF!+#REF!+#REF!+#REF!+#REF!+#REF!+#REF!+#REF!+#REF!+#REF!+#REF!+#REF!+#REF!+#REF!+#REF!+#REF! -> #REF!
B29: Beban Kantor | E29: =#REF! -> #REF!
B30: Beban BBM | E30: =#REF! -> #REF!
B31: Beban Listrik | E31: =D32+D33 -> #REF!
C32: Beban Listrik Kantor | D32: =#REF! -> #REF!
C33: Beban Listrik Ins Pengolahan Air | D33: =#REF! -> #REF!
B34: Beban Operasi Pengolahan Air | E34: =SUM(D35:D37) -> #REF!
C35: Tawas | D35: =#REF! -> #REF!
C36: Soda Ash | D36: =#REF! -> #REF!
C37: Kaporit | D37: =#REF! -> #REF!
B38: Beban Pemakaian Bahan Pembantu | E38: =SUM(D39:D40) -> #REF!
C39: Oli | D39: =#REF! -> #REF!
C40: Perlengkapan Komputer | D40: =#REF! -> #REF!
B41: Beban ATK & Barang Cetakan | E41: =#REF! -> #REF!
B42: Beban Pemeliharaan | E42: =SUM(D44:D46) -> #REF!
C43: Biaya Pemeliharaan Sumber Air | D43: =#REF! -> #REF!
C44: Biaya Pemeliharaan Pengolahan | D44: =#REF! -> #REF!
C45: Biaya Pemeliharaan Tran & Dist | D45: =#REF! -> #REF!
...

Sheet RINCIAN B. LANGSUNG USAHA
A1: PEMERINTAH KABUPATEN SERUYAN
A2: PERUSAHAAN DAERAH AIR MINUM (PDAM) | Q2: P-11
A4: RINCIAN BIAYA LANGSUNG USAHA | U4: 12276 | V4: 18537 | W4: 43457
A5: TAHUN ANGGARAN 2025 | X5: =W37+W44+W50+W51+W52+W73+W77+W83+W84+W85+W29-W28+W63 -> 0
A7: PDAM KABUPATEN SERUYAN
A8: NO | B8: URAIAN | E8: BULAN | Q8: JUMLAH | R8: MAPPING BEBAN SAK - ETAP
A9: PERK. | E9: 1 | F9: 2 | G9: 3 | H9: 4 | I9: 5 | J9: 6 | K9: 7 | L9: 8 | M9: 9 | N9: 10 | O9: 11 | P9: 12 | Q9: 2025 | T9: 1 | U9: 2 | V9: 3 | W9: 4 | X9: 5 | Y9: 6 | Z9: 7 | AA9: 8 | AB9: 9 | AC9: 10 | AD9: 11 | AE9: 12
A10: 1 | B10: 2 | E10: 3 | F10: 4 | G10: 5 | H10: 6 | I10: 7 | J10: 8 | K10: 9 | L10: 10 | M10: 11 | N10: 12 | O10: 13 | P10: 14 | Q10: 15 | R10: 16
A11: 91.00.00 | B11: BEBAN SUMBER AIR | Q11: =SUM(F11:P11) -> 0 | T11: =E11 -> 0 | U11: =SUM(E11:F11) -> 0 | V11: =SUM(E11:G11) -> 0 | W11: =SUM(E11:H11) -> 0 | X11: =SUM(E11:I11) -> 0 | Y11: =SUM(E11:J11) -> 0 | Z11: =SUM(E11:K11) -> 0 | AA11: =SUM(E11:L11) -> 0 | AB11: =SUM(E11:M11) -> 0 | AC11: =SUM(E11:N11) -> 0 | AD11: =SUM(E11:O11) -> 0 | AE11: =SUM(E11:P11) -> 0
A12: 91.01.00 | B12: BEBAN OPERASIONAL SUMBER AIR | Q12: =SUM(F12:P12) -> 0 | T12: =E12 -> 0 | U12: =SUM(E12:F12) -> 0 | V12: =SUM(E12:G12) -> 0 | W12: =SUM(E12:H12) -> 0 | X12: =SUM(E12:I12) -> 0 | Y12: =SUM(E12:J12) -> 0 | Z12: =SUM(E12:K12) -> 0 | AA12: =SUM(E12:L12) -> 0 | AB12: =SUM(E12:M12) -> 0 | AC12: =SUM(E12:N12) -> 0 | AD12: =SUM(E12:O12) -> 0 | AE12: =SUM(E12:P12) -> 0
A13: 91.01.10 | B13: Beban Pegawai | Q13: =SUM(E13:P13) -> 0 | R13: B. PEGAWAI | T13: =E13 -> 0 | U13: =SUM(E13:F13) -> 0 | V13: =SUM(E13:G13) -> 0 | W13: =SUM(E13:H13) -> 0 | X13: =SUM(E13:I13) -> 0 | Y13: =SUM(E13:J13) -> 0 | Z13: =SUM(E13:K13) -> 0 | AA13: =SUM(E13:L13) -> 0 | AB13: =SUM(E13:M13) -> 0 | AC13: =SUM(E13:N13) -> 0 | AD13: =SUM(E13:O13) -> 0 | AE13: =SUM(E13:P13) -> 0
A14: 91.01.20 | B14: Beban Kesejahteraan Karyawan Sumber Air | Q14: =SUM(E14:P14) -> 0 | T14: =E14 -> 0 | U14: =SUM(E14:F14) -> 0 | V14: =SUM(E14:G14) -> 0 | W14: =SUM(E14:H14) -> 0 | X14: =SUM(E14:I14) -> 0 | Y14: =SUM(E14:J14) -> 0 | Z14: =SUM(E14:K14) -> 0 | AA14: =SUM(E14:L14) -> 0 | AB14: =SUM(E14:M14) -> 0 | AC14: =SUM(E14:N14) -> 0 | AD14: =SUM(E14:O14) -> 0 | AE14: =SUM(E14:P14) -> 0
A15: 91.01.30 | B15: Beban Pakaian Dinas & Olahraga | Q15: =SUM(E15:P15) -> 0 | T15: =E15 -> 0 | U15: =SUM(E15:F15) -> 0 | V15: =SUM(E15:G15) -> 0 | W15: =SUM(E15:H15) -> 0 | X15: =SUM(E15:I15) -> 0 | Y15: =SUM(E15:J15) -> 0 | Z15: =SUM(E15:K15) -> 0 | AA15: =SUM(E15:L15) -> 0 | AB15: =SUM(E15:M15) -> 0 | AC15: =SUM(E15:N15) -> 0 | AD15: =SUM(E15:O15) -> 0 | AE15: =SUM(E15:P15) -> 0
A16: 91.01.40 | B16: Beban Pendidikan & Latihan | Q16: =SUM(E16:P16) -> 0 | T16: =E16 -> 0 | U16: =SUM(E16:F16) -> 0 | V16: =SUM(E16:G16) -> 0 | W16: =SUM(E16:H16) -> 0 | X16: =SUM(E16:I16) -> 0 | Y16: =SUM(E16:J16) -> 0 | Z16: =SUM(E16:K16) -> 0 | AA16: =SUM(E16:L16) -> 0 | AB16: =SUM(E16:M16) -> 0 | AC16: =SUM(E16:N16) -> 0 | AD16: =SUM(E16:O16) -> 0 | AE16: =SUM(E16:P16) -> 0
A17: 91.01.50 | B17: Beban Pembinaan Pegawai Sumber | Q17: =SUM(E17:P17) -> 0 | T17: =E17 -> 0 | U17: =SUM(E17:F17) -> 0 | V17: =SUM(E17:G17) -> 0 | W17: =SUM(E17:H17) -> 0 | X17: =SUM(E17:I17) -> 0 | Y17: =SUM(E17:J17) -> 0 | Z17: =SUM(E17:K17) -> 0 | AA17: =SUM(E17:L17) -> 0 | AB17: =SUM(E17:M17) -> 0 | AC17: =SUM(E17:N17) -> 0 | AD17: =SUM(E17:O17) -> 0 | AE17: =SUM(E17:P17) -> 0
A18: 91.02.10 | B18: Pemakaian Bahan bakar (SOLAR) | Q18: =SUM(E18:P18) -> 0 | R18: B. PEMAKAIAN BAHAN BAKAR | T18: =E18 -> 0 | U18: =SUM(E18:F18) -> 0 | V18: =SUM(E18:G18) -> 0 | W18: =SUM(E18:H18) -> 0 | X18: =SUM(E18:I18) -> 0 | Y18: =SUM(E18:J18) -> 0 | Z18: =SUM(E18:K18) -> 0 | AA18: =SUM(E18:L18) -> 0 | AB18: =SUM(E18:M18) -> 0 | AC18: =SUM(E18:N18) -> 0 | AD18: =SUM(E18:O18) -> 0 | AE18: =SUM(E18:P18) -> 0
A19: 91.02.20 | B19: Beban Listrik PLN | Q19: =SUM(E19:P19) -> 0 | R19: B. LISTRIK | T19: =E19 -> 0 | U19: =SUM(E19:F19) -> 0 | V19: =SUM(E19:G19) -> 0 | W19: =SUM(E19:H19) -> 0 | X19: =SUM(E19:I19) -> 0 | Y19: =SUM(E19:J19) -> 0 | Z19: =SUM(E19:K19) -> 0 | AA19: =SUM(E19:L19) -> 0 | AB19: =SUM(E19:M19) -> 0 | AC19: =SUM(E19:N19) -> 0 | AD19: =SUM(E19:O19) -> 0 | AE19: =SUM(E19:P19) -> 0
A20: 91.02.30 | B20: Pemakaian Bahan Pembantu (oli) | E20: 0 | Q20: =SUM(E20:P20) -> 0 | R20: B. PEMAKAIAN BAHAN PEMBANTU | T20: =E20 -> 0 | U20: =SUM(E20:F20) -> 0 | V20: =SUM(E20:G20) -> 0 | W20: =SUM(E20:H20) -> 0 | X20: =SUM(E20:I20) -> 0 | Y20: =SUM(E20:J20) -> 0 | Z20: =SUM(E20:K20) -> 0 | AA20: =SUM(E20:L20) -> 0 | AB20: =SUM(E20:M20) -> 0 | AC20: =SUM(E20:N20) -> 0 | AD20: =SUM(E20:O20) -> 0 | AE20: =SUM(E20:P20) -> 0
A21: 91.02.40 | B21: Rupa-Rupa Beban Operasi | Q21: =SUM(E21:P21) -> 0 | R21: B. OPERASI LAINNYA | T21: =E21 -> 0 | U21: =SUM(E21:F21) -> 0 | V21: =SUM(E21:G21) -> 0 | W21: =SUM(E21:H21) -> 0 | X21: =SUM(E21:I21) -> 0 | Y21: =SUM(E21:J21) -> 0 | Z21: =SUM(E21:K21) -> 0 | AA21: =SUM(E21:L21) -> 0 | AB21: =SUM(E21:M21) -> 0 | AC21: =SUM(E21:N21) -> 0 | AD21: =SUM(E21:O21) -> 0 | AE21: =SUM(E21:P21) -> 0
B22: B. Operasi Sumber Air | E22: =SUM(E13:E21) -> 0 | F22: =SUM(F13:F21) -> 0 | G22: =SUM(G13:G21) -> 0 | H22: =SUM(H13:H21) -> 0 | I22: =SUM(I13:I21) -> 0 | J22: =SUM(J13:J21) -> 0 | K22: =SUM(K13:K21) -> 0 | L22: =SUM(L13:L21) -> 0 | ... P22: =SUM(P13:P21) -> 0 | Q22: =SUM(E22:P22) -> 0 | T22: =E22 -> 0 | U22: =SUM(E22:F22) -> 0 | V22: =SUM(E22:G22) -> 0 | W22: =SUM(E22:H22) -> 0 | X22: =SUM(E22:I22) -> 0 | Y22: =SUM(E22:J22) -> 0 | Z22: =SUM(E22:K22) -> 0 | AA22: =SUM(E22:L22) -> 0 | AB22: =SUM(E22:M22) -> 0 | AC22: =SUM(E22:N22) -> 0 | AD22: =SUM(E22:O22) -> 0 | AE22: =SUM(E22:P22) -> 0
A23: 91.03.00 | B23: BEBAN PEMELIHARAAN SUMBER AIR | T23: =E23 -> 0 | U23: =SUM(E23:F23) -> 0 | V23: =SUM(E23:G23) -> 0 | W23: =SUM(E23:H23) -> 0 | X23: =SUM(E23:I23) -> 0 | Y23: =SUM(E23:J23) -> 0 | Z23: =SUM(E23:K23) -> 0 | AA23: =SUM(E23:L23) -> 0 | AB23: =SUM(E23:M23) -> 0 | AC23: =SUM(E23:N23) -> 0 | AD23: =SUM(E23:O23) -> 0 | AE23: =SUM(E23:P23) -> 0
A24: 91.03.10 | B24: Pemeliharaan bangunan dan penyempurnaan tanah | Q24: =SUM(E24:P24) -> 0 | T24: =E24 -> 0 | U24: =SUM(E24:F24) -> 0 | V24: =SUM(E24:G24) -> 0 | W24: =SUM(E24:H24) -> 0 | X24: =SUM(E24:I24) -> 0 | Y24: =SUM(E24:J24) -> 0 | Z24: =SUM(E24:K24) -> 0 | AA24: =SUM(E24:L24) -> 0 | AB24: =SUM(E24:M24) -> 0 | AC24: =SUM(E24:N24) -> 0 | AD24: =SUM(E24:O24) -> 0 | AE24: =SUM(E24:P24) -> 0
A25: 91.03.40 | B25: Pemeliharaan Mata air dan Saluran | Q25: =SUM(E25:P25) -> 0 | T25: =E25 -> 0 | U25: =SUM(E25:F25) -> 0 | V25: =SUM(E25:G25) -> 0 | W25: =SUM(E25:H25) -> 0 | X25: =SUM(E25:I25) -> 0 | Y25: =SUM(E25:J25) -> 0 | Z25: =SUM(E25:K25) -> 0 | AA25: =SUM(E25:L25) -> 0 | AB25: =SUM(E25:M25) -> 0 | AC25: =SUM(E25:N25) -> 0 | AD25: =SUM(E25:O25) -> 0 | AE25: =SUM(E25:P25) -> 0
A26: 91.03.60 | B26: Pemeliharaan Pipa Induk | Q26: =SUM(E26:P26) -> 0 | T26: =E26 -> 0 | U26: =SUM(E26:F26) -> 0 | V26: =SUM(E26:G26) -> 0 | W26: =SUM(E26:H26) -> 0 | X26: =SUM(E26:I26) -> 0 | Y26: =SUM(E26:J26) -> 0 | Z26: =SUM(E26:K26) -> 0 | AA26: =SUM(E26:L26) -> 0 | AB26: =SUM(E26:M26) -> 0 | AC26: =SUM(E26:N26) -> 0 | AD26: =SUM(E26:O26) -> 0 | AE26: =SUM(E26:P26) -> 0
A27: 91.03.70 | B27: Pemeliharaan Alat Pembangkit Tenaga | Q27: =SUM(E27:P27) -> 0 | T27: =E27 -> 0 | U27: =SUM(E27:F27) -> 0 | V27: =SUM(E27:G27) -> 0 | W27: =SUM(E27:H27) -> 0 | X27: =SUM(E27:I27) -> 0 | Y27: =SUM(E27:J27) -> 0 | Z27: =SUM(E27:K27) -> 0 | AA27: =SUM(E27:L27) -> 0 | AB27: =SUM(E27:M27) -> 0 | AC27: =SUM(E27:N27) -> 0 | AD27: =SUM(E27:O27) -> 0 | AE27: =SUM(E27:P27) -> 0
A28: 91.03.80 | B28: Pemeliharaan Alat Perpompaan | Q28: =SUM(E28:P28) -> 0 | T28: =E28 -> 0 | U28: =SUM(E28:F28) -> 0 | V28: =SUM(E28:G28) -> 0 | W28: =SUM(E28:H28) -> 0 | X28: =SUM(E28:I28) -> 0 | Y28: =SUM(E28:J28) -> 0 | Z28: =SUM(E28:K28) -> 0 | AA28: =SUM(E28:L28) -> 0 | AB28: =SUM(E28:M28) -> 0 | AC28: =SUM(E28:N28) -> 0 | AD28: =SUM(E28:O28) -> 0 | AE28: =SUM(E28:P28) -> 0
A29: 91.03.90 | B29: Pemeliharaan Instalasi Sumber Air Lainnya | Q29: =SUM(E29:P29) -> 0 | T29: =E29 -> 0 | U29: =SUM(E29:F29) -> 0 | V29: =SUM(E29:G29) -> 0 | W29: =SUM(E29:H29) -> 0 | X29: =SUM(E29:I29) -> 0 | Y29: =SUM(E29:J29) -> 0 | Z29: =SUM(E29:K29) -> 0 | AA29: =SUM(E29:L29) -> 0 | AB29: =SUM(E29:M29) -> 0 | AC29: =SUM(E29:N29) -> 0 | AD29: =SUM(E29:O29) -> 0 | AE29: =SUM(E29:P29) -> 0
B30: Jumlah Beban Pemeliharaan Sumber Air | E30: =SUM(E24:E29) -> 0 | F30: =SUM(F24:F29) -> 0 | G30: =SUM(G24:G29) -> 0 | H30: =SUM(H24:H29) -> 0 | I30: =SUM(I24:I29) -> 0 | J30: =SUM(J24:J29) -> 0 | K30: =SUM(K24:K29) -> 0 | L30: =SUM(L24:L29) -> 0 | ... P30: =SUM(P24:P29) -> 0 | Q30: =SUM(E30:P30) -> 0 | R30: B. PEMELIHARAAN | T30: =E30 -> 0 | U30: =SUM(E30:F30) -> 0 | V30: =SUM(E30:G30) -> 0 | W30: =SUM(E30:H30) -> 0 | X30: =SUM(E30:I30) -> 0 | Y30: =SUM(E30:J30) -> 0 | Z30: =SUM(E30:K30) -> 0 | AA30: =SUM(E30:L30) -> 0 | AB30: =SUM(E30:M30) -> 0 | AC30: =SUM(E30:N30) -> 0 | AD30: =SUM(E30:O30) -> 0 | AE30: =SUM(E30:P30) -> 0
A31: 91.04.00 | B31: BEBAN AIR BAKU (PAJAK AIR PERMUKAAN) | Q31: =SUM(E31:P31) -> 0 | R31: B. AIR BAKU | T31: =E31 -> 0 | U31: =SUM(E31:F31) -> 0 | V31: =SUM(E31:G31) -> 0 | W31: =SUM(E31:H31) -> 0 | X31: =SUM(E31:I31) -> 0 | Y31: =SUM(E31:J31) -> 0 | Z31: =SUM(E31:K31) -> 0 | AA31: =SUM(E31:L31) -> 0 | AB31: =SUM(E31:M31) -> 0 | AC31: =SUM(E31:N31) -> 0 | AD31: =SUM(E31:O31) -> 0 | AE31: =SUM(E31:P31) -> 0
B32: JUMLAH SEBELUM PENYUSUTAN | E32: =E30+E22+E31 -> 0 | F32: =F30+F22+F31 -> 0 | G32: =G30+G22+G31 -> 0 | H32: =H30+H22+H31 -> 0 | I32: =I30+I22+I31 -> 0 | J32: =J30+J22+J31 -> 0 | K32: =K30+K22+K31 -> 0 | L32: =L30+L22+L31 -> 0 | ... P32: =P30+P22+P31 -> 0 | Q32: =SUM(E32:P32) -> 0 | T32: =E32 -> 0 | U32: =SUM(E32:F32) -> 0 | V32: =SUM(E32:G32) -> 0 | W32: =SUM(E32:H32) -> 0 | X32: =SUM(E32:I32) -> 0 | Y32: =SUM(E32:J32) -> 0 | Z32: =SUM(E32:K32) -> 0 | AA32: =SUM(E32:L32) -> 0 | AB32: =SUM(E32:M32) -> 0 | AC32: =SUM(E32:N32) -> 0 | AD32: =SUM(E32:O32) -> 0 | AE32: =SUM(E32:P32) -> 0
A33: 91.05.00 | B33: BEBAN PENYUSUTAN SUMBER AIR | Q33: =SUM(E33:P33) -> 0 | R33: B. PENYUSUTAN | T33: =E33 -> 0 | U33: =SUM(E33:F33) -> 0 | V33: =SUM(E33:G33) -> 0 | W33: =SUM(E33:H33) -> 0 | X33: =SUM(E33:I33) -> 0 | Y33: =SUM(E33:J33) -> 0 | Z33: =SUM(E33:K33) -> 0 | AA33: =SUM(E33:L33) -> 0 | AB33: =SUM(E33:M33) -> 0 | AC33: =SUM(E33:N33) -> 0 | AD33: =SUM(E33:O33) -> 0 | AE33: =SUM(E33:P33) -> 0
B34: JUMLAH BEBAN SUMBER AIR | J34: =SUM(J32:J33) -> 0 | K34: =SUM(K32:K33) -> 0 | L34: =SUM(L32:L33) -> 0 | M34: =SUM(M32:M33) -> 0 | N34: =SUM(N32:N33) -> 0 | O34: =SUM(O32:O33) -> 0 | P34: =SUM(P32:P33) -> 0 | Q34: =SUM(E34:P34) -> 0 | T34: =E34 -> 0 | U34: =SUM(E34:F34) -> 0 | V34: =SUM(E34:G34) -> 0 | W34: =SUM(E34:H34) -> 0 | X34: =SUM(E34:I34) -> 0 | Y34: =SUM(E34:J34) -> 0 | Z34: =SUM(E34:K34) -> 0 | AA34: =SUM(E34:L34) -> 0 | AB34: =SUM(E34:M34) -> 0 | AC34: =SUM(E34:N34) -> 0 | AD34: =SUM(E34:O34) -> 0 | AE34: =SUM(E34:P34) -> 0
Q35: =SUM(E35:P35) -> 0 | T35: =E35 -> 0 | U35: =SUM(E35:F35) -> 0 | V35: =SUM(E35:G35) -> 0 | W35: =SUM(E35:H35) -> 0 | X35: =SUM(E35:I35) -> 0 | Y35: =SUM(E35:J35) -> 0 | Z35: =SUM(E35:K35) -> 0 | AA35: =SUM(E35:L35) -> 0 | AB35: =SUM(E35:M35) -> 0 | AC35: =SUM(E35:N35) -> 0 | AD35: =SUM(E35:O35) -> 0 | AE35: =SUM(E35:P35) -> 0
A36: 92.00.00 | B36: BEBAN PENGOLAHAN AIR | Q36: =SUM(E36:P36) -> 0 | T36: =E36 -> 0 | U36: =SUM(E36:F36) -> 0 | V36: =SUM(E36:G36) -> 0 | W36: =SUM(E36:H36) -> 0 | X36: =SUM(E36:I36) -> 0 | Y36: =SUM(E36:J36) -> 0 | Z36: =SUM(E36:K36) -> 0 | AA36: =SUM(E36:L36) -> 0 | AB36: =SUM(E36:M36) -> 0 | AC36: =SUM(E36:N36) -> 0 | AD36: =SUM(E36:O36) -> 0 | AE36: =SUM(E36:P36) -> 0
A37: 92.01.10 | B37: Beban Pegawai | E37: =SUM(E39:E43) -> 0 | F37: =SUM(F39:F43) -> 0 | G37: =SUM(G39:G43) -> 0 | H37: =SUM(H39:H43) -> 0 | I37: =SUM(I39:I43) -> 0 | J37: =SUM(J39:J43) -> 0 | K37: =SUM(K39:K43) -> 0 | L37: =SUM(L39:L43) -> 0 | ... P37: =SUM(P39:P43) -> 0 | Q37: =SUM(E37:P37) -> 0 | R37: B. PEGAWAI | T37: =E37 -> 0 | U37: =SUM(E37:F37) -> 0 | V37: =SUM(E37:G37) -> 0 | W37: =SUM(E37:H37) -> 0 | X37: =SUM(E37:I37) -> 0 | Y37: =SUM(E37:J37) -> 0 | Z37: =SUM(E37:K37) -> 0 | AA37: =SUM(E37:L37) -> 0 | AB37: =SUM(E37:M37) -> 0 | AC37: =SUM(E37:N37) -> 0 | AD37: =SUM(E37:O37) -> 0 | AE37: =SUM(E37:P37) -> 0
C38: Gaji & honor Pengolahan Air | Q38: =SUM(E38:P38) -> 0 | T38: =E38 -> 0 | U38: =SUM(E38:F38) -> 0 | V38: =SUM(E38:G38) -> 0 | W38: =SUM(E38:H38) -> 0 | X38: =SUM(E38:I38) -> 0 | Y38: =SUM(E38:J38) -> 0 | Z38: =SUM(E38:K38) -> 0 | AA38: =SUM(E38:L38) -> 0 | AB38: =SUM(E38:M38) -> 0 | AC38: =SUM(E38:N38) -> 0 | AD38: =SUM(E38:O38) -> 0 | AE38: =SUM(E38:P38) -> 0
D39: PUSAT - INDUK | Q39: =SUM(E39:P39) -> 0 | T39: =E39 -> 0 | U39: =SUM(E39:F39) -> 0 | V39: =SUM(E39:G39) -> 0 | W39: =SUM(E39:H39) -> 0 | X39: =SUM(E39:I39) -> 0 | Y39: =SUM(E39:J39) -> 0 | Z39: =SUM(E39:K39) -> 0 | AA39: =SUM(E39:L39) -> 0 | AB39: =SUM(E39:M39) -> 0 | AC39: =SUM(E39:N39) -> 0 | AD39: =SUM(E39:O39) -> 0 | AE39: =SUM(E39:P39) -> 0
D40: IKK KARTIKA BHAKTI | Q40: =SUM(E40:P40) -> 0 | T40: =E40 -> 0 | U40: =SUM(E40:F40) -> 0 | V40: =SUM(E40:G40) -> 0 | W40: =SUM(E40:H40) -> 0 | X40: =SUM(E40:I40) -> 0 | Y40: =SUM(E40:J40) -> 0 | Z40: =SUM(E40:K40) -> 0 | AA40: =SUM(E40:L40) -> 0 | AB40: =SUM(E40:M40) -> 0 | AC40: =SUM(E40:N40) -> 0 | AD40: =SUM(E40:O40) -> 0 | AE40: =SUM(E40:P40) -> 0
D41: IKK PEMBUANG HULU | Q41: =SUM(E41:P41) -> 0 | T41: =E41 -> 0 | U41: =SUM(E41:F41) -> 0 | V41: =SUM(E41:G41) -> 0 | W41: =SUM(E41:H41) -> 0 | X41: =SUM(E41:I41) -> 0 | Y41: =SUM(E41:J41) -> 0 | Z41: =SUM(E41:K41) -> 0 | AA41: =SUM(E41:L41) -> 0 | AB41: =SUM(E41:M41) -> 0 | AC41: =SUM(E41:N41) -> 0 | AD41: =SUM(E41:O41) -> 0 | AE41: =SUM(E41:P41) -> 0
C42: Lembur | Q42: =SUM(E42:P42) -> 0 | R42: B. PEGAWAI | T42: =E42 -> 0 | U42: =SUM(E42:F42) -> 0 | V42: =SUM(E42:G42) -> 0 | W42: =SUM(E42:H42) -> 0 | X42: =SUM(E42:I42) -> 0 | Y42: =SUM(E42:J42) -> 0 | Z42: =SUM(E42:K42) -> 0 | AA42: =SUM(E42:L42) -> 0 | AB42: =SUM(E42:M42) -> 0 | AC42: =SUM(E42:N42) -> 0 | AD42: =SUM(E42:O42) -> 0 | AE42: =SUM(E42:P42) -> 0
...

Sheet RINCIAN B. TDK LANGSUNG
A1: PEMERINTAH KABUPATEN SERUYAN
A2: PERUSAHAAN DAERAH AIR MINUM (PDAM) | Q2: P-11
A4: RINCIAN BIAYA UMUM DAN ADMINISTRASI
A5: TAHUN ANGGARAN 2026
A7: PDAM KABUPATEN SERUYAN
A8: NO | B8: URAIAN | E8: BULAN | Q8: JUMLAH | R8: MAPPING BEBAN
A9: PERK. | E9: 1 | F9: 2 | G9: 3 | H9: 4 | I9: 5 | J9: 6 | K9: 7 | L9: 8 | M9: 9 | N9: 10 | O9: 11 | P9: 12 | Q9: 2025 | R9: SAK - ETAP
A10: 1 | B10: 2 | E10: 3 | F10: 4 | G10: 5 | H10: 6 | I10: 7 | J10: 8 | K10: 9 | L10: 10 | M10: 11 | N10: 12 | O10: 13 | P10: 14 | Q10: 15 | R10: 16
A11: 97.00.00 | B11: BEBAN UMUM & ADMINISTRASI | T11: 1 | U11: 2 | V11: 3 | W11: 4 | X11: 5 | Y11: 6 | Z11: 7 | AA11: 8 | AB11: 9 | AC11: 10 | AD11: 11 | AE11: 12
A12: 97.01.10 | B12: Beban Pegawai Umum & Adm | E12: =SUM(E13:E16) -> 0 | F12: =SUM(F13:F16) -> 0 | G12: =SUM(G13:G16) -> 0 | H12: =SUM(H13:H16) -> 0 | I12: =SUM(I13:I16) -> 0 | J12: =SUM(J13:J16) -> 0 | K12: =SUM(K13:K16) -> 0 | L12: =SUM(L13:L16) -> 0 | ... P12: =SUM(P13:P16) -> 0 | Q12: =SUM(E12:P12) -> 0 | T12: =E12 -> 0 | U12: =SUM(E12:F12) -> 0 | V12: =SUM(E12:G12) -> 0 | W12: =SUM(E12:H12) -> 0 | X12: =SUM(E12:I12) -> 0 | Y12: =SUM(E12:J12) -> 0 | Z12: =SUM(E12:K12) -> 0 | AA12: =SUM(E12:L12) -> 0 | AB12: =SUM(E12:M12) -> 0 | AC12: =SUM(E12:N12) -> 0 | AD12: =SUM(E12:O12) -> 0 | AE12: =SUM(E12:P12) -> 0
C13: Direktur | Q13: =SUM(E13:P13) -> 0 | T13: =E13 -> 0 | U13: =SUM(E13:F13) -> 0 | V13: =SUM(E13:G13) -> 0 | W13: =SUM(E13:H13) -> 0 | X13: =SUM(E13:I13) -> 0 | Y13: =SUM(E13:J13) -> 0 | Z13: =SUM(E13:K13) -> 0 | AA13: =SUM(E13:L13) -> 0 | AB13: =SUM(E13:M13) -> 0 | AC13: =SUM(E13:N13) -> 0 | AD13: =SUM(E13:O13) -> 0 | AE13: =SUM(E13:P13) -> 0
C14: Pegawai Adm &Umum | Q14: =SUM(E14:P14) -> 0 | T14: =E14 -> 0 | U14: =SUM(E14:F14) -> 0 | V14: =SUM(E14:G14) -> 0 | W14: =SUM(E14:H14) -> 0 | X14: =SUM(E14:I14) -> 0 | Y14: =SUM(E14:J14) -> 0 | Z14: =SUM(E14:K14) -> 0 | AA14: =SUM(E14:L14) -> 0 | AB14: =SUM(E14:M14) -> 0 | AC14: =SUM(E14:N14) -> 0 | AD14: =SUM(E14:O14) -> 0 | AE14: =SUM(E14:P14) -> 0
C15: Lembur | Q15: =SUM(E15:P15) -> 0 | T15: =E15 -> 0 | U15: =SUM(E15:F15) -> 0 | V15: =SUM(E15:G15) -> 0 | W15: =SUM(E15:H15) -> 0 | X15: =SUM(E15:I15) -> 0 | Y15: =SUM(E15:J15) -> 0 | Z15: =SUM(E15:K15) -> 0 | AA15: =SUM(E15:L15) -> 0 | AB15: =SUM(E15:M15) -> 0 | AC15: =SUM(E15:N15) -> 0 | AD15: =SUM(E15:O15) -> 0 | AE15: =SUM(E15:P15) -> 0
C16: Insentife/THR/Dana Kesejahteraan/Bonus | Q16: =SUM(E16:P16) -> 0 | T16: =E16 -> 0 | U16: =SUM(E16:F16) -> 0 | V16: =SUM(E16:G16) -> 0 | W16: =SUM(E16:H16) -> 0 | X16: =SUM(E16:I16) -> 0 | Y16: =SUM(E16:J16) -> 0 | Z16: =SUM(E16:K16) -> 0 | AA16: =SUM(E16:L16) -> 0 | AB16: =SUM(E16:M16) -> 0 | AC16: =SUM(E16:N16) -> 0 | AD16: =SUM(E16:O16) -> 0 | AE16: =SUM(E16:P16) -> 0
A17: 97.01.20 | B17: Beban Kesejahteraan Karyawan Adm Umum | E17: =SUM(E18:E22) -> 0 | F17: =SUM(F18:F22) -> 0 | G17: =SUM(G18:G22) -> 0 | H17: =SUM(H18:H22) -> 0 | I17: =SUM(I18:I22) -> 0 | J17: =SUM(J18:J22) -> 0 | K17: =SUM(K18:K22) -> 0 | L17: =SUM(L18:L22) -> 0 | ... P17: =SUM(P18:P22) -> 0 | Q17: =SUM(E17:P17) -> 0 | T17: =E17 -> 0 | U17: =SUM(E17:F17) -> 0 | V17: =SUM(E17:G17) -> 0 | W17: =SUM(E17:H17) -> 0 | X17: =SUM(E17:I17) -> 0 | Y17: =SUM(E17:J17) -> 0 | Z17: =SUM(E17:K17) -> 0 | AA17: =SUM(E17:L17) -> 0 | AB17: =SUM(E17:M17) -> 0 | AC17: =SUM(E17:N17) -> 0 | AD17: =SUM(E17:O17) -> 0 | AE17: =SUM(E17:P17) -> 0
C18: Iuran Dana Pensiun | Q18: =SUM(E18:P18) -> 0 | T18: =E18 -> 0 | U18: =SUM(E18:F18) -> 0 | V18: =SUM(E18:G18) -> 0 | W18: =SUM(E18:H18) -> 0 | X18: =SUM(E18:I18) -> 0 | Y18: =SUM(E18:J18) -> 0 | Z18: =SUM(E18:K18) -> 0 | AA18: =SUM(E18:L18) -> 0 | AB18: =SUM(E18:M18) -> 0 | AC18: =SUM(E18:N18) -> 0 | AD18: =SUM(E18:O18) -> 0 | AE18: =SUM(E18:P18) -> 0
C19: Beban BPJS Kesehatan | Q19: =SUM(E19:P19) -> 0 | T19: =E19 -> 0 | U19: =SUM(E19:F19) -> 0 | V19: =SUM(E19:G19) -> 0 | W19: =SUM(E19:H19) -> 0 | X19: =SUM(E19:I19) -> 0 | Y19: =SUM(E19:J19) -> 0 | Z19: =SUM(E19:K19) -> 0 | AA19: =SUM(E19:L19) -> 0 | AB19: =SUM(E19:M19) -> 0 | AC19: =SUM(E19:N19) -> 0 | AD19: =SUM(E19:O19) -> 0 | AE19: =SUM(E19:P19) -> 0
C20: Beban BPJS Ketenagakerjaan | Q20: =SUM(E20:P20) -> 0 | T20: =E20 -> 0 | U20: =SUM(E20:F20) -> 0 | V20: =SUM(E20:G20) -> 0 | W20: =SUM(E20:H20) -> 0 | X20: =SUM(E20:I20) -> 0 | Y20: =SUM(E20:J20) -> 0 | Z20: =SUM(E20:K20) -> 0 | AA20: =SUM(E20:L20) -> 0 | AB20: =SUM(E20:M20) -> 0 | AC20: =SUM(E20:N20) -> 0 | AD20: =SUM(E20:O20) -> 0 | AE20: =SUM(E20:P20) -> 0
C21: Uang Makan & Minum | Q21: =SUM(E21:P21) -> 0 | T21: =E21 -> 0 | U21: =SUM(E21:F21) -> 0 | V21: =SUM(E21:G21) -> 0 | W21: =SUM(E21:H21) -> 0 | X21: =SUM(E21:I21) -> 0 | Y21: =SUM(E21:J21) -> 0 | Z21: =SUM(E21:K21) -> 0 | AA21: =SUM(E21:L21) -> 0 | AB21: =SUM(E21:M21) -> 0 | AC21: =SUM(E21:N21) -> 0 | AD21: =SUM(E21:O21) -> 0 | AE21: =SUM(E21:P21) -> 0
C22: Uang Pisah / Purna Tugas | Q22: =SUM(E22:P22) -> 0 | T22: =E22 -> 0 | U22: =SUM(E22:F22) -> 0 | V22: =SUM(E22:G22) -> 0 | W22: =SUM(E22:H22) -> 0 | X22: =SUM(E22:I22) -> 0 | Y22: =SUM(E22:J22) -> 0 | Z22: =SUM(E22:K22) -> 0 | AA22: =SUM(E22:L22) -> 0 | AB22: =SUM(E22:M22) -> 0 | AC22: =SUM(E22:N22) -> 0 | AD22: =SUM(E22:O22) -> 0 | AE22: =SUM(E22:P22) -> 0
A23: 97.01.30 | B23: Beban Pakaian Dinas & Olahraga | Q23: =SUM(E23:P23) -> 0 | T23: =E23 -> 0 | U23: =SUM(E23:F23) -> 0 | V23: =SUM(E23:G23) -> 0 | W23: =SUM(E23:H23) -> 0 | X23: =SUM(E23:I23) -> 0 | Y23: =SUM(E23:J23) -> 0 | Z23: =SUM(E23:K23) -> 0 | AA23: =SUM(E23:L23) -> 0 | AB23: =SUM(E23:M23) -> 0 | AC23: =SUM(E23:N23) -> 0 | AD23: =SUM(E23:O23) -> 0 | AE23: =SUM(E23:P23) -> 0
A24: 97.01.40 | B24: Pendidikan dan latihan | Q24: =SUM(E24:P24) -> 0 | T24: =E24 -> 0 | U24: =SUM(E24:F24) -> 0 | V24: =SUM(E24:G24) -> 0 | W24: =SUM(E24:H24) -> 0 | X24: =SUM(E24:I24) -> 0 | Y24: =SUM(E24:J24) -> 0 | Z24: =SUM(E24:K24) -> 0 | AA24: =SUM(E24:L24) -> 0 | AB24: =SUM(E24:M24) -> 0 | AC24: =SUM(E24:N24) -> 0 | AD24: =SUM(E24:O24) -> 0 | AE24: =SUM(E24:P24) -> 0
A25: 97.01.50 | B25: Beban Pembinaan Pegawai Umum | Q25: =SUM(E25:P25) -> 0 | T25: =E25 -> 0 | U25: =SUM(E25:F25) -> 0 | V25: =SUM(E25:G25) -> 0 | W25: =SUM(E25:H25) -> 0 | X25: =SUM(E25:I25) -> 0 | Y25: =SUM(E25:J25) -> 0 | Z25: =SUM(E25:K25) -> 0 | AA25: =SUM(E25:L25) -> 0 | AB25: =SUM(E25:M25) -> 0 | AC25: =SUM(E25:N25) -> 0 | AD25: =SUM(E25:O25) -> 0 | AE25: =SUM(E25:P25) -> 0
A26: 97.01.60 | B26: Beban Bantuan & sumbangan | Q26: =SUM(E26:P26) -> 0 | T26: =E26 -> 0 | U26: =SUM(E26:F26) -> 0 | V26: =SUM(E26:G26) -> 0 | W26: =SUM(E26:H26) -> 0 | X26: =SUM(E26:I26) -> 0 | Y26: =SUM(E26:J26) -> 0 | Z26: =SUM(E26:K26) -> 0 | AA26: =SUM(E26:L26) -> 0 | AB26: =SUM(E26:M26) -> 0 | AC26: =SUM(E26:N26) -> 0 | AD26: =SUM(E26:O26) -> 0 | AE26: =SUM(E26:P26) -> 0
A27: 97.01.90 | B27: Rupa-Rupa Beban Pegawai | Q27: =SUM(E27:P27) -> 0 | T27: =E27 -> 0 | U27: =SUM(E27:F27) -> 0 | V27: =SUM(E27:G27) -> 0 | W27: =SUM(E27:H27) -> 0 | X27: =SUM(E27:I27) -> 0 | Y27: =SUM(E27:J27) -> 0 | Z27: =SUM(E27:K27) -> 0 | AA27: =SUM(E27:L27) -> 0 | AB27: =SUM(E27:M27) -> 0 | AC27: =SUM(E27:N27) -> 0 | AD27: =SUM(E27:O27) -> 0 | AE27: =SUM(E27:P27) -> 0
B28: Pjak Pegawai | Q28: =SUM(E28:P28) -> 0 | T28: =E28 -> 0 | U28: =SUM(E28:F28) -> 0 | V28: =SUM(E28:G28) -> 0 | W28: =SUM(E28:H28) -> 0 | X28: =SUM(E28:I28) -> 0 | Y28: =SUM(E28:J28) -> 0 | Z28: =SUM(E28:K28) -> 0 | AA28: =SUM(E28:L28) -> 0 | AB28: =SUM(E28:M28) -> 0 | AC28: =SUM(E28:N28) -> 0 | AD28: =SUM(E28:O28) -> 0 | AE28: =SUM(E28:P28) -> 0
B29: Jumlah Beban Pegawai | E29: =SUM(E23:E28)+E17+E12 -> 0 | F29: =SUM(F23:F28)+F17+F12 -> 0 | G29: =SUM(G23:G28)+G17+G12 -> 0 | H29: =SUM(H23:H28)+H17+H12 -> 0 | I29: =SUM(I23:I28)+I17+I12 -> 0 | J29: =SUM(J23:J28)+J17+J12 -> 0 | K29: =SUM(K23:K28)+K17+K12 -> 0 | L29: =SUM(L23:L28)+L17+L12 -> 0 | ... P29: =SUM(P23:P28)+P17+P12 -> 0 | Q29: =SUM(E29:P29) -> 0 | R29: B. PEGAWAI | T29: =E29 -> 0 | U29: =SUM(E29:F29) -> 0 | V29: =SUM(E29:G29) -> 0 | W29: =SUM(E29:H29) -> 0 | X29: =SUM(E29:I29) -> 0 | Y29: =SUM(E29:J29) -> 0 | Z29: =SUM(E29:K29) -> 0 | AA29: =SUM(E29:L29) -> 0 | AB29: =SUM(E29:M29) -> 0 | AC29: =SUM(E29:N29) -> 0 | AD29: =SUM(E29:O29) -> 0 | AE29: =SUM(E29:P29) -> 0
A30: 97.02.00 | B30: BEBAN KANTOR | Q30: =SUM(E30:P30) -> 0 | T30: =E30 -> 0 | U30: =SUM(E30:F30) -> 0 | V30: =SUM(E30:G30) -> 0 | W30: =SUM(E30:H30) -> 0 | X30: =SUM(E30:I30) -> 0 | Y30: =SUM(E30:J30) -> 0 | Z30: =SUM(E30:K30) -> 0 | AA30: =SUM(E30:L30) -> 0 | AB30: =SUM(E30:M30) -> 0 | AC30: =SUM(E30:N30) -> 0 | AD30: =SUM(E30:O30) -> 0 | AE30: =SUM(E30:P30) -> 0
A31: 97.02.10 | B31: Beban Alat Tulis Kantor dan Fotocopy | Q31: =SUM(E31:P31) -> 0 | T31: =E31 -> 0 | U31: =SUM(E31:F31) -> 0 | V31: =SUM(E31:G31) -> 0 | W31: =SUM(E31:H31) -> 0 | X31: =SUM(E31:I31) -> 0 | Y31: =SUM(E31:J31) -> 0 | Z31: =SUM(E31:K31) -> 0 | AA31: =SUM(E31:L31) -> 0 | AB31: =SUM(E31:M31) -> 0 | AC31: =SUM(E31:N31) -> 0 | AD31: =SUM(E31:O31) -> 0 | AE31: =SUM(E31:P31) -> 0
A32: 97.02.20 | B32: Barang-barang Cetakkan | Q32: =SUM(E32:P32) -> 0 | T32: =E32 -> 0 | U32: =SUM(E32:F32) -> 0 | V32: =SUM(E32:G32) -> 0 | W32: =SUM(E32:H32) -> 0 | X32: =SUM(E32:I32) -> 0 | Y32: =SUM(E32:J32) -> 0 | Z32: =SUM(E32:K32) -> 0 | AA32: =SUM(E32:L32) -> 0 | AB32: =SUM(E32:M32) -> 0 | AC32: =SUM(E32:N32) -> 0 | AD32: =SUM(E32:O32) -> 0 | AE32: =SUM(E32:P32) -> 0
A33: 97.02.30 | B33: Perlengkapan Komputer | Q33: =SUM(E33:P33) -> 0 | T33: =E33 -> 0 | U33: =SUM(E33:F33) -> 0 | V33: =SUM(E33:G33) -> 0 | W33: =SUM(E33:H33) -> 0 | X33: =SUM(E33:I33) -> 0 | Y33: =SUM(E33:J33) -> 0 | Z33: =SUM(E33:K33) -> 0 | AA33: =SUM(E33:L33) -> 0 | AB33: =SUM(E33:M33) -> 0 | AC33: =SUM(E33:N33) -> 0 | AD33: =SUM(E33:O33) -> 0 | AE33: =SUM(E33:P33) -> 0
A34: 97.02.40 | B34: Beban Telepon, Telek dan Telegram | Q34: =SUM(E34:P34) -> 0 | T34: =E34 -> 0 | U34: =SUM(E34:F34) -> 0 | V34: =SUM(E34:G34) -> 0 | W34: =SUM(E34:H34) -> 0 | X34: =SUM(E34:I34) -> 0 | Y34: =SUM(E34:J34) -> 0 | Z34: =SUM(E34:K34) -> 0 | AA34: =SUM(E34:L34) -> 0 | AB34: =SUM(E34:M34) -> 0 | AC34: =SUM(E34:N34) -> 0 | AD34: =SUM(E34:O34) -> 0 | AE34: =SUM(E34:P34) -> 0
A35: 97.02.50 | B35: Beban Rapat dan Tamu | Q35: =SUM(E35:P35) -> 0 | T35: =E35 -> 0 | U35: =SUM(E35:F35) -> 0 | V35: =SUM(E35:G35) -> 0 | W35: =SUM(E35:H35) -> 0 | X35: =SUM(E35:I35) -> 0 | Y35: =SUM(E35:J35) -> 0 | Z35: =SUM(E35:K35) -> 0 | AA35: =SUM(E35:L35) -> 0 | AB35: =SUM(E35:M35) -> 0 | AC35: =SUM(E35:N35) -> 0 | AD35: =SUM(E35:O35) -> 0 | AE35: =SUM(E35:P35) -> 0
C36: Dana Representatif Direktur | Q36: =SUM(E36:P36) -> 0 | T36: =E36 -> 0 | U36: =SUM(E36:F36) -> 0 | V36: =SUM(E36:G36) -> 0 | W36: =SUM(E36:H36) -> 0 | X36: =SUM(E36:I36) -> 0 | Y36: =SUM(E36:J36) -> 0 | Z36: =SUM(E36:K36) -> 0 | AA36: =SUM(E36:L36) -> 0 | AB36: =SUM(E36:M36) -> 0 | AC36: =SUM(E36:N36) -> 0 | AD36: =SUM(E36:O36) -> 0 | AE36: =SUM(E36:P36) -> 0
C37: Biaya Rapat dan Tamu | Q37: =SUM(E37:P37) -> 0 | T37: =E37 -> 0 | U37: =SUM(E37:F37) -> 0 | V37: =SUM(E37:G37) -> 0 | W37: =SUM(E37:H37) -> 0 | X37: =SUM(E37:I37) -> 0 | Y37: =SUM(E37:J37) -> 0 | Z37: =SUM(E37:K37) -> 0 | AA37: =SUM(E37:L37) -> 0 | AB37: =SUM(E37:M37) -> 0 | AC37: =SUM(E37:N37) -> 0 | AD37: =SUM(E37:O37) -> 0 | AE37: =SUM(E37:P37) -> 0
A38: 97.02.60 | B38: Benda Pos dan materai | Q38: =SUM(E38:P38) -> 0 | T38: =E38 -> 0 | U38: =SUM(E38:F38) -> 0 | V38: =SUM(E38:G38) -> 0 | W38: =SUM(E38:H38) -> 0 | X38: =SUM(E38:I38) -> 0 | Y38: =SUM(E38:J38) -> 0 | Z38: =SUM(E38:K38) -> 0 | AA38: =SUM(E38:L38) -> 0 | AB38: =SUM(E38:M38) -> 0 | AC38: =SUM(E38:N38) -> 0 | AD38: =SUM(E38:O38) -> 0 | AE38: =SUM(E38:P38) -> 0
A39: 97.02.70 | B39: Beban Listrik/Penerangan | Q39: =SUM(E39:P39) -> 0 | T39: =E39 -> 0 | U39: =SUM(E39:F39) -> 0 | V39: =SUM(E39:G39) -> 0 | W39: =SUM(E39:H39) -> 0 | X39: =SUM(E39:I39) -> 0 | Y39: =SUM(E39:J39) -> 0 | Z39: =SUM(E39:K39) -> 0 | AA39: =SUM(E39:L39) -> 0 | AB39: =SUM(E39:M39) -> 0 | AC39: =SUM(E39:N39) -> 0 | AD39: =SUM(E39:O39) -> 0 | AE39: =SUM(E39:P39) -> 0
A40: 97.02.80 | B40: Beban cleaning Service | Q40: =SUM(E40:P40) -> 0 | T40: =E40 -> 0 | U40: =SUM(E40:F40) -> 0 | V40: =SUM(E40:G40) -> 0 | W40: =SUM(E40:H40) -> 0 | X40: =SUM(E40:I40) -> 0 | Y40: =SUM(E40:J40) -> 0 | Z40: =SUM(E40:K40) -> 0 | AA40: =SUM(E40:L40) -> 0 | AB40: =SUM(E40:M40) -> 0 | AC40: =SUM(E40:N40) -> 0 | AD40: =SUM(E40:O40) -> 0 | AE40: =SUM(E40:P40) -> 0
A41: 97.02.90 | B41: Rupa-rupa Beban Kantor | Q41: =SUM(E41:P41) -> 0 | T41: =E41 -> 0 | U41: =SUM(E41:F41) -> 0 | V41: =SUM(E41:G41) -> 0 | W41: =SUM(E41:H41) -> 0 | X41: =SUM(E41:I41) -> 0 | Y41: =SUM(E41:J41) -> 0 | Z41: =SUM(E41:K41) -> 0 | AA41: =SUM(E41:L41) -> 0 | AB41: =SUM(E41:M41) -> 0 | AC41: =SUM(E41:N41) -> 0 | AD41: =SUM(E41:O41) -> 0 | AE41: =SUM(E41:P41) -> 0
B42: Paket Internet (Wifi) | Q42: =SUM(E42:P42) -> 0 | T42: =E42 -> 0 | U42: =SUM(E42:F42) -> 0 | V42: =SUM(E42:G42) -> 0 | W42: =SUM(E42:H42) -> 0 | X42: =SUM(E42:I42) -> 0 | Y42: =SUM(E42:J42) -> 0 | Z42: =SUM(E42:K42) -> 0 | AA42: =SUM(E42:L42) -> 0 | AB42: =SUM(E42:M42) -> 0 | AC42: =SUM(E42:N42) -> 0 | AD42: =SUM(E42:O42) -> 0 | AE42: =SUM(E42:P42) -> 0
...

Sheet B. NON OPERASIONAL
A1: PEMERINTAH KABUPATEN SERUYAN
A2: PERUSAHAAN DAERAH AIR MINUM (PDAM) | O2: P-12
A4: RENCANA BIAYA DILUAR USAHA / LAIN-LAIN
A5: TAHUN ANGGARAN 2025
A7: PDAM KABUPATEN SERUYAN
A8: NO | B8: URAIAN | C8: BULAN | O8: JUMLAH | P8: MAPPING BEBAN
A9: PERK. | C9: 1 | D9: 2 | E9: 3 | F9: 4 | G9: 5 | H9: 6 | I9: 7 | J9: 8 | K9: 9 | L9: 10 | M9: 11 | N9: 12 | O9: 2025 | P9: SAK ETAP
A10: 1 | B10: 2 | C10: 3 | D10: 4 | E10: 5 | F10: 6 | G10: 7 | H10: 8 | I10: 9 | J10: 10 | K10: 11 | L10: 12 | M10: 13 | N10: 14 | O10: 15 | P10: 16
A11: 98.00.00 | B11: BEBAN NON OPERASIONAL
A12: 98.01.00 | B12: Beban Bank | O12: =SUM(C12:N12) -> 0 | P12: B. BANK
A14: JUMLAH BIAYA UMUM & ADM | C14: =SUM(C11:C13) -> 0 | D14: =SUM(D11:D13) -> 0 | E14: =SUM(E11:E13) -> 0 | F14: =SUM(F11:F13) -> 0 | G14: =SUM(G11:G13) -> 0 | H14: =SUM(H11:H13) -> 0 | I14: =SUM(I11:I13) -> 0 | J14: =SUM(J11:J13) -> 0 | ... O14: =SUM(O11:O13) -> 0

Sheet P-9. Beban Operasi
A1: PEMERINTAH KABUPATEN SERUYAN
A2: PERUSAHAAN UMUM DAERAH AIR MINUM (PERUMDAM) | P2: LAMPIRAN 9
A3: TIRTA SERUYAN
A4: RENCANA BIAYA OPERASI
A5: TAHUN ANGGARAN 2026 | S5: =S64+S113+'P-10. Beban Umum & Adm'!S25 -> 0
A7: PERUMDAM TIRTA SERUYAN
A8: NO | B8: URAIAN | E8: BULAN | Q8: JUMLAH | R8: REALISASI | S8: SISA
A9: PERK. | E9: 1 | F9: 2 | G9: 3 | H9: 4 | I9: 5 | J9: 6 | K9: 7 | L9: 8 | M9: 9 | N9: 10 | O9: 11 | P9: 12 | Q9: 2026 | R9: 2026 | S9: 2026
A10: 1 | B10: 2 | E10: 3 | F10: 4 | G10: 5 | H10: 6 | I10: 7 | J10: 8 | K10: 9 | L10: 10 | M10: 11 | N10: 12 | O10: 13 | P10: 14 | Q10: 16
A11: 91.00.00 | B11: BEBAN SUMBER AIR | Q11: =SUM(F11:P11) -> 0 | S11: =Q11-R11 -> 0
A12: 91.01.00 | B12: BEBAN OPERASIONAL SUMBER AIR | Q12: =SUM(E12:P12) -> 0 | S12: =Q12-R12 -> 0
A13: 91.01.10 | B13: Biaya Pegawai | Q13: =SUM(E13:P13) -> 0 | S13: =Q13-R13 -> 0
B14: Gaji dan Honor Sumber Air | Q14: =SUM(E14:P14) -> 0 | S14: =Q14-R14 -> 0
B15: Insentif / THR dan Bonus | Q15: =SUM(E15:P15) -> 0 | S15: =Q15-R15 -> 0
A16: 91.01.20 | B16: Beban Kesejahteraan Karyawan Sumber Air | Q16: =SUM(E16:P16) -> 0 | S16: =Q16-R16 -> 0
B17: Beban Iuran Dana Pensiun Sumber Air | Q17: =SUM(E17:P17) -> 0 | S17: =Q17-R17 -> 0
B18: Beban BPJS Kesehatan Sumber Air | Q18: =SUM(E18:P18) -> 0 | S18: =Q18-R18 -> 0
B19: Beban BPJS Ketenagkerjaan Sumber Air | Q19: =SUM(E19:P19) -> 0 | S19: =Q19-R19 -> 0
B20: Uang Makan dan minum Sumber Air | Q20: =SUM(E20:P20) -> 0 | S20: =Q20-R20 -> 0
B21: Uang Pisah/Purna Tugas | Q21: =SUM(E21:P21) -> 0 | S21: =Q21-R21 -> 0
A22: 91.01.30 | B22: Beban Pakaian Dinas & Olahraga | Q22: =SUM(E22:P22) -> 0 | S22: =Q22-R22 -> 0
A23: 91.01.40 | B23: Beban Pendidikan & latihan Sumber air | Q23: =SUM(E23:P23) -> 0 | S23: =Q23-R23 -> 0
A24: 91.01.50 | B24: Beban Pembinaan Pegawai Sumber Air | Q24: =SUM(E24:P24) -> 0 | S24: =Q24-R24 -> 0
A25: 91.02.10 | B25: Pemakaian Bahan bakar (SOLAR) | Q25: =SUM(E25:P25) -> 0 | S25: =Q25-R25 -> 0
C26: Intake Sei. Mitak | Q26: =SUM(E26:P26) -> 0 | U26: asumsi harga dexlite 15,000
C27: Intake Tanjung Paring | Q27: =SUM(E27:P27) -> 0 | Z27: =Q28-S28 -> 0
C28: Jumlah Bahan Bakar | E28: =SUM(E26:E27) -> 0 | F28: =SUM(F26:F27) -> 0 | G28: =SUM(G26:G27) -> 0 | H28: =SUM(H26:H27) -> 0 | I28: =SUM(I26:I27) -> 0 | J28: =SUM(J26:J27) -> 0 | K28: =SUM(K26:K27) -> 0 | L28: =SUM(L26:L27) -> 0 | ... Q28: =SUM(Q26:Q27) -> 0 | R28: ='RINCIAN B. LANGSUNG USAHA'!Q18 -> 0 | S28: =Q28-R28 -> 0 | Z28: =Q29-S29 -> 0
A29: 91.02.20 | B29: Biaya Listrik PLN | Q29: =SUM(E29:P29) -> 0 | S29: =Q29-R29 -> 0 | Z29: =Q30-S30 -> 0
C30: Induk PDAM | Q30: =SUM(E30:P30) -> 0 | Z30: =Q31-S31 -> 0
C31: IKK Kartika Bhakti | Q31: =SUM(E31:P31) -> 0 | Z31: =Q32-S32 -> 0
C32: IKK Pembuang Hulu | Q32: =SUM(E32:P32) -> 0 | Z32: =Q33-S33 -> 0
C33: Jumlah Biaya Listrik PLN | E33: =SUM(E30:E32) -> 0 | F33: =SUM(F30:F32) -> 0 | G33: =SUM(G30:G32) -> 0 | H33: =SUM(H30:H32) -> 0 | I33: =SUM(I30:I32) -> 0 | J33: =SUM(J30:J32) -> 0 | K33: =SUM(K30:K32) -> 0 | L33: =SUM(L30:L32) -> 0 | ... Q33: =SUM(Q30:Q32) -> 0 | R33: ='RINCIAN B. LANGSUNG USAHA'!Q19 -> 0 | S33: =Q33-R33 -> 0 | Z33: =Q34-S34 -> 0
A34: 91.02.30 | B34: Pemakaian Bahan Pembantu | Q34: =SUM(E34:P34) -> 0 | R34: ='RINCIAN B. LANGSUNG USAHA'!Q20 -> 0 | S34: =Q34-R34 -> 0 | Z34: =Q35-S35 -> 0
A35: 91.02.40 | B35: Rupa-Rupa Biaya Operasi Sumber Air | Q35: =SUM(E35:P35) -> 0 | R35: ='RINCIAN B. LANGSUNG USAHA'!Q21 -> 0 | S35: =Q35-R35 -> 0 | Z35: =Q36-S36 -> 0
B36: Beban Operasi Sumber Air | E36: =SUM(E13:E24)+E28+E33+E34+E35 -> 0 | F36: =SUM(F13:F24)+F28+F33+F34+F35 -> 0 | G36: =SUM(G13:G24)+G28+G33+G34+G35 -> 0 | H36: =SUM(H13:H24)+H28+H33+H34+H35 -> 0 | I36: =SUM(I13:I24)+I28+I33+I34+I35 -> 0 | J36: =SUM(J13:J24)+J28+J33+J34+J35 -> 0 | K36: =SUM(K13:K24)+K28+K33+K34+K35 -> 0 | L36: =SUM(L13:L24)+L28+L33+L34+L35 -> 0 | ... P36: =SUM(P13:P24)+P28+P33+P34+P35 -> 0 | Q36: =SUM(E36:P36) -> 0 | R36: =SUM(R11:R35) -> 0 | S36: =SUM(S11:S35) -> 0 | T36: ='RINCIAN B. LANGSUNG USAHA'!Q22 -> 0 | Z36: =Q37-S37 -> 0
A37: 91.03.00 | B37: BEBAN PEMELIHARAAN SUMBER AIR | Z37: =Q38-S38 -> 0
A38: 91.03.10 | B38: Pemeliharaan bangunan dan penyempurnaan tanah | Q38: =SUM(E38:P38) -> 0 | R38: ='RINCIAN B. LANGSUNG USAHA'!Q24 -> 0 | S38: =Q38-R38 -> 0 | U38: Perbaikan intake | Z38: =Q39-S39 -> 0
A39: 91.03.40 | B39: Pemeliharaan Mata air dan Saluran | Q39: =SUM(E39:P39) -> 0 | R39: ='RINCIAN B. LANGSUNG USAHA'!Q25 -> 0 | S39: =Q39-R39 -> 0 | Z39: =Q40-S40 -> 0
A40: 91.03.60 | B40: Pemeliharaan Pipa Induk | Q40: =SUM(E40:P40) -> 0 | R40: ='RINCIAN B. LANGSUNG USAHA'!Q26 -> 0 | S40: =Q40-R40 -> 0 | Z40: =Q41-S41 -> 0
A41: 91.03.70 | B41: Pemeliharaan Alat Pembangkit Tenaga | Q41: =SUM(E41:P41) -> 0 | R41: ='RINCIAN B. LANGSUNG USAHA'!Q27 -> 0 | S41: =Q41-R41 -> 0 | Z41: =Q42-S42 -> 0
...

Sheet P-10. Beban Umum & Adm
A1: PEMERINTAH KABUPATEN SERUYAN
A2: PERUSAHAAN UMUM DAERAH AIR MINUM (PERUMDAM) | P2: LAMPIRAN 10
A3: TIRTA SERUYAN
A5: RENCANA BIAYA UMUM DAN ADMINISTRASI
A6: TAHUN ANGGARAN 2026
A8: PERUMDAM TIRTA SERUYAN
A9: NO | B9: URAIAN | E9: BULAN | Q9: JUMLAH | R9: REALISASI | S9: SISA
A10: PERK. | E10: 1 | F10: 2 | G10: 3 | H10: 4 | I10: 5 | J10: 6 | K10: 7 | L10: 8 | M10: 9 | N10: 10 | O10: 11 | P10: 12 | Q10: 2026 | R10: 2026 | S10: 2026
A11: 1 | B11: 2 | E11: 3 | F11: 4 | G11: 5 | H11: 6 | I11: 7 | J11: 8 | K11: 9 | L11: 10 | M11: 11 | N11: 12 | O11: 13 | P11: 14 | Q11: 15
A12: 97.00.00 | B12: BEBAN UMUM DAN ADMINISTRASI
A13: 97.01.10 | B13: Beban Pegawai Umum & Administrasi | R13: ='RINCIAN B. TDK LANGSUNG'!Q12 -> 0 | S13: =SUM(Q14:Q17)-R13 -> 0
B14: Direktur | Q14: =SUM(E14:P14) -> 0
B15: Pegawai Induk PERUMDAM | Q15: =SUM(E15:P15) -> 0
B16: Lembur pegawai Adm & Umum | Q16: =SUM(E16:P16) -> 0
B17: Insentif / THR , dana kesejahteraan pegawai dan Bonus / Uang Cuti | Q17: =SUM(E17:P17) -> 0
A18: 97.01.20 | B18: Beban Kesejahteraan Karyawan Umum & Adm | Q18: =SUM(E18:P18) -> 0
B19: Beban Iuran Dana Pensiun Umum & Adm | Q19: =SUM(E19:P19) -> 0 | R19: ='RINCIAN B. TDK LANGSUNG'!Q18 -> 0 | S19: =Q19-R19 -> 0
B20: Beban BPJS Kesehatan Umum & Adm | Q20: =SUM(E20:P20) -> 0 | R20: ='RINCIAN B. TDK LANGSUNG'!Q19 -> 0 | S20: =Q20-R20 -> 0
B21: Beban BPJS Ketenagkerjaan Umum & Adm | Q21: =SUM(E21:P21) -> 0 | R21: ='RINCIAN B. TDK LANGSUNG'!Q20 -> 0 | S21: =Q21-R21 -> 0
B22: Uang Makan/Minum Pegawai | Q22: =SUM(E22:P22) -> 0 | R22: ='RINCIAN B. TDK LANGSUNG'!Q21 -> 0 | S22: =Q22-R22 -> 0
B23: Uang Pisah/Purna Tugas | Q23: =SUM(E23:P23) -> 0 | R23: ='RINCIAN B. TDK LANGSUNG'!Q22 -> 0 | S23: =Q23-R23 -> 0
A24: 97.01.30 | B24: Beban Pakaian Dinas & Olahraga | Q24: =SUM(E24:P24) -> 0 | R24: ='RINCIAN B. TDK LANGSUNG'!Q23 -> 0 | S24: =Q24-R24 -> 0
A25: 97.01.40 | B25: Beban Pendidikan & latihan Umum & Adm | Q25: =SUM(E25:P25) -> 0 | R25: ='RINCIAN B. TDK LANGSUNG'!Q24 -> 0 | S25: =Q25-R25 -> 0 | V25: =U25/12 -> 0
A26: 97.01.50 | B26: Beban Pembinaan Pegawai Umum & Adm | Q26: =SUM(E26:P26) -> 0 | R26: ='RINCIAN B. TDK LANGSUNG'!Q25 -> 0 | S26: =Q26-R26 -> 0
A27: 97.01.60 | B27: Beban Bantuan & Sumbangan | Q27: =SUM(E27:P27) -> 0 | R27: ='RINCIAN B. TDK LANGSUNG'!Q26 -> 0 | S27: =Q27-R27 -> 0
A28: 97.01.90 | B28: Rupa-Rupa Biaya Pegawai | Q28: =SUM(E28:P28) -> 0 | R28: ='RINCIAN B. TDK LANGSUNG'!Q27 -> 0 | S28: =Q28-R28 -> 0
B29: Pajak Pegawai | Q29: =SUM(E29:P29) -> 0 | R29: ='RINCIAN B. TDK LANGSUNG'!Q28 -> 0 | S29: =Q29-R29 -> 0
B30: Jumlah Biaya Pegawai | E30: =SUM(E14:E29) -> 0 | F30: =SUM(F14:F29) -> 0 | G30: =SUM(G14:G29) -> 0 | H30: =SUM(H14:H29) -> 0 | I30: =SUM(I14:I29) -> 0 | J30: =SUM(J14:J29) -> 0 | K30: =SUM(K14:K29) -> 0 | L30: =SUM(L14:L29) -> 0 | ... P30: =SUM(P14:P29) -> 0 | Q30: =SUM(E30:P30) -> 0 | R30: =SUM(R11:R29) -> 0 | S30: =SUM(S11:S29) -> 0 | T30: ='RINCIAN B. TDK LANGSUNG'!Q29 -> 0
A31: 97.02.00 | B31: BEBAN KANTOR
A32: 97.02.10 | B32: Beban Alat Tulis Kantor dan Fotocopy | Q32: =SUM(E32:P32) -> 0 | R32: ='RINCIAN B. TDK LANGSUNG'!Q31 -> 0 | S32: =Q32-R32 -> 0
A33: 97.02.20 | B33: Barang-barang Cetakkan | Q33: =SUM(E33:P33) -> 0 | R33: ='RINCIAN B. TDK LANGSUNG'!Q32 -> 0 | S33: =Q33-R33 -> 0
A34: 97.02.30 | B34: Perlengkapan Komputer | Q34: =SUM(E34:P34) -> 0 | R34: ='RINCIAN B. TDK LANGSUNG'!Q33 -> 0 | S34: =Q34-R34 -> 0
A35: 97.02.40 | B35: Beban Telepon, Telek dan Telegram | Q35: =SUM(E35:P35) -> 0 | R35: ='RINCIAN B. TDK LANGSUNG'!Q34 -> 0 | S35: =Q35-R35 -> 0
A36: 97.02.50 | B36: Beban Rapat dan Tamu | Q36: =SUM(E36:P36) -> 0 | R36: ='RINCIAN B. TDK LANGSUNG'!Q36+'RINCIAN B. TDK LANGSUNG'!Q37 -> 0 | S36: =Q36-R36 -> 0
A37: 97.02.60 | B37: Benda Pos dan materai | Q37: =SUM(E37:P37) -> 0 | R37: ='RINCIAN B. TDK LANGSUNG'!Q38 -> 0 | S37: =Q37-R37 -> 0
A38: 97.02.70 | B38: Beban Listrik/Penerangan | Q38: =SUM(E38:P38) -> 0 | R38: ='RINCIAN B. TDK LANGSUNG'!Q39 -> 0 | S38: =Q38-R38 -> 0
A39: 97.02.80 | B39: Beban cleaning Service | Q39: =SUM(E39:P39) -> 0 | R39: ='RINCIAN B. TDK LANGSUNG'!Q40 -> 0 | S39: =Q39-R39 -> 0
A40: 97.02.90 | B40: Rupa-rupa Beban Kantor | S40: =Q40-R40 -> 0
B41: Paket Internet (Wifi) | Q41: =SUM(E41:P41) -> 0 | R41: ='RINCIAN B. TDK LANGSUNG'!Q42 -> 0 | S41: =Q41-R41 -> 0
B42: Rupa-rupa beban kantor lainnya | Q42: =SUM(E42:P42) -> 0 | R42: ='RINCIAN B. TDK LANGSUNG'!Q43 -> 0 | S42: =Q42-R42 -> 0
...

Sheet P-10. Biaya Operasi
A1: PEMERINTAH KABUPATEN SERUYAN
A2: PERUSAHAAN DAERAH AIR MINUM (PDAM) | Q2: P-10
A4: RENCANA BIAYA OPERASI
A5: TAHUN ANGGARAN 2023
A7: PDAM KABUPATEN SERUYAN
A8: NO | B8: URAIAN | E8: BULAN | Q8: JUMLAH | R8: MAPPING BEBAN SAK - ETAP | S8: REALISASI | T8: SISA ANGGARAN
A9: PERK. | E9: 1 | F9: 2 | G9: 3 | H9: 4 | I9: 5 | J9: 6 | K9: 7 | L9: 8 | M9: 9 | N9: 10 | O9: 11 | P9: 12 | Q9: 2023 | S9: 2023 | T9: 2023
A10: 1 | B10: 2 | E10: 3 | F10: 4 | G10: 5 | H10: 6 | I10: 7 | J10: 8 | K10: 9 | L10: 10 | M10: 11 | N10: 12 | O10: 13 | P10: 14 | Q10: 15 | R10: 16 | S10: 17 | T10: 17
A11: 91.00.00 | B11: BIAYA SUMBER AIR | Q11: =SUM(F11:P11) -> 0
A12: 91.01.00 | B12: BIAYA OPERASIONAL SUMBER AIR | Q12: =SUM(F12:P12) -> 0
A13: 91.01.10 | B13: Biaya Pegawai | J13: 3000000 | K13: 3000000 | L13: 3000000 | M13: 3000000 | N13: 3000000 | Q13: =SUM(E13:P13) -> 15000000 | R13: B. PEGAWAI | S13: ='RINCIAN B. LANGSUNG USAHA'!Q13 -> 0 | T13: =Q13-S13 -> 15000000
A14: 91.01.20 | B14: Pemakaian Bahan bakar (SOLAR) | Q14: =SUM(E14:P14) -> 0
C15: Intake Sei. Mitak | E15: =16000*35 -> 560000 | F15: =16000*35 -> 560000 | G15: =16000*35 -> 560000 | H15: =16000*35 -> 560000 | I15: =16000*35 -> 560000 | J15: =16000*35 -> 560000 | K15: =16000*35 -> 560000 | L15: =16000*35 -> 560000 | ... P15: =16000*35 -> 560000 | Q15: =SUM(E15:P15) -> 6720000
C16: Intake Tanjung Paring | J16: =16000*1300 -> 20800000 | K16: =16000*1300 -> 20800000 | L16: =16000*1300 -> 20800000 | M16: =16000*1300 -> 20800000 | N16: =16000*1300 -> 20800000 | Q16: =SUM(E16:P16) -> 104000000
C17: Jumlah Bahan Bakar | E17: =SUM(E15:E16) -> 560000 | F17: =SUM(F15:F16) -> 560000 | G17: =SUM(G15:G16) -> 560000 | H17: =SUM(H15:H16) -> 560000 | I17: =SUM(I15:I16) -> 560000 | J17: =SUM(J15:J16) -> 21360000 | K17: =SUM(K15:K16) -> 21360000 | L17: =SUM(L15:L16) -> 21360000 | ... Q17: =SUM(Q15:Q16) -> 110720000 | R17: B. PEMAKAIAN BAHAN BAKAR | S17: ='RINCIAN B. LANGSUNG USAHA'!Q18 -> 0 | T17: =Q17-S17 -> 110720000
A18: 91.01.30 | B18: Biaya Listrik PLN | Q18: =SUM(E18:P18) -> 0 | T18: =Q18-S18 -> 0
C19: Induk PDAM | E19: 49000000 | F19: 49000000 | G19: 49000000 | H19: 49000000 | I19: 49000000 | J19: 49000000 | K19: 49000000 | L19: 49000000 | M19: 49000000 | N19: 49000000 | O19: 49000000 | P19: 49000000 | Q19: =SUM(E19:P19) -> 588000000
C20: IKK Kartika Bhakti | E20: 9000000 | F20: 9000000 | G20: 9000000 | H20: 9000000 | I20: 9000000 | J20: 9000000 | K20: 9000000 | L20: 9000000 | M20: 9000000 | N20: 9000000 | O20: 9000000 | P20: 9000000 | Q20: =SUM(E20:P20) -> 108000000
C21: IKK Pembuang Hulu | E21: 22000000 | F21: 22000000 | G21: 22000000 | H21: 22000000 | I21: 22000000 | J21: 22000000 | K21: 22000000 | L21: 22000000 | M21: 22000000 | N21: 22000000 | O21: 22000000 | P21: 22000000 | Q21: =SUM(E21:P21) -> 264000000
C22: Jumlah Biaya Listrik PLN | E22: =SUM(E19:E21) -> 80000000 | F22: =SUM(F19:F21) -> 80000000 | G22: =SUM(G19:G21) -> 80000000 | H22: =SUM(H19:H21) -> 80000000 | I22: =SUM(I19:I21) -> 80000000 | J22: =SUM(J19:J21) -> 80000000 | K22: =SUM(K19:K21) -> 80000000 | L22: =SUM(L19:L21) -> 80000000 | ... Q22: =SUM(Q19:Q21) -> 960000000 | R22: B. LISTRIK | S22: ='RINCIAN B. LANGSUNG USAHA'!Q19 -> 0 | T22: =Q22-S22 -> 960000000
A23: 91.01.40 | B23: Pemakaian Bahan Pembantu | E23: 500000 | F23: 0 | G23: 0 | H23: 500000 | I23: 0 | J23: 500000 | K23: 0 | L23: 500000 | M23: 0 | N23: 0 | O23: 500000 | P23: 0 | Q23: =SUM(E23:P23) -> 2500000 | R23: B. PEMAKAIAN BAHAN PEMBANTU | S23: ='RINCIAN B. LANGSUNG USAHA'!Q20 -> 0 | T23: =Q23-S23 -> 2500000
A24: 91.01.90 | B24: Rupa-Rupa Biaya Operasi | E24: 250000 | F24: 250000 | G24: 250000 | H24: 250000 | I24: 250000 | J24: 250000 | K24: 250000 | L24: 250000 | M24: 250000 | N24: 250000 | O24: 250000 | P24: 250000 | Q24: =SUM(E24:P24) -> 3000000 | R24: B. OPERASI LAINNYA | S24: ='RINCIAN B. LANGSUNG USAHA'!Q21 -> 0 | T24: =Q24-S24 -> 3000000
B25: B. Operasi Sumber Air | E25: =E12+E13+E17+E22+E23+E24 -> 81310000 | F25: =F12+F13+F17+F22+F23+F24 -> 80810000 | G25: =G12+G13+G17+G22+G23+G24 -> 80810000 | H25: =H12+H13+H17+H22+H23+H24 -> 81310000 | I25: =I12+I13+I17+I22+I23+I24 -> 80810000 | J25: =J12+J13+J17+J22+J23+J24 -> 105110000 | K25: =K12+K13+K17+K22+K23+K24 -> 104610000 | L25: =L12+L13+L17+L22+L23+L24 -> 105110000 | ... P25: =P12+P13+P17+P22+P23+P24 -> 80810000 | Q25: =SUM(E25:P25) -> 1091220000 | S25: =SUM(S13:S24) -> 0 | T25: =SUM(T13:T24) -> 1091220000
A26: 91.02.00 | B26: BIAYA PEMELIHARAAN SUMBER AIR
A27: 91.02.10 | B27: Pemeliharaan bangunan dan penyempurnaan tanah | M27: 10000000 | Q27: =SUM(E27:P27) -> 10000000 | S27: ='RINCIAN B. LANGSUNG USAHA'!Q24 -> 0 | T27: =Q27-S27 -> 10000000
A28: 91.02.40 | B28: Pemeliharaan Mata air dan Saluran | Q28: =SUM(E28:P28) -> 0 | S28: ='RINCIAN B. LANGSUNG USAHA'!Q25 -> 0 | T28: =Q28-S28 -> 0
A29: 91.02.60 | B29: Pemeliharaan Pipa Induk | E29: 500000 | F29: 500000 | G29: 500000 | H29: 500000 | I29: 500000 | J29: 500000 | K29: 500000 | L29: 500000 | M29: 500000 | N29: 500000 | O29: 500000 | P29: 500000 | Q29: =SUM(E29:P29) -> 6000000 | S29: ='RINCIAN B. LANGSUNG USAHA'!Q26 -> 0 | T29: =Q29-S29 -> 6000000
A30: 91.02.70 | B30: Pemeliharaan Alat Pembangkit Tenaga | F30: 1500000 | O30: 1500000 | Q30: =SUM(E30:P30) -> 3000000 | S30: ='RINCIAN B. LANGSUNG USAHA'!Q27 -> 0 | T30: =Q30-S30 -> 3000000
A31: 91.02.80 | B31: Pemeliharaan Alat Perpompaan | E31: 16500000 | F31: 16500000 | J31: 16500000 | K31: 16500000 | N31: 16500000 | Q31: =SUM(E31:P31) -> 82500000 | S31: ='RINCIAN B. LANGSUNG USAHA'!Q28 -> 0 | T31: =Q31-S31 -> 82500000
A32: 91.02.90 | B32: Pemeliharaan Instalasi Sumber Air Lainnya | E32: 500000 | F32: 500000 | G32: 500000 | H32: 500000 | I32: 500000 | J32: 500000 | K32: 500000 | L32: 500000 | M32: 500000 | N32: 500000 | O32: 500000 | P32: 500000 | Q32: =SUM(E32:P32) -> 6000000 | S32: ='RINCIAN B. LANGSUNG USAHA'!Q29 -> 0 | T32: =Q32-S32 -> 6000000
B33: Jumlah Biaya Pemeliharaan Sumber Air | E33: =SUM(E27:E32) -> 17500000 | F33: =SUM(F27:F32) -> 19000000 | G33: =SUM(G27:G32) -> 1000000 | H33: =SUM(H27:H32) -> 1000000 | I33: =SUM(I27:I32) -> 1000000 | J33: =SUM(J27:J32) -> 17500000 | K33: =SUM(K27:K32) -> 17500000 | L33: =SUM(L27:L32) -> 1000000 | ... P33: =SUM(P27:P32) -> 1000000 | Q33: =SUM(E33:P33) -> 107500000 | R33: B. PEMELIHARAAN | S33: =SUM(S27:S32) -> 0 | T33: =SUM(T27:T32) -> 107500000
A34: 91.03.00 | B34: BIAYA AIR BAKU (PAJAK AIR PERMUKAAN) | G34: =(121889+53632+870246)*150*10% -> 15686505 | Q34: =SUM(E34:P34) -> 15686505 | R34: B. BAHAN BAKU | S34: ='RINCIAN B. LANGSUNG USAHA'!Q31 -> 0 | T34: =Q34-S34 -> 15686505
B35: JUMLAH SEBELUM PENYUSUTAN | E35: =E33+E25+E34 -> 98810000 | F35: =F33+F25+F34 -> 99810000 | G35: =G33+G25+G34 -> 97496505 | H35: =H33+H25+H34 -> 82310000 | I35: =I33+I25+I34 -> 81810000 | J35: =J33+J25+J34 -> 122610000 | K35: =K33+K25+K34 -> 122110000 | L35: =L33+L25+L34 -> 106110000 | ... P35: =P33+P25+P34 -> 81810000 | Q35: =SUM(E35:P35) -> 1214406505 | S35: =S34+S33+S25 -> 0 | T35: =Q35-S35 -> 1214406505
A36: 91.09.00 | B36: BIAYA PENYUSUTAN SUMBER AIR | E36: =9180831+18140880+1000000 -> 28321711 | F36: =9180831+18140880+1000000 -> 28321711 | G36: =9180831+18140880+1000000 -> 28321711 | H36: =9180831+18140880+1000000 -> 28321711 | I36: =9180831+18140880+1000000 -> 28321711 | J36: =9180831+18140880+1000000 -> 28321711 | K36: =9180831+18140880+1000000 -> 28321711 | L36: =9180831+18140880+1000000 -> 28321711 | ... P36: =9180831+18140880+1000000 -> 28321711 | Q36: =SUM(E36:P36) -> 339860532 | R36: B. PENYUSUTAN | S36: ='RINCIAN B. LANGSUNG USAHA'!Q33 -> 0 | T36: =Q36-S36 -> 339860532
B37: JUMLAH BIAYA SUMBER AIR | E37: =SUM(E35:E36) -> 127131711 | F37: =SUM(F35:F36) -> 128131711 | G37: =SUM(G35:G36) -> 125818216 | H37: =SUM(H35:H36) -> 110631711 | I37: =SUM(I35:I36) -> 110131711 | J37: =SUM(J35:J36) -> 150931711 | K37: =SUM(K35:K36) -> 150431711 | L37: =SUM(L35:L36) -> 134431711 | ... P37: =SUM(P35:P36) -> 110131711 | Q37: =SUM(E37:P37) -> 1554267037 | S37: =SUM(S35:S36) -> 0 | T37: =SUM(T35:T36) -> 1554267037
Q38: =SUM(E38:P38) -> 0
A39: 92.00.00 | B39: BIAYA PENGOLAHAN AIR | Q39: =SUM(E39:P39) -> 0
A40: 92.01.10 | B40: Biaya Pegawai
C41: Induk PDAM | E41: 26500000 | F41: 26500000 | G41: 26500000 | H41: 26500000 | I41: 26500000 | J41: 26500000 | K41: 26500000 | L41: 26500000 | M41: 26500000 | N41: 26500000 | O41: 26500000 | P41: 26500000 | Q41: =SUM(E41:P41) -> 318000000
C42: IKK Kartika Bhakti | E42: =14000000 -> 14000000 | F42: =14000000 -> 14000000 | G42: =14000000 -> 14000000 | H42: =14000000 -> 14000000 | I42: =14000000 -> 14000000 | J42: =14000000 -> 14000000 | K42: =14000000 -> 14000000 | L42: =14000000 -> 14000000 | ... P42: =14000000 -> 14000000 | Q42: =SUM(E42:P42) -> 168000000
...

Sheet P-11. Biaya UMUM & ADM
A1: PEMERINTAH KABUPATEN SERUYAN
A2: PERUSAHAAN DAERAH AIR MINUM (PDAM) | Q2: P-11
A4: RENCANA BIAYA UMUM DAN ADMINISTRASI
A5: TAHUN ANGGARAN 2023
A7: PDAM KABUPATEN SERUYAN
A8: NO | B8: URAIAN | E8: BULAN | Q8: JUMLAH | R8: MAPPING BEBAN | S8: REALISASI | T8: SISA ANGGARAN
A9: PERK. | E9: 1 | F9: 2 | G9: 3 | H9: 4 | I9: 5 | J9: 6 | K9: 7 | L9: 8 | M9: 9 | N9: 10 | O9: 11 | P9: 12 | Q9: 2023 | R9: SAK - ETAP | S9: 2023 | T9: 2023
A10: 1 | B10: 2 | E10: 3 | F10: 4 | G10: 5 | H10: 6 | I10: 7 | J10: 8 | K10: 9 | L10: 10 | M10: 11 | N10: 12 | O10: 13 | P10: 14 | Q10: 15 | R10: 16 | S10: 17 | T10: 17
A11: 96.01.00 | B11: BIAYA PEGAWAI
A12: 96.01.10 | B12: Gaji dan Tunjangan Pegawai
B13: Direktur | E13: 17550000 | F13: 17550000 | G13: 17550000 | H13: 17550000 | I13: 17550000 | J13: 17550000 | K13: 17550000 | L13: 17550000 | M13: 17550000 | N13: 17550000 | O13: 17550000 | P13: 17550000 | Q13: =SUM(E13:P13) -> 210600000
B14: Pegawai Induk PDAM | E14: =110000000-E13 -> 92450000 | F14: =110000000-F13 -> 92450000 | G14: =110000000-G13 -> 92450000 | H14: =110000000-H13 -> 92450000 | I14: =110000000-I13 -> 92450000 | J14: =110000000-J13 -> 92450000 | K14: =110000000-K13 -> 92450000 | L14: =110000000-L13 -> 92450000 | ... P14: =110000000-P13 -> 92450000 | Q14: =SUM(E14:P14) -> 1109400000
B15: Jumlah Gaji dan Honor Pegawai | E15: =SUM(E13:E14) -> 110000000 | F15: =SUM(F13:F14) -> 110000000 | G15: =SUM(G13:G14) -> 110000000 | H15: =SUM(H13:H14) -> 110000000 | I15: =SUM(I13:I14) -> 110000000 | J15: =SUM(J13:J14) -> 110000000 | K15: =SUM(K13:K14) -> 110000000 | L15: =SUM(L13:L14) -> 110000000 | ... Q15: =SUM(Q13:Q14) -> 1320000000 | R15: B. PEGAWAI | S15: ='RINCIAN B. TDK LANGSUNG'!#REF! -> #REF! | T15: =Q15-S15 -> #REF!
A16: 96.01.30 | B16: Iuran Pensiun | E16: 20000000 | F16: 20000000 | G16: 20000000 | H16: 20000000 | I16: 20000000 | J16: 20000000 | K16: 20000000 | L16: 20000000 | M16: 20000000 | N16: 20000000 | O16: 20000000 | P16: 20000000 | Q16: =SUM(E16:P16) -> 240000000 | S16: ='RINCIAN B. TDK LANGSUNG'!#REF! -> #REF! | T16: =Q16-S16 -> #REF!
A17: 96.01.50 | B17: Insentife/Kesejahteraan Karyawan | Q17: =SUM(Q18:Q20) -> 452800320 | S17: ='RINCIAN B. TDK LANGSUNG'!#REF! -> #REF! | T17: =Q17-S17 -> #REF!
B18: Uang Makan/Minum Pegawai | E18: 27500000 | F18: 27500000 | G18: 27500000 | H18: 27500000 | I18: 27500000 | J18: 27500000 | K18: 27500000 | L18: 27500000 | M18: 27500000 | N18: 27500000 | O18: 27500000 | P18: 27500000 | Q18: =SUM(E18:P18) -> 330000000
B19: Honor Tim Pengadaan dan Tim Kegiatan | F19: =7000000+(4*3000000) -> 19000000 | H19: =3000000+11000000 -> 14000000 | I19: 3000000 | J19: 6000000 | L19: 6000000 | N19: 6000000 | O19: 3000000 | P19: 12000000 | Q19: =SUM(E19:P19) -> 69000000
B20: Pesangon dan Jasa Pengabdian | E20: 36250320 | I20: 17550000 | Q20: =SUM(E20:P20) -> 53800320
B21: Gaji Ke 13 (Tunjangan Hari Raya) | H21: =H15+'[7]P-10. Biaya Operasi'!H79+'[7]P-10. Biaya Operasi'!H44 -> 193500000 | Q21: =SUM(E21:P21) -> 193500000 | S21: ='RINCIAN B. TDK LANGSUNG'!#REF! -> #REF! | T21: =Q21-S21 -> #REF!
B22: Gaji ke 14 (Tunjangan Cuti) | P22: 120000000 | Q22: =SUM(E22:P22) -> 120000000 | S22: ='RINCIAN B. TDK LANGSUNG'!#REF! -> #REF! | T22: =Q22-S22 -> #REF!
