Workbook

Sheet Laba-ETAP 
A1: 2. 1. LAPORAN LABA / (RUGI)
B3: PERUMDAM TIRTA SERUYAN
B4: LAPORAN LABA RUGI BERDASARKAN SAK - ETAP
B5: Untuk bulan yang berakhir pada tanggal 31 Maret 2026 dan 31 Desember 2025
B6: (Dalam Rupiah)
B8: URAIAN | F8: Tahun 2026 | H8: Tahun 2025 | O8: 0
B10: PENDAPATAN USAHA
C11: Pendapatan Penjualan Air
D12: Pendapatan Harga Air | H12: 0
D13: Pendapatan Administrasi & Dana Meter | H13: 0
D14: Pendapatan Air Mobil Tangki | F14: 0 | H14: 0
D15: Jumlah Pendapatan Penjualan Air | F15: =SUM(F12:F14) -> 0 | H15: 0 | M15: =F15-H15 -> 0 | O15: =M15/H15*100 -> #DIV/0! | P15: % | Q15: Kenaikan Pend. air 1 th
C16: Pendapatan Non Air
D17: Pendapatan Sambungan Baru | F17: 0 | H17: 0 | M17: =F24-H24 -> 0 | O17: =(M17/H24)*100 -> #DIV/0! | P17: % | Q17: Kenaikan Pend. Usaha 1 th
D18: Pendapatan Penyambungan Kembali | F18: ='[1]81.02-81.03'!$F$37 -> 0
D19: Pendapatan Denda | F19: 0 | H19: 0 | M19: =F43-H43 -> 0 | O19: =M19/H43*100 -> #DIV/0! | Q19: Kanaikan Biaya 1 TH
D20: Pendapatan Penggantian Meter Rusak | F20: ='[1]81.02-81.03'!$F$78 -> 0
D21: Pendapatan Penggantian Pipa Persil | F21: ='[1]81.02-81.03'!$F$95 -> 0 | H21: 0 | M21: =H55-F55 -> 0 | O21: =M21/H55*100 -> #DIV/0! | Q21: Penurunan kerugian usaha
D22: Pendapatan Non Air Lainnya | F22: ='[1]81.02-81.03'!$F$118 -> 0 | H22: 0
D23: Jumlah Pendapatan Non Air | F23: =SUM(F17:F22) -> 0 | G23: =SUM(G17:G22) -> 0 | H23: =SUM(H17:H22) -> 0
B24: Jumlah Pendapatan Usaha | E24: =#REF!+E23+E11 -> #REF! | F24: =F23+F15 -> 0 | H24: =H23+H15 -> 0
B25: BEBAN USAHA | M25: Penurunan /Kenaikan Biaya | O25: Kerugian :
C26: Beban Pegawai | F26: ='RINCIAN B. LANGSUNG USAHA'!Q37+'RINCIAN B. LANGSUNG USAHA'!Q44+'RINCIAN B. LANGSUNG USAHA'!Q50+'RINCIAN B. LANGSUNG USAHA'!Q51+'RINCIAN B. LANGSUNG USAHA'!Q52+'RINCIAN B. LANGSUNG USAHA'!Q73+'RINCIAN B. LANGSUNG USAHA'!Q77+'RINCIAN B. LANGSUNG USAHA'!Q83+'RINCIAN B. LANGSUNG USAHA'!Q84+'RINCIAN B. LANGSUNG USAHA'!Q85+'RINCIAN B. TDK LANGSUNG'!Q29-'RINCIAN B. TDK LANGSUNG'!Q28+'RINCIAN B. TDK LANGSUNG'!Q63 -> 0 | H26: 0 | M26: =F26-H26 -> 0 | O26: Kenaikan Bahan Kimia | Q26: 0
C27: Beban Listrik | F27: ='RINCIAN B. LANGSUNG USAHA'!Q19 -> 0 | H27: 0 | M27: =F27-H27 -> 0 | O27: Penyusutan (Habis Umur ekonomis) | Q27: 0
C28: Beban Pemakaian Bahan Kimia | F28: ='RINCIAN B. LANGSUNG USAHA'!Q53 -> 0 | H28: 0 | M28: =F28-H28 -> 0 | O28: Defisit Imbalan Kerja Dapenma | Q28: 0
C29: Beban Hubungan Langganan | F29: ='RINCIAN B. TDK LANGSUNG'!Q49 -> 0 | H29: 0 | M29: =F29-H29 -> 0 | Q29: 0
C30: Beban Pemeliharan | F30: ='RINCIAN B. LANGSUNG USAHA'!Q30+'RINCIAN B. LANGSUNG USAHA'!Q66+'RINCIAN B. LANGSUNG USAHA'!Q97+'RINCIAN B. TDK LANGSUNG'!Q59 -> 0 | H30: 0 | M30: =F30-H30 -> 0
C31: Beban Imbalan Kerja | F31: ='RINCIAN B. TDK LANGSUNG'!Q76 -> 0 | H31: 0 | M31: =F31-H31 -> 0
C32: Beban Penyusutan Aset Tetap | F32: ='RINCIAN B. LANGSUNG USAHA'!Q33+'RINCIAN B. LANGSUNG USAHA'!Q68+'RINCIAN B. LANGSUNG USAHA'!Q99+'RINCIAN B. TDK LANGSUNG'!Q78 -> 0 | H32: 0 | M32: =F32-H32 -> 0 | Q32: 0
C33: Beban Amortisasi Aset Tidak Berwujud | F33: ='RINCIAN B. TDK LANGSUNG'!Q79 -> 0 | H33: 0 | M33: =F33-H33 -> 0
C34: Beban Penyisihan Kerugian Piutang | F34: ='RINCIAN B. TDK LANGSUNG'!Q62 -> 0 | H34: 0 | M34: =F34-H34 -> 0 | O34: Kenaikan Beban Pegawi
C35: Beban Pemakaian Bahan pembantu | F35: ='RINCIAN B. LANGSUNG USAHA'!Q20+'RINCIAN B. LANGSUNG USAHA'!Q58+'RINCIAN B. LANGSUNG USAHA'!Q86 -> 0 | H35: 0 | M35: =F35-H35 -> 0 | O35: - Kenaikan Status Pegawai | Q35: 0
C36: Beban Pemakaian Bahan Bakar | F36: ='RINCIAN B. LANGSUNG USAHA'!Q18+'RINCIAN B. LANGSUNG USAHA'!Q87 -> 0 | H36: 0 | M36: =F36-H36 -> 0 | O36: - Dapenma | Q36: 0
C37: Beban Kantor | F37: ='RINCIAN B. TDK LANGSUNG'!Q44 -> 0 | H37: 0 | M37: =F37-H37 -> 0 | O37: - Diklat | Q37: 0
C38: Beban Penelitian dan Pengembangan | F38: ='RINCIAN B. TDK LANGSUNG'!Q52 -> 0 | H38: 0 | M38: =F38-H38 -> 0 | O38: - Purna Tugas/Pisah Pegawai | Q38: 0
C39: Beban Air Baku | F39: ='RINCIAN B. LANGSUNG USAHA'!Q31 -> 0 | H39: 0 | M39: =F39-H39 -> 0 | O39: - Seragam | Q39: 0
C40: Beban PPh 21 | F40: ='RINCIAN B. TDK LANGSUNG'!Q28 -> 0 | H40: 0 | M40: =F40-H40 -> 0 | Q40: 0
C41: Beban Operasional Lainnya | F41: ='RINCIAN B. LANGSUNG USAHA'!Q21+'RINCIAN B. LANGSUNG USAHA'!Q59+'RINCIAN B. LANGSUNG USAHA'!Q88+'RINCIAN B. TDK LANGSUNG'!Q75-'RINCIAN B. TDK LANGSUNG'!Q63-'RINCIAN B. TDK LANGSUNG'!Q62 -> 0 | H41: 0 | M41: =F41-H41 -> 0
C42: Beban Harga Pokok Sambungan Baru | F42: ='RINCIAN B. LANGSUNG USAHA'!Q101 -> 0 | H42: 0
B43: Jumlah BebanUsaha | F43: =SUM(F26:F42) -> 0 | H43: =SUM(H26:H42) -> 0 | O43: Kenaikan Operasional lainnya :
...

Sheet Laba-OTDA
A1: 2.2 | C1: LAPORAN LABA - RUGI
B3: PERUMDAM TIRTA SERUYAN
B4: LAPORAN LABA RUGI
B5: Untuk bulan yang berakhir pada tanggal 28 Februari 2026 dan 31 Desember 2025
B6: (Dalam Rupiah)
B8: URAIAN | F8: Tahun 2026 | H8: Tahun 2025
B10: PENDAPATAN USAHA
C11: Pendapatan Penjualan Air
B12: 81.01.10 | D12: Pendapatan Harga Air | F12: =H135 -> 0 | G12: =I732 -> 0 | H12: 0
B13: 81.01.20 | D13: Pendapatan Administrasi & Dana Meter | F13: =H136 -> 0 | G13: =I733 -> 0 | H13: 0
B14: 81.01.30 | D14: Pendapatan Rekening Air Tangki | F14: =H137 -> 0 | H14: 0
D15: Jumlah Pendapatan Penjualan Air | F15: =SUM(F12:F14) -> 0 | H15: =SUM(H12:H14) -> 0
C16: Pendapatan Non Air
B17: 81.02.10 | D17: Pendapatan Sambungan Baru | F17: =H140 -> 0 | H17: 0
B18: 81.02.40 | D18: Pendapatan Penyambungan Kembali | F18: =H196 -> 0
B19: 81.02.50 | D19: Pendapatan Denda | F19: =H142 -> 0 | H19: 0
B20: 81.02.70 | D20: Pendapatan Penggantian Meter Rusak | F20: =H198 -> 0
B21: 81.02.80 | D21: Pendapatan Penggantian Pipa Persil | F21: =H199 -> 0 | H21: 0
B22: 81.02.90 | D22: Pendapatan Non Air Lainnya | F22: =H200 -> 0 | H22: 0
D23: Jumlah Pendapatan Non Air | F23: =SUM(F17:F22) -> 0 | H23: =SUM(H17:H22) -> 0
B24: Jumlah Pendapatan Usaha | E24: =#REF!+E23+E11 -> #REF! | F24: =F23+F15 -> 0 | H24: =H23+H15 -> 0
B25: BEBAN USAHA
B26: I | C26: BEBAN USAHA
B27: 91.00.00 | D27: Beban Sumber Air | F27: =H150 -> 0 | H27: 0
B28: 92.00.00 | D28: Beban Pengolahan Air | F28: =H151 -> 0 | H28: 0
B29: 93.00.00 | D29: Beban Transmisi dan Distribusi | F29: =H152 -> 0 | H29: 0
B30: 91.09.00 | D30: Beban Penyusutan Sumber Air | F30: =H153 -> 0 | H30: 0
B31: 92.09.00 | D31: Beban Penyusutan Pengolahan Air | F31: =H154 -> 0 | H31: 0
B32: 93.09.00 | D32: Beban Penyusutan Trandist | F32: =H155 -> 0 | H32: 0
B33: 96.00.00 | D33: Beban Harga Pokok Sambungan Baru | F33: =H156 -> 0 | H33: 0
B34: Jumlah Beban usaha | F34: =SUM(F27:F33) -> 0 | H34: =SUM(H27:H33) -> 0
B35: Laba (Rugi) Kotor Usaha | F35: =F24-F34 -> 0 | H35: =H24-H34 -> 0
B36: II | C36: BEBAN UMUM DAN ADMINISTRASI
B37: 96.00.00 | D37: Beban Umum Administrasi | F37: =H160 -> 0 | H37: 0
B38: 96.07.00 | D38: Beban Penyisihan dan Penghapusan Piutang | F38: =H216 -> 0 | H38: 0
B39: 96.09.00 | D39: Beban Penys. Dan Amortisasi Non Pabrik Air | F39: =H162 -> 0 | H39: 0
B40: Jumlah Beban Umum Dan Administrasi | F40: =SUM(F37:F39) -> 0 | H40: 0
B41: Laba(Rugi) Operasional | F41: =F35-F40 -> 0 | H41: =H35-H40 -> 0
B42: III | C42: PENDAPATAN - BEBAN LAIN-LAIN
B43: 88.00.00 | D43: Pendapatan Lain-lain | F43: =H166 -> 0 | H43: 0
...

Sheet Neraca 
A2: 1. | C2: LAPORAN POSISI KEUANGAN
B4: PERUMDAM TIRTA SERUYAN
B5: LAPORAN POSISI KEUANGAN
B6: PER 31 JANUARI 2026 DAN 31 DESEMBER 2025
A7: {=+K7:AA54} -> #VALUE!
B8: Uraian | F8: Catatan | H8: Tahun 2026 | J8: Tahun 2025
H9: (Rp.) | J9: (Rp.)
B10: ASET
B11: ►ASET LANCAR
B12: ● | C12: Kas dan Bank | H12: 0 | J12: 0 | L12: =J12-H12 -> 0
B13: ● | C13: DEPOSITO | H13: 0 | J13: 0 | L13: =J13-H13 -> 0
B14: ● | C14: Piutang Usaha | H14: 0 | J14: 0 | L14: =J14-H14 -> 0
C15: Akum.Peny. Kerugian Piutang Usaha | H15: 0 | J15: 0 | L15: =J15-H15 -> 0
C16: Piutang Usaha Bersih | H16: =SUM(H14:H15) -> 0 | J16: =SUM(J14:J15) -> 0 | L16: =J16-H16 -> 0
B17: ● | C17: Piutang Lain-Lain | J17: 0 | L17: =J17-H17 -> 0
B18: ● | C18: Persediaan | H18: 0 | J18: 0 | L18: =J18-H18 -> 0
B19: ● | C19: Beban Sewa Dibayar Dimuka | J19: 0 | L19: =J19-H19 -> 0
C20: Total Aset Lancar | H20: =H12+H16+H17+H18+H19+H13 -> 0 | J20: =SUM(J16:J19)+J12+J13 -> 0
L21: =J21-H21 -> 0
B22: ► ASET TETAP | L22: =J22-H22 -> 0
C23: Nilai Perolehan Aset Tetap | H23: 0 | J23: 0 | L23: =J23-H23 -> 0
B24: ● | C24: Akumulasi Penyusutan | H24: 0 | J24: 0 | L24: =J24-H24 -> 0
D25: Nilai Buku | H25: =SUM(H23:H24) -> 0 | J25: =SUM(J23:J24) -> 0 | L25: =J25-H25 -> 0
B26: ► Aset Tetap Tidak Berwujud | L26: =J26-H26 -> 0
C27: Nilai Perolehan Aset Tetap Tdk Berwujud | H27: 0 | J27: 0 | L27: =J27-H27 -> 0
B28: ● | C28: Akumulasi Amortisasi Aktiva Tidak Berwujud | H28: 0 | J28: 0 | L28: =J28-H28 -> 0
C29: Nilai Buku | H29: =SUM(H27:H28) -> 0 | J29: =SUM(J27:J28) -> 0 | L29: =J29-H29 -> 0
B30: ► Aset Tetap Lainnya | L30: =J30-H30 -> 0
C31: Nilai Perolehan Aset Tetap Dalam Penyelesaian | H31: 0 | J31: 0 | L31: =J31-H31 -> 0
B32: ► Aset Tidak Lancar | L32: =J32-H32 -> 0
C33: Aset Pajak Tangguhan | H33: 0 | I33: 0 | J33: 0
L34: =J34-H34 -> 0
B35: TOTAL ASET | H35: =H20+H25+H29+H33 -> 0 | I35: =I20+I25 -> 0 | J35: =J20+J25+J29+J33 -> 0 | L35: =J35-H35 -> 0
L36: =J36-H36 -> 0
L37: =J37-H37 -> 0
B38: ► LIABILITAS & EKUITAS | L38: =J38-H38 -> 0
C39: ● | D39: LIABILITAS | L39: =J39-H39 -> 0
D40: - Liabilitas Jangka Pendek | L40: =J40-H40 -> 0
D41: - Utang | H41: 0 | L41: =J41-H41 -> 0
D42: - Pendapatan Diterima Dimuka | J42: 0
...

Sheet ARUS KAS
A1: 3. | C1: LAPORAN ARUS KAS
A3: PERUMDAM TIRTA SERUYAN
A4: LAPORAN ARUS KAS
A5: UNTUK TAHUN YANG BERAKHIR 31 JANUARI 2026 DAN TAHUN 2025
B7: Uraian | E7: Per 31-01-2026 | G7: Per 31-12-2025
E8: (Rp.) | G8: (Rp.)
B10: Arus Kas dari Aktivitas Operasi
C11: Laba Rugi Bersih | E11: ='Neraca '!H51 -> 0
B12: Penyesuaian untuk :
C13: Beban Penyusutan dan Amortisasi | E13: ='Neraca '!L24+'Neraca '!L28 -> 0 | G13: 0
C14: Laba di tahan | E14: ='Neraca '!L50+'Neraca '!L15 -> 0 | G14: 0
B15: Laba (Rugi) Operasi Sebelum Perubahan Modal Kerja | E15: =SUM(E11:E14) -> 0 | G15: =SUM(G11:G14) -> 0
C16: Penurunan (Kenaikan) Piutang Usaha | E16: ='Neraca '!L16 -> 0 | G16: 0
C17: Penurunan (Kenaikan) Piutang Non Usaha | E17: ='Neraca '!L17 -> 0 | G17: 0
C18: Penurunan (Kenaikan) Persediaan | E18: ='Neraca '!L18 -> 0 | G18: 0
C19: Penurunan (Kenaikan) Pembayaran Di Muka
C20: Kenaikan (Penurunan) Imbalan Pasca Kerja | G20: 0
C21: Kenaikan (Penurunan) Hutang Usaha | E21: =-'Neraca '!L41 -> 0
C22: Kenaikan (Penurunan) Beban Yang Masih Harus Dibayar | E22: =-'Neraca '!L43 -> 0 | G22: 0
C23: Kenaikan (Penurunan) Pendapatan Diterima Dimuka
C24: Kenaikan (Penurunan) Hutang Pajak
C25: Kenaikan (Penurunan) Hutang Retribusi
C26: Kenaikan (Penurunan) Hutang Jangka Pendek Jatuh Tempo
C27: Kenaikan (Penurunan) Hutang Jangka Panjang
C28: Kenaikan (Penurunan) Kewajiban Lainnya
C29: Arus Kas Bersih dari Aktivitas Operasi | E29: =SUM(E15:E28) -> 0 | G29: =SUM(G15:G28) -> 0
B30: Arus Kas dari Aktivitas Investasi
C31: Pengurangan (Penambahan) Aktiva Tetap | E31: ='Neraca '!L23 -> 0 | G31: 0
C32: Pengurangan (Penambahan) Bahan Instalasi
C33: Pengurangan (Penambahan)Aktiva Tetap Dalam Penyelesaian | E33: ='Neraca '!L31 -> 0
C34: Arus Kas Bersih yang Digunakan untuk Aktivitas Investasi | E34: =SUM(E31:E33) -> 0 | G34: =SUM(G31:G33) -> 0
B35: Arus Kas dari Aktivitas Pendanaan
C36: Hibah
C37: Penyertaan Pemda
C38: Penyertaan Pemerintah Pusat
C39: Arus Kas Bersih dari Aktivitas Pendanaan | E39: =SUM(E37:E38) -> 0 | G39: =SUM(G36:G38) -> 0
B41: Kenaikan (Penurunan) Bersih Kas dan Setara Kas | E41: =E29+E34+E39 -> 0 | G41: =G29+G34+G39 -> 0
B42: Kas dan Setara Kas Awal Periode | E42: =G43 -> 0
B43: Kas dan Setara Kas Akhir Periode | E43: =SUM(E41:E42) -> 0 | G43: =SUM(G41:G42) -> 0
E44: ='Neraca '!H12 -> 0 | G44: ='Neraca '!J12 -> 0
...

Sheet LAP ARUS KAS
A1: 3. | C1: LAPORAN ARUS KAS
B4: PERUMDAM TIRTA SERUYAN
B5: LAPORAN ARUS KAS
B6: UNTUK TAHUN YANG BERAKHIR 31 JANUARI 2025 DAN TAHUN 2024
B8: URAIAN | G8: TAHUN | I8: TAHUN
G9: 2025 | I9: 2024
B10: A. ARUS KAS OPERASI | C10: ARUS KAS OPERASI
C11: I. PENERIMAAN
D12: 1 | E12: Penerimaan dari Pendapatan Air | G12: =I875 -> 0 | I12: 6000650100
D13: 2 | E13: Penerimaan dari Pendapatan Non Air | G13: =I876 -> 0 | I13: 386252632
D14: 3 | E14: Penerimaan dari Pendapatan Lain-lain | G14: =I877 -> 0 | I14: 2041490791
D15: 4 | E15: Penerimaan dari Aset Lancar Lain-lain | G15: =I878 -> 0
D16: 5 | E16: Penambahan Liabilitas Lancar | G16: =I879 -> 0
D18: JUMLAH PENERIMAAN | G18: =SUM(G12:G16) -> 0 | I18: =SUM(I12:I16) -> 8428393523
C20: II. PENGELUARAN | L20: =[3]JU!$E$1021 -> 1204164
D21: 1 | E21: Beban Sumber Air | G21: =I884 -> 0 | I21: =1111320581-1204164 -> 1110116417 | L21: (-) hutang pap desember
D22: 2 | E22: Beban Pengolahan Air | G22: =I885 -> 0 | I22: =1595983560 -> 1595983560
D23: 3 | E23: Beban Transmisi & Distribusi | G23: =I886 -> 1200000 | I23: =791611737 -> 791611737
D24: 4 | E24: Beban Umum & Administrasi | G24: =I887 -> 0 | I24: =8414279225-(I21+I22+I23+I34+I25+I27) -> 4086728863 | L24: Total pengeluaran kas dlm 1 tahun dikurang (1+2+3+5+6+pengeluaran aset)
D25: 5 | E25: Beban Lain-lain | G25: =I888 -> 0 | I25: 110400 | L25: 8414279225 | M25: (pengeluaran kas 1 th)
D26: 6 | E26: Pembayaran Aset Lancar Lain - lain | G26: =I889 -> 0
D27: 7 | E27: Pembayaran Liabilitas Lancar Lain - lain | G27: =I890 -> 0 | I27: 13680368 | L27: pembayaran utang sesuai neraca 2023
D29: JUMLAH PENGELUARAN | G29: =SUM(G21:G28) -> 1200000 | I29: =SUM(I21:I28) -> 7598231345
C31: ARUS KAS BERSIH DARI AKTIVITAS OPERASI | G31: =G18-G29 -> -1200000 | I31: =I18-I29 -> 830162178
B33: B. | C33: ARUS KAS DARI AKTIVITAS INVESTASI | L33: Reklas pembelian bahan karena sdh dipakai assesories & bahan kimia
D34: Penambahan Aset Tetap | G34: =I897 -> 0 | I34: =782747880+33300000 -> 816047880 | L34: Pemeliharaan trandist | M34: 203476069
C35: ARUS KAS BERSIH DIGUNAKAN AKTIVITAS INVESTASI | G35: =SUM(G34) -> 0 | I35: =SUM(I34) -> 816047880 | L35: DM | M35: 111540600
L36: Bahan kimia | M36: 805603800
B37: C. | C37: ARUS KAS DARI AKTIVITAS PENDANAAN | L37: Pemasangan SR &Jaringan | M37: 112943995
D38: Penambahan PMP | G38: =I901 -> 0
D39: Pembayaran Deviden kepada KPM | G39: =I902 -> 0 | M39: =SUM(M34:M38) -> 1233564464
D40: Pembayaran Jasa Produksi dan Tantiem | G40: =I903 -> 0
D41: Penambahan Cadangan Dana/Koreksi Tahu Lalu | G41: =I904 -> 0
C42: ARUS KAS BERSIH UNTUK AKTIVITAS PENDANAAN | G42: =SUM(G38:G41) -> 0 | I42: =SUM(I38:I41) -> 0
B44: D. | C44: KENAIKAN/BERKURANG BERSIH KAS DAN SETARA KAS | G44: =G31-G35+G42 -> -1200000 | I44: =I31-I35+I42 -> 14114298
B46: E. | C46: SALDO KAS SETARA KAS AWAL TAHUN | G46: 1.3122519e+09 | I46: 1.2981376e+09
B48: F. | C48: SALDO KAS SETARA KAS AWAL TAHUN | G48: =G44+G46 -> 1.3110519e+09 | I48: =I44+I46 -> 1.3122519e+09
G50: ='Neraca '!H12 -> 0
A51: Diketahui / Disetujui Oleh, | F51: Dibuat Oleh,
A52: Pjs. Direktur | F52: Kabag. Adm. & Keuangan
...

Sheet LAP ARUS KAS (2)
A1: 3. | C1: LAPORAN ARUS KAS
B4: PERUMDAM TIRTA SERUYAN
B5: LAPORAN ARUS KAS
B6: UNTUK TAHUN YANG BERAKHIR 31 JANUARI 2025 DAN TAHUN 2024
B8: URAIAN | G8: TAHUN | I8: TAHUN
G9: 2025 | I9: 2024
B10: A. ARUS KAS OPERASI | C10: ARUS KAS OPERASI
C11: I. PENERIMAAN
D12: 1 | E12: Penerimaan dari Pendapatan Air | G12: =I875 -> 0 | I12: 6000650100 | L12: =I12-6000670100 -> -20000
D13: 2 | E13: Penerimaan dari Pendapatan Non Air | G13: =I876 -> 0 | I13: 386252632 | L13: =I13-386232632 -> 20000
D14: 3 | E14: Penerimaan dari Pendapatan Lain-lain | G14: =I877 -> 0 | I14: 2041490791
D15: 4 | E15: Penerimaan dari Aset Lancar Lain-lain | G15: =I878 -> 0
D16: 5 | E16: Penambahan Liabilitas Lancar | G16: =I879 -> 0
D18: JUMLAH PENERIMAAN | G18: =SUM(G12:G16) -> 0 | I18: =SUM(I12:I16) -> 8428393523
C20: II. PENGELUARAN | L20: =[3]JU!$E$1021 -> 1204164
D21: 1 | E21: Beban Sumber Air | G21: =I884 -> 0 | I21: =1111320581-1204164 -> 1110116417 | L21: (-) hutang pap desember
D22: 2 | E22: Beban Pengolahan Air | G22: =I885 -> 0 | I22: =1595983560-M36 -> 790379760
D23: 3 | E23: Beban Transmisi & Distribusi | G23: =I886 -> 1200000 | I23: =791611737-M34+M35+M37 -> 812620263
D24: 4 | E24: Beban Umum & Administrasi | G24: =I887 -> 0 | I24: =4152198749-26434435-26503037 -> 4099261277 | L24: Beban ADM -B.Imbalan kerja-B.penysihan
D25: 5 | E25: Beban Lain-lain | G25: =I888 -> 0 | I25: 110400 | L25: 8414279225 | M25: (pengeluaran kas 1 th)
D26: 6 | E26: Pembayaran Aset Lancar Lain - lain | G26: =I889 -> 0 | I26: =8414279225-(I21+I22+I23+I24+I25+I34+I27) -> 772062860 | L26: Total pengeluaran kas dlm 1 tahun dikurang (1+2+3+5+6+pengeluaran aset)
D27: 7 | E27: Pembayaran Liabilitas Lancar Lain - lain | G27: =I890 -> 0 | I27: 13680368 | L27: pembayaran utang sesuai neraca 2023
D29: JUMLAH PENGELUARAN | G29: =SUM(G21:G28) -> 1200000 | I29: =SUM(I21:I28) -> 7598231345
C31: ARUS KAS BERSIH DARI AKTIVITAS OPERASI | G31: =G18-G29 -> -1200000 | I31: =I18-I29 -> 830162178
B33: B. | C33: ARUS KAS DARI AKTIVITAS INVESTASI | L33: Reklas pembelian bahan karena sdh dipakai assesories & bahan kimia
D34: Penambahan Aset Tetap | G34: =I897 -> 0 | I34: =782747880+33300000 -> 816047880 | L34: Pemeliharaan trandist | M34: 203476069
C35: ARUS KAS BERSIH DIGUNAKAN AKTIVITAS INVESTASI | G35: =SUM(G34) -> 0 | I35: =SUM(I34) -> 816047880 | L35: DM | M35: 111540600
L36: Bahan kimia | M36: 805603800
B37: C. | C37: ARUS KAS DARI AKTIVITAS PENDANAAN | L37: Pemasangan SR &Jaringan | M37: 112943995
D38: Penambahan PMP | G38: =I901 -> 0
D39: Pembayaran Deviden kepada KPM | G39: =I902 -> 0 | M39: =SUM(M34:M38) -> 1233564464
D40: Pembayaran Jasa Produksi dan Tantiem | G40: =I903 -> 0
D41: Penambahan Cadangan Dana/Koreksi Tahu Lalu | G41: =I904 -> 0
C42: ARUS KAS BERSIH UNTUK AKTIVITAS PENDANAAN | G42: =SUM(G38:G41) -> 0 | I42: =SUM(I38:I41) -> 0
B44: D. | C44: KENAIKAN/BERKURANG BERSIH KAS DAN SETARA KAS | G44: =G31-G35+G42 -> -1200000 | I44: =I31-I35+I42 -> 14114298
B46: E. | C46: SALDO KAS SETARA KAS AWAL TAHUN | G46: 1.3122519e+09 | I46: 1.2981376e+09
B48: F. | C48: SALDO KAS SETARA KAS AWAL TAHUN | G48: =G44+G46 -> 1.3110519e+09 | I48: =I44+I46 -> 1.3122519e+09
G50: ='Neraca '!H12 -> 0
A51: Diketahui / Disetujui Oleh, | F51: Dibuat Oleh,
A52: Pjs. Direktur | F52: Kabag. Adm. & Keuangan
...

Sheet Lap. Perputaran Uang 
A1: 4. | C1: LAPORAN PERPUTARAN UANG
B4: PERUMDAM TIRTA SERUYAN
B5: LAPORAN PERPUTARAN UANG
B6: UNTUK TAHUN YANG BERAKHIR 31 JANUARI 2026 DAN TAHUN 2025
B8: URAIAN | G8: Tahun 2026 | I8: Tahun 2025
G9: Rp. | I9: Rp.
B10: A. PENERIMAAN
C11: I. PENERIMAAN OPERASIONAL
D12: a. Penerimaan Tagihan Rek. Air | G12: =I83 -> 0 | I12: 0
D13: b. Penerimaan Air Mobil Tangki | G13: =I84 -> 0 | I13: 0
D14: c. Penerimaan Piutang Rek. Air dari MITRA | G14: =I157 -> 0
D15: d. Penerimaan Dimuka Rek. Air | G15: =I158 -> 0
E16: Jumlah Penerimaan Rekening Air | G16: =SUM(G12:G15) -> 0 | I16: =SUM(I12:I15) -> 0
D17: c. Penerimaan Non Air
E18: - Penerimaan Sambungan Rumah | G18: =I89 -> 0 | I18: 0
E19: - Penerimaan Pendaftaran | G19: =I162 -> 0 | I19: 0
E20: - Penerimaan Penyambungan Kembali | G20: =I163 -> 0 | I20: 0
E21: - Penerimaan Denda | G21: =I92 -> 0 | I21: 0
E22: - Penerimaan Meter Air Rusak | G22: =I93 -> 0 | I22: 0
E23: - Penerimaan Non Air Lain (Balik Nama) | G23: =I166 -> 0 | I23: 0
E24: Jumlah Penerimaan Non Air | G24: =SUM(G18:G23) -> 0 | I24: =SUM(I18:I23) -> 0
C26: Jumlah Penerimaan Operasional | G26: =G24+G16 -> 0 | I26: =I24+I16 -> 0
C27: II. PENERIMAAN NON OPERASIONAL
D28: a. Jasa Giro & Lain-lain | G28: =I99 -> 0 | I28: 0
D29: b. Penyertaan Modal | G29: =I100 -> 0 | I29: 0
D30: c. Penerimaan Lain-lain | G30: =I172 -> 0 | I30: 0
C31: Jumlah Penerimaan Non Operasional | G31: =SUM(G28:G30) -> 0 | I31: =SUM(I28:I30) -> 0
B33: JUMLAH PENERIMAAN | G33: =G31+G26 -> 0 | I33: =I31+I26 -> 0
B34: B. PENGELUARAN
C35: I. PENGELUARAN OPERASIONAL
D36: a. Pengeluaran Pembelian Bahan | G36: =I107 -> 0 | I36: 0
D37: b. Pengeluaran Tenaga Kerja | G37: =I108 -> 0 | I37: 0
D38: c. Pengeluaran Operasi Lainnya | G38: =I109 -> 0 | I38: 0
C39: Jumlah pengeluaran Operasional | G39: =SUM(G36:G38) -> 0 | I39: =SUM(I36:I38) -> 0
C40: II. PENGELUARAN NON OPERASIONAL
D41: a. Pembayaran Utang Usaha & Non Usaha | G41: =I112 -> 0 | I41: 0
D42: b. Pengeluaran Investasi,Aktiva Tetap & Inventaris | G42: =I184 -> 0 | I42: 0
D43: c. Pengeluaran Non Air Lainnya | G43: =I114 -> 0 | I43: 0
C44: Jumlah Pengeluaran Non Operasional | G44: =SUM(G41:G43) -> 0 | I44: =SUM(I41:I43) -> 0
B46: JUMLAH PENGELUARAN | G46: =G39+G44 -> 0 | I46: =I44+I39 -> 0
...

Sheet Ekuitas
B1: 5. LAPORAN PERUBAHAN EKUITAS
B3: PERUMDAM TIRTA SERUYAN
B4: LAPORAN PERUBAHAN EKUITAS
B5: Untuk Tahun Yang Berakhir Tanggal 31 Januari 2026 dan 31 Desember 2025
B7: Uraian | C7: Modal Hibah | D7: Penyertaan Pemerintah Seruyan | E7: Laba (rugi) | F7: Laba (Rugi) | G7: Total Ekuitas
E8: Tahun - Tahun Lalu | F8: Tahun Berjalan
B10: Saldo 31 Desember 2025 | C10: ='Neraca '!J49 -> 0 | D10: ='Neraca '!J48 -> 0 | E10: ='Neraca '!J50 -> 0 | F10: ='Neraca '!J51 -> 0 | G10: =SUM(+C10+D10+E10+F10) -> 0
B12: Penambahan/Koreksi | C12: 0 | D12: 0 | E12: 0 | F12: 0 | G12: =SUM(+C12+D12+E12+F12) -> 0
B14: Pengalihan Kerugian ke Akumulasi Rugi | C14: 0 | D14: 0 | E14: =F10 -> 0 | F14: =-F10 -> 0 | G14: =SUM(+C14+D14+E14+F14) -> 0
B16: Laba (Rugi) bersih selama tahun berjalan | C16: 0 | D16: 0 | F16: ='Laba-ETAP '!F168 -> 0 | G16: =SUM(+C16+D16+E16+F16) -> 0
B18: Saldo 31 Januari 2026 | C18: =SUM(C10:C17) -> 0 | D18: =SUM(D10:D17) -> 0 | E18: =SUM(E10:E17) -> 0 | F18: =SUM(F10:F17) -> 0 | G18: =SUM(G10:G17) -> 0
G19: ='Neraca '!H960 -> 0
B20: Diketahui / Disetujui Oleh, | F20: Mengetahui,
B21: Pjs. Direktur | F21: Kabag. Adm & Keuangan
B24: AFIRUS FEBIAN | F24: TRI MURTIANI
G27: =G18-G19 -> 0
B31: 5. LAPORAN PERUBAHAN EKUITAS
B33: PERUMDAM TIRTA SERUYAN
B34: LAPORAN PERUBAHAN EKUITAS
B35: Untuk Tahun Yang Berakhir Tanggal 28 Februari 2026 dan 31 Desember 2025
B37: Uraian | C37: Modal Hibah | D37: Penyertaan Pemerintah Seruyan | E37: Laba (rugi) | F37: Laba (Rugi) | G37: Total Ekuitas
E38: Tahun - Tahun Lalu | F38: Tahun Berjalan
B40: Saldo 31 Desember 2025 | C40: ='Neraca '!J49 -> 0 | D40: ='Neraca '!J48 -> 0 | E40: ='Neraca '!J50 -> 0 | F40: ='Neraca '!J51 -> 0 | G40: =SUM(+C40+D40+E40+F40) -> 0
B42: Penambahan/Koreksi | C42: 0 | D42: 0 | E42: 0 | F42: 0 | G42: =SUM(+C42+D42+E42+F42) -> 0
B44: Pengalihan Kerugian ke Akumulasi Rugi | C44: 0 | D44: 0 | E44: =F40 -> 0 | F44: =-F40 -> 0 | G44: =SUM(+C44+D44+E44+F44) -> 0
B46: Laba (Rugi) bersih selama tahun berjalan | C46: 0 | D46: 0 | G46: =SUM(+C46+D46+E46+F46) -> 0
B48: Saldo 28 Februari 2026 | C48: =SUM(C40:C47) -> 0 | D48: =SUM(D40:D47) -> 0 | E48: =SUM(E40:E47) -> 0 | F48: =SUM(F40:F47) -> 0 | G48: =SUM(G40:G47) -> 0
G49: ='Neraca '!H995 -> 0
B50: Diketahui / Disetujui Oleh, | F50: Mengetahui, | J50: ='Neraca '!H132 -> 0
B51: Pjs. Direktur | F51: Kabag. Adm & Keuangan
B54: AFIRUS FEBIAN | F54: TRI MURTIANI
G57: =G48-G49 -> 0
B72: 5. LAPORAN PERUBAHAN EKUITAS
B74: PERUMDAM TIRTA SERUYAN
B75: LAPORAN PERUBAHAN EKUITAS
B76: Untuk Tahun Yang Berakhir Tanggal 31 Maret 2026 dan 31 Desember 2025
B78: Uraian | C78: Modal Hibah | D78: Penyertaan Pemerintah Seruyan | E78: Laba (rugi) | F78: Laba (Rugi) | G78: Total Ekuitas
E79: Tahun - Tahun Lalu | F79: Tahun Berjalan
B81: Saldo 31 Desember 2025 | C81: ='Neraca '!J130 -> 0 | D81: ='Neraca '!J129 -> 0 | E81: ='Neraca '!J131 -> 0 | F81: ='Neraca '!J132 -> 0 | G81: =SUM(+C81+D81+E81+F81) -> 0
B83: Penambahan/Koreksi | C83: 0 | D83: 0 | E83: 0 | F83: 0 | G83: =SUM(+C83+D83+E83+F83) -> 0
...

Sheet NERACA KOMPARATIF
A1: PERUSAHAAN DAERAH AIR MINUM (PDAM)
A2: KABUPATEN SERUYAN
A3: NERACA KOMPORATIF TAHUN 2012
A5: AKTIVA
A6: URAIAN | E6: TAHUN 2012
A8: AKTIVA LANCAR | G8: =F9+F15+F18+F19+F22 -> 1.1431059e+09
B9: KAS DAN BANK | F9: =E10+E11 -> 7.960439e+08
C10: Kas | E10: 589885
C11: Bank | E11: =[6]Kas!$G$33-E10 -> 7.9545401e+08
B12: INVESTASI JANGKA PENDEK | F12: =0 -> 0
C13: Deposito | E13: =0 -> 0
C14: Surat Berharga | E14: =0 -> 0
B15: PIUTANG USAHA | F15: =E16 -> 108725960
C16: Piutang Rek Air | E16: =[6]Piutang!$F$32 -> 108725960
C17: Piutang Rekening Non Air | E17: =0 -> 0
B18: PENYISIHAN PIUTANG USAHA | F18: =-[6]Piutang!$F$50 -> -29241802
B19: PIUTANG NON USAHA | F19: =E20+E21 -> 17713535
C20: Piutang Non Air | E20: =[6]Piutang!$D$60 -> 87535
C21: Pinjaman Pegawai | E21: =[6]Piutang!$F$97 -> 17626000
B22: PERSEDIAAN | F22: =E23+E24+E25 -> 2.4986429e+08
C23: Persediaan Bahan Kimia | E23: =[6]Persediaan!$F$21+[6]Persediaan!$F$39+[6]Persediaan!$F$57 -> 125608580
C24: Persediaan BBM | E24: =[6]Persediaan!$F$98 -> 2097500
C25: Persediaan Instalasi SR | E25: =[6]Persediaan!$F$80 -> 1.2215821e+08
B26: PEMBAYARAN DIMUKA | F26: =0 -> 0
C27: Biaya di bayar dimuka | E27: =0 -> 0
B28: INVESTASI JANGKA PANJANG
C29: Deposito Berjangka Lebih dari 1 tahun | E29: =0 -> 0
C30: Penyertaan | E30: =0 -> 0
C31: Penanaman dalam aktiva tak berwujud | E31: =0 -> 0
C32: Investasi Jangka Panjang Lainnya | E32: =0 -> 0
A33: AKTIVA TETAP | G33: =F34+F44 -> 4.120016e+09
B34: AKTIVA TETAP PRODUKTIF | F34: =SUM(E35:E43) -> 6.5291748e+09
C35: Tanah dan Penyempurnaan Tanah | E35: ='[6]Aktiva Tetap'!$D$9 -> 232450000
C36: Instalasi Sumber Iar | E36: ='[6]Aktiva Tetap'!$F$20 -> 510559191
C37: Instalasi Pompa | E37: ='[6]Aktiva Tetap'!$F$30 -> 117602561
C38: Instalasi Pengolahan Air | E38: ='[6]Aktiva Tetap'!$F$39 -> 2528466809
C39: Instalasi Tranmisi & distribusi | E39: ='[6]Aktiva Tetap'!$F$59 -> 2.333422e+09
C40: Bangunan/Gedung | E40: ='[6]Aktiva Tetap'!$F$76 -> 409862308
C41: Peralatan & Perlengkapan | E41: ='[6]Aktiva Tetap'!$D$90 -> 10182000
C42: Kendaraan/Alat Pengangkutan | E42: ='[6]Aktiva Tetap'!$F$100 -> 284050000
...

Sheet RL KOMPARATIF
A2: PERUSAHAAN DAERAH AIR MINUM (PDAM) KABUPATEN SERUYAN
A3: LAPORAN LABA RUGI KOMPARATIF
A4: TAHUN 2012
A6: URAIAN | D6: 41274
A7: PENDAPATAN
B8: Pendapatan Penjualan Air | E8: =D9 -> #REF!
C9: Penjualan Rekening Air | D9: =#REF! -> #REF!
B10: Pendapatan Non Air | E10: =SUM(D11:D17) -> #REF!
C11: Pendapatan Sambungan Baru | D11: =#REF! -> #REF!
C12: Pendapatan Denda | D12: =#REF! -> #REF!
C13: Pendapatan Administrasi | D13: =#REF! -> #REF!
C14: Pendapatan Penyambungan Kembali | D14: =#REF! -> #REF!
C15: Pendapatan Balik Nama | D15: =#REF! -> #REF!
C16: Pendapatan Mobil Tangki | D16: =#REF! -> #REF!
C17: Pendapatan Subsidi | D17: =#REF! -> #REF!
B19: Pendapatan Lain-lain | E19: =SUM(D20:D21) -> #REF!
C20: Pendapatan Jasa Giro | D20: =#REF! -> #REF!
C21: Pendapatan Lainnya | D21: =#REF! -> #REF!
C23: Jumlah Pendapatan Usaha | F23: =E8+E10+E19 -> #REF!
A25: BIAYA USAHA
B26: Beban Pegawai | E26: =SUM(D27:D28) -> #REF!
C27: Gaji dan Tunjangan | D27: =#REF! -> #REF!
C28: Beban Pegawai Linnya | D28: =#REF!+#REF!+#REF!+#REF!+#REF!+#REF!+#REF!+#REF!+#REF!+#REF!+#REF!+#REF!+#REF!+#REF!+#REF!+#REF!+#REF! -> #REF!
B29: Beban Kantor | E29: =#REF! -> #REF!
B30: Beban BBM | E30: =#REF! -> #REF!
B31: Beban Listrik | E31: =D32+D33 -> #REF!
C32: Beban Listrik Kantor | D32: =#REF! -> #REF!
C33: Beban Listrik Ins Pengolahan Air | D33: =#REF! -> #REF!
B34: Beban Operasi Pengolahan Air | E34: =SUM(D35:D37) -> #REF!
C35: Tawas | D35: =#REF! -> #REF!
C36: Soda Ash | D36: =#REF! -> #REF!
C37: Kaporit | D37: =#REF! -> #REF!
B38: Beban Pemakaian Bahan Pembantu | E38: =SUM(D39:D40) -> #REF!
C39: Oli | D39: =#REF! -> #REF!
C40: Perlengkapan Komputer | D40: =#REF! -> #REF!
B41: Beban ATK & Barang Cetakan | E41: =#REF! -> #REF!
B42: Beban Pemeliharaan | E42: =SUM(D44:D46) -> #REF!
C43: Biaya Pemeliharaan Sumber Air | D43: =#REF! -> #REF!
C44: Biaya Pemeliharaan Pengolahan | D44: =#REF! -> #REF!
C45: Biaya Pemeliharaan Tran & Dist | D45: =#REF! -> #REF!
...

Sheet RINCIAN B. LANGSUNG USAHA
A1: PEMERINTAH KABUPATEN SERUYAN
A2: PERUSAHAAN DAERAH AIR MINUM (PDAM) | Q2: P-11
A4: RINCIAN BIAYA LANGSUNG USAHA
A5: TAHUN ANGGARAN 2025
A7: PDAM KABUPATEN SERUYAN
A8: NO | B8: URAIAN | E8: BULAN | Q8: JUMLAH | R8: MAPPING BEBAN SAK - ETAP
A9: PERK. | E9: 1 | F9: 2 | G9: 3 | H9: 4 | I9: 5 | J9: 6 | K9: 7 | L9: 8 | M9: 9 | N9: 10 | O9: 11 | P9: 12 | Q9: 2025
A10: 1 | B10: 2 | E10: 3 | F10: 4 | G10: 5 | H10: 6 | I10: 7 | J10: 8 | K10: 9 | L10: 10 | M10: 11 | N10: 12 | O10: 13 | P10: 14 | Q10: 15 | R10: 16
A11: 91.00.00 | B11: BEBAN SUMBER AIR | Q11: =SUM(F11:P11) -> 0
A12: 91.01.00 | B12: BEBAN OPERASIONAL SUMBER AIR | Q12: =SUM(F12:P12) -> 0
A13: 91.01.10 | B13: Beban Pegawai | Q13: =SUM(E13:P13) -> 0 | R13: B. PEGAWAI
A14: 91.01.20 | B14: Beban Kesejahteraan Karyawan Sumber Air | Q14: =SUM(E14:P14) -> 0
A15: 91.01.30 | B15: Beban Pakaian Dinas & Olahraga | Q15: =SUM(E15:P15) -> 0
A16: 91.01.40 | B16: Beban Pendidikan & Latihan | Q16: =SUM(E16:P16) -> 0
A17: 91.01.50 | B17: Beban Pembinaan Pegawai Sumber | Q17: =SUM(E17:P17) -> 0
A18: 91.02.10 | B18: Pemakaian Bahan bakar (SOLAR) | Q18: =SUM(E18:P18) -> 0 | R18: B. PEMAKAIAN BAHAN BAKAR
A19: 91.02.20 | B19: Beban Listrik PLN | Q19: =SUM(E19:P19) -> 0 | R19: B. LISTRIK
A20: 91.02.30 | B20: Pemakaian Bahan Pembantu (oli) | E20: 0 | Q20: =SUM(E20:P20) -> 0 | R20: B. PEMAKAIAN BAHAN PEMBANTU
A21: 91.02.40 | B21: Rupa-Rupa Beban Operasi | Q21: =SUM(E21:P21) -> 0 | R21: B. OPERASI LAINNYA
B22: B. Operasi Sumber Air | E22: =SUM(E13:E21) -> 0 | F22: =SUM(F13:F21) -> 0 | G22: =SUM(G13:G21) -> 0 | H22: =SUM(H13:H21) -> 0 | I22: =SUM(I13:I21) -> 0 | J22: =SUM(J13:J21) -> 0 | K22: =SUM(K13:K21) -> 0 | L22: =SUM(L13:L21) -> 0 | ... P22: =SUM(P13:P21) -> 0 | Q22: =SUM(E22:P22) -> 0
A23: 91.03.00 | B23: BEBAN PEMELIHARAAN SUMBER AIR
A24: 91.03.10 | B24: Pemeliharaan bangunan dan penyempurnaan tanah | Q24: =SUM(E24:P24) -> 0
A25: 91.03.40 | B25: Pemeliharaan Mata air dan Saluran | Q25: =SUM(E25:P25) -> 0
A26: 91.03.60 | B26: Pemeliharaan Pipa Induk | Q26: =SUM(E26:P26) -> 0
A27: 91.03.70 | B27: Pemeliharaan Alat Pembangkit Tenaga | Q27: =SUM(E27:P27) -> 0
A28: 91.03.80 | B28: Pemeliharaan Alat Perpompaan | Q28: =SUM(E28:P28) -> 0
A29: 91.03.90 | B29: Pemeliharaan Instalasi Sumber Air Lainnya | Q29: =SUM(E29:P29) -> 0
B30: Jumlah Beban Pemeliharaan Sumber Air | E30: =SUM(E24:E29) -> 0 | F30: =SUM(F24:F29) -> 0 | G30: =SUM(G24:G29) -> 0 | H30: =SUM(H24:H29) -> 0 | I30: =SUM(I24:I29) -> 0 | J30: =SUM(J24:J29) -> 0 | K30: =SUM(K24:K29) -> 0 | L30: =SUM(L24:L29) -> 0 | ... P30: =SUM(P24:P29) -> 0 | Q30: =SUM(E30:P30) -> 0 | R30: B. PEMELIHARAAN
A31: 91.04.00 | B31: BEBAN AIR BAKU (PAJAK AIR PERMUKAAN) | Q31: =SUM(E31:P31) -> 0 | R31: B. AIR BAKU
B32: JUMLAH SEBELUM PENYUSUTAN | E32: =E30+E22+E31 -> 0 | F32: =F30+F22+F31 -> 0 | H32: =H30+H22+H31 -> 0 | I32: =I30+I22+I31 -> 0 | J32: =J30+J22+J31 -> 0 | K32: =K30+K22+K31 -> 0 | L32: =L30+L22+L31 -> 0 | M32: =M30+M22+M31 -> 0 | N32: =N30+N22+N31 -> 0 | O32: =O30+O22+O31 -> 0 | P32: =P30+P22+P31 -> 0 | Q32: =SUM(E32:P32) -> 0
A33: 91.05.00 | B33: BEBAN PENYUSUTAN SUMBER AIR | Q33: =SUM(E33:P33) -> 0 | R33: B. PENYUSUTAN
B34: JUMLAH BEBAN SUMBER AIR | E34: =SUM(E32:E33) -> 0 | F34: =SUM(F32:F33) -> 0 | G34: =SUM(G32:G33) -> 0 | H34: =SUM(H32:H33) -> 0 | I34: =SUM(I32:I33) -> 0 | J34: =SUM(J32:J33) -> 0 | K34: =SUM(K32:K33) -> 0 | L34: =SUM(L32:L33) -> 0 | ... P34: =SUM(P32:P33) -> 0 | Q34: =SUM(E34:P34) -> 0
Q35: =SUM(E35:P35) -> 0
A36: 92.00.00 | B36: BEBAN PENGOLAHAN AIR | Q36: =SUM(E36:P36) -> 0
A37: 92.01.10 | B37: Beban Pegawai | E37: =SUM(E39:E43) -> 0 | F37: =SUM(F39:F43) -> 0 | G37: =SUM(G39:G43) -> 0 | H37: =SUM(H39:H43) -> 0 | I37: =SUM(I39:I43) -> 0 | J37: =SUM(J39:J43) -> 0 | K37: =SUM(K39:K43) -> 0 | L37: =SUM(L39:L43) -> 0 | ... P37: =SUM(P39:P43) -> 0 | Q37: =SUM(E37:P37) -> 0 | R37: B. PEGAWAI
C38: Gaji & honor Pengolahan Air | Q38: =SUM(E38:P38) -> 0
D39: PUSAT - INDUK | Q39: =SUM(E39:P39) -> 0
D40: IKK KARTIKA BHAKTI | Q40: =SUM(E40:P40) -> 0
D41: IKK PEMBUANG HULU | Q41: =SUM(E41:P41) -> 0
C42: Lembur | Q42: =SUM(E42:P42) -> 0 | R42: B. PEGAWAI
...

Sheet RINCIAN B. TDK LANGSUNG
A1: PEMERINTAH KABUPATEN SERUYAN
A2: PERUSAHAAN DAERAH AIR MINUM (PDAM) | Q2: P-11
A4: RINCIAN BIAYA UMUM DAN ADMINISTRASI
A5: TAHUN ANGGARAN 2025
A7: PDAM KABUPATEN SERUYAN
A8: NO | B8: URAIAN | E8: BULAN | Q8: JUMLAH | R8: MAPPING BEBAN
A9: PERK. | E9: 1 | F9: 2 | G9: 3 | H9: 4 | I9: 5 | J9: 6 | K9: 7 | L9: 8 | M9: 9 | N9: 10 | O9: 11 | P9: 12 | Q9: 2025 | R9: SAK - ETAP
A10: 1 | B10: 2 | E10: 3 | F10: 4 | G10: 5 | H10: 6 | I10: 7 | J10: 8 | K10: 9 | L10: 10 | M10: 11 | N10: 12 | O10: 13 | P10: 14 | Q10: 15 | R10: 16
A11: 97.00.00 | B11: BEBAN UMUM & ADMINISTRASI
A12: 97.01.10 | B12: Beban Pegawai Umum & Adm | E12: =SUM(E13:E16) -> 0 | F12: =SUM(F13:F16) -> 0 | G12: =SUM(G13:G16) -> 0 | H12: =SUM(H13:H16) -> 0 | I12: =SUM(I13:I16) -> 0 | J12: =SUM(J13:J16) -> 0 | K12: =SUM(K13:K16) -> 0 | L12: =SUM(L13:L16) -> 0 | ... P12: =SUM(P13:P16) -> 0 | Q12: =SUM(E12:P12) -> 0
C13: Direktur | Q13: =SUM(E13:P13) -> 0
C14: Pegawai Adm &Umum | Q14: =SUM(E14:P14) -> 0
C15: Lembur | Q15: =SUM(E15:P15) -> 0
C16: Insentife/THR/Dana Kesejahteraan/Bonus | Q16: =SUM(E16:P16) -> 0
A17: 97.01.20 | B17: Beban Kesejahteraan Karyawan Adm Umum | E17: =SUM(E18:E22) -> 0 | F17: =SUM(F18:F22) -> 0 | G17: =SUM(G18:G22) -> 0 | H17: =SUM(H18:H22) -> 0 | I17: =SUM(I18:I22) -> 0 | J17: =SUM(J18:J22) -> 0 | K17: =SUM(K18:K22) -> 0 | L17: =SUM(L18:L22) -> 0 | ... P17: =SUM(P18:P22) -> 0 | Q17: =SUM(E17:P17) -> 0
C18: Iuran Dana Pensiun | Q18: =SUM(E18:P18) -> 0
C19: Beban BPJS Kesehatan | Q19: =SUM(E19:P19) -> 0
C20: Beban BPJS Ketenagakerjaan | Q20: =SUM(E20:P20) -> 0
C21: Uang Makan & Minum | Q21: =SUM(E21:P21) -> 0
C22: Uang Pisah / Purna Tugas | Q22: =SUM(E22:P22) -> 0
A23: 97.01.30 | B23: Beban Pakaian Dinas & Olahraga | Q23: =SUM(E23:P23) -> 0
A24: 97.01.40 | B24: Pendidikan dan latihan | Q24: =SUM(E24:P24) -> 0
A25: 97.01.50 | B25: Beban Pembinaan Pegawai Umum | Q25: =SUM(E25:P25) -> 0
A26: 97.01.60 | B26: Beban Bantuan & sumbangan | Q26: =SUM(E26:P26) -> 0
A27: 97.01.90 | B27: Rupa-Rupa Beban Pegawai | Q27: =SUM(E27:P27) -> 0
B28: Pjak Pegawai | Q28: =SUM(E28:P28) -> 0
B29: Jumlah Beban Pegawai | E29: =SUM(E23:E28)+E17+E12 -> 0 | F29: =SUM(F23:F28)+F17+F12 -> 0 | G29: =SUM(G23:G28)+G17+G12 -> 0 | H29: =SUM(H23:H28)+H17+H12 -> 0 | I29: =SUM(I23:I28)+I17+I12 -> 0 | J29: =SUM(J23:J28)+J17+J12 -> 0 | K29: =SUM(K23:K28)+K17+K12 -> 0 | L29: =SUM(L23:L28)+L17+L12 -> 0 | ... P29: =SUM(P23:P28)+P17+P12 -> 0 | Q29: =SUM(E29:P29) -> 0 | R29: B. PEGAWAI
A30: 97.02.00 | B30: BEBAN KANTOR | Q30: =SUM(E30:P30) -> 0
A31: 97.02.10 | B31: Beban Alat Tulis Kantor dan Fotocopy | Q31: =SUM(E31:P31) -> 0
A32: 97.02.20 | B32: Barang-barang Cetakkan | Q32: =SUM(E32:P32) -> 0
A33: 97.02.30 | B33: Perlengkapan Komputer | Q33: =SUM(E33:P33) -> 0
A34: 97.02.40 | B34: Beban Telepon, Telek dan Telegram | Q34: =SUM(E34:P34) -> 0
A35: 97.02.50 | B35: Beban Rapat dan Tamu | Q35: =SUM(E35:P35) -> 0
C36: Dana Representatif Direktur | Q36: =SUM(E36:P36) -> 0
C37: Biaya Rapat dan Tamu | Q37: =SUM(E37:P37) -> 0
A38: 97.02.60 | B38: Benda Pos dan materai | Q38: =SUM(E38:P38) -> 0
A39: 97.02.70 | B39: Beban Listrik/Penerangan | Q39: =SUM(E39:P39) -> 0
A40: 97.02.80 | B40: Beban cleaning Service | Q40: =SUM(E40:P40) -> 0
A41: 97.02.90 | B41: Rupa-rupa Beban Kantor | Q41: =SUM(E41:P41) -> 0
B42: Paket Internet (Wifi) | Q42: =SUM(E42:P42) -> 0
...

Sheet B. NON OPERASIONAL
A1: PEMERINTAH KABUPATEN SERUYAN
A2: PERUSAHAAN DAERAH AIR MINUM (PDAM) | O2: P-12
A4: RENCANA BIAYA DILUAR USAHA / LAIN-LAIN
A5: TAHUN ANGGARAN 2025
A7: PDAM KABUPATEN SERUYAN
A8: NO | B8: URAIAN | C8: BULAN | O8: JUMLAH | P8: MAPPING BEBAN
A9: PERK. | C9: 1 | D9: 2 | E9: 3 | F9: 4 | G9: 5 | H9: 6 | I9: 7 | J9: 8 | K9: 9 | L9: 10 | M9: 11 | N9: 12 | O9: 2025 | P9: SAK ETAP
A10: 1 | B10: 2 | C10: 3 | D10: 4 | E10: 5 | F10: 6 | G10: 7 | H10: 8 | I10: 9 | J10: 10 | K10: 11 | L10: 12 | M10: 13 | N10: 14 | O10: 15 | P10: 16
A11: 98.00.00 | B11: BEBAN NON OPERASIONAL
A12: 98.01.00 | B12: Beban Bank | O12: =SUM(C12:N12) -> 0 | P12: B. BANK
A14: JUMLAH BIAYA UMUM & ADM | C14: =SUM(C11:C13) -> 0 | D14: =SUM(D11:D13) -> 0 | E14: =SUM(E11:E13) -> 0 | F14: =SUM(F11:F13) -> 0 | G14: =SUM(G11:G13) -> 0 | H14: =SUM(H11:H13) -> 0 | I14: =SUM(I11:I13) -> 0 | J14: =SUM(J11:J13) -> 0 | ... O14: =SUM(O11:O13) -> 0

Sheet P-9. Beban Operasi
A1: PEMERINTAH KABUPATEN SERUYAN
A2: PERUSAHAAN UMUM DAERAH AIR MINUM (PERUMDAM) | P2: LAMPIRAN 9
A3: TIRTA SERUYAN
A4: RENCANA BIAYA OPERASI
A5: TAHUN ANGGARAN 2026 | S5: =S64+S113+'P-10. Beban Umum & Adm'!S25 -> 0
A7: PERUMDAM TIRTA SERUYAN
A8: NO | B8: URAIAN | E8: BULAN | Q8: JUMLAH | R8: REALISASI | S8: SISA
A9: PERK. | E9: 1 | F9: 2 | G9: 3 | H9: 4 | I9: 5 | J9: 6 | K9: 7 | L9: 8 | M9: 9 | N9: 10 | O9: 11 | P9: 12 | Q9: 2026 | R9: 2026 | S9: 2026
A10: 1 | B10: 2 | E10: 3 | F10: 4 | G10: 5 | H10: 6 | I10: 7 | J10: 8 | K10: 9 | L10: 10 | M10: 11 | N10: 12 | O10: 13 | P10: 14 | Q10: 16
A11: 91.00.00 | B11: BEBAN SUMBER AIR | Q11: =SUM(F11:P11) -> 0 | S11: =Q11-R11 -> 0
A12: 91.01.00 | B12: BEBAN OPERASIONAL SUMBER AIR | Q12: =SUM(E12:P12) -> 0 | S12: =Q12-R12 -> 0
A13: 91.01.10 | B13: Biaya Pegawai | Q13: =SUM(E13:P13) -> 0 | S13: =Q13-R13 -> 0
B14: Gaji dan Honor Sumber Air | Q14: =SUM(E14:P14) -> 0 | S14: =Q14-R14 -> 0
B15: Insentif / THR dan Bonus | Q15: =SUM(E15:P15) -> 0 | S15: =Q15-R15 -> 0
A16: 91.01.20 | B16: Beban Kesejahteraan Karyawan Sumber Air | Q16: =SUM(E16:P16) -> 0 | S16: =Q16-R16 -> 0
B17: Beban Iuran Dana Pensiun Sumber Air | Q17: =SUM(E17:P17) -> 0 | S17: =Q17-R17 -> 0
B18: Beban BPJS Kesehatan Sumber Air | Q18: =SUM(E18:P18) -> 0 | S18: =Q18-R18 -> 0
B19: Beban BPJS Ketenagkerjaan Sumber Air | Q19: =SUM(E19:P19) -> 0 | S19: =Q19-R19 -> 0
B20: Uang Makan dan minum Sumber Air | Q20: =SUM(E20:P20) -> 0 | S20: =Q20-R20 -> 0
B21: Uang Pisah/Purna Tugas | Q21: =SUM(E21:P21) -> 0 | S21: =Q21-R21 -> 0
A22: 91.01.30 | B22: Beban Pakaian Dinas & Olahraga | Q22: =SUM(E22:P22) -> 0 | S22: =Q22-R22 -> 0
A23: 91.01.40 | B23: Beban Pendidikan & latihan Sumber air | Q23: =SUM(E23:P23) -> 0 | S23: =Q23-R23 -> 0
A24: 91.01.50 | B24: Beban Pembinaan Pegawai Sumber Air | Q24: =SUM(E24:P24) -> 0 | S24: =Q24-R24 -> 0
A25: 91.02.10 | B25: Pemakaian Bahan bakar (SOLAR) | Q25: =SUM(E25:P25) -> 0 | S25: =Q25-R25 -> 0
C26: Intake Sei. Mitak | Q26: =SUM(E26:P26) -> 0
C27: Intake Tanjung Paring | Q27: =SUM(E27:P27) -> 0
C28: Jumlah Bahan Bakar | E28: =SUM(E26:E27) -> 0 | F28: =SUM(F26:F27) -> 0 | G28: =SUM(G26:G27) -> 0 | H28: =SUM(H26:H27) -> 0 | I28: =SUM(I26:I27) -> 0 | J28: =SUM(J26:J27) -> 0 | K28: =SUM(K26:K27) -> 0 | L28: =SUM(L26:L27) -> 0 | ... Q28: =SUM(Q26:Q27) -> 0 | R28: ='RINCIAN B. LANGSUNG USAHA'!Q18 -> 0 | S28: =Q28-R28 -> 0
A29: 91.02.20 | B29: Biaya Listrik PLN | Q29: =SUM(E29:P29) -> 0 | S29: =Q29-R29 -> 0
C30: Induk PDAM | Q30: =SUM(E30:P30) -> 0
C31: IKK Kartika Bhakti | Q31: =SUM(E31:P31) -> 0
C32: IKK Pembuang Hulu | Q32: =SUM(E32:P32) -> 0
C33: Jumlah Biaya Listrik PLN | E33: =SUM(E30:E32) -> 0 | F33: =SUM(F30:F32) -> 0 | G33: =SUM(G30:G32) -> 0 | H33: =SUM(H30:H32) -> 0 | I33: =SUM(I30:I32) -> 0 | J33: =SUM(J30:J32) -> 0 | K33: =SUM(K30:K32) -> 0 | L33: =SUM(L30:L32) -> 0 | ... Q33: =SUM(Q30:Q32) -> 0 | R33: ='RINCIAN B. LANGSUNG USAHA'!Q19 -> 0 | S33: =Q33-R33 -> 0
A34: 91.02.30 | B34: Pemakaian Bahan Pembantu | Q34: =SUM(E34:P34) -> 0 | R34: ='RINCIAN B. LANGSUNG USAHA'!Q20 -> 0 | S34: =Q34-R34 -> 0
A35: 91.02.40 | B35: Rupa-Rupa Biaya Operasi Sumber Air | Q35: =SUM(E35:P35) -> 0 | R35: ='RINCIAN B. LANGSUNG USAHA'!Q21 -> 0 | S35: =Q35-R35 -> 0
B36: Beban Operasi Sumber Air | E36: =SUM(E13:E24)+E28+E33+E34+E35 -> 0 | F36: =SUM(F13:F24)+F28+F33+F34+F35 -> 0 | G36: =SUM(G13:G24)+G28+G33+G34+G35 -> 0 | H36: =SUM(H13:H24)+H28+H33+H34+H35 -> 0 | I36: =SUM(I13:I24)+I28+I33+I34+I35 -> 0 | J36: =SUM(J13:J24)+J28+J33+J34+J35 -> 0 | K36: =SUM(K13:K24)+K28+K33+K34+K35 -> 0 | L36: =SUM(L13:L24)+L28+L33+L34+L35 -> 0 | ... P36: =SUM(P13:P24)+P28+P33+P34+P35 -> 0 | Q36: =SUM(E36:P36) -> 0 | R36: =SUM(R11:R35) -> 0 | S36: =SUM(S11:S35) -> 0 | T36: ='RINCIAN B. LANGSUNG USAHA'!Q22 -> 0 | U36: 1275000
A37: 91.03.00 | B37: BEBAN PEMELIHARAAN SUMBER AIR
A38: 91.03.10 | B38: Pemeliharaan bangunan dan penyempurnaan tanah | Q38: =SUM(E38:P38) -> 0 | R38: ='RINCIAN B. LANGSUNG USAHA'!Q24 -> 0 | S38: =Q38-R38 -> 0
A39: 91.03.40 | B39: Pemeliharaan Mata air dan Saluran | Q39: =SUM(E39:P39) -> 0 | R39: ='RINCIAN B. LANGSUNG USAHA'!Q25 -> 0 | S39: =Q39-R39 -> 0
A40: 91.03.60 | B40: Pemeliharaan Pipa Induk | Q40: =SUM(E40:P40) -> 0 | R40: ='RINCIAN B. LANGSUNG USAHA'!Q26 -> 0 | S40: =Q40-R40 -> 0
A41: 91.03.70 | B41: Pemeliharaan Alat Pembangkit Tenaga | Q41: =SUM(E41:P41) -> 0 | R41: ='RINCIAN B. LANGSUNG USAHA'!Q27 -> 0 | S41: =Q41-R41 -> 0
...

Sheet P-10. Beban Umum & Adm
A1: PEMERINTAH KABUPATEN SERUYAN
A2: PERUSAHAAN UMUM DAERAH AIR MINUM (PERUMDAM) | P2: LAMPIRAN 10
A3: TIRTA SERUYAN
A5: RENCANA BIAYA UMUM DAN ADMINISTRASI
A6: TAHUN ANGGARAN 2026
A8: PERUMDAM TIRTA SERUYAN
A9: NO | B9: URAIAN | E9: BULAN | Q9: JUMLAH | R9: REALISASI | S9: SISA
A10: PERK. | E10: 1 | F10: 2 | G10: 3 | H10: 4 | I10: 5 | J10: 6 | K10: 7 | L10: 8 | M10: 9 | N10: 10 | O10: 11 | P10: 12 | Q10: 2026 | R10: 2026 | S10: 2026
A11: 1 | B11: 2 | E11: 3 | F11: 4 | G11: 5 | H11: 6 | I11: 7 | J11: 8 | K11: 9 | L11: 10 | M11: 11 | N11: 12 | O11: 13 | P11: 14 | Q11: 15
A12: 97.00.00 | B12: BEBAN UMUM DAN ADMINISTRASI
A13: 97.01.10 | B13: Beban Pegawai Umum & Administrasi | R13: ='RINCIAN B. TDK LANGSUNG'!Q12 -> 0 | S13: =SUM(Q14:Q17)-R13 -> 0
B14: Direktur | Q14: =SUM(E14:P14) -> 0
B15: Pegawai Induk PERUMDAM | Q15: =SUM(E15:P15) -> 0
B16: Lembur pegawai Adm & Umum | Q16: =SUM(E16:P16) -> 0
B17: Insentif / THR , dana kesejahteraan pegawai dan Bonus / Uang Cuti | G17: =G14+G15 -> 0 | P17: =P14+P15 -> 0 | Q17: =SUM(E17:P17) -> 0
A18: 97.01.20 | B18: Beban Kesejahteraan Karyawan Umum & Adm | Q18: =SUM(E18:P18) -> 0
B19: Beban Iuran Dana Pensiun Umum & Adm | Q19: =SUM(E19:P19) -> 0 | R19: ='RINCIAN B. TDK LANGSUNG'!Q18 -> 0 | S19: =Q19-R19 -> 0
B20: Beban BPJS Kesehatan Umum & Adm | Q20: =SUM(E20:P20) -> 0 | R20: ='RINCIAN B. TDK LANGSUNG'!Q19 -> 0 | S20: =Q20-R20 -> 0
B21: Beban BPJS Ketenagkerjaan Umum & Adm | Q21: =SUM(E21:P21) -> 0 | R21: ='RINCIAN B. TDK LANGSUNG'!Q20 -> 0 | S21: =Q21-R21 -> 0
B22: Uang Makan/Minum Pegawai | Q22: =SUM(E22:P22) -> 0 | R22: ='RINCIAN B. TDK LANGSUNG'!Q21 -> 0 | S22: =Q22-R22 -> 0
B23: Uang Pisah/Purna Tugas | Q23: =SUM(E23:P23) -> 0 | R23: ='RINCIAN B. TDK LANGSUNG'!Q22 -> 0 | S23: =Q23-R23 -> 0
A24: 97.01.30 | B24: Beban Pakaian Dinas & Olahraga | Q24: =SUM(E24:P24) -> 0 | R24: ='RINCIAN B. TDK LANGSUNG'!Q23 -> 0 | S24: =Q24-R24 -> 0
A25: 97.01.40 | B25: Beban Pendidikan & latihan Umum & Adm | Q25: =SUM(E25:P25) -> 0 | R25: ='RINCIAN B. TDK LANGSUNG'!Q24 -> 0 | S25: =Q25-R25 -> 0
A26: 97.01.50 | B26: Beban Pembinaan Pegawai Umum & Adm | Q26: =SUM(E26:P26) -> 0 | R26: ='RINCIAN B. TDK LANGSUNG'!Q25 -> 0 | S26: =Q26-R26 -> 0
A27: 97.01.60 | B27: Beban Bantuan & Sumbangan | Q27: =SUM(E27:P27) -> 0 | R27: ='RINCIAN B. TDK LANGSUNG'!Q26 -> 0 | S27: =Q27-R27 -> 0
A28: 97.01.90 | B28: Rupa-Rupa Biaya Pegawai | Q28: =SUM(E28:P28) -> 0 | R28: ='RINCIAN B. TDK LANGSUNG'!Q27 -> 0 | S28: =Q28-R28 -> 0
B29: Pajak Pegawai | Q29: =SUM(E29:P29) -> 0 | R29: ='RINCIAN B. TDK LANGSUNG'!Q28 -> 0 | S29: =Q29-R29 -> 0
B30: Jumlah Biaya Pegawai | E30: =SUM(E14:E29) -> 0 | F30: =SUM(F14:F29) -> 0 | G30: =SUM(G14:G29) -> 0 | H30: =SUM(H14:H29) -> 0 | I30: =SUM(I14:I29) -> 0 | J30: =SUM(J14:J29) -> 0 | K30: =SUM(K14:K29) -> 0 | L30: =SUM(L14:L29) -> 0 | ... P30: =SUM(P14:P29) -> 0 | Q30: =SUM(E30:P30) -> 0 | R30: =SUM(R11:R29) -> 0 | S30: =SUM(S11:S29) -> 0 | T30: ='RINCIAN B. TDK LANGSUNG'!Q29 -> 0
A31: 97.02.00 | B31: BEBAN KANTOR
A32: 97.02.10 | B32: Beban Alat Tulis Kantor dan Fotocopy | Q32: =SUM(E32:P32) -> 0 | R32: ='RINCIAN B. TDK LANGSUNG'!Q31 -> 0 | S32: =Q32-R32 -> 0
A33: 97.02.20 | B33: Barang-barang Cetakkan | Q33: =SUM(E33:P33) -> 0 | R33: ='RINCIAN B. TDK LANGSUNG'!Q32 -> 0 | S33: =Q33-R33 -> 0
A34: 97.02.30 | B34: Perlengkapan Komputer | Q34: =SUM(E34:P34) -> 0 | R34: ='RINCIAN B. TDK LANGSUNG'!Q33 -> 0 | S34: =Q34-R34 -> 0
A35: 97.02.40 | B35: Beban Telepon, Telek dan Telegram | Q35: =SUM(E35:P35) -> 0 | R35: ='RINCIAN B. TDK LANGSUNG'!Q34 -> 0 | S35: =Q35-R35 -> 0
A36: 97.02.50 | B36: Beban Rapat dan Tamu | Q36: =SUM(E36:P36) -> 0 | R36: ='RINCIAN B. TDK LANGSUNG'!Q36+'RINCIAN B. TDK LANGSUNG'!Q37 -> 0 | S36: =Q36-R36 -> 0
A37: 97.02.60 | B37: Benda Pos dan materai | Q37: =SUM(E37:P37) -> 0 | R37: ='RINCIAN B. TDK LANGSUNG'!Q38 -> 0 | S37: =Q37-R37 -> 0
A38: 97.02.70 | B38: Beban Listrik/Penerangan | Q38: =SUM(E38:P38) -> 0 | R38: ='RINCIAN B. TDK LANGSUNG'!Q39 -> 0 | S38: =Q38-R38 -> 0
A39: 97.02.80 | B39: Beban cleaning Service | Q39: =SUM(E39:P39) -> 0 | R39: ='RINCIAN B. TDK LANGSUNG'!Q40 -> 0 | S39: =Q39-R39 -> 0
A40: 97.02.90 | B40: Rupa-rupa Beban Kantor | S40: =Q40-R40 -> 0
B41: Paket Internet (Wifi) | Q41: =SUM(E41:P41) -> 0 | R41: ='RINCIAN B. TDK LANGSUNG'!Q42 -> 0 | S41: =Q41-R41 -> 0
B42: Rupa-rupa beban kantor lainnya | Q42: =SUM(E42:P42) -> 0 | R42: ='RINCIAN B. TDK LANGSUNG'!Q43 -> 0 | S42: =Q42-R42 -> 0
...

Sheet Sheet1
A5: ='RINCIAN B. LANGSUNG USAHA'!B37 -> Beban Pegawai | B5: ='P-9. Beban Operasi'!Q52+'P-9. Beban Operasi'!Q53+'P-9. Beban Operasi'!Q54+'P-9. Beban Operasi'!Q55+'P-9. Beban Operasi'!Q56+'P-9. Beban Operasi'!Q58+'P-9. Beban Operasi'!Q59+'P-9. Beban Operasi'!Q60+'P-9. Beban Operasi'!Q61+'P-9. Beban Operasi'!Q63+'P-9. Beban Operasi'!Q64 -> 0
B6: ='P-9. Beban Operasi'!Q118-'P-9. Beban Operasi'!Q115-'P-9. Beban Operasi'!Q116-'P-9. Beban Operasi'!Q117 -> 0
B7: ='P-10. Beban Umum & Adm'!Q30+'P-10. Beban Umum & Adm'!Q68-B24 -> 0
B8: =SUM(B5:B7) -> 0
A11: Beban Listrik | B11: ='P-9. Beban Operasi'!Q33 -> 0
A12: Beban Pemakaian Bahan Kimia | B12: ='P-9. Beban Operasi'!Q87 -> 0
A13: Beban Hubungan Langganan | B13: ='P-10. Beban Umum & Adm'!Q48 -> 0
A14: Beban Pemeliharan | B14: ='P-9. Beban Operasi'!Q44+'P-9. Beban Operasi'!Q96+'P-9. Beban Operasi'!Q126+'P-10. Beban Umum & Adm'!Q62 -> 0
A15: Beban Imbalan Kerja | B15: 0
A16: Beban Penyusutan Aset Tetap | B16: ='P-9. Beban Operasi'!Q132+'P-10. Beban Umum & Adm'!Q84-B17 -> 0
A17: Beban Amortisasi Aset Tidak Berwujud
A18: Beban Penyisihan Kerugian Piutang | B18: ='P-10. Beban Umum & Adm'!Q67 -> 0
A19: Beban Pemakaian Bahan pembantu | B19: ='P-9. Beban Operasi'!Q34+'P-9. Beban Operasi'!Q88+'P-9. Beban Operasi'!Q115 -> 0
A20: Beban Pemakaian Bahan Bakar | B20: ='P-9. Beban Operasi'!Q28+'P-9. Beban Operasi'!Q116 -> 0
A21: Beban Kantor | B21: ='P-10. Beban Umum & Adm'!Q43 -> 0
A22: Beban Penelitian dan Pengembangan | B22: ='P-10. Beban Umum & Adm'!Q55 -> 0
A23: Beban Air Baku | B23: ='P-9. Beban Operasi'!Q45 -> 0
A24: Beban PPh 21 | B24: ='P-10. Beban Umum & Adm'!Q29 -> 0
A25: Beban Operasional Lainnya | B25: ='P-9. Beban Operasi'!Q35+'P-9. Beban Operasi'!Q89+'P-9. Beban Operasi'!Q117+'P-10. Beban Umum & Adm'!Q82-'P-10. Beban Umum & Adm'!Q68-B18 -> 0
A26: Beban Harga Pokok Sambungan Baru | B26: ='P-9. Beban Operasi'!Q130 -> 0
B27: =SUM(B8:B26) -> 0
B31: =B27-B29 -> 0

Sheet P-10. Biaya Operasi
A1: PEMERINTAH KABUPATEN SERUYAN
A2: PERUSAHAAN DAERAH AIR MINUM (PDAM) | Q2: P-10
A4: RENCANA BIAYA OPERASI
A5: TAHUN ANGGARAN 2023
A7: PDAM KABUPATEN SERUYAN
A8: NO | B8: URAIAN | E8: BULAN | Q8: JUMLAH | R8: MAPPING BEBAN SAK - ETAP | S8: REALISASI | T8: SISA ANGGARAN
A9: PERK. | E9: 1 | F9: 2 | G9: 3 | H9: 4 | I9: 5 | J9: 6 | K9: 7 | L9: 8 | M9: 9 | N9: 10 | O9: 11 | P9: 12 | Q9: 2023 | S9: 2023 | T9: 2023
A10: 1 | B10: 2 | E10: 3 | F10: 4 | G10: 5 | H10: 6 | I10: 7 | J10: 8 | K10: 9 | L10: 10 | M10: 11 | N10: 12 | O10: 13 | P10: 14 | Q10: 15 | R10: 16 | S10: 17 | T10: 17
A11: 91.00.00 | B11: BIAYA SUMBER AIR | Q11: =SUM(F11:P11) -> 0
A12: 91.01.00 | B12: BIAYA OPERASIONAL SUMBER AIR | Q12: =SUM(F12:P12) -> 0
A13: 91.01.10 | B13: Biaya Pegawai | J13: 3000000 | K13: 3000000 | L13: 3000000 | M13: 3000000 | N13: 3000000 | Q13: =SUM(E13:P13) -> 15000000 | R13: B. PEGAWAI | S13: ='RINCIAN B. LANGSUNG USAHA'!Q13 -> 0 | T13: =Q13-S13 -> 15000000
A14: 91.01.20 | B14: Pemakaian Bahan bakar (SOLAR) | Q14: =SUM(E14:P14) -> 0
C15: Intake Sei. Mitak | E15: =16000*35 -> 560000 | F15: =16000*35 -> 560000 | G15: =16000*35 -> 560000 | H15: =16000*35 -> 560000 | I15: =16000*35 -> 560000 | J15: =16000*35 -> 560000 | K15: =16000*35 -> 560000 | L15: =16000*35 -> 560000 | ... P15: =16000*35 -> 560000 | Q15: =SUM(E15:P15) -> 6720000
C16: Intake Tanjung Paring | J16: =16000*1300 -> 20800000 | K16: =16000*1300 -> 20800000 | L16: =16000*1300 -> 20800000 | M16: =16000*1300 -> 20800000 | N16: =16000*1300 -> 20800000 | Q16: =SUM(E16:P16) -> 104000000
C17: Jumlah Bahan Bakar | E17: =SUM(E15:E16) -> 560000 | F17: =SUM(F15:F16) -> 560000 | G17: =SUM(G15:G16) -> 560000 | H17: =SUM(H15:H16) -> 560000 | I17: =SUM(I15:I16) -> 560000 | J17: =SUM(J15:J16) -> 21360000 | K17: =SUM(K15:K16) -> 21360000 | L17: =SUM(L15:L16) -> 21360000 | ... Q17: =SUM(Q15:Q16) -> 110720000 | R17: B. PEMAKAIAN BAHAN BAKAR | S17: ='RINCIAN B. LANGSUNG USAHA'!Q18 -> 0 | T17: =Q17-S17 -> 110720000
A18: 91.01.30 | B18: Biaya Listrik PLN | Q18: =SUM(E18:P18) -> 0 | T18: =Q18-S18 -> 0
C19: Induk PDAM | E19: 49000000 | F19: 49000000 | G19: 49000000 | H19: 49000000 | I19: 49000000 | J19: 49000000 | K19: 49000000 | L19: 49000000 | M19: 49000000 | N19: 49000000 | O19: 49000000 | P19: 49000000 | Q19: =SUM(E19:P19) -> 588000000
C20: IKK Kartika Bhakti | E20: 9000000 | F20: 9000000 | G20: 9000000 | H20: 9000000 | I20: 9000000 | J20: 9000000 | K20: 9000000 | L20: 9000000 | M20: 9000000 | N20: 9000000 | O20: 9000000 | P20: 9000000 | Q20: =SUM(E20:P20) -> 108000000
C21: IKK Pembuang Hulu | E21: 22000000 | F21: 22000000 | G21: 22000000 | H21: 22000000 | I21: 22000000 | J21: 22000000 | K21: 22000000 | L21: 22000000 | M21: 22000000 | N21: 22000000 | O21: 22000000 | P21: 22000000 | Q21: =SUM(E21:P21) -> 264000000
C22: Jumlah Biaya Listrik PLN | E22: =SUM(E19:E21) -> 80000000 | F22: =SUM(F19:F21) -> 80000000 | G22: =SUM(G19:G21) -> 80000000 | H22: =SUM(H19:H21) -> 80000000 | I22: =SUM(I19:I21) -> 80000000 | J22: =SUM(J19:J21) -> 80000000 | K22: =SUM(K19:K21) -> 80000000 | L22: =SUM(L19:L21) -> 80000000 | ... Q22: =SUM(Q19:Q21) -> 960000000 | R22: B. LISTRIK | S22: ='RINCIAN B. LANGSUNG USAHA'!Q19 -> 0 | T22: =Q22-S22 -> 960000000
A23: 91.01.40 | B23: Pemakaian Bahan Pembantu | E23: 500000 | F23: 0 | G23: 0 | H23: 500000 | I23: 0 | J23: 500000 | K23: 0 | L23: 500000 | M23: 0 | N23: 0 | O23: 500000 | P23: 0 | Q23: =SUM(E23:P23) -> 2500000 | R23: B. PEMAKAIAN BAHAN PEMBANTU | S23: ='RINCIAN B. LANGSUNG USAHA'!Q20 -> 0 | T23: =Q23-S23 -> 2500000
A24: 91.01.90 | B24: Rupa-Rupa Biaya Operasi | E24: 250000 | F24: 250000 | G24: 250000 | H24: 250000 | I24: 250000 | J24: 250000 | K24: 250000 | L24: 250000 | M24: 250000 | N24: 250000 | O24: 250000 | P24: 250000 | Q24: =SUM(E24:P24) -> 3000000 | R24: B. OPERASI LAINNYA | S24: ='RINCIAN B. LANGSUNG USAHA'!Q21 -> 0 | T24: =Q24-S24 -> 3000000
B25: B. Operasi Sumber Air | E25: =E12+E13+E17+E22+E23+E24 -> 81310000 | F25: =F12+F13+F17+F22+F23+F24 -> 80810000 | G25: =G12+G13+G17+G22+G23+G24 -> 80810000 | H25: =H12+H13+H17+H22+H23+H24 -> 81310000 | I25: =I12+I13+I17+I22+I23+I24 -> 80810000 | J25: =J12+J13+J17+J22+J23+J24 -> 105110000 | K25: =K12+K13+K17+K22+K23+K24 -> 104610000 | L25: =L12+L13+L17+L22+L23+L24 -> 105110000 | ... P25: =P12+P13+P17+P22+P23+P24 -> 80810000 | Q25: =SUM(E25:P25) -> 1091220000 | S25: =SUM(S13:S24) -> 0 | T25: =SUM(T13:T24) -> 1091220000
A26: 91.02.00 | B26: BIAYA PEMELIHARAAN SUMBER AIR
A27: 91.02.10 | B27: Pemeliharaan bangunan dan penyempurnaan tanah | M27: 10000000 | Q27: =SUM(E27:P27) -> 10000000 | S27: ='RINCIAN B. LANGSUNG USAHA'!Q24 -> 0 | T27: =Q27-S27 -> 10000000
A28: 91.02.40 | B28: Pemeliharaan Mata air dan Saluran | Q28: =SUM(E28:P28) -> 0 | S28: ='RINCIAN B. LANGSUNG USAHA'!Q25 -> 0 | T28: =Q28-S28 -> 0
A29: 91.02.60 | B29: Pemeliharaan Pipa Induk | E29: 500000 | F29: 500000 | G29: 500000 | H29: 500000 | I29: 500000 | J29: 500000 | K29: 500000 | L29: 500000 | M29: 500000 | N29: 500000 | O29: 500000 | P29: 500000 | Q29: =SUM(E29:P29) -> 6000000 | S29: ='RINCIAN B. LANGSUNG USAHA'!Q26 -> 0 | T29: =Q29-S29 -> 6000000
A30: 91.02.70 | B30: Pemeliharaan Alat Pembangkit Tenaga | F30: 1500000 | O30: 1500000 | Q30: =SUM(E30:P30) -> 3000000 | S30: ='RINCIAN B. LANGSUNG USAHA'!Q27 -> 0 | T30: =Q30-S30 -> 3000000
A31: 91.02.80 | B31: Pemeliharaan Alat Perpompaan | E31: 16500000 | F31: 16500000 | J31: 16500000 | K31: 16500000 | N31: 16500000 | Q31: =SUM(E31:P31) -> 82500000 | S31: ='RINCIAN B. LANGSUNG USAHA'!Q28 -> 0 | T31: =Q31-S31 -> 82500000
A32: 91.02.90 | B32: Pemeliharaan Instalasi Sumber Air Lainnya | E32: 500000 | F32: 500000 | G32: 500000 | H32: 500000 | I32: 500000 | J32: 500000 | K32: 500000 | L32: 500000 | M32: 500000 | N32: 500000 | O32: 500000 | P32: 500000 | Q32: =SUM(E32:P32) -> 6000000 | S32: ='RINCIAN B. LANGSUNG USAHA'!Q29 -> 0 | T32: =Q32-S32 -> 6000000
B33: Jumlah Biaya Pemeliharaan Sumber Air | E33: =SUM(E27:E32) -> 17500000 | F33: =SUM(F27:F32) -> 19000000 | G33: =SUM(G27:G32) -> 1000000 | H33: =SUM(H27:H32) -> 1000000 | I33: =SUM(I27:I32) -> 1000000 | J33: =SUM(J27:J32) -> 17500000 | K33: =SUM(K27:K32) -> 17500000 | L33: =SUM(L27:L32) -> 1000000 | ... P33: =SUM(P27:P32) -> 1000000 | Q33: =SUM(E33:P33) -> 107500000 | R33: B. PEMELIHARAAN | S33: =SUM(S27:S32) -> 0 | T33: =SUM(T27:T32) -> 107500000
A34: 91.03.00 | B34: BIAYA AIR BAKU (PAJAK AIR PERMUKAAN) | G34: =(121889+53632+870246)*150*10% -> 15686505 | Q34: =SUM(E34:P34) -> 15686505 | R34: B. BAHAN BAKU | S34: ='RINCIAN B. LANGSUNG USAHA'!Q31 -> 0 | T34: =Q34-S34 -> 15686505
B35: JUMLAH SEBELUM PENYUSUTAN | E35: =E33+E25+E34 -> 98810000 | F35: =F33+F25+F34 -> 99810000 | G35: =G33+G25+G34 -> 97496505 | H35: =H33+H25+H34 -> 82310000 | I35: =I33+I25+I34 -> 81810000 | J35: =J33+J25+J34 -> 122610000 | K35: =K33+K25+K34 -> 122110000 | L35: =L33+L25+L34 -> 106110000 | ... P35: =P33+P25+P34 -> 81810000 | Q35: =SUM(E35:P35) -> 1214406505 | S35: =S34+S33+S25 -> 0 | T35: =Q35-S35 -> 1214406505
A36: 91.09.00 | B36: BIAYA PENYUSUTAN SUMBER AIR | E36: =9180831+18140880+1000000 -> 28321711 | F36: =9180831+18140880+1000000 -> 28321711 | G36: =9180831+18140880+1000000 -> 28321711 | H36: =9180831+18140880+1000000 -> 28321711 | I36: =9180831+18140880+1000000 -> 28321711 | J36: =9180831+18140880+1000000 -> 28321711 | K36: =9180831+18140880+1000000 -> 28321711 | L36: =9180831+18140880+1000000 -> 28321711 | ... P36: =9180831+18140880+1000000 -> 28321711 | Q36: =SUM(E36:P36) -> 339860532 | R36: B. PENYUSUTAN | S36: ='RINCIAN B. LANGSUNG USAHA'!Q33 -> 0 | T36: =Q36-S36 -> 339860532
B37: JUMLAH BIAYA SUMBER AIR | E37: =SUM(E35:E36) -> 127131711 | F37: =SUM(F35:F36) -> 128131711 | G37: =SUM(G35:G36) -> 125818216 | H37: =SUM(H35:H36) -> 110631711 | I37: =SUM(I35:I36) -> 110131711 | J37: =SUM(J35:J36) -> 150931711 | K37: =SUM(K35:K36) -> 150431711 | L37: =SUM(L35:L36) -> 134431711 | ... P37: =SUM(P35:P36) -> 110131711 | Q37: =SUM(E37:P37) -> 1554267037 | S37: =SUM(S35:S36) -> 0 | T37: =SUM(T35:T36) -> 1554267037
Q38: =SUM(E38:P38) -> 0
A39: 92.00.00 | B39: BIAYA PENGOLAHAN AIR | Q39: =SUM(E39:P39) -> 0
A40: 92.01.10 | B40: Biaya Pegawai
C41: Induk PDAM | E41: 26500000 | F41: 26500000 | G41: 26500000 | H41: 26500000 | I41: 26500000 | J41: 26500000 | K41: 26500000 | L41: 26500000 | M41: 26500000 | N41: 26500000 | O41: 26500000 | P41: 26500000 | Q41: =SUM(E41:P41) -> 318000000
C42: IKK Kartika Bhakti | E42: =14000000 -> 14000000 | F42: =14000000 -> 14000000 | G42: =14000000 -> 14000000 | H42: =14000000 -> 14000000 | I42: =14000000 -> 14000000 | J42: =14000000 -> 14000000 | K42: =14000000 -> 14000000 | L42: =14000000 -> 14000000 | ... P42: =14000000 -> 14000000 | Q42: =SUM(E42:P42) -> 168000000
...

Sheet P-11. Biaya UMUM & ADM
A1: PEMERINTAH KABUPATEN SERUYAN
A2: PERUSAHAAN DAERAH AIR MINUM (PDAM) | Q2: P-11
A4: RENCANA BIAYA UMUM DAN ADMINISTRASI
A5: TAHUN ANGGARAN 2023
A7: PDAM KABUPATEN SERUYAN
A8: NO | B8: URAIAN | E8: BULAN | Q8: JUMLAH | R8: MAPPING BEBAN | S8: REALISASI | T8: SISA ANGGARAN
A9: PERK. | E9: 1 | F9: 2 | G9: 3 | H9: 4 | I9: 5 | J9: 6 | K9: 7 | L9: 8 | M9: 9 | N9: 10 | O9: 11 | P9: 12 | Q9: 2023 | R9: SAK - ETAP | S9: 2023 | T9: 2023
A10: 1 | B10: 2 | E10: 3 | F10: 4 | G10: 5 | H10: 6 | I10: 7 | J10: 8 | K10: 9 | L10: 10 | M10: 11 | N10: 12 | O10: 13 | P10: 14 | Q10: 15 | R10: 16 | S10: 17 | T10: 17
A11: 96.01.00 | B11: BIAYA PEGAWAI
A12: 96.01.10 | B12: Gaji dan Tunjangan Pegawai
B13: Direktur | E13: 17550000 | F13: 17550000 | G13: 17550000 | H13: 17550000 | I13: 17550000 | J13: 17550000 | K13: 17550000 | L13: 17550000 | M13: 17550000 | N13: 17550000 | O13: 17550000 | P13: 17550000 | Q13: =SUM(E13:P13) -> 210600000
B14: Pegawai Induk PDAM | E14: =110000000-E13 -> 92450000 | F14: =110000000-F13 -> 92450000 | G14: =110000000-G13 -> 92450000 | H14: =110000000-H13 -> 92450000 | I14: =110000000-I13 -> 92450000 | J14: =110000000-J13 -> 92450000 | K14: =110000000-K13 -> 92450000 | L14: =110000000-L13 -> 92450000 | ... P14: =110000000-P13 -> 92450000 | Q14: =SUM(E14:P14) -> 1109400000
B15: Jumlah Gaji dan Honor Pegawai | E15: =SUM(E13:E14) -> 110000000 | F15: =SUM(F13:F14) -> 110000000 | G15: =SUM(G13:G14) -> 110000000 | H15: =SUM(H13:H14) -> 110000000 | I15: =SUM(I13:I14) -> 110000000 | J15: =SUM(J13:J14) -> 110000000 | K15: =SUM(K13:K14) -> 110000000 | L15: =SUM(L13:L14) -> 110000000 | ... Q15: =SUM(Q13:Q14) -> 1320000000 | R15: B. PEGAWAI | S15: ='RINCIAN B. TDK LANGSUNG'!#REF! -> #REF! | T15: =Q15-S15 -> #REF!
A16: 96.01.30 | B16: Iuran Pensiun | E16: 20000000 | F16: 20000000 | G16: 20000000 | H16: 20000000 | I16: 20000000 | J16: 20000000 | K16: 20000000 | L16: 20000000 | M16: 20000000 | N16: 20000000 | O16: 20000000 | P16: 20000000 | Q16: =SUM(E16:P16) -> 240000000 | S16: ='RINCIAN B. TDK LANGSUNG'!#REF! -> #REF! | T16: =Q16-S16 -> #REF!
A17: 96.01.50 | B17: Insentife/Kesejahteraan Karyawan | Q17: =SUM(Q18:Q20) -> 452800320 | S17: ='RINCIAN B. TDK LANGSUNG'!#REF! -> #REF! | T17: =Q17-S17 -> #REF!
B18: Uang Makan/Minum Pegawai | E18: 27500000 | F18: 27500000 | G18: 27500000 | H18: 27500000 | I18: 27500000 | J18: 27500000 | K18: 27500000 | L18: 27500000 | M18: 27500000 | N18: 27500000 | O18: 27500000 | P18: 27500000 | Q18: =SUM(E18:P18) -> 330000000
B19: Honor Tim Pengadaan dan Tim Kegiatan | F19: =7000000+(4*3000000) -> 19000000 | H19: =3000000+11000000 -> 14000000 | I19: 3000000 | J19: 6000000 | L19: 6000000 | N19: 6000000 | O19: 3000000 | P19: 12000000 | Q19: =SUM(E19:P19) -> 69000000
B20: Pesangon dan Jasa Pengabdian | E20: 36250320 | I20: 17550000 | Q20: =SUM(E20:P20) -> 53800320
B21: Gaji Ke 13 (Tunjangan Hari Raya) | H21: =H15+'[9]P-10. Biaya Operasi'!H79+'[9]P-10. Biaya Operasi'!H44 -> 193500000 | Q21: =SUM(E21:P21) -> 193500000 | S21: ='RINCIAN B. TDK LANGSUNG'!#REF! -> #REF! | T21: =Q21-S21 -> #REF!
B22: Gaji ke 14 (Tunjangan Cuti) | P22: 120000000 | Q22: =SUM(E22:P22) -> 120000000 | S22: ='RINCIAN B. TDK LANGSUNG'!#REF! -> #REF! | T22: =Q22-S22 -> #REF!
A23: 96.01.60 | B23: Pembinaan Karyawan & Pakaian Dinas | E23: =(500000*47) -> 23500000 | G23: =(600000*47) -> 28200000 | Q23: =SUM(E23:P23) -> 51700000 | S23: ='RINCIAN B. TDK LANGSUNG'!Q23 -> 0 | T23: =Q23-S23 -> 51700000
A24: 96.01.70 | B24: Bantuan dan Sumbangan Uang Duka | E24: 250000 | F24: 250000 | G24: 250000 | H24: 250000 | I24: 250000 | J24: 250000 | K24: 250000 | L24: 250000 | M24: 250000 | N24: 250000 | O24: 250000 | P24: 250000 | Q24: =SUM(E24:P24) -> 3000000 | S24: ='RINCIAN B. TDK LANGSUNG'!Q24 -> 0 | T24: =Q24-S24 -> 3000000
A25: 96.01.80 | B25: Pendidikan dan latihan | E25: 10000000 | F25: 12500000 | G25: 10000000 | H25: 10000000 | I25: 12500000 | J25: 12500000 | K25: 15000000 | L25: 15000000 | M25: 15000000 | N25: 15000000 | O25: 15000000 | P25: 12500000 | Q25: =SUM(E25:P25) -> 155000000 | S25: ='RINCIAN B. TDK LANGSUNG'!Q25 -> 0 | T25: =Q25-S25 -> 155000000
A26: 96.01.90 | B26: Rupa-Rupa Biaya Pegawai | Q26: =SUM(E26:P26) -> 0 | T26: =Q26-S26 -> 0
