Workbook

Sheet BPTRA
A1: PERUSAHAAN DAERAH AIR MINUM
A2: KABUPATEN SERUYAN
A4: BUKTI PENERIMAAN TAGIHAN REKENING NON AIR
A5: BULAN : JANUARI 2021
E7: BPTRNA/01/I/2021
A8: NO | B8: NAMA PELANGGAN | C8: NO. PELANGGAN | D8: NO. BUKTI | E8: JUMLAH
A9: 1
A10: 2 | B10: Tidak Ada Transaksi Penerimaan Rek. Air
A11: 3
A12: 4
B14: JUMLAH | E14: =SUM(E9:E13) -> 0
D16: Kuala Pembuang, ... Januari 2021
D17: Kasi. Pembukuan

Sheet BPTRNA
A1: PERUSAHAAN DAERAH AIR MINUM
A2: KABUPATEN SERUYAN
A4: BUKTI PENERIMAAN TAGIHAN REKENING NON AIR
A5: BULAN : JANUARI 2021
E7: BPTRNA/01/I/2021
A8: NO | B8: NAMA PELANGGAN | C8: NO. PELANGGAN | D8: NO. BUKTI | E8: JUMLAH
A9: 1 | B9: Penerimaan SR Baru 3 SR | E9: =875000*3 -> 2625000
A10: =A9+1 -> 2
A11: =A10+1 -> 3
A12: =A11+1 -> 4
A13: =A12+1 -> 5
A14: =A13+1 -> 6
A15: =A14+1 -> 7
B17: JUMLAH | E17: =SUM(E9:E15) -> 2625000
D19: Kuala Pembuang, 06 Januari 2021
A54: PERUSAHAAN DAERAH AIR MINUM
A55: KABUPATEN SERUYAN
A57: BUKTI PENERIMAAN TAGIHAN REKENING NON AIR
A58: BULAN : JANUARI 2021
E60: BPTRNA/02/I/2021
A61: NO | B61: NAMA PELANGGAN | C61: NO. PELANGGAN | D61: NO. BUKTI | E61: JUMLAH
A62: 1 | B62: Penerimaan SR Baru 19 SR | E62: =19*875000 -> 16625000
A63: =A62+1 -> 2
A64: =A63+1 -> 3
A65: =A64+1 -> 4
A66: =A65+1 -> 5
A67: =A66+1 -> 6
A68: =A67+1 -> 7
B70: JUMLAH | E70: =SUM(E62:E68) -> 16625000
D72: Kuala Pembuang, 12 Januari 2021
A107: PERUSAHAAN DAERAH AIR MINUM
A108: KABUPATEN SERUYAN
A110: BUKTI PENERIMAAN TAGIHAN REKENING NON AIR
A111: BULAN : JANUARI 2021
E113: BPTRNA/03/I/2021
A114: NO | B114: NAMA PELANGGAN | C114: NO. PELANGGAN | D114: NO. BUKTI | E114: JUMLAH
A115: 1 | B115: Penerimaan Balik Nama | E115: 100000
A116: =A115+1 -> 2
A117: =A116+1 -> 3
A118: =A117+1 -> 4
...

Sheet BPTDN
A1: PERUSAHAAN DAERAH AIR MINUM
A2: KABUPATEN SERUYAN
A4: BUKTI PENERIMAAN DENDA
A5: BULAN : JANUARI 2018
E7: BPTDN/01/I/2018
A8: NO | B8: NAMA PELANGGAN | C8: NO. PELANGGAN | D8: NO. BUKTI | E8: JUMLAH
A9: 1 | B9: Rafiah | C9: 000408 | E9: 50000
A10: =A9+1 -> 2 | B10: Hj. Nurlaila A | C10: 000802 | E10: 12500
A11: =A10+1 -> 3 | B11: Eko Budi S | C11: 000942 | E11: 5000
A12: =A11+1 -> 4 | B12: Titin Yuli Susanti | C12: 000966 | E12: 42500
A13: =A12+1 -> 5 | B13: Irsyad Munawar, ST | C13: 000969 | E13: 42500
A14: =A13+1 -> 6 | B14: Sudirman | C14: 001430 | E14: 12500
A15: =A14+1 -> 7 | B15: Norhanisah | C15: 001491 | E15: 32500
A16: =A15+1 -> 8 | B16: Heri | C16: 001658 | E16: 17500
A17: =A16+1 -> 9 | B17: Raden Kartono, S. Pd | C17: 001809 | E17: 5000
A18: =A17+1 -> 10 | B18: Suriansyah | C18: 001820 | E18: 5000
A19: =A18+1 -> 11 | B19: H. Muhammad Hanafie | C19: 002055 | E19: 12500
A20: =A19+1 -> 12 | B20: Agus Wakidjo | C20: 002381 | E20: 5000
A21: =A20+1 -> 13 | B21: Wahana | C21: 002452 | E21: 5000
A22: =A21+1 -> 14 | B22: Norhayati | C22: 002542 | E22: 5000
B24: JUMLAH | E24: =SUM(E9:E23) -> 252500
D26: Kuala Pembuang, 02 Januari 2018
D27: Kasi. Pembukuan
A54: PERUSAHAAN DAERAH AIR MINUM
A55: KABUPATEN SERUYAN
A57: BUKTI PENERIMAAN DENDA
A58: BULAN : JANUARI 2018
E60: BPTDN/02/I/2018
A61: NO | B61: NAMA PELANGGAN | C61: NO. PELANGGAN | D61: NO. BUKTI | E61: JUMLAH
A62: 1 | B62: Nur Aiti | C62: 000134 | E62: 12500
A63: =A62+1 -> 2 | B63: Suriyadi | C63: 000203 | E63: 5000
A64: =A63+1 -> 3 | B64: Koesnan AS | C64: 000318 | E64: 5000
A65: =A64+1 -> 4 | B65: Bandu | C65: 000345 | E65: 5000
A66: =A65+1 -> 5 | B66: Roby Kurniawan | C66: 000425 | E66: 22500
A67: =A66+1 -> 6 | B67: Susilawati | C67: 000712 | E67: 42500
A68: =A67+1 -> 7 | B68: H. Ahmad Dehen | C68: 000735 | E68: 22500
A69: =A68+1 -> 8 | B69: Mujibur Rahman | C69: 000745 | E69: 47500
A70: =A69+1 -> 9 | B70: Indra Gunawi | C70: 000872 | E70: 52500
A71: =A70+1 -> 10 | B71: H. Sutriasmono | C71: 000925 | E71: 62500
A72: =A71+1 -> 11 | B72: Muliannor | C72: 000935 | E72: 5000
...

Sheet BKM
A1: PERUSAHAAN DAERAH AIR MINUM
A2: KABUPATEN SERUYAN
A5: BUKTI KAS MASUK
A6: BULAN : JANUARI 2021
I7: No. KM/01/I/2021
A8: NO | B8: URAIAN | C8: NO. BUKTI | D8: PENERIMAAN | I8: JUMLAH
D9: TAGIHAN | E9: TAGIHAN | F9: DENDA | G9: ANGSURAN | H9: DANA
D10: REKENING | E10: REKENING | F10: REKENING | G10: PIUTANG | H10: METER
D11: AIR | E11: NON AIR | F11: AIR | G11: KARYAWAN
A12: 1 | B12: Penerimaan Rek Air & Adm | C12: BPTRA/01/I/2021 | D12: Tidak Ada Transaksi | I12: =SUM(D12:H12) -> 0
I13: =SUM(D13:H13) -> 0
I14: =SUM(D14:H14) -> 0
I15: =SUM(D15:H15) -> 0
B18: JUMLAH | D18: =SUM(D12:D17) -> 0 | E18: =SUM(E12:E17) -> 0 | F18: =SUM(F12:F17) -> 0 | G18: =SUM(G12:G17) -> 0 | H18: =SUM(H12:H17) -> 0 | I18: =SUM(I12:I17) -> 0
G20: Kuala Pembuang, 01 Januari 2021
A34: PERUSAHAAN DAERAH AIR MINUM
A35: KABUPATEN SERUYAN
A38: BUKTI KAS MASUK
A39: BULAN : JANUARI 2021
I40: No. KM/02/I/2021
A41: NO | B41: URAIAN | C41: NO. BUKTI | D41: PENERIMAAN | I41: JUMLAH
D42: TAGIHAN | E42: TAGIHAN | F42: DENDA | G42: ANGSURAN | H42: DANA
D43: REKENING | E43: REKENING | F43: REKENING | G43: PIUTANG | H43: METER
D44: AIR | E44: NON AIR | F44: AIR | G44: KARYAWAN
A45: 1 | B45: Penerimaan Rek Air & Adm | C45: BPTRA/02/I/2021 | D45: 412045 | F45: 10000 | H45: 120000 | I45: =SUM(D45:H45) -> 542045
I46: =SUM(D46:H46) -> 0
I47: =SUM(D47:H47) -> 0
I48: =SUM(D48:H48) -> 0
B51: JUMLAH | D51: =SUM(D45:D50) -> 412045 | E51: =SUM(E45:E50) -> 0 | F51: =SUM(F45:F50) -> 10000 | G51: =SUM(G45:G50) -> 0 | H51: =SUM(H45:H50) -> 120000 | I51: =SUM(I45:I50) -> 542045
G53: Kuala Pembuang, 02 Januari 2021
A67: PERUSAHAAN DAERAH AIR MINUM
A68: KABUPATEN SERUYAN
A71: BUKTI KAS MASUK
A72: BULAN : JANUARI 2021
I73: No. KM/03/I/2021
A74: NO | B74: URAIAN | C74: NO. BUKTI | D74: PENERIMAAN | I74: JUMLAH
D75: TAGIHAN | E75: TAGIHAN | F75: DENDA | G75: ANGSURAN | H75: DANA
D76: REKENING | E76: REKENING | F76: REKENING | G76: PIUTANG | H76: METER
D77: AIR | E77: NON AIR | F77: AIR | G77: KARYAWAN
A78: 1 | B78: Penerimaan Rek Air & Adm | C78: BPTRA/03/I/2021 | D78: 96478 | F78: 10000 | H78: 40000 | I78: =SUM(D78:H78) -> 146478
...

Sheet JPK. RA
A1: PERUSAHAAN UMUM DAERAH AIR MINUM
A2: TIRTA SERUYAN
A3: JOURNAL PENERIMAAN KAS (JPK)
A4: REKENING AIR (RA)
A5: BULAN : JANUARI 2026
A7: TGL | B7: NO. BUKTI | C7: URAIAN | D7: DEBET | E7: PERKIRAAN DI KREDIT | G7: RUPA-RUPA
D8: KAS/BANK | E8: PIUTANG | F8: PIUTANG | G8: KODE PERK. | H8: NAMA PERKIRAAN | I8: DEBET | J8: KREDIT
E9: REK. AIR | F9: REK. AIR (ADM& DM)
D10: (11.01.00) | E10: (13.01.00) | F10: (13.01.00)
A12: 46023 | B12: No. KM/01/I/2026 | C12: Penerimaan Tagihan Rekening Air | D12: =SUM(E12:F12) -> 0 | E12: 0 | F12: 0
A13: 46024 | B13: No. KM/02/I/2026 | C13: Penerimaan Tagihan Rekening Air | D13: =SUM(E13:F13) -> 0 | E13: 0 | F13: 0
A14: 46025 | B14: No. KM/03/I/2026 | C14: Penerimaan Tagihan Rekening Air | D14: =SUM(E14:F14) -> 0 | E14: 0 | F14: 0
A15: 46026 | B15: No. KM/04/I/2026 | C15: Penerimaan Tagihan Rekening Air | D15: =SUM(E15:F15) -> 0 | E15: 0 | F15: 0
A16: 46027 | B16: No. KM/05/I/2026 | C16: Penerimaan Tagihan Rekening Air | D16: =SUM(E16:F16) -> 0 | E16: 0 | F16: 0
A17: 46028 | B17: No. KM/06/I/2026 | C17: Penerimaan Tagihan Rekening Air | D17: =SUM(E17:F17) -> 0 | E17: 0 | F17: 0
A18: 46029 | B18: No. KM/07/I/2026 | C18: Penerimaan Tagihan Rekening Air | D18: =SUM(E18:F18) -> 0 | E18: 0 | F18: 0
A19: 46030 | B19: No. KM/08/I/2026 | C19: Penerimaan Tagihan Rekening Air | D19: =SUM(E19:F19) -> 0 | E19: 0 | F19: 0
A20: 46031 | B20: No. KM/09/I/2026 | C20: Penerimaan Tagihan Rekening Air | D20: =SUM(E20:F20) -> 0 | E20: 0 | F20: 0
A21: 46032 | B21: No. KM/10/I/2026 | C21: Penerimaan Tagihan Rekening Air | D21: =SUM(E21:F21) -> 0 | E21: 0 | F21: 0
A22: 46033 | B22: No. KM/11/I/2026 | C22: Penerimaan Tagihan Rekening Air | D22: =SUM(E22:F22) -> 0 | E22: 0 | F22: 0
A23: 46034 | B23: No. KM/12/I/2026 | C23: Penerimaan Tagihan Rekening Air | D23: =SUM(E23:F23) -> 0 | E23: 0 | F23: 0
... A27: 46038 | B27: No. KM/16/I/2026 | C27: Penerimaan Tagihan Rekening Air | D27: =SUM(E27:F27) -> 0 | E27: 0 | F27: 0
A28: 46039 | B28: =[1]BKM!I567 -> No. KM/17/I/2026 | C28: Penerimaan Tagihan Rekening Air | D28: =SUM(E28:F28) -> 0 | E28: 0 | F28: 0
A29: 46040 | B29: =[1]BKM!I602 -> No. KM/18/I/2026 | C29: Penerimaan Tagihan Rekening Air | D29: =SUM(E29:F29) -> 0 | E29: 0 | F29: 0
A30: 46041 | B30: =[1]BKM!I637 -> No. KM/19/I/2026 | C30: Penerimaan Tagihan Rekening Air | D30: =SUM(E30:F30) -> 0 | E30: 0 | F30: 0
A31: 46042 | B31: =[1]BKM!I672 -> No. KM/20/I/2026 | C31: Penerimaan Tagihan Rekening Air | D31: =SUM(E31:F31) -> 0 | E31: 0 | F31: 0
A32: 46043 | B32: =[1]BKM!I707 -> No. KM/21/I/2026 | C32: Penerimaan Tagihan Rekening Air | D32: =SUM(E32:F32) -> 0 | E32: 0 | F32: 0
A33: 46044 | B33: =[1]BKM!I742 -> No. KM/22/I/2026 | C33: Penerimaan Tagihan Rekening Air | D33: =SUM(E33:F33) -> 0 | E33: 0 | F33: 0
A34: 46045 | B34: =[1]BKM!I777 -> No. KM/23/I/2026 | C34: Penerimaan Tagihan Rekening Air | D34: =SUM(E34:F34) -> 0 | E34: 0 | F34: 0
A35: 46046 | B35: =[1]BKM!I812 -> No. KM/24/I/2026 | C35: Penerimaan Tagihan Rekening Air | D35: =SUM(E35:F35) -> 0 | E35: 0 | F35: 0
A36: 46047 | B36: =[1]BKM!I847 -> No. KM/25/I/2026 | C36: Penerimaan Tagihan Rekening Air | D36: =SUM(E36:F36) -> 0 | E36: 0 | F36: 0
A37: 46048 | B37: =[1]BKM!I882 -> No. KM/26/I/2026 | C37: Penerimaan Tagihan Rekening Air | D37: =SUM(E37:F37) -> 0 | E37: 0 | F37: 0
A38: 46049 | B38: =[1]BKM!I917 -> No. KM/27/I/2026 | C38: Penerimaan Tagihan Rekening Air | D38: =SUM(E38:F38) -> 0 | E38: 0 | F38: 0 | G38: 11.01.00 | H38: kas
D39: =SUM(E39:F39) -> 0 | E39: 0 | F39: 0 | G39: 81.01.30 | H39: Pendapatan Rek Air Tangki
A40: 46050 | B40: =[1]BKM!I952 -> No. KM/28/I/2026 | C40: Penerimaan Tagihan Rekening Air | D40: =SUM(E40:F40) -> 0 | E40: 0 | F40: 0
A41: 46051 | B41: =[1]BKM!I987 -> No. KM/29/I/2026 | C41: Penerimaan Tagihan Rekening Air | D41: =SUM(E41:F41) -> 0 | E41: 0 | F41: 0
A42: 46052 | B42: =[1]BKM!I1022 -> No. KM/30/I/2026 | C42: Penerimaan Tagihan Rekening Air | D42: =SUM(E42:F42) -> 0 | E42: 0 | F42: 0
A43: 46053 | B43: =[1]BKM!I1057 -> No. KM/31/I/2026 | C43: Penerimaan Tagihan Rekening Air | D43: =SUM(E43:F43) -> 0 | E43: 0 | F43: 0
D44: =SUM(E44:F44) -> 0
C45: Jumlah | D45: =SUM(D12:D44) -> 0 | E45: =SUM(E12:E44) -> 0 | F45: =SUM(F12:F44) -> 0 | I45: =SUM(I12:I44) -> 0 | J45: =SUM(J12:J44) -> 0
...

Sheet JPK. RNA 
A1: PERUSAHAAN DAERAH AIR MINUM
A2: KABUPATEN SERUYAN
A3: JURNAL PENERIMAAN KAS (JPK)
A4: REKENING NON AIR (RNA)
A5: BULAN : JANUARI 2026
A7: TGL | B7: NO. BUKTI | C7: URAIAN | D7: DEBET | E7: PERKIRAAN DI KREDIT
D8: KAS/BANK | E8: PENDAPATAN NON AIR
E9: SR Baru | F9: Penyambungan Kembali | G9: Denda | H9: Meter Air | I9: Pipa Persil | J9: Non Air Lainnya ( 81.02.90)
D10: 11.01.00 | E10: 81.02.10 | F10: 81.02.40 | G10: 81.02.50 | H10: 81..02.70 | I10: 81.02.80 | J10: Jumlah | K10: Ket.
A12: 46023 | B12: No. KM/01/I/2026 | C12: Penerimaan dan Pendapatan | D12: =SUM(E12:J12) -> 0
A13: 46024 | B13: No. KM/02/I/2026 | C13: Penerimaan dan Pendapatan | D13: =SUM(E13:J13) -> 0
A14: 46025 | B14: No. KM/03/I/2026 | C14: Penerimaan dan Pendapatan | D14: =SUM(E14:J14) -> 0
A15: 46026 | B15: No. KM/04/I/2026 | C15: Penerimaan dan Pendapatan | D15: =SUM(E15:J15) -> 0
A16: 46027 | B16: No. KM/05/I/2026 | C16: Penerimaan dan Pendapatan | D16: =SUM(E16:J16) -> 0
A17: 46028 | B17: No. KM/06/I/2026 | C17: Penerimaan dan Pendapatan | D17: =SUM(E17:J17) -> 0
A18: 46029 | B18: No. KM/07/I/2026 | C18: Penerimaan dan Pendapatan | D18: =SUM(E18:J18) -> 0
A19: 46030 | B19: No. KM/08/I/2026 | C19: Penerimaan dan Pendapatan | D19: =SUM(E19:J19) -> 0
A20: 46031 | B20: No. KM/09/I/2026 | C20: Penerimaan dan Pendapatan | D20: =SUM(E20:J20) -> 0
A21: 46032 | B21: No. KM/10/I/2026 | C21: Penerimaan dan Pendapatan | D21: =SUM(E21:J21) -> 0
A22: 46033 | B22: No. KM/11/I/2026 | C22: Penerimaan dan Pendapatan | D22: =SUM(E22:J22) -> 0
A23: 46034 | B23: No. KM/12/I/2026 | C23: Penerimaan dan Pendapatan | D23: =SUM(E23:J23) -> 0
... A27: 46038 | B27: No. KM/16/I/2026 | C27: Penerimaan dan Pendapatan | D27: =SUM(E27:J27) -> 0
A28: 46039 | B28: =[1]BKM!I567 -> No. KM/17/I/2026 | C28: Penerimaan dan Pendapatan | D28: =SUM(E28:J28) -> 0
A29: 46040 | B29: =[1]BKM!I602 -> No. KM/18/I/2026 | C29: Penerimaan dan Pendapatan | D29: =SUM(E29:J29) -> 0
A30: 46041 | B30: =[1]BKM!I637 -> No. KM/19/I/2026 | C30: Penerimaan dan Pendapatan | D30: =SUM(E30:J30) -> 0
A31: 46042 | B31: =[1]BKM!I672 -> No. KM/20/I/2026 | C31: Penerimaan dan Pendapatan | D31: =SUM(E31:J31) -> 0
A32: 46043 | B32: =[1]BKM!I707 -> No. KM/21/I/2026 | C32: Penerimaan dan Pendapatan | D32: =SUM(E32:J32) -> 0
A33: 46044 | B33: =[1]BKM!I742 -> No. KM/22/I/2026 | C33: Penerimaan dan Pendapatan | D33: =SUM(E33:J33) -> 0
A34: 46045 | B34: =[1]BKM!I777 -> No. KM/23/I/2026 | C34: Penerimaan dan Pendapatan | D34: =SUM(E34:J34) -> 0
A35: 46046 | B35: =[1]BKM!I812 -> No. KM/24/I/2026 | C35: Penerimaan dan Pendapatan | D35: =SUM(E35:J35) -> 0
A36: 46047 | B36: =[1]BKM!I847 -> No. KM/25/I/2026 | C36: Penerimaan dan Pendapatan | D36: =SUM(E36:J36) -> 0
A37: 46048 | B37: =[1]BKM!I882 -> No. KM/26/I/2026 | C37: Penerimaan dan Pendapatan | D37: =SUM(E37:J37) -> 0
A38: 46049 | B38: =[1]BKM!I917 -> No. KM/27/I/2026 | C38: Penerimaan dan Pendapatan | D38: =SUM(E38:J38) -> 0
A39: 46050 | B39: =[1]BKM!I952 -> No. KM/28/I/2026 | C39: Penerimaan dan Pendapatan | D39: =SUM(E39:J39) -> 0
A40: 46051 | B40: =[1]BKM!I987 -> No. KM/29/I/2026 | C40: Penerimaan dan Pendapatan | D40: =SUM(E40:J40) -> 0
A41: 46052 | B41: =[1]BKM!I1022 -> No. KM/30/I/2026 | C41: Penerimaan dan Pendapatan | D41: =SUM(E41:J41) -> 0
A42: 46053 | B42: =[1]BKM!I1057 -> No. KM/31/I/2026 | C42: Penerimaan dan Pendapatan | D42: =SUM(E42:J42) -> 0
C43: Jumlah | D43: =SUM(D12:D42) -> 0 | E43: =SUM(E12:E42) -> 0 | F43: =SUM(F12:F42) -> 0 | G43: =SUM(G12:G42) -> 0 | H43: =SUM(H12:H42) -> 0 | I43: =SUM(I12:I42) -> 0 | J43: =SUM(J12:J42) -> 0 | K43: 0
A46: PERUSAHAAN DAERAH AIR MINUM
A47: KABUPATEN SERUYAN
...

Sheet JU
A1: PERUSAHAAN DAERAH AIR MINUM
A2: KABUPATEN SERUYAN
A3: Jalan : Soekarno-Hatta No. Telp (0538) 2706777 Fax (0538) 21815
A4: JURNAL UMUM
A5: BULAN : JANUARI 2026
A6: TGL | B6: NO. PERK | C6: NAMA PERKIRAAN | E6: DEBET | F6: KREDIT
A7: 01 Jan | B7: 70.05.00 | C7: Laba Tahun Berjalan 2026
B8: 70.04.00 | D8: Laba ditahan/Akum Kerugian | F8: =E7 -> 0
A10: 02 Jan | B10: 11.01.00 | C10: Kas
B11: 13.03.00 | D11: Piutang Mitra
C12: (Pembayaran Oleh Mitra)
A14: 02 Jan | B14: 11.01.00 | C14: Kas
B15: 50.03.00 | D15: Beban Yang Masih Harus Dibayar | F15: =E14 -> 0
C16: (Kelebihan Setoran Rekening Air PT. Pos)
A18: 10 Jan | B18: 11.01.00 | C18: Kas
B19: 13.04.00 | D19: Piutang Non Air (Bunga Deposito)
B20: 88.00.10 | D20: Pendapatan Bunga Deposito
A22: 13 Jan | B22: 98.01.00 | C22: Beban Non usaha (B. Bank)
B23: 11.01.00 | D23: Kas | F23: =E22 -> 0
C24: (Biaya Admin/Kirim/Transfer)
A26: 19 Jan | B26: 98.01.00 | C26: Beban Non usaha (B. Bank)
B27: 11.01.00 | D27: Kas | F27: =E26 -> 0
C28: (Biaya Admin/Kirim/Transfer)
A30: 29 Jan | B30: 98.01.00 | C30: Beban Non usaha (B. Bank)
B31: 11.01.00 | D31: Kas | F31: =SUM(E30:E30) -> 0
C32: (Biaya Admin/Kirim/Transfer)
A34: 29 Jan | B34: 98.01.00 | C34: Beban Non usaha (B. Bank)
B35: 11.01.00 | D35: Kas | F35: =E34 -> 0
C36: (Biaya Admin/Kirim/Transfer)
A38: 29 Jan | B38: 50.03.00 | C38: Beban Yang Masih Harus Dibayar
B39: 11.01.00 | D39: Kas | F39: =E38 -> 0
C40: (Pembayaran Kelebihan Setoran PT. Pos atas Kelebihan Setoran Rekening Air pada Tanggal 02 Januari 2026)
A42: 31 Jan | B42: 13.03.00 | C42: Piutang Mitra PT POS
B43: 13.03.00 | C43: Piutang Mitra KOPERASI
B44: 13.03.00 | C44: Piutang Mitra PT BANK KALTENG
B45: 13.03.00 | C45: Piutang Mitra Fastpay
B46: 11.01.00 | D46: Kas | F46: =SUM(E42:E45) -> 0
C47: (Penyesuaian Untuk Penerimaan Rekening Mitra yang sdh di catat di JPK tp Blm disetor oleh Mitra)
A49: 31 Jan | B49: 15.03.00 | C49: Persediaan Bahan Instalasi
B50: 50.01.00 | D50: Utang Usaha | F50: =E49 -> 0
...

Sheet JRA
A1: PERUSAHAAN DAERAH AIR MINUM
A2: KABUPATEN SERUYAN
A3: Jalan : Soekarno-Hatta No. Telp (0538) 2706777 Fax (0538) 21815
A4: JOURNAL REKENING AIR (JRA)
A5: BULAN : JANUARI 2026
A7: TGL | B7: NOMOR DRD | C7: NO. PERK | D7: NAMA PERKIRAAN | F7: LEMBAR | G7: Debet | H7: Kredit
A9: 31 Januari | C9: 13.01.11 | D9: Piutang Rek Air - Tempat Ibadah (TI)
C10: 13.01.14 | D10: Piutang Rek Air - Panti Asuhan (PA)
C11: 13.01.15 | D11: Piutang Rek Air - Yayasan Sosial (YS)
C12: 13.01.16 | D12: Piutang Rek Air - Sekolah Negeri & Swasta (S)
C13: 13.01.21 | D13: Piutang Rek Air - Rumah Tangga 1 (R1)
C14: 13.01.22 | D14: Piutang Rek Air - Rumah Tangga 2 (R2)
C15: 13.01.23 | D15: Piutang Rek Air - Rumah Tangga 3 (R3)
C16: 13.01.31 | D16: Piutang Rek Air - Niaga Kecil (NK)
C17: 13.01.32 | D17: Piutang Rek Air - Industri Rumah Tangga
C18: 13.01.33 | D18: Piutang Rek Air - Inst Pemerintah kel/Kec/Kab/Kota
C19: 13.01.35 | D19: Piutang Rek Air - Industri/Niaga Besar (NB)
C20: 13.01.36 | D20: Piutang Rek Air - Pelabuhan
C21: 81..01.10 | E21: Pendapatan Air -Harga Air | F21: =SUM(F9:F20) -> 0 | H21: =SUM(G9:G20) -> 0 | I21: =H21+H52 -> 0
K22: =H21 -> 0 | L22: =H21+H35+H49 -> 0
A23: 31 Januari | C23: 13.01.11 | D23: Piutang Rek Air - Tempat Ibadah (TI)
C24: 13.01.14 | D24: Piutang Rek Air - Panti Asuhan (PA)
C25: 13.01.15 | D25: Piutang Rek Air - Yayasan Sosial (YS)
C26: 13.01.16 | D26: Piutang Rek Air - Sekolah Negeri & Swasta (S)
C27: 13.01.21 | D27: Piutang Rek Air - Rumah Tangga 1 (R1) | L27: =H21+H35+H49 -> 0
C28: 13.01.22 | D28: Piutang Rek Air - Rumah Tangga 2 (R2)
C29: 13.01.23 | D29: Piutang Rek Air - Rumah Tangga 3 (R3)
C30: 13.01.31 | D30: Piutang Rek Air - Niaga Kecil (NK)
C31: 13.01.32 | D31: Piutang Rek Air - Industri Rumah Tangga
C32: 13.01.33 | D32: Piutang Rek Air - Inst Pemerintah kel/Kec/Kab/Kota
C33: 13.01.35 | D33: Piutang Rek Air - Industri/Niaga Besar (NB)
C34: 13.01.36 | D34: Piutang Rek Air - Pelabuhan
C35: 81..01.10 | E35: Pendapatan Air -Harga Air (KARTIKA BHAKTI) | F35: =SUM(F23:F34) -> 0 | H35: =SUM(G23:G33) -> 0
A37: 31 Januari | C37: 13.01.11 | D37: Piutang Rek Air - Tempat Ibadah (TI) | I37: =H35+H55 -> 0
C38: 13.01.14 | D38: Piutang Rek Air - Panti Asuhan (PA)
C39: 13.01.15 | D39: Piutang Rek Air - Yayasan Sosial (YS)
C40: 13.01.16 | D40: Piutang Rek Air - Sekolah Negeri & Swasta (S)
C41: 13.01.21 | D41: Piutang Rek Air - Rumah Tangga 1 (R1)
C42: 13.01.22 | D42: Piutang Rek Air - Rumah Tangga 2 (R2)
C43: 13.01.23 | D43: Piutang Rek Air - Rumah Tangga 3 (R3)
...

Sheet JRNA2 
A1: PERUSAHAAN DAERAH AIR MINUM
A2: KABUPATEN SERUYAN
A3: Jalan : Soekarno-Hatta No. Telp (0538) 2706777 Fax (0538) 21815
A4: JOURNAL REKENING NON AIR (JRNA)
A5: BULAN : JANUARI 2020
A7: No | B7: Tgl | C7: Uraian | E7: Ref. | F7: Debet | G7: Kredit
B9: 30 Sept | C9: Piutang Non Air
D10: Pendapatan Non Air (Samb. Baru)
D11: Pendapatan Non Air ( Assessories SR)
A21: JUMLAH | F21: =SUM(F8:F19) -> 0 | G21: =SUM(G8:G19) -> 0

Sheet DVUD(1)
A1: PERUSAHAAN DAERAH AIR MINUM
A2: KABUPATEN SERUYAN
A3: DAFTAR VOUCHER UTANG YANG HARUS DIBAYAR
A4: BULAN JANUARI
A6: VOUCHER | C6: URAIAN | D6: DIBAYAR | F6: KREDIT | M6: DEBET
A7: TGL | B7: NO | D7: TGL | E7: CHEK/B. GIRO | F7: UTANG | H7: ASET TETAP | K7: PERSEDIAAN BAHAN KIMIA | N7: BAHAN INSTALASI | Q7: BIAYA OPRS SUMBER | T7: BIAYA OPRS PENGOLAHAN | W7: BIAYA OPRS DISTRIBUSI | Z7: BIAYA UMUM & ADM
F8: USAHA | G8: NON USAHA | H8: SUB. PERK | I8: Nama Perkiraan | J8: JUMLAH | K8: SUB. PERK | L8: Nama Perkiraan | M8: JUMLAH | N8: SUB. PERK | O8: Nama Perkiraan | P8: JUMLAH | Q8: SUB. PERK | R8: Nama Perkiraan | S8: JUMLAH | T8: SUB. PERK | U8: Nama Perkiraan | V8: JUMLAH | W8: SUB. PERK | X8: Nama Perkiraan | Y8: JUMLAH | Z8: B. PEGAWAI UMUM&ADM (96.01.00) | AC8: B. KANTOR (96.02.00) | AF8: B. HUBLANG ( 96.03.00) | AI8: B. PENELITIAN & PENGEMBANGAN (96.04.00) | AL8: B. PEMELIHARAAN (96.06.00) | AO8: BIAYA UMUM LAINNYA (96.07.00 DAN 96.08.00)
F9: 50.01.00 | G9: 50.02.00 | H9: 31.01.00 | K9: 15.01.00 | N9: 41.02.00 | Q9: 91.01.00 | T9: 92.01.00 | W9: 93.01.00 | Z9: SUB. PERK | AA9: Nama Perkiraan | AB9: JUMLAH | AC9: SUB. PERK | AD9: Nama Perkiraan | AE9: JUMLAH | AF9: SUB. PERK | AG9: Nama Perkiraan | AH9: JUMLAH | AI9: SUB. PERK | AJ9: Nama Perkiraan | AK9: JUMLAH | AL9: SUB. PERK | AM9: Nama Perkiraan | AN9: JUMLAH | AO9: SUB. PERK | AP9: Nama Perkiraan | AQ9: JUMLAH
A10: 02 Jan | B10: 001 | C10: Pembelian Pengukur Kadar Garam | D10: 02 Jan | E10: Tunai | F10: =M10+P10+S10+V10+Y10+AB10+AE10+AH10+AK10+AN10+AQ10+J10 -> 150000 | T10: 92.02.90 | U10: B. Pemeliharaan Pengolahan | V10: 150000
B11: 002 | C11: Pembelian Sylinder 3 Zel | D11: 02 Jan | E11: Tunai | F11: =M11+P11+S11+V11+Y11+AB11+AE11+AH11+AK11+AN11+AQ11+J11 -> 130000 | AC11: 96.02.90 | AD11: Rupa2 B. Kantor | AE11: 130000
B12: 003 | C12: Pembelian Tas Lap top | D12: =A12 -> 0 | E12: Tunai | F12: =M12+P12+S12+V12+Y12+AB12+AE12+AH12+AK12+AN12+AQ12+J12 -> 150000 | AC12: 96.02.90 | AD12: Rupa2 B. Kantor | AE12: 150000
A13: 04 Jan | B13: 004 | C13: Pembelian Pasir Cor | D13: =A13 -> 04 Jan | E13: Tunai | F13: =M13+P13+S13+V13+Y13+AB13+AE13+AH13+AK13+AN13+AQ13+J13 -> 110000 | W13: 93.02.90 | X13: B. Pemeliharaan Trandist lainnya | Y13: 110000
A14: 06 jan | B14: 005 | C14: Pembelian Terminal, Stiker Braco, Paku | D14: =A14 -> 06 jan | E14: Tunai | F14: =M14+P14+S14+V14+Y14+AB14+AE14+AH14+AK14+AN14+AQ14+J14 -> 188000 | AC14: 96.02.90 | AD14: Rupa2 B. Kantor | AE14: 188000
B15: 006 | C15: Pemb. Gorden, Tutup Gorden, Tongkat dan Rol Gorden | D15: =A15 -> 0 | E15: Tunai | F15: =M15+P15+S15+V15+Y15+AB15+AE15+AH15+AK15+AN15+AQ15+J15 -> 334000 | AC15: 96.02.90 | AD15: Rupa2 B. Kantor | AE15: 334000
A16: 20 Jan | B16: 007 | C16: Pemb. Raoundap & Primaxone | D16: =A16 -> 20 Jan | E16: Tunai | F16: =M16+P16+S16+V16+Y16+AB16+AE16+AH16+AK16+AN16+AQ16+J16 -> 185000 | AL16: 96.06.50 | AM16: B. Pemeliharaan taman & lapangan | AN16: 185000
A17: 22 Jan | B17: 008 | C17: Pemeliharaan avanza KH 1407PE | D17: =A17 -> 22 Jan | E17: Tunai | F17: =M17+P17+S17+V17+Y17+AB17+AE17+AH17+AK17+AN17+AQ17+J17 -> 636000 | AL17: 96.06.20 | AM17: Pemeliharaan Kendaraan | AN17: 636000
B18: 009 | C18: SPPD ke Sampit An. Ilias dll | D18: 22 Jan | E18: Tunai | F18: =M18+P18+S18+V18+Y18+AB18+AE18+AH18+AK18+AN18+AQ18+J18 -> 12550000 | AO18: 96.08.30 | AP18: B. Perjalanan Dinas | AQ18: 12550000
B19: 010 | C19: Pemy. Listrik Bag. Produksi | D19: 22 Jan | E19: Tunai | F19: =M19+P19+S19+V19+Y19+AB19+AE19+AH19+AK19+AN19+AQ19+J19 -> 28173777 | Q19: 91.01.30 | R19: B. Listrik PLN Sumber Air | S19: 28173777
B20: 011 | C20: Pemb. Lap Top Acer | D20: =A20 -> 0 | E20: Tunai | F20: =M20+P20+S20+V20+Y20+AB20+AE20+AH20+AK20+AN20+AQ20+J20 -> 6800000 | H20: 31.09..20 | I20: Mesin-mesin kantor | J20: 6800000
B21: 012 | C21: Pemb. 2 unit sepeda motor | D21: =A21 -> 0 | E21: Tunai | F21: =M21+P21+S21+V21+Y21+AB21+AE21+AH21+AK21+AN21+AQ21+J21 -> 41820000 | H21: 31.08.00 | I21: Kendaraan/Alat Pengangkutan | J21: 41820000
B22: 013 | C22: Pemb. Aki Mobil Avanza KH 1179PU | D22: =A22 -> 0 | E22: Tunai | F22: =M22+P22+S22+V22+Y22+AB22+AE22+AH22+AK22+AN22+AQ22+J22 -> 810000 | AL22: 96.06.20 | AM22: Pemeliharaan Kendaraan | AN22: 810000
B23: 014 | C23: Pemb. Cat & Kuas Utk Pipa Intake | D23: =A23 -> 0 | E23: Tunai | F23: =M23+P23+S23+V23+Y23+AB23+AE23+AH23+AK23+AN23+AQ23+J23 -> 202000 | Q23: 91.02.90 | R23: Pemelih Inst. Sumber lainnya | S23: 202000
A24: 23 Jan | B24: 015 | C24: Pemb. Paket Internet | D24: =A24 -> 23 Jan | E24: Tunai | F24: =M24+P24+S24+V24+Y24+AB24+AE24+AH24+AK24+AN24+AQ24+J24 -> 1023500 | AC24: 96.02.90 | AD24: Rupa2 B. Kantor | AE24: 1023500
B25: 016 | C25: Pulsa Listrik kantor, Loket dan Gudang | D25: =A25 -> 0 | E25: Tunai | F25: =M25+P25+S25+V25+Y25+AB25+AE25+AH25+AK25+AN25+AQ25+J25 -> 1207500 | AC25: 96.02.70 | AD25: B. Listrik/Penerangan | AE25: 1207500
B26: 017 | C26: Pemby. Rek Telp/HP/Fax | D26: =A26 -> 0 | E26: Tunai | F26: =M26+P26+S26+V26+Y26+AB26+AE26+AH26+AK26+AN26+AQ26+J26 -> 71660 | AC26: 96.02.40 | AD26: B. Telepon | AE26: 71660
B27: 018 | C27: Pemb. Sapu Lidi, soklin lantai,tisu,dll | D27: =A27 -> 0 | E27: Tunai | F27: =M27+P27+S27+V27+Y27+AB27+AE27+AH27+AK27+AN27+AQ27+J27 -> 377000 | AC27: 96.02.90 | AD27: Rupa2 B. Kantor | AE27: 377000
B28: 019 | C28: Pemb. ATK & B. Fotocopy | D28: =A28 -> 0 | E28: Tunai | F28: =M28+P28+S28+V28+Y28+AB28+AE28+AH28+AK28+AN28+AQ28+J28 -> 4230575 | AC28: 96.02.10 | AD28: B. ATK dan Fotocopy | AE28: 4230575
B29: 020 | C29: Pemb. Kertas De Paper (rek) | D29: =A29 -> 0 | E29: Tunai | F29: =M29+P29+S29+V29+Y29+AB29+AE29+AH29+AK29+AN29+AQ29+J29 -> 500000 | AC29: 96.02.20 | AD29: Barang2 Cetakkan | AE29: 500000
A30: 24 Jan | B30: 021 | C30: SPPD A. Rijali,Kardi,Bagus ke Sampit | D30: =A30 -> 24 Jan | E30: Tunai | F30: =M30+P30+S30+V30+Y30+AB30+AE30+AH30+AK30+AN30+AQ30+J30 -> 5850000 | AC30: 96.02.90 | AO30: 96.08.30 | AP30: B. Perjalanan Dinas | AQ30: 5850000
B31: 022 | C31: Pemb. Kabel &terminal | D31: =A31 -> 0 | E31: Tunai | F31: =M31+P31+S31+V31+Y31+AB31+AE31+AH31+AK31+AN31+AQ31+J31 -> 229000 | AD31: Rupa2 B. Kantor | AE31: 229000
A32: 27 Jan | B32: 023 | C32: Pemy. SPPD Ilias dan Jawi ke SBY | D32: =A32 -> 27 Jan | E32: Tunai | F32: =M32+P32+S32+V32+Y32+AB32+AE32+AH32+AK32+AN32+AQ32+J32 -> 12282800 | AO32: 96.08.30 | AP32: B. Perjalanan Dinas | AQ32: 12282800
B33: 024 | C33: Pemby. Iuran DPD PERPAMSI Kal-Teng | D33: =A33 -> 0 | E33: Tunai | F33: =M33+P33+S33+V33+Y33+AB33+AE33+AH33+AK33+AN33+AQ33+J33 -> 1500000 | AO33: 96.08.10 | AP33: B. Iuran Berlangganan | AQ33: 1500000
B34: 025 | C34: Pemby. Iuran DAPENMA PAMSI | D34: =A34 -> 0 | E34: Tunai | F34: =M34+P34+S34+V34+Y34+AB34+AE34+AH34+AK34+AN34+AQ34+J34 -> 9987916 | Z34: 96.01.30 | AA34: Iuran Pensiun | AB34: 9987916
B35: 026 | C35: Iuran BPJS Ketenagakerjaan | D35: =A35 -> 0 | E35: Tunai | F35: =M35+P35+S35+V35+Y35+AB35+AE35+AH35+AK35+AN35+AQ35+J35 -> 4399533 | AO35: 96.08.60 | AP35: B. Asuransi | AQ35: 4399533
B36: 027 | C36: Pemby. Dana Representatif Direktur | D36: =A36 -> 0 | E36: Tunai | F36: =M36+P36+S36+V36+Y36+AB36+AE36+AH36+AK36+AN36+AQ36+J36 -> 8000000 | AO36: 96.08.80 | AP36: Rupa2 B. Umum Lainnya | AQ36: 8000000
B37: 028 | C37: Pemby. Biaya Konsumsi Pegawai | D37: =A37 -> 0 | E37: Tunai | F37: =M37+P37+S37+V37+Y37+AB37+AE37+AH37+AK37+AN37+AQ37+J37 -> 14855000 | AO37: 96.08.80 | AP37: Rupa2 B. Umum Lainnya | AQ37: 14855000
B38: 029 | C38: Pemb. Kasur,bantal, dll | D38: =A38 -> 0 | E38: Tunai | F38: =M38+P38+S38+V38+Y38+AB38+AE38+AH38+AK38+AN38+AQ38+J38 -> 195000 | AO38: 96.08.81 | AP38: Rupa2 B. Umum Lainnya | AQ38: 195000
B39: 030 | C39: Honorarium Dewas & Sekretariat Dewas | D39: =A39 -> 0 | E39: Tunai | F39: =M39+P39+S39+V39+Y39+AB39+AE39+AH39+AK39+AN39+AQ39+J39 -> 9970080 | AO39: 96.08.20 | AP39: B. Badan Pengawas | AQ39: 9970080
B40: 031 | C40: Gaji Pegawai Bag. Umum | D40: =A40 -> 0 | E40: Tunai | F40: =M40+P40+S40+V40+Y40+AB40+AE40+AH40+AK40+AN40+AQ40+J40 -> 82346378 | Z40: 96.01.10 | AA40: B. Pegawai Bagian Umum | AB40: 82346378
B41: 032 | C41: Gaji Bagian Transist | D41: =A41 -> 0 | E41: Tunai | F41: =M41+P41+S41+V41+Y41+AB41+AE41+AH41+AK41+AN41+AQ41+J41 -> 17840702 | W41: 93.01.10 | X41: B. Pegawai Operasi Trandist | Y41: 17840702
...

Sheet DVUD
A1: PERUSAHAAN DAERAH AIR MINUM
A2: KABUPATEN SERUYAN
A3: DAFTAR VOUCHER UTANG YANG HARUS DIBAYAR
A4: BULAN JANUARI
A6: VOUCHER | C6: URAIAN | D6: DIBAYAR | F6: DEBET | I6: KREDIT
A7: TGL | B7: NO | D7: TGL | E7: CHEK/B. GIRO | F7: NO. PERK | G7: NAMA PERKIRAAN | H7: JUMLAH (Rp) | I7: NO. PERK | J7: NAMA PERKIRAAN | K7: JUMLAH (Rp)
A9: 05 Jan | B9: 01 | C9: Pemby. Service Mobil Avanza KH 1252 PU | D9: =A9 -> 05 Jan | E9: Tunai | F9: 97.06.20 | G9: Pemeliharaan Kendaraan | I9: 50.01.00 | J9: Utang Usaha | K9: =H9 -> 0
B10: 02 | C10: Pembuatan Spanduk untuk Pemberitahuan Operasional Pelayanan Air 24 Jam di Unit IKK Pembuang Hulu | D10: =A10 -> 0 | E10: Tunai | F10: 97.03.70 | G10: Beban Promosi | I10: 50.01.00 | J10: Utang Usaha | K10: =H10 -> 0
B11: 03 | C11: Pemby. Biaya Perpanjangan STNK Mobil PICK UP KH 8088 PW | D11: =A11 -> 0 | E11: Tunai | F11: 97.06.20 | G11: Pemeliharaan Kendaraan | I11: 50.01.00 | J11: Utang Usaha | K11: =H11 -> 0
B12: 04 | C12: Pembelian Pulsa Listrik Bagian Kantor dan Loket Pembayaran | D12: =A12 -> 0 | E12: Tunai | F12: 97.02.70 | G12: B. Listrik/Penerangan | I12: 50.01.00 | J12: Utang Usaha | K12: =H12 -> 0
B13: 05 | C13: Pembelian Paket Internet Kantor, IKK Kartika Bhakti, IKK Hanau, Tanjung Paring, Mulyono | D13: =A13 -> 0 | E13: Tunai | F13: 97.02.90 | G13: Rupa-Rupa Beban Kantor | I13: 50.01.00 | J13: Utang Usaha | K13: =H13 -> 0
B14: 06 | C14: Pemby. Rekening Telepon/HP/Fax | D14: =A14 -> 0 | E14: Tunai | F14: 97.02.40 | G14: B. Telepon | I14: 50.01.00 | J14: Utang Usaha | K14: =H14 -> 0
B15: 07 | C15: Klaim Belanja melalui Kas Kecil IKK PEMBUANG HULU | D15: =A15 -> 0 | E15: Tunai | F15: 92.03.90 | G15: Pemeliharaan Instalasi Pengolahan Lainnya | I15: 50.01.00 | J15: Utang Usaha | K15: =H15 -> 0
A16: 08 Jan | B16: 08 | C16: Pembelian Pulsa Listrik Bagian Kantor | D16: =A16 -> 08 Jan | E16: Tunai | F16: 97.02.70 | G16: B. Listrik/Penerangan | I16: 50.01.00 | J16: Utang Usaha | K16: =H16 -> 0
B17: 09 | C17: Pembay. Pembuatan Spanduk dan Brosur Kenaikan Tarif | D17: =A17 -> 0 | E17: Tunai | F17: 97.03.80 | G17: Rupa-rupa Biaya Langganan | I17: 50.01.00 | J17: Utang Usaha | K17: =H17 -> 0
A18: 12 Jan | B18: 10 | C18: Klaim Belanja Melalui Kas Kecil IKK Pembuang Hulu. | D18: =A18 -> 12 Jan | E18: Tunai | F18: 92.03.90 | G18: Pemeliharaan Instalasi Pengolahan Lainnya | I18: 50.01.00 | J18: Utang Usaha | K18: =H18 -> 0
A19: 13 Jan | B19: 11 | C19: Pembelian Materai @10.000 | D19: =A19 -> 13 Jan | E19: Tunai | F19: 97.02.60 | G19: B. Pos & Materai | I19: 50.01.00 | J19: Utang Usaha | K19: =H19 -> 0
B20: 12 | C20: Pembayaran Pajak Air Permukaan & Biaya Kirim Periode Bulan Desember 2025 | D20: =A20 -> 0 | E20: Tunai | F20: 50.03.00 | G20: B. Yang Masih Harus Dibayar | I20: 50.01.00 | J20: Utang Usaha | K20: =H20 -> 0
B21: 13 | C21: Pembayaran PPH 21 Gaji Bulan Desember dan Uang Cuti Tahun 2025 | D21: =A21 -> 0 | E21: Tunai | F21: 50.03.00 | G21: B. Yang Masih Harus Dibayar | I21: 50.01.00 | J21: Utang Usaha | K21: =H21 -> 0
A22: 14 Jan | B22: 14 | C22: Pembayaran Listrik Sumber Air | D22: =A22 -> 14 Jan | E22: Tunai | F22: 91.02.20 | G22: B. Listrik PLN Sumber Air | I22: 50.01.00 | J22: Utang Usaha | K22: =H22 -> 0
B23: 15 | C23: Pembayaran Listrik Sumber Air IKK Pembuang Hulu (Hanau) | D23: =A23 -> 0 | E23: Tunai | F23: 91.02.20 | G23: B. Listrik PLN Sumber Air | I23: 50.01.00 | J23: Utang Usaha | K23: =H23 -> 0
B24: 16 | C24: Pembayaran Listrik PLN Sumber Air IKK Kartika Bhakti (Kartika Bhakti) | D24: =A24 -> 0 | E24: Tunai | F24: 91.02.20 | G24: B. Listrik PLN Sumber Air | I24: 50.01.00 | J24: Utang Usaha | K24: =H24 -> 0
B25: 17 | C25: Pemby. Iuran BPJS Kesehatan | D25: =A25 -> 0 | E25: Tunai | F25: 97.01.20 | G25: B. BPJS Kesehatan Umum & Adm | I25: 50.01.00 | J25: Utang Usaha | K25: =H25 -> 0
D26: =A26 -> 0 | E26: Tunai | F26: 93.01.20 | G26: B. BPJS Kesehtan Trandist | I26: 50.01.00 | J26: Utang Usaha | K26: =H26 -> 0
D27: =A27 -> 0 | E27: Tunai | F27: 92.01.20 | G27: B. BPJS Kesehatan Pengolahan Air | I27: 50.01.00 | J27: Utang Usaha | K27: =H27 -> 0
B28: 18 | C28: Pembay. Iuan Anggota Biasa PERPAMSI Bulan Januari 2026 | D28: =A28 -> 0 | E28: Tunai | F28: 97.07.10 | G28: B. Iuran Berlangganan | I28: 50.01.00 | J28: Utang Usaha | K28: =H28 -> 0
B29: 19 | C29: Pemb. Pulsa Listrik Bagian Kantor | D29: =A29 -> 0 | E29: Tunai | F29: 97.02.70 | G29: B. Listrik/Penerangan | I29: 50.01.00 | J29: Utang Usaha | K29: =H29 -> 0
A30: 15 Jan | B30: 20 | C30: Pemby. Biaya Perpanjangan STNK Motor KH 2251 PI, KH 4995 Pg, dan Mobil Avanza KH 1252 PU | D30: =A30 -> 15 Jan | E30: Tunai | F30: 97.06.20 | G30: Pemeliharaan Kendaraan | I30: 50.01.00 | J30: Utang Usaha | K30: =H30 -> 0
B31: 21 | C31: Pemby. ATK IKK Pembuang Hulu | E31: Tunai | F31: 97.02.10 | G31: B. ATK dan Fotocopy | I31: 50.01.00 | J31: Utang Usaha | K31: =H31 -> 0
B32: 22 | C32: Pemby. SPPD a.n Hariono dn Hengky Muklis Samitra ke Kuala Pembuang | D32: =A32 -> 0 | E32: Tunai | F32: 97.07.40 | G32: B. Perjalanan Dinas | I32: 50.01.00 | J32: Utang Usaha | K32: =H32 -> 0
B33: 23 | C33: Klaim Belanja melalui Kas Kecil Bag. Administrasi Umum | D33: =A33 -> 0 | E33: Tunai | F33: 97.02.90 | G33: Rupa-Rupa Beban Kantor | I33: 50.01.00 | J33: Utang Usaha | K33: =H33 -> 0
A34: 19 Jan | B34: 24 | C34: Pemby. Perbaikan Pompa Intake 7,5 KW / 10 HP IKK Kartika Bhakti | D34: =A34 -> 19 Jan | E34: Tunai | F34: 91.03.80 | G34: Pemeliharaa Instalasi Pompa | I34: 50.01.00 | J34: Utang Usaha | K34: =H34 -> 0
B35: 25 | C35: Pemby. Biaya Pengantaran Pompa Intake Kota Kuala Pembuang dan IKK Kartika Bhakti | D35: =A35 -> 0 | E35: Tunai | F35: 97.07.90 | G35: Rupa-Rupa Beban Umum Lainnya | I35: 50.01.00 | J35: Utang Usaha | K35: =H35 -> 0
B36: 26 | C36: Pemby. Service Mobil Pick Up KH 8088 PW (IKK Pembuang Hulu) | D36: =A36 -> 0 | E36: Tunai | F36: 97.06.20 | G36: Pemeliharaan Kendaraan | I36: 50.01.00 | J36: Utang Usaha | K36: =H36 -> 0
B37: 27 | C37: Pemby. SPPD a.n. Agus Saputra dan Khusnul Siti Hatimah ke Kuala Pembuang | D37: =A37 -> 0 | E37: Tunai | F37: 97.07.40 | G37: B. Perjalanan Dinas | I37: 50.01.00 | J37: Utang Usaha | K37: =H37 -> 0
B38: 28 | C38: Pemby. Service Mobil Avanza KH 1252 PU | D38: =A38 -> 0 | E38: Tunai | F38: 97.06.20 | G38: Pemeliharaan Kendaraan | I38: 50.01.00 | J38: Utang Usaha | K38: =H38 -> 0
B39: 29 | C39: Pemb. Pulsa Listrik Bagian Kantor | D39: =A39 -> 0 | E39: Tunai | F39: 97.02.70 | G39: B. Listrik/Penerangan | I39: 50.01.00 | J39: Utang Usaha | K39: =H39 -> 0
A40: 20 Jan | B40: 30 | C40: Pemby. Pembuatan Karangan Bunga | D40: =A40 -> 20 Jan | E40: Tunai | F40: 97.03.70 | G40: B. Promosi | I40: 50.01.00 | J40: Utang Usaha | K40: =H40 -> 0
B41: 31 | C41: Pemby. Honorarium Tim Penguji dan Sekretariat Pelaksanaan Job Fit di Lingkungan Perusahaan Umum Daerah Air Minum Tirta Seruyan Berdasarkan Keputusan Direktur 71 Tahun 2025 Tanggal 29 Desember 2025 | D41: =A41 -> 0 | E41: Tunai | F41: 97.07.90 | G41: Rupa-rupa Beban Umum Lainnya | I41: 50.01.00 | J41: Utang Usaha | K41: =H41 -> 0
B42: 32 | C42: Pemby. Biaya Konsumsi dan Perlengkapan untuk Kegiatan Pelaksanaan Job Fit di Lingkungan Perusahaan Umm Daerah Air Minum Tirta Seruyan | D42: =A42 -> 0 | E42: Tunai | F42: 97.07.90 | G42: Rupa-Rupa Beban Umum Lainnya | I42: 50.01.00 | J42: Utang Usaha | K42: =H42 -> 0
...

Sheet JBK
A1: PERUSAHAAN DAERAH AIR MINUM
A2: KABUPATEN SERUYAN
A4: JOURNAL BAYAR KAS
A5: BULAN JANUARI
A6: Tgl | B6: Voucer | D6: Uraian | E6: Cek/Giro | G6: KREDIT | H6: DEBET
B7: No. | C7: Tgl | E7: No. | F7: Tgl | G7: Kas/Bank | H7: Utang Usaha | I7: Utang Non Usaha
G8: 11.01.00 | H8: 50.01.00 | I8: 50.02.00
A9: 05 Jan | B9: 01 | C9: =A9 -> 05 Jan | D9: Pemby. Service Mobil Avanza KH 1252 PU | G9: =H9 -> 0 | H9: =DVUD!K9 -> 0
B10: 02 | C10: =A10 -> 0 | D10: Pembuatan Spanduk untuk Pemberitahuan Operasional Pelayanan Air 24 Jam di Unit IKK Pembuang Hulu | G10: =H10 -> 0 | H10: =DVUD!K10 -> 0
B11: 03 | C11: =A11 -> 0 | D11: Pemby. Biaya Perpanjangan STNK Mobil PICK UP KH 8088 PW | G11: =H11 -> 0 | H11: =DVUD!K11 -> 0
B12: 04 | C12: =A12 -> 0 | D12: Pembelian Pulsa Listrik Bagian Kantor dan Loket Pembayaran | G12: =H12 -> 0 | H12: =DVUD!K12 -> 0
B13: 05 | C13: =A13 -> 0 | D13: Pembelian Paket Internet Kantor, IKK Kartika Bhakti, IKK Hanau, Tanjung Paring, Mulyono | G13: =H13 -> 0 | H13: =DVUD!K13 -> 0
B14: 06 | C14: =A14 -> 0 | D14: Pemby. Rekening Telepon/HP/Fax | G14: =H14 -> 0 | H14: =DVUD!K14 -> 0
B15: 07 | C15: =A15 -> 0 | D15: Klaim Belanja melalui Kas Kecil IKK PEMBUANG HULU | G15: =H15 -> 0 | H15: =DVUD!K15 -> 0
A16: 08 Jan | B16: 08 | C16: =A16 -> 08 Jan | D16: Pembelian Pulsa Listrik Bagian Kantor | G16: =H16 -> 0 | H16: =DVUD!K16 -> 0
B17: 09 | C17: =A17 -> 0 | D17: Pembay. Pembuatan Spanduk dan Brosur Kenaikan Tarif | G17: =H17 -> 0 | H17: =DVUD!K17 -> 0
A18: 12 Jan | B18: 10 | C18: =A18 -> 12 Jan | D18: Klaim Belanja Melalui Kas Kecil IKK Pembuang Hulu. | G18: =H18 -> 0 | H18: =DVUD!K18 -> 0
A19: 13 Jan | B19: 11 | C19: =A19 -> 13 Jan | D19: Pembelian Materai @10.000 | G19: =H19 -> 0 | H19: =DVUD!K19 -> 0
B20: 12 | C20: =A20 -> 0 | D20: Pembayaran Pajak Air Permukaan & Biaya Kirim Periode Bulan Desember 2025 | G20: =H20 -> 0 | H20: =DVUD!K20 -> 0
B21: 13 | C21: =A21 -> 0 | D21: Pembayaran PPH 21 Gaji Bulan Desember dan Uang Cuti Tahun 2025 | G21: =H21 -> 0 | H21: =DVUD!K21 -> 0
A22: 14 Jan | B22: 14 | C22: =A22 -> 14 Jan | D22: Pembayaran Listrik Sumber Air | G22: =H22 -> 0 | H22: =DVUD!K22 -> 0
B23: 15 | C23: =A23 -> 0 | D23: Pembayaran Listrik Sumber Air IKK Pembuang Hulu (Hanau) | G23: =H23 -> 0 | H23: =DVUD!K23 -> 0
B24: 16 | C24: =A24 -> 0 | D24: Pembayaran Listrik PLN Sumber Air IKK Kartika Bhakti (Kartika Bhakti) | G24: =H24 -> 0 | H24: =DVUD!K24 -> 0
B25: 17 | C25: =A25 -> 0 | D25: Pemby. Iuran BPJS Kesehatan | G25: =H25 -> 0 | H25: =DVUD!K25 -> 0
C26: =A26 -> 0 | G26: =H26 -> 0 | H26: =DVUD!K26 -> 0
C27: =A27 -> 0 | G27: =H27 -> 0 | H27: =DVUD!K27 -> 0
B28: 18 | C28: =A28 -> 0 | D28: Pembay. Iuan Anggota Biasa PERPAMSI Bulan Januari 2026 | G28: =H28 -> 0 | H28: =DVUD!K28 -> 0
B29: 19 | C29: =A29 -> 0 | D29: Pemb. Pulsa Listrik Bagian Kantor | G29: =H29 -> 0 | H29: =DVUD!K29 -> 0
A30: 15 Jan | B30: 20 | C30: =A30 -> 15 Jan | D30: Pemby. Biaya Perpanjangan STNK Motor KH 2251 PI, KH 4995 Pg, dan Mobil Avanza KH 1252 PU | G30: =H30 -> 0 | H30: =DVUD!K30 -> 0
B31: 21 | C31: =A31 -> 0 | D31: Pemby. ATK IKK Pembuang Hulu | G31: =H31 -> 0 | H31: =DVUD!K31 -> 0
B32: 22 | C32: =A32 -> 0 | D32: Pemby. SPPD a.n Hariono dn Hengky Muklis Samitra ke Kuala Pembuang | G32: =H32 -> 0 | H32: =DVUD!K32 -> 0
B33: 23 | C33: =A33 -> 0 | D33: Klaim Belanja melalui Kas Kecil Bag. Administrasi Umum | G33: =H33 -> 0 | H33: =DVUD!K33 -> 0
A34: 19 Jan | B34: 24 | C34: =A34 -> 19 Jan | D34: Pemby. Perbaikan Pompa Intake 7,5 KW / 10 HP IKK Kartika Bhakti | G34: =H34 -> 0 | H34: =DVUD!K34 -> 0
B35: 25 | C35: =A35 -> 0 | D35: Pemby. Biaya Pengantaran Pompa Intake Kota Kuala Pembuang dan IKK Kartika Bhakti | G35: =H35 -> 0 | H35: =DVUD!K35 -> 0
B36: 26 | C36: =A36 -> 0 | D36: Pemby. Service Mobil Pick Up KH 8088 PW (IKK Pembuang Hulu) | G36: =H36 -> 0 | H36: =DVUD!K36 -> 0
B37: 27 | C37: =A37 -> 0 | D37: Pemby. SPPD a.n. Agus Saputra dan Khusnul Siti Hatimah ke Kuala Pembuang | G37: =H37 -> 0 | H37: =DVUD!K37 -> 0
B38: 28 | C38: =A38 -> 0 | D38: Pemby. Service Mobil Avanza KH 1252 PU | G38: =H38 -> 0 | H38: =DVUD!K38 -> 0
B39: 29 | C39: =A39 -> 0 | D39: Pemb. Pulsa Listrik Bagian Kantor | G39: =H39 -> 0 | H39: =DVUD!K39 -> 0
A40: 20 Jan | B40: 30 | C40: =A40 -> 20 Jan | D40: Pemby. Pembuatan Karangan Bunga | G40: =H40 -> 0 | H40: =DVUD!K40 -> 0
B41: 31 | C41: =A41 -> 0 | D41: Pemby. Honorarium Tim Penguji dan Sekretariat Pelaksanaan Job Fit di Lingkungan Perusahaan Umum Daerah Air Minum Tirta Seruyan Berdasarkan Keputusan Direktur 71 Tahun 2025 Tanggal 29 Desember 2025 | G41: =H41 -> 0 | H41: =DVUD!K41 -> 0
...

Sheet JPBIK
A1: PERUSAHAAN DAERAH AIR MINUM
A2: KABUPATEN SERUYAN
A3: Jalan : Soekarno-Hatta No. Telp (0538) 2706777 Fax (0538) 21815
A4: JURNAL PEMAKAIAN BAHAN INSTALASI DAN BAHAN KIMIA
A5: BULAN JANUARI
A7: Tgl | B7: Kode Perkiraan | C7: Uraian | E7: Debet | F7: Kredit
A9: 31 Jan | B9: 93.02.30 | C9: B. Pemeliharaan Tran dist
B10: 93.02.30 | C10: B. Pemeliharaan Tran dist (HANAU)
B11: 93.02.30 | C11: B. Pemeliharaan Tran dist (KARTIKA BHAKTI)
B12: 93.02.60 | C12: B. Pemeliharaan Water Meter 12
B13: 93.02.60 | C13: B. Pemeliharaan Water Meter 4 (HANAU)
B14: 93.02.60 | C14: B. Pemeliharaan Water Meter 0 (K. BHAKTI)
B15: 96.00.00 | C15: B. Harga Pokok Sambungan Baru 17 SR
B16: 15.03.00 | D16: Persediaan Bahan Instalasi | F16: =SUM(E9:E15) -> 0
A18: =A9 -> 31 Jan | B18: 92.02.10 | C18: Pemakaian Bahan Kimia -Tawas
B19: 92.02.10 | C19: Pemakaian Bahan Kimia - Soda Ash
B20: 92.02.10 | C20: Pemakaian Bahan Kimia - Kaporit
B21: 92.02.10 | C21: Pemakaian Bahan Kimia - Magnoflog
B22: 15.01.00 | D22: Persediaan Bahan Kimia | F22: =SUM(E18:E21) -> 0
A24: =A18 -> 31 Jan | B24: 92.02.10 | C24: Pemakaian Bahan Kimia -Tawas
B25: 92.02.10 | C25: Pemakaian Bahan Kimia - Soda Ash
B26: 92.02.10 | C26: Pemakaian Bahan Kimia - Kaporit
B27: 92.02.10 | C27: Pemakaian Bahan Kimia - Magnoflog
B28: 15.01.00 | D28: Persediaan Bahan Kimia - (P. HULU) | F28: =SUM(E24:E27) -> 0
A30: =A24 -> 31 Jan | B30: 92.02.10 | C30: Pemakaian Bahan Kimia -Tawas
B31: 92.02.10 | C31: Pemakaian Bahan Kimia - Soda Ash
B32: 92.02.10 | C32: Pemakaian Bahan Kimia - Kaporit
B33: 92.02.10 | C33: Pemakaian Bahan Kimia - Magnoflog
B34: 15.01.00 | D34: Persediaan Bahan Kimia (IKK K. BHAKTI) | F34: =SUM(E30:E33) -> 0
A36: =A18 -> 31 Jan | B36: 91.01.20 | C36: Pemakaian Bahan Bakar Sumber Air
B37: 15.02.20 | D37: Persediaan Bahan Bakar dan Minyak Pelumas | F37: =E36 -> 0
E40: =SUM(E8:E38) -> 0 | F40: =SUM(F8:F38) -> 0
A51: PERUSAHAAN DAERAH AIR MINUM
A52: KABUPATEN SERUYAN
A53: Jalan : Soekarno-Hatta No. Telp (0538) 2706777 Fax (0538) 21815
A54: JURNAL PEMAKAIAN BAHAN INSTALASI DAN BAHAN KIMIA
A55: BULAN FEBRUARI
A57: Tgl | B57: Kode Perkiraan | C57: Uraian | E57: Debet | F57: Kredit
A59: 28 Feb | B59: 93.02.30 | C59: B. Pemeliharaan Tran dist
B60: 93.02.30 | C60: B. Pemeliharaan Tran dist (HANAU)
...

Sheet JP
A1: PERUSAHAAN DAERAH AIR MINUM
A2: KABUPATEN SERUYAN
A3: Jalan : Soekarno-Hatta No. Telp (0538) 2706777 Fax (0538) 21815
A5: JOURNAL PENYESUAIAN (JP)
A6: BULAN : JANUARI 2026
A8: TGL | B8: NO. PERK | C8: NAMA PERKIRAAN | F8: DEBET | G8: KREDIT
A10: 46081 | B10: 50.03.00 | C10: Beban Yang Masih Harus Dibayar
B11: 96.01.50 | D11: Beban Air Baku (Pajak Air Permukaan)
C12: ( Koreksi atas Utang Pajak Air Permukaan Des 25 pada saat transaksi pemby tgl 13 Feb diakui sebagai beban kembali )
A14: 28 Feb | B14: 50.03.00 | C14: Beban Yang Masih Harus Dibayar
B15: 97.01.90 | D15: Rupa-rupa Beban Pegawai
C16: (Koreksi atas Utang PPH 21 Pegawai Des 25 pada saat transaksi pembay tgl 13 Feb diakui sebagai beban kembali)
A18: JUMLAH | F18: =SUM(F10:F15) -> 0 | G18: =SUM(G10:G15) -> 0
A64: PERUSAHAAN DAERAH AIR MINUM
A65: KABUPATEN SERUYAN
A66: Jalan : Soekarno-Hatta No. Telp (0538) 2706777 Fax (0538) 21815
A68: JOURNAL PENYESUAIAN (JP)
A69: BULAN : DESEMBER 2025
A71: TGL | B71: NO. PERK | C71: NAMA PERKIRAAN | F71: DEBET | G71: KREDIT
A73: 31 Des | B73: 97.01.90 | C73: Rupa-rupa Biaya Pegawai
B74: 97.01.20 | D74: Beban Kesejahteraan Karyawan | G74: =F73 -> 0
C75: ( Koreksi atas biaya tersebut karena insentif dipot pph 21 sehingga atas potongan pajak tsb seharusnya masuk beban PPh 21 )
A79: JUMLAH | F79: =SUM(F73:F78) -> 0 | G79: =SUM(G73:G78) -> 0

Sheet J. Pemblk
A1: PERUSAHAAN DAERAH AIR MINUM
A2: KABUPATEN SERUYAN
A3: Jalan : Soekarno-Hatta No. Telp (0538) 2706777 Fax (0538) 21815
A5: JOURNAL PEMBALIK
A6: BULAN : JANUARI 2019
A8: No | B8: Tgl | C8: Uraian | E8: Ref. | F8: Debet | G8: Kredit
A10: 1 | B10: 1 Jan | C10: Beban Operasi Pengolahan Air (Tawas) | E10: JP '18 | F10: 107317500
C11: Beban Operasi Pengolahan Air (Kaporit) | E11: =E10 -> JP '18 | F11: 7112000
C12: Beban Operasi Pengolahan Air (Soda Ash) | E12: =E11 -> JP '18 | F12: 44280000
D13: Persediaan Bahan Kimia | E13: =E12 -> JP '18 | G13: =SUM(F10:F12) -> 158709500
B15: 1 Jan | C15: Beban ATK & Barang Cetakkan | E15: =E13 -> JP '18 | F15: 681000
D16: Persediaan ATK | E16: =E15 -> JP '18 | G16: =F15 -> 681000
A18: JUMLAH | F18: =SUM(F10:F17) -> 159390500 | G18: =SUM(G10:G17) -> 159390500
A50: PERUSAHAAN DAERAH AIR MINUM
A51: KABUPATEN SERUYAN
A52: Jalan : Soekarno-Hatta No. Telp (0538) 2706777 Fax (0538) 21815
A54: JOURNAL PEMBALIK
A55: BULAN : FEBRUARI 2019
A57: No | B57: Tgl | C57: Uraian | E57: Ref. | F57: Debet | G57: Kredit
A59: 1 | B59: 1 Feb | C59: Beban Operasi Pengolahan Air (Tawas) | E59: JP 'Jan | F59: =JP!#REF! -> #REF!
C60: Beban Operasi Pengolahan Air (Kaporit) | E60: JP 'Jan | F60: =JP!#REF! -> #REF!
C61: Beban Operasi Pengolahan Air (Soda Ash) | E61: JP 'Jan | F61: =JP!#REF! -> #REF!
D62: Persediaan Bahan Kimia | E62: JP 'Jan | G62: =JP!#REF! -> #REF!
A66: JUMLAH | F66: =SUM(F59:F65) -> #REF! | G66: =SUM(G59:G65) -> #REF!
A100: PERUSAHAAN DAERAH AIR MINUM
A101: KABUPATEN SERUYAN
A102: Jalan : Soekarno-Hatta No. Telp (0538) 2706777 Fax (0538) 21815
A104: JOURNAL PEMBALIK
A105: BULAN : MARET 2019
A107: No | B107: Tgl | C107: Uraian | E107: Ref. | F107: Debet | G107: Kredit
A109: 1 | B109: 1 Maret | C109: Beban Operasi Pengolahan Air (Tawas) | E109: JP 'FEB | F109: =JP!#REF! -> #REF!
C110: Beban Operasi Pengolahan Air (Kaporit) | E110: JP 'FEB | F110: =JP!#REF! -> #REF!
C111: Beban Operasi Pengolahan Air (Soda Ash) | E111: JP 'FEB | F111: =JP!#REF! -> #REF!
D112: Persediaan Bahan Kimia | E112: JP 'FEB | G112: =JP!#REF! -> #REF!
A117: JUMLAH | F117: =SUM(F109:F116) -> #REF! | G117: =SUM(G109:G116) -> #REF!
A150: PERUSAHAAN DAERAH AIR MINUM
A151: KABUPATEN SERUYAN
A152: Jalan : Soekarno-Hatta No. Telp (0538) 2706777 Fax (0538) 21815
A154: JOURNAL PEMBALIK
A155: BULAN : APRIL 2019
...

Sheet DUVHD
A1: PERUSAHAAN DAERAH AIR MINUM
A3: DAFTAR UTANG VOUCER YANG HARUS DIBAYAR (DUVHD)
A4: BULAN JANUARI 2012
A6: VOUCER | C6: URAIAN | D6: DIBAYAR | F6: PERKIRAAN DI KREDIT | H6: PERKIRAAN DI DEBET
A7: TGL | B7: NO | D7: TGL | E7: CEK/GIRO NO. | F7: UTANG | H7: PERSEDIAN | I7: BAHAN | J7: UANG MUKA | K7: BOP | L7: BOP | M7: BOP | N7: BIAYA UMUM & ADM | P7: RUPA-RUPA
F8: USAHA | G8: NON USAHA | H8: BHN. KIMIA | I8: INSTALASI | J8: KERJA | K8: SUMBER | L8: PENGOLAHAN | M8: DISTRIBUSI | N8: B. KANTOR | O8: B. HUB.PEL | P8: KD. PERKIRAAN | Q8: JUMLAH
F9: (50.01.00) | G9: (50.02.00) | H9: (15.00.01) | I9: (41.02.00) | J9: (16.02.00) | K9: (91.01.00) | L9: (92.01.00) | M9: (93.01.00) | N9: (96.02.00) | O9: (96.03.00)

Sheet J.Koreksi
A1: PERUSAHAAN DAERAH AIR MINUM
A2: KABUPATEN SERUYAN
A3: Jalan : Soekarno-Hatta No. Telp (0538) 2706777 Fax (0538) 21815
A4: JOURNAL KOREKSI
A5: BULAN : JANUARI 2020
A7: No | B7: Tgl | C7: Uraian | E7: Ref. | F7: Debet | G7: Kredit
B9: 81.01.10 | C9: Pendapatan Air-Harga Air
B10: 13.01.11 | D10: Piutang Rek Air - Tempat Ibadah (TI)
A21: JUMLAH | F21: =SUM(F8:F19) -> 0 | G21: =SUM(G8:G19) -> 0

Sheet BKU

Sheet BKU PM

Sheet JRNA
A1: PERUSAHAAN DAERAH AIR MINUM
A2: KABUPATEN SERUYAN
A3: Jalan : Soekarno-Hatta No. Telp (0538) 2706777 Fax (0538) 21815
A4: JOURNAL REKENING NON AIR (JRNA)
A5: BULAN : JANUARI 2020
A7: TGL | B7: NO. PERK | C7: NAMA PERKIRAAN | E7: LEMBAR | F7: Debet | G7: Kredit
A9: 31 Jan | C9: Piutang Non Air
B10: 81.02.10 | D10: Pendapatan Non Air - Samb. Baru
B11: 81.02.70 | D11: Pendapatan Non Air - Penggantian Meter Rusak
B12: 81.02.80 | D12: Pendapatan Non Air- Penggantian Pipa Persil
G26: =F25 -> 0
A29: JUMLAH | F29: =SUM(F9:F27) -> 0 | G29: =SUM(G9:G27) -> 0
